Workbook

Sheet Criteria & Weight
A1: Performance Evaluation Criteria & Weightage: FF | G1: Performance Evaluation Criteria & Weightage: DM | L1: Performance Evaluation Criteria & Weightage: RSM/ZSM/AGM
A3: Criteria | B3: Weightage | C3: Details | D3: Evaluation Period | G3: Criteria | H3: Weightage | I3: Details | J3: Evaluation Period | L3: Criteria | M3: Weightage | N3: Details | O3: Evaluation Period
A4: Sales Ach | B4: 30 | D4: Jul'25-Mar'26 | G4: Sales Ach | H4: 20 | J4: Jul'25-Mar'26 | L4: Sales Ach | M4: 20 | O4: Jul'25-Mar'26
A5: SKU/Unit Achievement | B5: 10 | D5: Jul'25-Mar'26 | G5: Unit Achievement | H5: 10 | J5: Jul'25-Mar'26 | L5: SKU/Unit Achievement | M5: 10 | O5: Jul'25-Mar'26
A6: New Product Ach | B6: 10 | D6: Jul'25-Mar'26 | G6: New Product Ach | H6: 10 | J6: Jul'25-Mar'26 | L6: New Product Ach | M6: 10 | O6: Jul'25-Mar'26
A7: Brand Basket Achivement | B7: 12 | D7: Jul'25-Mar'26 | G7: Brand Basket Achivement | H7: 13 | J7: Jul'25-Mar'26 | L7: Brand Basket Achivement | M7: 12 | O7: Jul'25-Mar'26
A8: Number of month achieved | B8: 7 | D8: Jul'25-Mar'26 | F8: For DMs without Synkei Territories | G8: Number of month achieved | H8: 6 | J8: Jul'25-Mar'26 | L8: Territory Month Ach | M8: 7 | O8: Jul'25-Mar'26
A9: Count Rx share | B9: 15 | C9: Insufficient Rx sample (Min 33 market Rx) considered | D9: Jul'25-Mar'26 | G9: Territory Month Ach | H9: 8 | J9: Jul'25-Mar'26 | L9: Number of month achieved | M9: 4 | O9: Jul'25-Mar'26
A10: Call Ach. | B10: 5 | C10: Best 9 months avg, Achv above 105% considered as 105% | D10: Jul'25-Nov'25 | G10: Or, | L10: Portoflio Ach. Month at 95% | M10: 4 | O10: Jul'25-Mar'26
A11: Written Test | B11: 8 | C11: Average of attended test results | D11: Jul'25-Nov'25 | F11: For DMs with Synkei Territories | G11: Number of month achieved | H11: 5 | J11: Jul'25-Mar'26 | L11: New Product Rx Share | M11: 5 | O11: Jul'25-Mar'26
A12: Detailing Test | B12: 3 | C12: Average of attended test results | D12: Jul'25-Nov'25 | G12: Territory Month Ach | H12: 5 | J12: Jul'25-Mar'26 | L12: SYNDIVA Rx Share | M12: 6 | N12: Insufficient Rx sample (Min 33 market Rx) considered | O12: Jul'25-Mar'26
A13: Qualitative | B13: 0 | G13: Synkei Portfolio Ach | H13: 4 | J13: Jul'25-Mar'26 | L13: SYNGENA Rx Share | M13: 6 | N13: Insufficient Rx sample (Min 33 market Rx) considered | O13: Jul'25-Mar'26
A14: Total | B14: =SUM(B4:B13) -> 100 | G14: Call Ach. | H14: 5 | I14: Best 9 months avg, Achv above 105% considered as 105% | J14: Jul'25-Mar'26 | L14: SYNKEI Rx Share | M14: 4 | N14: Insufficient Rx sample (Min 33 market Rx) considered | O14: Jul'25-Mar'26
G15: DM Coaching | H15: 0 | I15: Best 6 months avg, Achv above 120% considered as 120% | J15: Jul'25-Mar'26 | L15: Call Ach. | M15: 5 | N15: Best 9 months avg, Achv above 105% considered as 105% | O15: Jul'25-Mar'26
A16: *Rx not considered for Syncovax SFs | G16: Written Test | H16: 7 | I16: Average of attended test results | J16: Jul'25-Nov'25 | L16: DM Coaching | M16: 0 | O16: Jul'25-Mar'26
A17: * Any DM having most number of months(6+) working as FF, is considered in FF evaluation | G17: Own WT | H17: 3 | I17: Average of attended test results | J17: Jul'25-Nov'25 | L17: Written Test | M17: 7 | N17: Average of attended test results (DM+FF) | O17: Jul'25-Nov'25
G18: Detailing Test | H18: 3 | I18: Average of attended test results | J18: Jul'25-Nov'25 | L18: Detailing Test | M18: 0 | N18: Average of attended test results | O18: Jul'25-Nov'25
G19: Rx share | H19: 15 | I19: Insufficient Rx sample (Min 33 market Rx) considered | J19: Jul'25-Mar'26 | L19: Qualitative | M19: 0
G20: Qualitative | H20: 0 | L20: Total | M20: =SUM(M4:M19) -> 100
G21: Total | H21: =SUM(H4:H20)-H11-H12-H13 -> 100

Sheet SM
A1: Performance Evaluation: RSM/ZSM/AGM | K1: Performance Summary | R1: 6 | S1: 6 | T1: 4 | U1: 6 | AB1: Performance Rating | AI1: 6 | AJ1: 6 | AK1: 4 | AL1: 6
K2: 20 | L2: 8 | M2: 7 | N2: 8 | O2: 5 | P2: 4 | Q2: 4 | R2: RX Share Achv | V2: 5 | W2: 3 | X2: 7 | Y2: 3 | Z2: 10 | AB2: 20 | AC2: 8 | AD2: 7 | AE2: 8 | AF2: 5 | AG2: 4 | AH2: 4 | AI2: RX Share Achv | AM2: 5 | AN2: 3 | AO2: 7 | AP2: 3 | AS2: Special Award Data | AY2: Category wise Ranking
A3: SL | B3: Empl Code | C3: Employee Name | D3: Designation | E3: Region | F3: Zone | G3: Division | H3: Joining Date SBL | I3: Status | J3: # month as DM | K3: Sales Ach | L3: SKU/Unit Achievement | M3: New Product Ach | N3: Brand Basket Achivement | O3: Territory Month Ach | P3: Number of month achieved | Q3: Portoflio Ach. Month at 95% | R3: INSYN | S3: SYNGENA | T3: SYNKEI | U3: SYNTARA | V3: Call Ach. | W3: DM Coaching | X3: Written Test | Y3: Detailing Test | Z3: Qualitative | AA3: 0 | AB3: Sales Ach | AC3: SKU/Unit Achievement | AD3: New Product Ach | AE3: Brand Basket Achivement | AF3: Territory Month Ach | AG3: Number of month achieved | AH3: Portoflio Ach. Month at 95% | AI3: INSYN | AJ3: SYNGENA | AK3: SYNKEI | AL3: SYNTARA | AM3: Call Ach. | AN3: DM Coaching | AO3: Written Test | AP3: Detailing Test | AQ3: Weighted Average Rating | AR3: National Rank | AS3: Best Rx Drive | AT3: Best New Product Builder | AU3: Best SKU Achiever | AV3: Best Written Scorer | AW3: Best Territory Month Achiever | AX3: Consistent Call Budget Achiever | AY3: Best Rx Drive | AZ3: Best New Product Builder | BA3: Best SKU Achiever | BB3: Best Written Scorer | BC3: Best Territory Month Achiever | BD3: Consistent Call Budget Achiever
B4: 104661 | C4: Md Atikur Rahman | D4: RSM | E4: Khulna | F4: SYGK Dhaka Zone-2 | G4: Foundation SD | H4: 33993 | I4: Regular | J4: 9 | K4: 77.793146 | L4: 27.272727 | M4: 69.373314 | N4: 76.396987 | O4: 7.3033708 | P4: 0 | Q4: 0 | R4: 0 | S4: 79.374821 | T4: 151.02481 | U4: 0 | V4: 79.205903 | W4: 90.425532 | X4: 73.970588 | Y4: 78.960784 | Z4: 1 | AB4: =IF(K4>='Sales Ach'!L$3,'Sales Ach'!M$3,IF(K4>='Sales Ach'!L$4,('Sales Ach'!M$4+((K4-'Sales Ach'!L$4)/('Sales Ach'!L$3-'Sales Ach'!L$4))*'Sales Ach'!N$4),IF(K4>'Sales Ach'!L$5,('Sales Ach'!M$5+((K4-'Sales Ach'!L$5)/('Sales Ach'!L$4-'Sales Ach'!L$5))*'Sales Ach'!N$5),IF(K4>='Sales Ach'!L$6,('Sales Ach'!M$6+((K4-'Sales Ach'!L$6)/('Sales Ach'!L$5-'Sales Ach'!L$6)*'Sales Ach'!N$6)),0))))*$AB$2/10 -> 6.5586293 | AC4: =IF(L4>=UA!L$3,UA!M$3,IF(L4>=UA!L$4,(UA!M$4+((L4-UA!L$4)/(UA!L$3-UA!L$4))*UA!N$4),IF(L4>UA!L$5,(UA!M$5+((L4-UA!L$5)/(UA!L$4-UA!L$5))*UA!N$5),IF(L4>=UA!L$6,(UA!M$6+((L4-UA!L$6)/(UA!L$5-UA!L$6)*UA!N$6)),0))))*$AC$2/10 -> 0 | AD4: =IF(M4="","",(IF(M4>='New Product'!L$3,'New Product'!M$3,IF(M4>='New Product'!L$4,('New Product'!M$4+((M4-'New Product'!L$4)/('New Product'!L$3-'New Product'!L$4))*'New Product'!N$4),IF(M4>'New Product'!L$5,('New Product'!M$5+((M4-'New Product'!L$5)/('New Product'!L$4-'New Product'!L$5))*'New Product'!N$5),IF(M4>='New Product'!L$6,('New Product'!M$6+((M4-'New Product'!L$6)/('New Product'!L$5-'New Product'!L$6)*'New Product'!N$6)),0))))*$AD$2/10)) -> 2.1491155 | AE4: =IF(N4>='Basket Brand'!L$3,'Basket Brand'!M$3,IF(N4>='Basket Brand'!L$4,('Basket Brand'!M$4+((N4-'Basket Brand'!L$4)/('Basket Brand'!L$3-'Basket Brand'!L$4))*'Basket Brand'!N$4),IF(N4>'Basket Brand'!L$5,('Basket Brand'!M$5+((N4-'Basket Brand'!L$5)/('Basket Brand'!L$4-'Basket Brand'!L$5))*'Basket Brand'!N$5),IF(N4>='Basket Brand'!L$6,('Basket Brand'!M$6+((N4-'Basket Brand'!L$6)/('Basket Brand'!L$5-'Basket Brand'!L$6)*'Basket Brand'!N$6)),0))))*$AE$2/10 -> 2.511759 | AF4: =IF(O4>='Territory Month'!G$3,'Territory Month'!H$3,IF(O4>='Territory Month'!G$4,('Territory Month'!H$4+((O4-'Territory Month'!G$4)/('Territory Month'!G$3-'Territory Month'!G$4))*'Territory Month'!I$4),IF(O4>'Territory Month'!G$5,('Territory Month'!H$5+((O4-'Territory Month'!G$5)/('Territory Month'!G$4-'Territory Month'!G$5))*'Territory Month'!I$5),IF(O4>='Territory Month'!G$6,('Territory Month'!H$6+((O4-'Territory Month'!G$6)/('Territory Month'!G$5-'Territory Month'!G$6)*'Territory Month'!I$6)),0))))*$AF$2/10 -> 0 | AG4: =IF(P4>='No of Month Ach.'!L$3,'No of Month Ach.'!M$3,IF(P4>='No of Month Ach.'!L$4,('No of Month Ach.'!M$4+((P4-'No of Month Ach.'!L$4)/('No of Month Ach.'!L$3-'No of Month Ach.'!L$4))*'No of Month Ach.'!N$4),IF(P4>'No of Month Ach.'!L$5,('No of Month Ach.'!M$5+((P4-'No of Month Ach.'!L$5)/('No of Month Ach.'!L$4-'No of Month Ach.'!L$5))*'No of Month Ach.'!N$5),IF(P4>='No of Month Ach.'!L$6,('No of Month Ach.'!M$6+((P4-'No of Month Ach.'!L$6)/('No of Month Ach.'!L$5-'No of Month Ach.'!L$6)*'No of Month Ach.'!N$6)),0))))*$AG$2/10 -> 0 | AH4: =IF(Q4>='Portfolio Ach.'!B$3,'Portfolio Ach.'!C$3,IF(Q4>='Portfolio Ach.'!B$4,('Portfolio Ach.'!C$4+((Q4-'Portfolio Ach.'!B$4)/('Portfolio Ach.'!B$3-'Portfolio Ach.'!B$4))*'Portfolio Ach.'!D$4),IF(Q4>'Portfolio Ach.'!B$5,('Portfolio Ach.'!C$5+((Q4-'Portfolio Ach.'!B$5)/('Portfolio Ach.'!B$4-'Portfolio Ach.'!B$5))*'Portfolio Ach.'!D$5),IF(Q4>='Portfolio Ach.'!B$6,('Portfolio Ach.'!C$6+((Q4-'Portfolio Ach.'!B$6)/('Portfolio Ach.'!B$5-'Portfolio Ach.'!B$6)*'Portfolio Ach.'!D$6)),0))))*$AH$2/10 -> 0 | AI4: =IF(R4="","",IF(R4>='Rx Share'!L$3,'Rx Share'!M$3,IF(R4>='Rx Share'!L$4,('Rx Share'!M$4+((R4-'Rx Share'!L$4)/('Rx Share'!L$3-'Rx Share'!L$4))*'Rx Share'!N$4),IF(R4>'Rx Share'!L$5,('Rx Share'!M$5+((R4-'Rx Share'!L$5)/('Rx Share'!L$4-'Rx Share'!L$5))*'Rx Share'!N$5),IF(R4>='Rx Share'!L$6,('Rx Share'!M$6+((R4-'Rx Share'!L$6)/('Rx Share'!L$5-'Rx Share'!L$6)*'Rx Share'!N$6)),0)))))*$AI$1/10 -> 0 | AJ4: =IF(S4="","",IF(S4>='Rx Share'!L$3,'Rx Share'!M$3,IF(S4>='Rx Share'!L$4,('Rx Share'!M$4+((S4-'Rx Share'!L$4)/('Rx Share'!L$3-'Rx Share'!L$4))*'Rx Share'!N$4),IF(S4>'Rx Share'!L$5,('Rx Share'!M$5+((S4-'Rx Share'!L$5)/('Rx Share'!L$4-'Rx Share'!L$5))*'Rx Share'!N$5),IF(S4>='Rx Share'!L$6,('Rx Share'!M$6+((S4-'Rx Share'!L$6)/('Rx Share'!L$5-'Rx Share'!L$6)*'Rx Share'!N$6)),0)))))*$AJ$1/10 -> 3.5249785 | AK4: =IF(T4="","",IF(T4>='Rx Share'!L$3,'Rx Share'!M$3,IF(T4>='Rx Share'!L$4,('Rx Share'!M$4+((T4-'Rx Share'!L$4)/('Rx Share'!L$3-'Rx Share'!L$4))*'Rx Share'!N$4),IF(T4>'Rx Share'!L$5,('Rx Share'!M$5+((T4-'Rx Share'!L$5)/('Rx Share'!L$4-'Rx Share'!L$5))*'Rx Share'!N$5),IF(T4>='Rx Share'!L$6,('Rx Share'!M$6+((T4-'Rx Share'!L$6)/('Rx Share'!L$5-'Rx Share'!L$6)*'Rx Share'!N$6)),0)))))*$AK$1/10 -> 4 | AL4: =IF(U4="","",IF(U4>='Rx Share'!M$3,'Rx Share'!N$3,IF(U4>='Rx Share'!M$4,('Rx Share'!N$4+((U4-'Rx Share'!M$4)/('Rx Share'!M$3-'Rx Share'!M$4))*'Rx Share'!O$4),IF(U4>'Rx Share'!M$5,('Rx Share'!N$5+((U4-'Rx Share'!M$5)/('Rx Share'!M$4-'Rx Share'!M$5))*'Rx Share'!O$5),IF(U4>='Rx Share'!M$6,('Rx Share'!N$6+((U4-'Rx Share'!M$6)/('Rx Share'!M$5-'Rx Share'!M$6)*'Rx Share'!O$6)),0)))))*$AL$1/10 -> 0 | AM4: =IF(V4>='Call Achv'!L$3,'Call Achv'!M$3,IF(V4>='Call Achv'!L$4,('Call Achv'!M$4+((V4-'Call Achv'!L$4)/('Call Achv'!L$3-'Call Achv'!L$4))*'Call Achv'!N$4),IF(V4>'Call Achv'!L$5,('Call Achv'!M$5+((V4-'Call Achv'!L$5)/('Call Achv'!L$4-'Call Achv'!L$5))*'Call Achv'!N$5),IF(V4>='Call Achv'!L$6,('Call Achv'!M$6+((V4-'Call Achv'!L$6)/('Call Achv'!L$5-'Call Achv'!L$6)*'Call Achv'!N$6)),0))))*$AM$2/10 -> 0 | AN4: =IF(W4>='DM Coaching'!G$3,'DM Coaching'!H$3,IF(W4>='DM Coaching'!G$4,('DM Coaching'!H$4+((W4-'DM Coaching'!G$4)/('DM Coaching'!G$3-'DM Coaching'!G$4))*'DM Coaching'!I$4),IF(W4>'DM Coaching'!G$5,('DM Coaching'!H$5+((W4-'DM Coaching'!G$5)/('DM Coaching'!G$4-'DM Coaching'!G$5))*'DM Coaching'!I$5),IF(W4>='DM Coaching'!G$6,('DM Coaching'!H$6+((W4-'DM Coaching'!G$6)/('DM Coaching'!G$5-'DM Coaching'!G$6)*'DM Coaching'!I$6)),0))))*$AN$2/10 -> 3 | AO4: =IF(X4>='FF-Written'!L$3,'FF-Written'!M$3,IF(X4>='FF-Written'!L$4,('FF-Written'!M$4+((X4-'FF-Written'!L$4)/('FF-Written'!L$3-'FF-Written'!L$4))*'FF-Written'!N$4),IF(X4>'FF-Written'!L$5,('FF-Written'!M$5+((X4-'FF-Written'!L$5)/('FF-Written'!L$4-'FF-Written'!L$5))*'FF-Written'!N$5),IF(X4>='FF-Written'!L$6,('FF-Written'!M$6+((X4-'FF-Written'!L$6)/('FF-Written'!L$5-'FF-Written'!L$6)*'FF-Written'!N$6)),0))))*$AO$2/10 -> 6.1558824 | AP4: =IF(Y4>='FF-Detailing'!L$3,'FF-Detailing'!M$3,IF(Y4>='FF-Detailing'!L$4,('FF-Detailing'!M$4+((Y4-'FF-Detailing'!L$4)/('FF-Detailing'!L$3-'FF-Detailing'!L$4))*'FF-Detailing'!N$4),IF(Y4>'FF-Detailing'!L$5,('FF-Detailing'!M$5+((Y4-'FF-Detailing'!L$5)/('FF-Detailing'!L$4-'FF-Detailing'!L$5))*'FF-Detailing'!N$5),IF(Y4>='FF-Detailing'!L$6,('FF-Detailing'!M$6+((Y4-'FF-Detailing'!L$6)/('FF-Detailing'!L$5-'FF-Detailing'!L$6)*'FF-Detailing'!N$6)),0))))*$AP$2/10 -> 2.4564706 | AQ4: =SUM(AB4:AP4)*100/90 -> 33.729817 | AR4: =_xlfn.RANK.EQ($AQ4,$AQ$4:$AQ$21) -> 15 | AS4: 3.0611938 | AT4: =IFERROR(IF($K4>=99.5,M4,""),"") | AU4: =IFERROR(IF($K4>=99.5,L4,""),"") | AV4: =IFERROR(IF($K4>=99.5,X4,""),"") | AW4: =IFERROR(IF($K4>=99.5,O4,""),"") | AX4: =IFERROR(IF($K4>=99.5,#REF!,""),"") | AY4: =IFERROR(IF($K4>=99.5,_xlfn.RANK.EQ(AS4,AS$4:AS$21),"Disqualified"),"Not eligible") -> Disqualified | AZ4: =IFERROR(IF($K4>=99.5,_xlfn.RANK.EQ(AT4,AT$4:AT$21),"Disqualified"),"Not eligible") -> Disqualified | BA4: =IFERROR(IF($K4>=99.5,_xlfn.RANK.EQ(AU4,AU$4:AU$21),"Disqualified"),"Not eligible") -> Disqualified | BB4: =IFERROR(IF($K4>=99.5,_xlfn.RANK.EQ(AV4,AV$4:AV$21),"Disqualified"),"Not eligible") -> Disqualified | BC4: =IFERROR(IF($K4>=99.5,_xlfn.RANK.EQ(AW4,AW$4:AW$21),"Disqualified"),"Not eligible") -> Disqualified | BD4: =IFERROR(IF($K4>=99.5,_xlfn.RANK.EQ(AX4,AX$4:AX$21),"Disqualified"),"Not eligible") -> Disqualified
B5: 104706 | C5: Md. Mustafizur Rahman | D5: RSM | E5: Dhaka-4 | F5: SYGK Dhaka Zone-2 | G5: Foundation SD | H5: 36192 | I5: Regular | J5: 9 | K5: 90.79481 | L5: 17.087156 | M5: 59.49993 | N5: 96.267885 | O5: 29.856115 | P5: 0 | Q5: 0 | R5: 0 | S5: 58.515427 | T5: 125.21589 | U5: 0 | V5: 73.489283 | W5: 59.74026 | X5: 74.541826 | Y5: 88.761494 | Z5: 1 | AB5: =IF(K5>='Sales Ach'!L$3,'Sales Ach'!M$3,IF(K5>='Sales Ach'!L$4,('Sales Ach'!M$4+((K5-'Sales Ach'!L$4)/('Sales Ach'!L$3-'Sales Ach'!L$4))*'Sales Ach'!N$4),IF(K5>'Sales Ach'!L$5,('Sales Ach'!M$5+((K5-'Sales Ach'!L$5)/('Sales Ach'!L$4-'Sales Ach'!L$5))*'Sales Ach'!N$5),IF(K5>='Sales Ach'!L$6,('Sales Ach'!M$6+((K5-'Sales Ach'!L$6)/('Sales Ach'!L$5-'Sales Ach'!L$6)*'Sales Ach'!N$6)),0))))*$AB$2/10 -> 9.158962 | AC5: =IF(L5>=UA!L$3,UA!M$3,IF(L5>=UA!L$4,(UA!M$4+((L5-UA!L$4)/(UA!L$3-UA!L$4))*UA!N$4),IF(L5>UA!L$5,(UA!M$5+((L5-UA!L$5)/(UA!L$4-UA!L$5))*UA!N$5),IF(L5>=UA!L$6,(UA!M$6+((L5-UA!L$6)/(UA!L$5-UA!L$6)*UA!N$6)),0))))*$AC$2/10 -> 0 | AD5: =IF(M5="","",(IF(M5>='New Product'!L$3,'New Product'!M$3,IF(M5>='New Product'!L$4,('New Product'!M$4+((M5-'New Product'!L$4)/('New Product'!L$3-'New Product'!L$4))*'New Product'!N$4),IF(M5>'New Product'!L$5,('New Product'!M$5+((M5-'New Product'!L$5)/('New Product'!L$4-'New Product'!L$5))*'New Product'!N$5),IF(M5>='New Product'!L$6,('New Product'!M$6+((M5-'New Product'!L$6)/('New Product'!L$5-'New Product'!L$6)*'New Product'!N$6)),0))))*$AD$2/10)) -> 1.5443707 | AE5: =IF(N5>='Basket Brand'!L$3,'Basket Brand'!M$3,IF(N5>='Basket Brand'!L$4,('Basket Brand'!M$4+((N5-'Basket Brand'!L$4)/('Basket Brand'!L$3-'Basket Brand'!L$4))*'Basket Brand'!N$4),IF(N5>'Basket Brand'!L$5,('Basket Brand'!M$5+((N5-'Basket Brand'!L$5)/('Basket Brand'!L$4-'Basket Brand'!L$5))*'Basket Brand'!N$5),IF(N5>='Basket Brand'!L$6,('Basket Brand'!M$6+((N5-'Basket Brand'!L$6)/('Basket Brand'!L$5-'Basket Brand'!L$6)*'Basket Brand'!N$6)),0))))*$AE$2/10 -> 4.4057232 | AF5: =IF(O5>='Territory Month'!G$3,'Territory Month'!H$3,IF(O5>='Territory Month'!G$4,('Territory Month'!H$4+((O5-'Territory Month'!G$4)/('Territory Month'!G$3-'Territory Month'!G$4))*'Territory Month'!I$4),IF(O5>'Territory Month'!G$5,('Territory Month'!H$5+((O5-'Territory Month'!G$5)/('Territory Month'!G$4-'Territory Month'!G$5))*'Territory Month'!I$5),IF(O5>='Territory Month'!G$6,('Territory Month'!H$6+((O5-'Territory Month'!G$6)/('Territory Month'!G$5-'Territory Month'!G$6)*'Territory Month'!I$6)),0))))*$AF$2/10 -> 0 | AG5: =IF(P5>='No of Month Ach.'!L$3,'No of Month Ach.'!M$3,IF(P5>='No of Month Ach.'!L$4,('No of Month Ach.'!M$4+((P5-'No of Month Ach.'!L$4)/('No of Month Ach.'!L$3-'No of Month Ach.'!L$4))*'No of Month Ach.'!N$4),IF(P5>'No of Month Ach.'!L$5,('No of Month Ach.'!M$5+((P5-'No of Month Ach.'!L$5)/('No of Month Ach.'!L$4-'No of Month Ach.'!L$5))*'No of Month Ach.'!N$5),IF(P5>='No of Month Ach.'!L$6,('No of Month Ach.'!M$6+((P5-'No of Month Ach.'!L$6)/('No of Month Ach.'!L$5-'No of Month Ach.'!L$6)*'No of Month Ach.'!N$6)),0))))*$AG$2/10 -> 0 | AH5: =IF(Q5>='Portfolio Ach.'!B$3,'Portfolio Ach.'!C$3,IF(Q5>='Portfolio Ach.'!B$4,('Portfolio Ach.'!C$4+((Q5-'Portfolio Ach.'!B$4)/('Portfolio Ach.'!B$3-'Portfolio Ach.'!B$4))*'Portfolio Ach.'!D$4),IF(Q5>'Portfolio Ach.'!B$5,('Portfolio Ach.'!C$5+((Q5-'Portfolio Ach.'!B$5)/('Portfolio Ach.'!B$4-'Portfolio Ach.'!B$5))*'Portfolio Ach.'!D$5),IF(Q5>='Portfolio Ach.'!B$6,('Portfolio Ach.'!C$6+((Q5-'Portfolio Ach.'!B$6)/('Portfolio Ach.'!B$5-'Portfolio Ach.'!B$6)*'Portfolio Ach.'!D$6)),0))))*$AH$2/10 -> 0 | AI5: =IF(R5="","",IF(R5>='Rx Share'!L$3,'Rx Share'!M$3,IF(R5>='Rx Share'!L$4,('Rx Share'!M$4+((R5-'Rx Share'!L$4)/('Rx Share'!L$3-'Rx Share'!L$4))*'Rx Share'!N$4),IF(R5>'Rx Share'!L$5,('Rx Share'!M$5+((R5-'Rx Share'!L$5)/('Rx Share'!L$4-'Rx Share'!L$5))*'Rx Share'!N$5),IF(R5>='Rx Share'!L$6,('Rx Share'!M$6+((R5-'Rx Share'!L$6)/('Rx Share'!L$5-'Rx Share'!L$6)*'Rx Share'!N$6)),0)))))*$AI$1/10 -> 0 | AJ5: =IF(S5="","",IF(S5>='Rx Share'!L$3,'Rx Share'!M$3,IF(S5>='Rx Share'!L$4,('Rx Share'!M$4+((S5-'Rx Share'!L$4)/('Rx Share'!L$3-'Rx Share'!L$4))*'Rx Share'!N$4),IF(S5>'Rx Share'!L$5,('Rx Share'!M$5+((S5-'Rx Share'!L$5)/('Rx Share'!L$4-'Rx Share'!L$5))*'Rx Share'!N$5),IF(S5>='Rx Share'!L$6,('Rx Share'!M$6+((S5-'Rx Share'!L$6)/('Rx Share'!L$5-'Rx Share'!L$6)*'Rx Share'!N$6)),0)))))*$AJ$1/10 -> 1.1941198 | AK5: =IF(T5="","",IF(T5>='Rx Share'!L$3,'Rx Share'!M$3,IF(T5>='Rx Share'!L$4,('Rx Share'!M$4+((T5-'Rx Share'!L$4)/('Rx Share'!L$3-'Rx Share'!L$4))*'Rx Share'!N$4),IF(T5>'Rx Share'!L$5,('Rx Share'!M$5+((T5-'Rx Share'!L$5)/('Rx Share'!L$4-'Rx Share'!L$5))*'Rx Share'!N$5),IF(T5>='Rx Share'!L$6,('Rx Share'!M$6+((T5-'Rx Share'!L$6)/('Rx Share'!L$5-'Rx Share'!L$6)*'Rx Share'!N$6)),0)))))*$AK$1/10 -> 4 | AL5: =IF(U5="","",IF(U5>='Rx Share'!M$3,'Rx Share'!N$3,IF(U5>='Rx Share'!M$4,('Rx Share'!N$4+((U5-'Rx Share'!M$4)/('Rx Share'!M$3-'Rx Share'!M$4))*'Rx Share'!O$4),IF(U5>'Rx Share'!M$5,('Rx Share'!N$5+((U5-'Rx Share'!M$5)/('Rx Share'!M$4-'Rx Share'!M$5))*'Rx Share'!O$5),IF(U5>='Rx Share'!M$6,('Rx Share'!N$6+((U5-'Rx Share'!M$6)/('Rx Share'!M$5-'Rx Share'!M$6)*'Rx Share'!O$6)),0)))))*$AL$1/10 -> 0 | AM5: =IF(V5>='Call Achv'!L$3,'Call Achv'!M$3,IF(V5>='Call Achv'!L$4,('Call Achv'!M$4+((V5-'Call Achv'!L$4)/('Call Achv'!L$3-'Call Achv'!L$4))*'Call Achv'!N$4),IF(V5>'Call Achv'!L$5,('Call Achv'!M$5+((V5-'Call Achv'!L$5)/('Call Achv'!L$4-'Call Achv'!L$5))*'Call Achv'!N$5),IF(V5>='Call Achv'!L$6,('Call Achv'!M$6+((V5-'Call Achv'!L$6)/('Call Achv'!L$5-'Call Achv'!L$6)*'Call Achv'!N$6)),0))))*$AM$2/10 -> 0 | AN5: =IF(W5>='DM Coaching'!G$3,'DM Coaching'!H$3,IF(W5>='DM Coaching'!G$4,('DM Coaching'!H$4+((W5-'DM Coaching'!G$4)/('DM Coaching'!G$3-'DM Coaching'!G$4))*'DM Coaching'!I$4),IF(W5>'DM Coaching'!G$5,('DM Coaching'!H$5+((W5-'DM Coaching'!G$5)/('DM Coaching'!G$4-'DM Coaching'!G$5))*'DM Coaching'!I$5),IF(W5>='DM Coaching'!G$6,('DM Coaching'!H$6+((W5-'DM Coaching'!G$6)/('DM Coaching'!G$5-'DM Coaching'!G$6)*'DM Coaching'!I$6)),0))))*$AN$2/10 -> 2.3688312 | AO5: =IF(X5>='FF-Written'!L$3,'FF-Written'!M$3,IF(X5>='FF-Written'!L$4,('FF-Written'!M$4+((X5-'FF-Written'!L$4)/('FF-Written'!L$3-'FF-Written'!L$4))*'FF-Written'!N$4),IF(X5>'FF-Written'!L$5,('FF-Written'!M$5+((X5-'FF-Written'!L$5)/('FF-Written'!L$4-'FF-Written'!L$5))*'FF-Written'!N$5),IF(X5>='FF-Written'!L$6,('FF-Written'!M$6+((X5-'FF-Written'!L$6)/('FF-Written'!L$5-'FF-Written'!L$6)*'FF-Written'!N$6)),0))))*$AO$2/10 -> 6.2358557 | AP5: =IF(Y5>='FF-Detailing'!L$3,'FF-Detailing'!M$3,IF(Y5>='FF-Detailing'!L$4,('FF-Detailing'!M$4+((Y5-'FF-Detailing'!L$4)/('FF-Detailing'!L$3-'FF-Detailing'!L$4))*'FF-Detailing'!N$4),IF(Y5>'FF-Detailing'!L$5,('FF-Detailing'!M$5+((Y5-'FF-Detailing'!L$5)/('FF-Detailing'!L$4-'FF-Detailing'!L$5))*'FF-Detailing'!N$5),IF(Y5>='FF-Detailing'!L$6,('FF-Detailing'!M$6+((Y5-'FF-Detailing'!L$6)/('FF-Detailing'!L$5-'FF-Detailing'!L$6)*'FF-Detailing'!N$6)),0))))*$AP$2/10 -> 3 | AQ5: =SUM(AB5:AP5)*100/90 -> 35.453181 | AR5: =_xlfn.RANK.EQ(AQ5,$AQ$4:$AQ$21) -> 12 | AS5: 3.0004439 | AT5: =IFERROR(IF($K5>=99.5,M5,""),"") | AU5: =IFERROR(IF($K5>=99.5,L5,""),"") | AV5: =IFERROR(IF($K5>=99.5,X5,""),"") | AW5: =IFERROR(IF($K5>=99.5,O5,""),"") | AX5: =IFERROR(IF($K5>=99.5,#REF!,""),"") | AY5: =IFERROR(IF($K5>=99.5,_xlfn.RANK.EQ(AS5,AS$4:AS$21),"Disqualified"),"Not eligible") -> Disqualified | AZ5: =IFERROR(IF($K5>=99.5,_xlfn.RANK.EQ(AT5,AT$4:AT$21),"Disqualified"),"Not eligible") -> Disqualified | BA5: =IFERROR(IF($K5>=99.5,_xlfn.RANK.EQ(AU5,AU$4:AU$21),"Disqualified"),"Not eligible") -> Disqualified | BB5: =IFERROR(IF($K5>=99.5,_xlfn.RANK.EQ(AV5,AV$4:AV$21),"Disqualified"),"Not eligible") -> Disqualified | BC5: =IFERROR(IF($K5>=99.5,_xlfn.RANK.EQ(AW5,AW$4:AW$21),"Disqualified"),"Not eligible") -> Disqualified | BD5: =IFERROR(IF($K5>=99.5,_xlfn.RANK.EQ(AX5,AX$4:AX$21),"Disqualified"),"Not eligible") -> Disqualified
B6: 104722 | C6: Krishna Chandra Roy | D6: Sr. RSM | E6: Rangpur | F6: SYGK Bogura Zone-4 | G6: Foundation SD | H6: 36918 | I6: Regular | J6: 9 | K6: 80.129857 | L6: 27.178899 | M6: 56.983744 | N6: 87.244895 | O6: 20.720721 | P6: 0 | Q6: 0 | R6: 0 | S6: 88.437294 | T6: 192.01229 | U6: 0 | V6: 69.585938 | W6: 66.013072 | X6: 72.962515 | Y6: 79.800842 | Z6: 1 | AB6: =IF(K6>='Sales Ach'!L$3,'Sales Ach'!M$3,IF(K6>='Sales Ach'!L$4,('Sales Ach'!M$4+((K6-'Sales Ach'!L$4)/('Sales Ach'!L$3-'Sales Ach'!L$4))*'Sales Ach'!N$4),IF(K6>'Sales Ach'!L$5,('Sales Ach'!M$5+((K6-'Sales Ach'!L$5)/('Sales Ach'!L$4-'Sales Ach'!L$5))*'Sales Ach'!N$5),IF(K6>='Sales Ach'!L$6,('Sales Ach'!M$6+((K6-'Sales Ach'!L$6)/('Sales Ach'!L$5-'Sales Ach'!L$6)*'Sales Ach'!N$6)),0))))*$AB$2/10 -> 7.0259715 | AC6: =IF(L6>=UA!L$3,UA!M$3,IF(L6>=UA!L$4,(UA!M$4+((L6-UA!L$4)/(UA!L$3-UA!L$4))*UA!N$4),IF(L6>UA!L$5,(UA!M$5+((L6-UA!L$5)/(UA!L$4-UA!L$5))*UA!N$5),IF(L6>=UA!L$6,(UA!M$6+((L6-UA!L$6)/(UA!L$5-UA!L$6)*UA!N$6)),0))))*$AC$2/10 -> 0 | AD6: =IF(M6="","",(IF(M6>='New Product'!L$3,'New Product'!M$3,IF(M6>='New Product'!L$4,('New Product'!M$4+((M6-'New Product'!L$4)/('New Product'!L$3-'New Product'!L$4))*'New Product'!N$4),IF(M6>'New Product'!L$5,('New Product'!M$5+((M6-'New Product'!L$5)/('New Product'!L$4-'New Product'!L$5))*'New Product'!N$5),IF(M6>='New Product'!L$6,('New Product'!M$6+((M6-'New Product'!L$6)/('New Product'!L$5-'New Product'!L$6)*'New Product'!N$6)),0))))*$AD$2/10)) -> 1.3902543 | AE6: =IF(N6>='Basket Brand'!L$3,'Basket Brand'!M$3,IF(N6>='Basket Brand'!L$4,('Basket Brand'!M$4+((N6-'Basket Brand'!L$4)/('Basket Brand'!L$3-'Basket Brand'!L$4))*'Basket Brand'!N$4),IF(N6>'Basket Brand'!L$5,('Basket Brand'!M$5+((N6-'Basket Brand'!L$5)/('Basket Brand'!L$4-'Basket Brand'!L$5))*'Basket Brand'!N$5),IF(N6>='Basket Brand'!L$6,('Basket Brand'!M$6+((N6-'Basket Brand'!L$6)/('Basket Brand'!L$5-'Basket Brand'!L$6)*'Basket Brand'!N$6)),0))))*$AE$2/10 -> 3.3795916 | AF6: =IF(O6>='Territory Month'!G$3,'Territory Month'!H$3,IF(O6>='Territory Month'!G$4,('Territory Month'!H$4+((O6-'Territory Month'!G$4)/('Territory Month'!G$3-'Territory Month'!G$4))*'Territory Month'!I$4),IF(O6>'Territory Month'!G$5,('Territory Month'!H$5+((O6-'Territory Month'!G$5)/('Territory Month'!G$4-'Territory Month'!G$5))*'Territory Month'!I$5),IF(O6>='Territory Month'!G$6,('Territory Month'!H$6+((O6-'Territory Month'!G$6)/('Territory Month'!G$5-'Territory Month'!G$6)*'Territory Month'!I$6)),0))))*$AF$2/10 -> 0 | AG6: =IF(P6>='No of Month Ach.'!L$3,'No of Month Ach.'!M$3,IF(P6>='No of Month Ach.'!L$4,('No of Month Ach.'!M$4+((P6-'No of Month Ach.'!L$4)/('No of Month Ach.'!L$3-'No of Month Ach.'!L$4))*'No of Month Ach.'!N$4),IF(P6>'No of Month Ach.'!L$5,('No of Month Ach.'!M$5+((P6-'No of Month Ach.'!L$5)/('No of Month Ach.'!L$4-'No of Month Ach.'!L$5))*'No of Month Ach.'!N$5),IF(P6>='No of Month Ach.'!L$6,('No of Month Ach.'!M$6+((P6-'No of Month Ach.'!L$6)/('No of Month Ach.'!L$5-'No of Month Ach.'!L$6)*'No of Month Ach.'!N$6)),0))))*$AG$2/10 -> 0 | AH6: =IF(Q6>='Portfolio Ach.'!B$3,'Portfolio Ach.'!C$3,IF(Q6>='Portfolio Ach.'!B$4,('Portfolio Ach.'!C$4+((Q6-'Portfolio Ach.'!B$4)/('Portfolio Ach.'!B$3-'Portfolio Ach.'!B$4))*'Portfolio Ach.'!D$4),IF(Q6>'Portfolio Ach.'!B$5,('Portfolio Ach.'!C$5+((Q6-'Portfolio Ach.'!B$5)/('Portfolio Ach.'!B$4-'Portfolio Ach.'!B$5))*'Portfolio Ach.'!D$5),IF(Q6>='Portfolio Ach.'!B$6,('Portfolio Ach.'!C$6+((Q6-'Portfolio Ach.'!B$6)/('Portfolio Ach.'!B$5-'Portfolio Ach.'!B$6)*'Portfolio Ach.'!D$6)),0))))*$AH$2/10 -> 0 | AI6: =IF(R6="","",IF(R6>='Rx Share'!L$3,'Rx Share'!M$3,IF(R6>='Rx Share'!L$4,('Rx Share'!M$4+((R6-'Rx Share'!L$4)/('Rx Share'!L$3-'Rx Share'!L$4))*'Rx Share'!N$4),IF(R6>'Rx Share'!L$5,('Rx Share'!M$5+((R6-'Rx Share'!L$5)/('Rx Share'!L$4-'Rx Share'!L$5))*'Rx Share'!N$5),IF(R6>='Rx Share'!L$6,('Rx Share'!M$6+((R6-'Rx Share'!L$6)/('Rx Share'!L$5-'Rx Share'!L$6)*'Rx Share'!N$6)),0)))))*$AI$1/10 -> 0 | AJ6: =IF(S6="","",IF(S6>='Rx Share'!L$3,'Rx Share'!M$3,IF(S6>='Rx Share'!L$4,('Rx Share'!M$4+((S6-'Rx Share'!L$4)/('Rx Share'!L$3-'Rx Share'!L$4))*'Rx Share'!N$4),IF(S6>'Rx Share'!L$5,('Rx Share'!M$5+((S6-'Rx Share'!L$5)/('Rx Share'!L$4-'Rx Share'!L$5))*'Rx Share'!N$5),IF(S6>='Rx Share'!L$6,('Rx Share'!M$6+((S6-'Rx Share'!L$6)/('Rx Share'!L$5-'Rx Share'!L$6)*'Rx Share'!N$6)),0)))))*$AJ$1/10 -> 4.6124753 | AK6: =IF(T6="","",IF(T6>='Rx Share'!L$3,'Rx Share'!M$3,IF(T6>='Rx Share'!L$4,('Rx Share'!M$4+((T6-'Rx Share'!L$4)/('Rx Share'!L$3-'Rx Share'!L$4))*'Rx Share'!N$4),IF(T6>'Rx Share'!L$5,('Rx Share'!M$5+((T6-'Rx Share'!L$5)/('Rx Share'!L$4-'Rx Share'!L$5))*'Rx Share'!N$5),IF(T6>='Rx Share'!L$6,('Rx Share'!M$6+((T6-'Rx Share'!L$6)/('Rx Share'!L$5-'Rx Share'!L$6)*'Rx Share'!N$6)),0)))))*$AK$1/10 -> 4 | AL6: =IF(U6="","",IF(U6>='Rx Share'!M$3,'Rx Share'!N$3,IF(U6>='Rx Share'!M$4,('Rx Share'!N$4+((U6-'Rx Share'!M$4)/('Rx Share'!M$3-'Rx Share'!M$4))*'Rx Share'!O$4),IF(U6>'Rx Share'!M$5,('Rx Share'!N$5+((U6-'Rx Share'!M$5)/('Rx Share'!M$4-'Rx Share'!M$5))*'Rx Share'!O$5),IF(U6>='Rx Share'!M$6,('Rx Share'!N$6+((U6-'Rx Share'!M$6)/('Rx Share'!M$5-'Rx Share'!M$6)*'Rx Share'!O$6)),0)))))*$AL$1/10 -> 0 | AM6: =IF(V6>='Call Achv'!L$3,'Call Achv'!M$3,IF(V6>='Call Achv'!L$4,('Call Achv'!M$4+((V6-'Call Achv'!L$4)/('Call Achv'!L$3-'Call Achv'!L$4))*'Call Achv'!N$4),IF(V6>'Call Achv'!L$5,('Call Achv'!M$5+((V6-'Call Achv'!L$5)/('Call Achv'!L$4-'Call Achv'!L$5))*'Call Achv'!N$5),IF(V6>='Call Achv'!L$6,('Call Achv'!M$6+((V6-'Call Achv'!L$6)/('Call Achv'!L$5-'Call Achv'!L$6)*'Call Achv'!N$6)),0))))*$AM$2/10 -> 0 | AN6: =IF(W6>='DM Coaching'!G$3,'DM Coaching'!H$3,IF(W6>='DM Coaching'!G$4,('DM Coaching'!H$4+((W6-'DM Coaching'!G$4)/('DM Coaching'!G$3-'DM Coaching'!G$4))*'DM Coaching'!I$4),IF(W6>'DM Coaching'!G$5,('DM Coaching'!H$5+((W6-'DM Coaching'!G$5)/('DM Coaching'!G$4-'DM Coaching'!G$5))*'DM Coaching'!I$5),IF(W6>='DM Coaching'!G$6,('DM Coaching'!H$6+((W6-'DM Coaching'!G$6)/('DM Coaching'!G$5-'DM Coaching'!G$6)*'DM Coaching'!I$6)),0))))*$AN$2/10 -> 2.7607843 | AO6: =IF(X6>='FF-Written'!L$3,'FF-Written'!M$3,IF(X6>='FF-Written'!L$4,('FF-Written'!M$4+((X6-'FF-Written'!L$4)/('FF-Written'!L$3-'FF-Written'!L$4))*'FF-Written'!N$4),IF(X6>'FF-Written'!L$5,('FF-Written'!M$5+((X6-'FF-Written'!L$5)/('FF-Written'!L$4-'FF-Written'!L$5))*'FF-Written'!N$5),IF(X6>='FF-Written'!L$6,('FF-Written'!M$6+((X6-'FF-Written'!L$6)/('FF-Written'!L$5-'FF-Written'!L$6)*'FF-Written'!N$6)),0))))*$AO$2/10 -> 6.0147521 | AP6: =IF(Y6>='FF-Detailing'!L$3,'FF-Detailing'!M$3,IF(Y6>='FF-Detailing'!L$4,('FF-Detailing'!M$4+((Y6-'FF-Detailing'!L$4)/('FF-Detailing'!L$3-'FF-Detailing'!L$4))*'FF-Detailing'!N$4),IF(Y6>'FF-Detailing'!L$5,('FF-Detailing'!M$5+((Y6-'FF-Detailing'!L$5)/('FF-Detailing'!L$4-'FF-Detailing'!L$5))*'FF-Detailing'!N$5),IF(Y6>='FF-Detailing'!L$6,('FF-Detailing'!M$6+((Y6-'FF-Detailing'!L$6)/('FF-Detailing'!L$5-'FF-Detailing'!L$6)*'FF-Detailing'!N$6)),0))))*$AP$2/10 -> 2.5320758 | AQ6: =SUM(AB6:AP6)*100/90 -> 35.239894 | AR6: =_xlfn.RANK.EQ(AQ6,$AQ$4:$AQ$21) -> 13 | AS6: 2.9565217 | AT6: =IFERROR(IF($K6>=99.5,M6,""),"") | AU6: =IFERROR(IF($K6>=99.5,L6,""),"") | AV6: =IFERROR(IF($K6>=99.5,X6,""),"") | AW6: =IFERROR(IF($K6>=99.5,O6,""),"") | AX6: =IFERROR(IF($K6>=99.5,#REF!,""),"") | AY6: =IFERROR(IF($K6>=99.5,_xlfn.RANK.EQ(AS6,AS$4:AS$21),"Disqualified"),"Not eligible") -> Disqualified | AZ6: =IFERROR(IF($K6>=99.5,_xlfn.RANK.EQ(AT6,AT$4:AT$21),"Disqualified"),"Not eligible") -> Disqualified | BA6: =IFERROR(IF($K6>=99.5,_xlfn.RANK.EQ(AU6,AU$4:AU$21),"Disqualified"),"Not eligible") -> Disqualified | BB6: =IFERROR(IF($K6>=99.5,_xlfn.RANK.EQ(AV6,AV$4:AV$21),"Disqualified"),"Not eligible") -> Disqualified | BC6: =IFERROR(IF($K6>=99.5,_xlfn.RANK.EQ(AW6,AW$4:AW$21),"Disqualified"),"Not eligible") -> Disqualified | BD6: =IFERROR(IF($K6>=99.5,_xlfn.RANK.EQ(AX6,AX$4:AX$21),"Disqualified"),"Not eligible") -> Disqualified
B7: 104757 | C7: Shafiqur Rahman | D7: RSM | E7: SYT Rajshahi | F7: SYT Zone | G7: Foundation SD | H7: 38362 | I7: Regular | J7: 9 | K7: 79.976507 | L7: 12.121212 | M7: 65.01286 | N7: 83.051653 | O7: 18.148148 | P7: 0 | Q7: 0 | R7: 23.602033 | S7: 0 | T7: 0 | U7: 108.26592 | V7: 82.563988 | W7: 91.37935 | X7: 65.908205 | Y7: 82.7014 | Z7: 1 | AB7: =IF(K7>='Sales Ach'!L$3,'Sales Ach'!M$3,IF(K7>='Sales Ach'!L$4,('Sales Ach'!M$4+((K7-'Sales Ach'!L$4)/('Sales Ach'!L$3-'Sales Ach'!L$4))*'Sales Ach'!N$4),IF(K7>'Sales Ach'!L$5,('Sales Ach'!M$5+((K7-'Sales Ach'!L$5)/('Sales Ach'!L$4-'Sales Ach'!L$5))*'Sales Ach'!N$5),IF(K7>='Sales Ach'!L$6,('Sales Ach'!M$6+((K7-'Sales Ach'!L$6)/('Sales Ach'!L$5-'Sales Ach'!L$6)*'Sales Ach'!N$6)),0))))*$AB$2/10 -> 6.9953014 | AC7: =IF(L7>=UA!L$3,UA!M$3,IF(L7>=UA!L$4,(UA!M$4+((L7-UA!L$4)/(UA!L$3-UA!L$4))*UA!N$4),IF(L7>UA!L$5,(UA!M$5+((L7-UA!L$5)/(UA!L$4-UA!L$5))*UA!N$5),IF(L7>=UA!L$6,(UA!M$6+((L7-UA!L$6)/(UA!L$5-UA!L$6)*UA!N$6)),0))))*$AC$2/10 -> 0 | AD7: =IF(M7="","",(IF(M7>='New Product'!L$3,'New Product'!M$3,IF(M7>='New Product'!L$4,('New Product'!M$4+((M7-'New Product'!L$4)/('New Product'!L$3-'New Product'!L$4))*'New Product'!N$4),IF(M7>'New Product'!L$5,('New Product'!M$5+((M7-'New Product'!L$5)/('New Product'!L$4-'New Product'!L$5))*'New Product'!N$5),IF(M7>='New Product'!L$6,('New Product'!M$6+((M7-'New Product'!L$6)/('New Product'!L$5-'New Product'!L$6)*'New Product'!N$6)),0))))*$AD$2/10)) -> 1.8820377 | AE7: =IF(N7>='Basket Brand'!L$3,'Basket Brand'!M$3,IF(N7>='Basket Brand'!L$4,('Basket Brand'!M$4+((N7-'Basket Brand'!L$4)/('Basket Brand'!L$3-'Basket Brand'!L$4))*'Basket Brand'!N$4),IF(N7>'Basket Brand'!L$5,('Basket Brand'!M$5+((N7-'Basket Brand'!L$5)/('Basket Brand'!L$4-'Basket Brand'!L$5))*'Basket Brand'!N$5),IF(N7>='Basket Brand'!L$6,('Basket Brand'!M$6+((N7-'Basket Brand'!L$6)/('Basket Brand'!L$5-'Basket Brand'!L$6)*'Basket Brand'!N$6)),0))))*$AE$2/10 -> 3.0441323 | AF7: =IF(O7>='Territory Month'!G$3,'Territory Month'!H$3,IF(O7>='Territory Month'!G$4,('Territory Month'!H$4+((O7-'Territory Month'!G$4)/('Territory Month'!G$3-'Territory Month'!G$4))*'Territory Month'!I$4),IF(O7>'Territory Month'!G$5,('Territory Month'!H$5+((O7-'Territory Month'!G$5)/('Territory Month'!G$4-'Territory Month'!G$5))*'Territory Month'!I$5),IF(O7>='Territory Month'!G$6,('Territory Month'!H$6+((O7-'Territory Month'!G$6)/('Territory Month'!G$5-'Territory Month'!G$6)*'Territory Month'!I$6)),0))))*$AF$2/10 -> 0 | AG7: =IF(P7>='No of Month Ach.'!L$3,'No of Month Ach.'!M$3,IF(P7>='No of Month Ach.'!L$4,('No of Month Ach.'!M$4+((P7-'No of Month Ach.'!L$4)/('No of Month Ach.'!L$3-'No of Month Ach.'!L$4))*'No of Month Ach.'!N$4),IF(P7>'No of Month Ach.'!L$5,('No of Month Ach.'!M$5+((P7-'No of Month Ach.'!L$5)/('No of Month Ach.'!L$4-'No of Month Ach.'!L$5))*'No of Month Ach.'!N$5),IF(P7>='No of Month Ach.'!L$6,('No of Month Ach.'!M$6+((P7-'No of Month Ach.'!L$6)/('No of Month Ach.'!L$5-'No of Month Ach.'!L$6)*'No of Month Ach.'!N$6)),0))))*$AG$2/10 -> 0 | AH7: =IF(Q7>='Portfolio Ach.'!B$3,'Portfolio Ach.'!C$3,IF(Q7>='Portfolio Ach.'!B$4,('Portfolio Ach.'!C$4+((Q7-'Portfolio Ach.'!B$4)/('Portfolio Ach.'!B$3-'Portfolio Ach.'!B$4))*'Portfolio Ach.'!D$4),IF(Q7>'Portfolio Ach.'!B$5,('Portfolio Ach.'!C$5+((Q7-'Portfolio Ach.'!B$5)/('Portfolio Ach.'!B$4-'Portfolio Ach.'!B$5))*'Portfolio Ach.'!D$5),IF(Q7>='Portfolio Ach.'!B$6,('Portfolio Ach.'!C$6+((Q7-'Portfolio Ach.'!B$6)/('Portfolio Ach.'!B$5-'Portfolio Ach.'!B$6)*'Portfolio Ach.'!D$6)),0))))*$AH$2/10 -> 0 | AI7: =IF(R7="","",IF(R7>='Rx Share'!L$3,'Rx Share'!M$3,IF(R7>='Rx Share'!L$4,('Rx Share'!M$4+((R7-'Rx Share'!L$4)/('Rx Share'!L$3-'Rx Share'!L$4))*'Rx Share'!N$4),IF(R7>'Rx Share'!L$5,('Rx Share'!M$5+((R7-'Rx Share'!L$5)/('Rx Share'!L$4-'Rx Share'!L$5))*'Rx Share'!N$5),IF(R7>='Rx Share'!L$6,('Rx Share'!M$6+((R7-'Rx Share'!L$6)/('Rx Share'!L$5-'Rx Share'!L$6)*'Rx Share'!N$6)),0)))))*$AI$1/10 -> 0 | AJ7: =IF(S7="","",IF(S7>='Rx Share'!L$3,'Rx Share'!M$3,IF(S7>='Rx Share'!L$4,('Rx Share'!M$4+((S7-'Rx Share'!L$4)/('Rx Share'!L$3-'Rx Share'!L$4))*'Rx Share'!N$4),IF(S7>'Rx Share'!L$5,('Rx Share'!M$5+((S7-'Rx Share'!L$5)/('Rx Share'!L$4-'Rx Share'!L$5))*'Rx Share'!N$5),IF(S7>='Rx Share'!L$6,('Rx Share'!M$6+((S7-'Rx Share'!L$6)/('Rx Share'!L$5-'Rx Share'!L$6)*'Rx Share'!N$6)),0)))))*$AJ$1/10 -> 0 | AK7: =IF(T7="","",IF(T7>='Rx Share'!L$3,'Rx Share'!M$3,IF(T7>='Rx Share'!L$4,('Rx Share'!M$4+((T7-'Rx Share'!L$4)/('Rx Share'!L$3-'Rx Share'!L$4))*'Rx Share'!N$4),IF(T7>'Rx Share'!L$5,('Rx Share'!M$5+((T7-'Rx Share'!L$5)/('Rx Share'!L$4-'Rx Share'!L$5))*'Rx Share'!N$5),IF(T7>='Rx Share'!L$6,('Rx Share'!M$6+((T7-'Rx Share'!L$6)/('Rx Share'!L$5-'Rx Share'!L$6)*'Rx Share'!N$6)),0)))))*$AK$1/10 -> 0 | AL7: =IF(U7="","",IF(U7>='Rx Share'!M$3,'Rx Share'!N$3,IF(U7>='Rx Share'!M$4,('Rx Share'!N$4+((U7-'Rx Share'!M$4)/('Rx Share'!M$3-'Rx Share'!M$4))*'Rx Share'!O$4),IF(U7>'Rx Share'!M$5,('Rx Share'!N$5+((U7-'Rx Share'!M$5)/('Rx Share'!M$4-'Rx Share'!M$5))*'Rx Share'!O$5),IF(U7>='Rx Share'!M$6,('Rx Share'!N$6+((U7-'Rx Share'!M$6)/('Rx Share'!M$5-'Rx Share'!M$6)*'Rx Share'!O$6)),0)))))*$AL$1/10 -> 0 | AM7: =IF(V7>='Call Achv'!L$3,'Call Achv'!M$3,IF(V7>='Call Achv'!L$4,('Call Achv'!M$4+((V7-'Call Achv'!L$4)/('Call Achv'!L$3-'Call Achv'!L$4))*'Call Achv'!N$4),IF(V7>'Call Achv'!L$5,('Call Achv'!M$5+((V7-'Call Achv'!L$5)/('Call Achv'!L$4-'Call Achv'!L$5))*'Call Achv'!N$5),IF(V7>='Call Achv'!L$6,('Call Achv'!M$6+((V7-'Call Achv'!L$6)/('Call Achv'!L$5-'Call Achv'!L$6)*'Call Achv'!N$6)),0))))*$AM$2/10 -> 0.69869785 | AN7: =IF(W7>='DM Coaching'!G$3,'DM Coaching'!H$3,IF(W7>='DM Coaching'!G$4,('DM Coaching'!H$4+((W7-'DM Coaching'!G$4)/('DM Coaching'!G$3-'DM Coaching'!G$4))*'DM Coaching'!I$4),IF(W7>'DM Coaching'!G$5,('DM Coaching'!H$5+((W7-'DM Coaching'!G$5)/('DM Coaching'!G$4-'DM Coaching'!G$5))*'DM Coaching'!I$5),IF(W7>='DM Coaching'!G$6,('DM Coaching'!H$6+((W7-'DM Coaching'!G$6)/('DM Coaching'!G$5-'DM Coaching'!G$6)*'DM Coaching'!I$6)),0))))*$AN$2/10 -> 3 | AO7: =IF(X7>='FF-Written'!L$3,'FF-Written'!M$3,IF(X7>='FF-Written'!L$4,('FF-Written'!M$4+((X7-'FF-Written'!L$4)/('FF-Written'!L$3-'FF-Written'!L$4))*'FF-Written'!N$4),IF(X7>'FF-Written'!L$5,('FF-Written'!M$5+((X7-'FF-Written'!L$5)/('FF-Written'!L$4-'FF-Written'!L$5))*'FF-Written'!N$5),IF(X7>='FF-Written'!L$6,('FF-Written'!M$6+((X7-'FF-Written'!L$6)/('FF-Written'!L$5-'FF-Written'!L$6)*'FF-Written'!N$6)),0))))*$AO$2/10 -> 4.4542974 | AP7: =IF(Y7>='FF-Detailing'!L$3,'FF-Detailing'!M$3,IF(Y7>='FF-Detailing'!L$4,('FF-Detailing'!M$4+((Y7-'FF-Detailing'!L$4)/('FF-Detailing'!L$3-'FF-Detailing'!L$4))*'FF-Detailing'!N$4),IF(Y7>'FF-Detailing'!L$5,('FF-Detailing'!M$5+((Y7-'FF-Detailing'!L$5)/('FF-Detailing'!L$4-'FF-Detailing'!L$5))*'FF-Detailing'!N$5),IF(Y7>='FF-Detailing'!L$6,('FF-Detailing'!M$6+((Y7-'FF-Detailing'!L$6)/('FF-Detailing'!L$5-'FF-Detailing'!L$6)*'FF-Detailing'!N$6)),0))))*$AP$2/10 -> 2.793126 | AQ7: =SUM(AB7:AP7)*100/90 -> 25.408436 | AR7: =_xlfn.RANK.EQ(AQ7,$AQ$4:$AQ$21) -> 17 | AS7: 2.751974 | AT7: =IFERROR(IF($K7>=99.5,M7,""),"") | AU7: =IFERROR(IF($K7>=99.5,L7,""),"") | AV7: =IFERROR(IF($K7>=99.5,X7,""),"") | AW7: =IFERROR(IF($K7>=99.5,O7,""),"") | AX7: =IFERROR(IF($K7>=99.5,#REF!,""),"") | AY7: =IFERROR(IF($K7>=99.5,_xlfn.RANK.EQ(AS7,AS$4:AS$21),"Disqualified"),"Not eligible") -> Disqualified | AZ7: =IFERROR(IF($K7>=99.5,_xlfn.RANK.EQ(AT7,AT$4:AT$21),"Disqualified"),"Not eligible") -> Disqualified | BA7: =IFERROR(IF($K7>=99.5,_xlfn.RANK.EQ(AU7,AU$4:AU$21),"Disqualified"),"Not eligible") -> Disqualified | BB7: =IFERROR(IF($K7>=99.5,_xlfn.RANK.EQ(AV7,AV$4:AV$21),"Disqualified"),"Not eligible") -> Disqualified | BC7: =IFERROR(IF($K7>=99.5,_xlfn.RANK.EQ(AW7,AW$4:AW$21),"Disqualified"),"Not eligible") -> Disqualified | BD7: =IFERROR(IF($K7>=99.5,_xlfn.RANK.EQ(AX7,AX$4:AX$21),"Disqualified"),"Not eligible") -> Disqualified
B8: 104766 | C8: Amit Kumar Saha | D8: RSM | E8: Chattogram-2 | F8: SYGK Chattogram Zone-3 | G8: Foundation SD | H8: 38518 | I8: Regular | J8: 9 | K8: 83.027512 | L8: 25.802752 | M8: 50.283759 | N8: 95.274568 | O8: 12.946429 | P8: 0 | Q8: 0 | R8: 0 | S8: 109.41858 | T8: 176.73049 | U8: 0 | V8: 77.276861 | W8: 87.801418 | X8: 73.703704 | Y8: 83.403175 | Z8: 1 | AB8: =IF(K8>='Sales Ach'!L$3,'Sales Ach'!M$3,IF(K8>='Sales Ach'!L$4,('Sales Ach'!M$4+((K8-'Sales Ach'!L$4)/('Sales Ach'!L$3-'Sales Ach'!L$4))*'Sales Ach'!N$4),IF(K8>'Sales Ach'!L$5,('Sales Ach'!M$5+((K8-'Sales Ach'!L$5)/('Sales Ach'!L$4-'Sales Ach'!L$5))*'Sales Ach'!N$5),IF(K8>='Sales Ach'!L$6,('Sales Ach'!M$6+((K8-'Sales Ach'!L$6)/('Sales Ach'!L$5-'Sales Ach'!L$6)*'Sales Ach'!N$6)),0))))*$AB$2/10 -> 7.6055024 | AC8: =IF(L8>=UA!L$3,UA!M$3,IF(L8>=UA!L$4,(UA!M$4+((L8-UA!L$4)/(UA!L$3-UA!L$4))*UA!N$4),IF(L8>UA!L$5,(UA!M$5+((L8-UA!L$5)/(UA!L$4-UA!L$5))*UA!N$5),IF(L8>=UA!L$6,(UA!M$6+((L8-UA!L$6)/(UA!L$5-UA!L$6)*UA!N$6)),0))))*$AC$2/10 -> 0 | AD8: =IF(M8="","",(IF(M8>='New Product'!L$3,'New Product'!M$3,IF(M8>='New Product'!L$4,('New Product'!M$4+((M8-'New Product'!L$4)/('New Product'!L$3-'New Product'!L$4))*'New Product'!N$4),IF(M8>'New Product'!L$5,('New Product'!M$5+((M8-'New Product'!L$5)/('New Product'!L$4-'New Product'!L$5))*'New Product'!N$5),IF(M8>='New Product'!L$6,('New Product'!M$6+((M8-'New Product'!L$6)/('New Product'!L$5-'New Product'!L$6)*'New Product'!N$6)),0))))*$AD$2/10)) -> 0.97988026 | AE8: =IF(N8>='Basket Brand'!L$3,'Basket Brand'!M$3,IF(N8>='Basket Brand'!L$4,('Basket Brand'!M$4+((N8-'Basket Brand'!L$4)/('Basket Brand'!L$3-'Basket Brand'!L$4))*'Basket Brand'!N$4),IF(N8>'Basket Brand'!L$5,('Basket Brand'!M$5+((N8-'Basket Brand'!L$5)/('Basket Brand'!L$4-'Basket Brand'!L$5))*'Basket Brand'!N$5),IF(N8>='Basket Brand'!L$6,('Basket Brand'!M$6+((N8-'Basket Brand'!L$6)/('Basket Brand'!L$5-'Basket Brand'!L$6)*'Basket Brand'!N$6)),0))))*$AE$2/10 -> 4.0878617 | AF8: =IF(O8>='Territory Month'!G$3,'Territory Month'!H$3,IF(O8>='Territory Month'!G$4,('Territory Month'!H$4+((O8-'Territory Month'!G$4)/('Territory Month'!G$3-'Territory Month'!G$4))*'Territory Month'!I$4),IF(O8>'Territory Month'!G$5,('Territory Month'!H$5+((O8-'Territory Month'!G$5)/('Territory Month'!G$4-'Territory Month'!G$5))*'Territory Month'!I$5),IF(O8>='Territory Month'!G$6,('Territory Month'!H$6+((O8-'Territory Month'!G$6)/('Territory Month'!G$5-'Territory Month'!G$6)*'Territory Month'!I$6)),0))))*$AF$2/10 -> 0 | AG8: =IF(P8>='No of Month Ach.'!L$3,'No of Month Ach.'!M$3,IF(P8>='No of Month Ach.'!L$4,('No of Month Ach.'!M$4+((P8-'No of Month Ach.'!L$4)/('No of Month Ach.'!L$3-'No of Month Ach.'!L$4))*'No of Month Ach.'!N$4),IF(P8>'No of Month Ach.'!L$5,('No of Month Ach.'!M$5+((P8-'No of Month Ach.'!L$5)/('No of Month Ach.'!L$4-'No of Month Ach.'!L$5))*'No of Month Ach.'!N$5),IF(P8>='No of Month Ach.'!L$6,('No of Month Ach.'!M$6+((P8-'No of Month Ach.'!L$6)/('No of Month Ach.'!L$5-'No of Month Ach.'!L$6)*'No of Month Ach.'!N$6)),0))))*$AG$2/10 -> 0 | AH8: =IF(Q8>='Portfolio Ach.'!B$3,'Portfolio Ach.'!C$3,IF(Q8>='Portfolio Ach.'!B$4,('Portfolio Ach.'!C$4+((Q8-'Portfolio Ach.'!B$4)/('Portfolio Ach.'!B$3-'Portfolio Ach.'!B$4))*'Portfolio Ach.'!D$4),IF(Q8>'Portfolio Ach.'!B$5,('Portfolio Ach.'!C$5+((Q8-'Portfolio Ach.'!B$5)/('Portfolio Ach.'!B$4-'Portfolio Ach.'!B$5))*'Portfolio Ach.'!D$5),IF(Q8>='Portfolio Ach.'!B$6,('Portfolio Ach.'!C$6+((Q8-'Portfolio Ach.'!B$6)/('Portfolio Ach.'!B$5-'Portfolio Ach.'!B$6)*'Portfolio Ach.'!D$6)),0))))*$AH$2/10 -> 0 | AI8: =IF(R8="","",IF(R8>='Rx Share'!L$3,'Rx Share'!M$3,IF(R8>='Rx Share'!L$4,('Rx Share'!M$4+((R8-'Rx Share'!L$4)/('Rx Share'!L$3-'Rx Share'!L$4))*'Rx Share'!N$4),IF(R8>'Rx Share'!L$5,('Rx Share'!M$5+((R8-'Rx Share'!L$5)/('Rx Share'!L$4-'Rx Share'!L$5))*'Rx Share'!N$5),IF(R8>='Rx Share'!L$6,('Rx Share'!M$6+((R8-'Rx Share'!L$6)/('Rx Share'!L$5-'Rx Share'!L$6)*'Rx Share'!N$6)),0)))))*$AI$1/10 -> 0 | AJ8: =IF(S8="","",IF(S8>='Rx Share'!L$3,'Rx Share'!M$3,IF(S8>='Rx Share'!L$4,('Rx Share'!M$4+((S8-'Rx Share'!L$4)/('Rx Share'!L$3-'Rx Share'!L$4))*'Rx Share'!N$4),IF(S8>'Rx Share'!L$5,('Rx Share'!M$5+((S8-'Rx Share'!L$5)/('Rx Share'!L$4-'Rx Share'!L$5))*'Rx Share'!N$5),IF(S8>='Rx Share'!L$6,('Rx Share'!M$6+((S8-'Rx Share'!L$6)/('Rx Share'!L$5-'Rx Share'!L$6)*'Rx Share'!N$6)),0)))))*$AJ$1/10 -> 6 | AK8: =IF(T8="","",IF(T8>='Rx Share'!L$3,'Rx Share'!M$3,IF(T8>='Rx Share'!L$4,('Rx Share'!M$4+((T8-'Rx Share'!L$4)/('Rx Share'!L$3-'Rx Share'!L$4))*'Rx Share'!N$4),IF(T8>'Rx Share'!L$5,('Rx Share'!M$5+((T8-'Rx Share'!L$5)/('Rx Share'!L$4-'Rx Share'!L$5))*'Rx Share'!N$5),IF(T8>='Rx Share'!L$6,('Rx Share'!M$6+((T8-'Rx Share'!L$6)/('Rx Share'!L$5-'Rx Share'!L$6)*'Rx Share'!N$6)),0)))))*$AK$1/10 -> 4 | AL8: =IF(U8="","",IF(U8>='Rx Share'!M$3,'Rx Share'!N$3,IF(U8>='Rx Share'!M$4,('Rx Share'!N$4+((U8-'Rx Share'!M$4)/('Rx Share'!M$3-'Rx Share'!M$4))*'Rx Share'!O$4),IF(U8>'Rx Share'!M$5,('Rx Share'!N$5+((U8-'Rx Share'!M$5)/('Rx Share'!M$4-'Rx Share'!M$5))*'Rx Share'!O$5),IF(U8>='Rx Share'!M$6,('Rx Share'!N$6+((U8-'Rx Share'!M$6)/('Rx Share'!M$5-'Rx Share'!M$6)*'Rx Share'!O$6)),0)))))*$AL$1/10 -> 0 | AM8: =IF(V8>='Call Achv'!L$3,'Call Achv'!M$3,IF(V8>='Call Achv'!L$4,('Call Achv'!M$4+((V8-'Call Achv'!L$4)/('Call Achv'!L$3-'Call Achv'!L$4))*'Call Achv'!N$4),IF(V8>'Call Achv'!L$5,('Call Achv'!M$5+((V8-'Call Achv'!L$5)/('Call Achv'!L$4-'Call Achv'!L$5))*'Call Achv'!N$5),IF(V8>='Call Achv'!L$6,('Call Achv'!M$6+((V8-'Call Achv'!L$6)/('Call Achv'!L$5-'Call Achv'!L$6)*'Call Achv'!N$6)),0))))*$AM$2/10 -> 0 | AN8: =IF(W8>='DM Coaching'!G$3,'DM Coaching'!H$3,IF(W8>='DM Coaching'!G$4,('DM Coaching'!H$4+((W8-'DM Coaching'!G$4)/('DM Coaching'!G$3-'DM Coaching'!G$4))*'DM Coaching'!I$4),IF(W8>'DM Coaching'!G$5,('DM Coaching'!H$5+((W8-'DM Coaching'!G$5)/('DM Coaching'!G$4-'DM Coaching'!G$5))*'DM Coaching'!I$5),IF(W8>='DM Coaching'!G$6,('DM Coaching'!H$6+((W8-'DM Coaching'!G$6)/('DM Coaching'!G$5-'DM Coaching'!G$6)*'DM Coaching'!I$6)),0))))*$AN$2/10 -> 3 | AO8: =IF(X8>='FF-Written'!L$3,'FF-Written'!M$3,IF(X8>='FF-Written'!L$4,('FF-Written'!M$4+((X8-'FF-Written'!L$4)/('FF-Written'!L$3-'FF-Written'!L$4))*'FF-Written'!N$4),IF(X8>'FF-Written'!L$5,('FF-Written'!M$5+((X8-'FF-Written'!L$5)/('FF-Written'!L$4-'FF-Written'!L$5))*'FF-Written'!N$5),IF(X8>='FF-Written'!L$6,('FF-Written'!M$6+((X8-'FF-Written'!L$6)/('FF-Written'!L$5-'FF-Written'!L$6)*'FF-Written'!N$6)),0))))*$AO$2/10 -> 6.1185185 | AP8: =IF(Y8>='FF-Detailing'!L$3,'FF-Detailing'!M$3,IF(Y8>='FF-Detailing'!L$4,('FF-Detailing'!M$4+((Y8-'FF-Detailing'!L$4)/('FF-Detailing'!L$3-'FF-Detailing'!L$4))*'FF-Detailing'!N$4),IF(Y8>'FF-Detailing'!L$5,('FF-Detailing'!M$5+((Y8-'FF-Detailing'!L$5)/('FF-Detailing'!L$4-'FF-Detailing'!L$5))*'FF-Detailing'!N$5),IF(Y8>='FF-Detailing'!L$6,('FF-Detailing'!M$6+((Y8-'FF-Detailing'!L$6)/('FF-Detailing'!L$5-'FF-Detailing'!L$6)*'FF-Detailing'!N$6)),0))))*$AP$2/10 -> 2.8562857 | AQ8: =SUM(AB8:AP8)*100/90 -> 38.497832 | AR8: =_xlfn.RANK.EQ(AQ8,$AQ$4:$AQ$21) -> 10 | AS8: 2.6654638 | AT8: =IFERROR(IF($K8>=99.5,M8,""),"") | AU8: =IFERROR(IF($K8>=99.5,L8,""),"") | AV8: =IFERROR(IF($K8>=99.5,X8,""),"") | AW8: =IFERROR(IF($K8>=99.5,O8,""),"") | AX8: =IFERROR(IF($K8>=99.5,#REF!,""),"") | AY8: =IFERROR(IF($K8>=99.5,_xlfn.RANK.EQ(AS8,AS$4:AS$21),"Disqualified"),"Not eligible") -> Disqualified | AZ8: =IFERROR(IF($K8>=99.5,_xlfn.RANK.EQ(AT8,AT$4:AT$21),"Disqualified"),"Not eligible") -> Disqualified | BA8: =IFERROR(IF($K8>=99.5,_xlfn.RANK.EQ(AU8,AU$4:AU$21),"Disqualified"),"Not eligible") -> Disqualified | BB8: =IFERROR(IF($K8>=99.5,_xlfn.RANK.EQ(AV8,AV$4:AV$21),"Disqualified"),"Not eligible") -> Disqualified | BC8: =IFERROR(IF($K8>=99.5,_xlfn.RANK.EQ(AW8,AW$4:AW$21),"Disqualified"),"Not eligible") -> Disqualified | BD8: =IFERROR(IF($K8>=99.5,_xlfn.RANK.EQ(AX8,AX$4:AX$21),"Disqualified"),"Not eligible") -> Disqualified
B9: 104819 | C9: Pronob Mohanta | D9: RSM | E9: Sylhet | F9: SYGK Dhaka Zone-1 | G9: Foundation SD | H9: 38777 | I9: Regular | J9: 9 | K9: 100.52562 | L9: 37.385321 | M9: 56.201153 | N9: 106.54528 | O9: 60.185185 | P9: 5 | Q9: 4 | R9: 0 | S9: 89.556044 | T9: 247.39583 | U9: 0 | V9: 110.48549 | W9: 66.737589 | X9: 90.155123 | Y9: 80.764069 | Z9: 1 | AB9: =IF(K9>='Sales Ach'!L$3,'Sales Ach'!M$3,IF(K9>='Sales Ach'!L$4,('Sales Ach'!M$4+((K9-'Sales Ach'!L$4)/('Sales Ach'!L$3-'Sales Ach'!L$4))*'Sales Ach'!N$4),IF(K9>'Sales Ach'!L$5,('Sales Ach'!M$5+((K9-'Sales Ach'!L$5)/('Sales Ach'!L$4-'Sales Ach'!L$5))*'Sales Ach'!N$5),IF(K9>='Sales Ach'!L$6,('Sales Ach'!M$6+((K9-'Sales Ach'!L$6)/('Sales Ach'!L$5-'Sales Ach'!L$6)*'Sales Ach'!N$6)),0))))*$AB$2/10 -> 16.210247 | AC9: =IF(L9>=UA!L$3,UA!M$3,IF(L9>=UA!L$4,(UA!M$4+((L9-UA!L$4)/(UA!L$3-UA!L$4))*UA!N$4),IF(L9>UA!L$5,(UA!M$5+((L9-UA!L$5)/(UA!L$4-UA!L$5))*UA!N$5),IF(L9>=UA!L$6,(UA!M$6+((L9-UA!L$6)/(UA!L$5-UA!L$6)*UA!N$6)),0))))*$AC$2/10 -> 4.1724771 | AD9: =IF(M9="","",(IF(M9>='New Product'!L$3,'New Product'!M$3,IF(M9>='New Product'!L$4,('New Product'!M$4+((M9-'New Product'!L$4)/('New Product'!L$3-'New Product'!L$4))*'New Product'!N$4),IF(M9>'New Product'!L$5,('New Product'!M$5+((M9-'New Product'!L$5)/('New Product'!L$4-'New Product'!L$5))*'New Product'!N$5),IF(M9>='New Product'!L$6,('New Product'!M$6+((M9-'New Product'!L$6)/('New Product'!L$5-'New Product'!L$6)*'New Product'!N$6)),0))))*$AD$2/10)) -> 1.3423206 | AE9: =IF(N9>='Basket Brand'!L$3,'Basket Brand'!M$3,IF(N9>='Basket Brand'!L$4,('Basket Brand'!M$4+((N9-'Basket Brand'!L$4)/('Basket Brand'!L$3-'Basket Brand'!L$4))*'Basket Brand'!N$4),IF(N9>'Basket Brand'!L$5,('Basket Brand'!M$5+((N9-'Basket Brand'!L$5)/('Basket Brand'!L$4-'Basket Brand'!L$5))*'Basket Brand'!N$5),IF(N9>='Basket Brand'!L$6,('Basket Brand'!M$6+((N9-'Basket Brand'!L$6)/('Basket Brand'!L$5-'Basket Brand'!L$6)*'Basket Brand'!N$6)),0))))*$AE$2/10 -> 7.4472448 | AF9: =IF(O9>='Territory Month'!G$3,'Territory Month'!H$3,IF(O9>='Territory Month'!G$4,('Territory Month'!H$4+((O9-'Territory Month'!G$4)/('Territory Month'!G$3-'Territory Month'!G$4))*'Territory Month'!I$4),IF(O9>'Territory Month'!G$5,('Territory Month'!H$5+((O9-'Territory Month'!G$5)/('Territory Month'!G$4-'Territory Month'!G$5))*'Territory Month'!I$5),IF(O9>='Territory Month'!G$6,('Territory Month'!H$6+((O9-'Territory Month'!G$6)/('Territory Month'!G$5-'Territory Month'!G$6)*'Territory Month'!I$6)),0))))*$AF$2/10 -> 5 | AG9: =IF(P9>='No of Month Ach.'!L$3,'No of Month Ach.'!M$3,IF(P9>='No of Month Ach.'!L$4,('No of Month Ach.'!M$4+((P9-'No of Month Ach.'!L$4)/('No of Month Ach.'!L$3-'No of Month Ach.'!L$4))*'No of Month Ach.'!N$4),IF(P9>'No of Month Ach.'!L$5,('No of Month Ach.'!M$5+((P9-'No of Month Ach.'!L$5)/('No of Month Ach.'!L$4-'No of Month Ach.'!L$5))*'No of Month Ach.'!N$5),IF(P9>='No of Month Ach.'!L$6,('No of Month Ach.'!M$6+((P9-'No of Month Ach.'!L$6)/('No of Month Ach.'!L$5-'No of Month Ach.'!L$6)*'No of Month Ach.'!N$6)),0))))*$AG$2/10 -> 1.6 | AH9: =IF(Q9>='Portfolio Ach.'!B$3,'Portfolio Ach.'!C$3,IF(Q9>='Portfolio Ach.'!B$4,('Portfolio Ach.'!C$4+((Q9-'Portfolio Ach.'!B$4)/('Portfolio Ach.'!B$3-'Portfolio Ach.'!B$4))*'Portfolio Ach.'!D$4),IF(Q9>'Portfolio Ach.'!B$5,('Portfolio Ach.'!C$5+((Q9-'Portfolio Ach.'!B$5)/('Portfolio Ach.'!B$4-'Portfolio Ach.'!B$5))*'Portfolio Ach.'!D$5),IF(Q9>='Portfolio Ach.'!B$6,('Portfolio Ach.'!C$6+((Q9-'Portfolio Ach.'!B$6)/('Portfolio Ach.'!B$5-'Portfolio Ach.'!B$6)*'Portfolio Ach.'!D$6)),0))))*$AH$2/10 -> 2.2 | AI9: =IF(R9="","",IF(R9>='Rx Share'!L$3,'Rx Share'!M$3,IF(R9>='Rx Share'!L$4,('Rx Share'!M$4+((R9-'Rx Share'!L$4)/('Rx Share'!L$3-'Rx Share'!L$4))*'Rx Share'!N$4),IF(R9>'Rx Share'!L$5,('Rx Share'!M$5+((R9-'Rx Share'!L$5)/('Rx Share'!L$4-'Rx Share'!L$5))*'Rx Share'!N$5),IF(R9>='Rx Share'!L$6,('Rx Share'!M$6+((R9-'Rx Share'!L$6)/('Rx Share'!L$5-'Rx Share'!L$6)*'Rx Share'!N$6)),0)))))*$AI$1/10 -> 0 | AJ9: =IF(S9="","",IF(S9>='Rx Share'!L$3,'Rx Share'!M$3,IF(S9>='Rx Share'!L$4,('Rx Share'!M$4+((S9-'Rx Share'!L$4)/('Rx Share'!L$3-'Rx Share'!L$4))*'Rx Share'!N$4),IF(S9>'Rx Share'!L$5,('Rx Share'!M$5+((S9-'Rx Share'!L$5)/('Rx Share'!L$4-'Rx Share'!L$5))*'Rx Share'!N$5),IF(S9>='Rx Share'!L$6,('Rx Share'!M$6+((S9-'Rx Share'!L$6)/('Rx Share'!L$5-'Rx Share'!L$6)*'Rx Share'!N$6)),0)))))*$AJ$1/10 -> 4.7467253 | AK9: =IF(T9="","",IF(T9>='Rx Share'!L$3,'Rx Share'!M$3,IF(T9>='Rx Share'!L$4,('Rx Share'!M$4+((T9-'Rx Share'!L$4)/('Rx Share'!L$3-'Rx Share'!L$4))*'Rx Share'!N$4),IF(T9>'Rx Share'!L$5,('Rx Share'!M$5+((T9-'Rx Share'!L$5)/('Rx Share'!L$4-'Rx Share'!L$5))*'Rx Share'!N$5),IF(T9>='Rx Share'!L$6,('Rx Share'!M$6+((T9-'Rx Share'!L$6)/('Rx Share'!L$5-'Rx Share'!L$6)*'Rx Share'!N$6)),0)))))*$AK$1/10 -> 4 | AL9: =IF(U9="","",IF(U9>='Rx Share'!M$3,'Rx Share'!N$3,IF(U9>='Rx Share'!M$4,('Rx Share'!N$4+((U9-'Rx Share'!M$4)/('Rx Share'!M$3-'Rx Share'!M$4))*'Rx Share'!O$4),IF(U9>'Rx Share'!M$5,('Rx Share'!N$5+((U9-'Rx Share'!M$5)/('Rx Share'!M$4-'Rx Share'!M$5))*'Rx Share'!O$5),IF(U9>='Rx Share'!M$6,('Rx Share'!N$6+((U9-'Rx Share'!M$6)/('Rx Share'!M$5-'Rx Share'!M$6)*'Rx Share'!O$6)),0)))))*$AL$1/10 -> 0 | AM9: =IF(V9>='Call Achv'!L$3,'Call Achv'!M$3,IF(V9>='Call Achv'!L$4,('Call Achv'!M$4+((V9-'Call Achv'!L$4)/('Call Achv'!L$3-'Call Achv'!L$4))*'Call Achv'!N$4),IF(V9>'Call Achv'!L$5,('Call Achv'!M$5+((V9-'Call Achv'!L$5)/('Call Achv'!L$4-'Call Achv'!L$5))*'Call Achv'!N$5),IF(V9>='Call Achv'!L$6,('Call Achv'!M$6+((V9-'Call Achv'!L$6)/('Call Achv'!L$5-'Call Achv'!L$6)*'Call Achv'!N$6)),0))))*$AM$2/10 -> 5 | AN9: =IF(W9>='DM Coaching'!G$3,'DM Coaching'!H$3,IF(W9>='DM Coaching'!G$4,('DM Coaching'!H$4+((W9-'DM Coaching'!G$4)/('DM Coaching'!G$3-'DM Coaching'!G$4))*'DM Coaching'!I$4),IF(W9>'DM Coaching'!G$5,('DM Coaching'!H$5+((W9-'DM Coaching'!G$5)/('DM Coaching'!G$4-'DM Coaching'!G$5))*'DM Coaching'!I$5),IF(W9>='DM Coaching'!G$6,('DM Coaching'!H$6+((W9-'DM Coaching'!G$6)/('DM Coaching'!G$5-'DM Coaching'!G$6)*'DM Coaching'!I$6)),0))))*$AN$2/10 -> 2.8042553 | AO9: =IF(X9>='FF-Written'!L$3,'FF-Written'!M$3,IF(X9>='FF-Written'!L$4,('FF-Written'!M$4+((X9-'FF-Written'!L$4)/('FF-Written'!L$3-'FF-Written'!L$4))*'FF-Written'!N$4),IF(X9>'FF-Written'!L$5,('FF-Written'!M$5+((X9-'FF-Written'!L$5)/('FF-Written'!L$4-'FF-Written'!L$5))*'FF-Written'!N$5),IF(X9>='FF-Written'!L$6,('FF-Written'!M$6+((X9-'FF-Written'!L$6)/('FF-Written'!L$5-'FF-Written'!L$6)*'FF-Written'!N$6)),0))))*$AO$2/10 -> 7 | AP9: =IF(Y9>='FF-Detailing'!L$3,'FF-Detailing'!M$3,IF(Y9>='FF-Detailing'!L$4,('FF-Detailing'!M$4+((Y9-'FF-Detailing'!L$4)/('FF-Detailing'!L$3-'FF-Detailing'!L$4))*'FF-Detailing'!N$4),IF(Y9>'FF-Detailing'!L$5,('FF-Detailing'!M$5+((Y9-'FF-Detailing'!L$5)/('FF-Detailing'!L$4-'FF-Detailing'!L$5))*'FF-Detailing'!N$5),IF(Y9>='FF-Detailing'!L$6,('FF-Detailing'!M$6+((Y9-'FF-Detailing'!L$6)/('FF-Detailing'!L$5-'FF-Detailing'!L$6)*'FF-Detailing'!N$6)),0))))*$AP$2/10 -> 2.6187662 | AQ9: =SUM(AB9:AP9)*100/90 -> 71.268929 | AR9: =_xlfn.RANK.EQ(AQ9,$AQ$4:$AQ$21) -> 1 | AS9: 3.1961884 | AT9: =IFERROR(IF($K9>=99.5,M9,""),"") -> 56.201153 | AU9: =IFERROR(IF($K9>=99.5,L9,""),"") -> 37.385321 | AV9: =IFERROR(IF($K9>=99.5,X9,""),"") -> 90.155123 | AW9: =IFERROR(IF($K9>=99.5,O9,""),"") -> 60.185185 | AX9: =IFERROR(IF($K9>=99.5,#REF!,""),"") | AY9: =IFERROR(IF($K9>=99.5,_xlfn.RANK.EQ(AS9,AS$4:AS$21),"Disqualified"),"Not eligible") -> 3 | AZ9: =IFERROR(IF($K9>=99.5,_xlfn.RANK.EQ(AT9,AT$4:AT$21),"Disqualified"),"Not eligible") -> 2 | BA9: =IFERROR(IF($K9>=99.5,_xlfn.RANK.EQ(AU9,AU$4:AU$21),"Disqualified"),"Not eligible") -> 2 | BB9: =IFERROR(IF($K9>=99.5,_xlfn.RANK.EQ(AV9,AV$4:AV$21),"Disqualified"),"Not eligible") -> 1 | BC9: =IFERROR(IF($K9>=99.5,_xlfn.RANK.EQ(AW9,AW$4:AW$21),"Disqualified"),"Not eligible") -> 2 | BD9: =IFERROR(IF($K9>=99.5,_xlfn.RANK.EQ(AX9,AX$4:AX$21),"Disqualified"),"Not eligible") -> Not eligible
