Workbook

Sheet Terr. Ratio Dev
D1: -ve | E1: -1 | AF1: =AF3-AF2 -> 0 | AG1: =AG3-AG2 -> 0 | AH1: =AH3-AH2 -> 0 | AI1: =AI3-AI2 -> 0 | AJ1: =AJ3-AJ2 -> 0 | AK1: =AK3-AK2 -> 0 | AL1: =AL3-AL2 -> 0 | AM1: =AM3-AM2 -> 0 | ... BD1: =BD3-BD2 -> 0
D2: ve | E2: 1 | AE2: MKT | AF2: =_xlfn.XLOOKUP(AF$7,'Product Tgt'!$B:$B,'Product Tgt'!$G:$G) -> 793997 | AG2: =_xlfn.XLOOKUP(AG$7,'Product Tgt'!$B:$B,'Product Tgt'!$G:$G) -> 1169961.6 | AH2: =_xlfn.XLOOKUP(AH$7,'Product Tgt'!$B:$B,'Product Tgt'!$G:$G) -> 4740808.2 | AI2: =_xlfn.XLOOKUP(AI$7,'Product Tgt'!$B:$B,'Product Tgt'!$G:$G) -> 5743513.4 | AJ2: =_xlfn.XLOOKUP(AJ$7,'Product Tgt'!$B:$B,'Product Tgt'!$G:$G) -> 727002.84 | AK2: =_xlfn.XLOOKUP(AK$7,'Product Tgt'!$B:$B,'Product Tgt'!$G:$G) -> 372298.3 | AL2: =_xlfn.XLOOKUP(AL$7,'Product Tgt'!$B:$B,'Product Tgt'!$G:$G) -> 39924.12 | AM2: =_xlfn.XLOOKUP(AM$7,'Product Tgt'!$B:$B,'Product Tgt'!$G:$G) -> 217261.8 | ... BD2: =_xlfn.XLOOKUP(BD$7,'Product Tgt'!$B:$B,'Product Tgt'!$G:$G) -> 49470
D3: Max | E3: =MAX(D8:D56) -> 4.724597 | AE3: SM | AF3: =SUM(AF8:AF59) -> 793997 | AG3: =SUM(AG8:AG59) -> 1169961.6 | AH3: =SUM(AH8:AH59) -> 4740808.2 | AI3: =SUM(AI8:AI59) -> 5743513.4 | AJ3: =SUM(AJ8:AJ59) -> 727002.84 | AK3: =SUM(AK8:AK59) -> 372298.3 | AL3: =SUM(AL8:AL59) -> 39924.12 | AM3: =SUM(AM8:AM59) -> 217261.8 | ... BD3: =SUM(BD8:BD59) -> 49470
D4: Min | E4: =MIN(D8:D56) -> -3.4010392 | G4: RSM Ratio
F5: Price | G5: =_xlfn.XLOOKUP(G$7,'Product Tgt'!$B:$B,'Product Tgt'!$D:$D) -> 60.38 | H5: =_xlfn.XLOOKUP(H$7,'Product Tgt'!$B:$B,'Product Tgt'!$D:$D) -> 225.6 | I5: =_xlfn.XLOOKUP(I$7,'Product Tgt'!$B:$B,'Product Tgt'!$D:$D) -> 360.6 | J5: =_xlfn.XLOOKUP(J$7,'Product Tgt'!$B:$B,'Product Tgt'!$D:$D) -> 433.44 | K5: =_xlfn.XLOOKUP(K$7,'Product Tgt'!$B:$B,'Product Tgt'!$D:$D) -> 269.86 | L5: =_xlfn.XLOOKUP(L$7,'Product Tgt'!$B:$B,'Product Tgt'!$D:$D) -> 157.42 | M5: =_xlfn.XLOOKUP(M$7,'Product Tgt'!$B:$B,'Product Tgt'!$D:$D) -> 225.56 | N5: =_xlfn.XLOOKUP(N$7,'Product Tgt'!$B:$B,'Product Tgt'!$D:$D) -> 360.9 | ... Q5: =_xlfn.XLOOKUP(Q$7,'Product Tgt'!$B:$B,'Product Tgt'!$D:$D) -> 449.8 | U5: =_xlfn.XLOOKUP(U$7,'Product Tgt'!$B:$B,'Product Tgt'!$D:$D) -> 226.32 | V5: =_xlfn.XLOOKUP(V$7,'Product Tgt'!$B:$B,'Product Tgt'!$D:$D) -> 113 | W5: =_xlfn.XLOOKUP(W$7,'Product Tgt'!$B:$B,'Product Tgt'!$D:$D) -> 188 | X5: =_xlfn.XLOOKUP(X$7,'Product Tgt'!$B:$B,'Product Tgt'!$D:$D) -> 180.6 | Y5: =_xlfn.XLOOKUP(Y$7,'Product Tgt'!$B:$B,'Product Tgt'!$D:$D) -> 224.89 | Z5: =_xlfn.XLOOKUP(Z$7,'Product Tgt'!$B:$B,'Product Tgt'!$D:$D) -> 562.5 | AA5: =_xlfn.XLOOKUP(AA$7,'Product Tgt'!$B:$B,'Product Tgt'!$D:$D) -> 674.8 | AB5: =_xlfn.XLOOKUP(AB$7,'Product Tgt'!$B:$B,'Product Tgt'!$D:$D) -> 337.5 | ... BZ5: =_xlfn.XLOOKUP(BZ$7,'Product Tgt'!$B:$B,'Product Tgt'!$D:$D) -> #N/A
A6: Month | B6: Current Month | F6: Brand | G6: EPILIM 100ml Syrup 1 Bottle | H6: EPILIM 200mg Tab 6x10's | I6: EPILIM 300mg Tab 6x10's | J6: EPILIM 500mg Tab 8x6's | K6: EXPRES 10mg tab 3x10's | L6: EXPRES 5mg Tab 3x10's | M6: IMOVANE 7.5mg Tablet 3x10's | N6: LEVERON 250mg Tab 3X10's | O6: LEVERON 500mg Tab 2X10's | P6: Leveron Syrup 100 ml 1X 100 ml Bottle | Q6: Leveron XR 500 mg Tab 2x10's | R6: Leveron XR 750 mg Tab 2x6's | S6: QPINE 100mg Tablet 3x10's | T6: QPINE 200mg Tablet 3x10's | U6: QPINE 25mg Tablet 10x10's | V6: SPERDAL 1mg tablet 5X10's | W6: SPERDAL 2mg tablet 5X10's | X6: SPERDAL 4mg tablet 3x10's | Y6: Sperdal Oral Solution 100 ml | Z6: Vortiox 10 mg Tablet 3x10's | AA6: Vortiox 20 mg Tablet 2x10's | AB6: Vortiox 5 mg Tablet 3x10's | AC6: Qpine XR 50 mg Tab 5 x 10's | AD6: Qpine XR 200 mg Tab 3 x 10's | AE6: Qpine XR 300 mg Tab 2 x 10's | AF6: =_xlfn.XLOOKUP(AF$7,'Product Tgt'!$B:$B,'Product Tgt'!$C:$C) -> Epilim 100ml Syp | AG6: =_xlfn.XLOOKUP(AG$7,'Product Tgt'!$B:$B,'Product Tgt'!$C:$C) -> EPILIM 200mg Tab | AH6: =_xlfn.XLOOKUP(AH$7,'Product Tgt'!$B:$B,'Product Tgt'!$C:$C) -> EPILIM 300mg Tab | AI6: =_xlfn.XLOOKUP(AI$7,'Product Tgt'!$B:$B,'Product Tgt'!$C:$C) -> EPILIM 500mg Tab | AJ6: =_xlfn.XLOOKUP(AJ$7,'Product Tgt'!$B:$B,'Product Tgt'!$C:$C) -> EXPRES 10mg Tab | AK6: =_xlfn.XLOOKUP(AK$7,'Product Tgt'!$B:$B,'Product Tgt'!$C:$C) -> EXPRES 5mg Tab | AL6: =_xlfn.XLOOKUP(AL$7,'Product Tgt'!$B:$B,'Product Tgt'!$C:$C) -> Imovane 7.5mg Tab 3x10's | AM6: =_xlfn.XLOOKUP(AM$7,'Product Tgt'!$B:$B,'Product Tgt'!$C:$C) -> Leveron 250mg Tab 5x6's | ... BD6: =_xlfn.XLOOKUP(BD$7,'Product Tgt'!$B:$B,'Product Tgt'!$C:$C) -> Qpine XR 300 mg Tab 2x10's | BE6: Epilim 100ml Syp | BF6: EPILIM 200mg Tab | BG6: EPILIM 300mg Tab | BH6: EPILIM 500mg Tab | BI6: EXPRES 10mg Tab | BJ6: EXPRES 5mg Tab | BK6: Imovane 7.5mg Tab 3x10's | BL6: Leveron 250mg Tab 5x6's | BM6: Leveron 500mg Tab 5x4's | BN6: LEVERON 100ml Syp | BO6: Leveron XR 500mg Tablet | BP6: Leveron XR 750mg Tablet | BQ6: Qpine 100mg Tab 3x10's | BR6: Qpine 200mg Tab 3x10's | BS6: Qpine 25mg Tab 10x10's | BT6: SPERDAL 100ml Solution | BU6: Sperdal 1mg Tab 5x10's | BV6: Sperdal 2mg Tab 5x10's | BW6: Sperdal 4mg Tab 3x10's | BX6: Vortiox 10 mg Tablet 3x10's | BY6: Vortiox 20 mg Tablet 2x10's | BZ6: Vortiox 5 mg Tablet 3x10's
A7: Territory | B7: Total | C7: New Terr | D7: Diff | E7: Diff% | F7: Multiplier | G7: 542 | H7: 543 | I7: 545 | J7: 547 | K7: 551 | L7: 552 | M7: 578 | N7: 596 | O7: 598 | P7: 597 | Q7: 788 | R7: 789 | S7: 634 | T7: 635 | U7: 636 | V7: 666 | W7: 667 | X7: 668 | Y7: 665 | Z7: 770 | AA7: 771 | AB7: 769 | AC7: 813 | AD7: 814 | AE7: 815 | AF7: 542 | AG7: 543 | AH7: 545 | AI7: 547 | AJ7: 551 | AK7: 552 | AL7: 578 | AM7: 596 | AN7: 598 | AO7: 597 | AP7: 788 | AQ7: 789 | AR7: 634 | AS7: 635 | AT7: 636 | AU7: 666 | AV7: 667 | AW7: 668 | AX7: 665 | AY7: 770 | AZ7: 771 | BA7: 769 | BB7: 813 | BC7: 814 | BD7: 815 | BE7: 331006 | BF7: 347706 | BG7: 347707 | BH7: 347708 | BI7: 342923 | BJ7: 342922 | BK7: 372979 | BL7: 330444 | BM7: 330445 | BN7: 340941 | BO7: 4011000154 | BP7: 4011000155 | BQ7: 318732 | BR7: 328438 | BS7: 318678 | BT7: 339923 | BU7: 329832 | BV7: 329833 | BW7: 329834 | BX7: 4011000135 | BY7: 4011000136 | BZ7: 4011000134
A8: SYK-BBRB-BBR1 | B8: =_xlfn.XLOOKUP(A8,'Terr Target'!$A:$A,'Terr Target'!$E:$E) -> 458787.33 | C8: =SUM(AF8:BD8) -> 458786.71 | D8: =C8-B8 -> -0.62387958 | E8: =ABS(D8)/C8 -> 1.3598467e-06 | F8: =(1-(D8/C8)) -> 1.0000014 | G8: 15530.526 | H8: 19860.686 | I8: 88402.866 | J8: 94036.922 | K8: 26953.527 | L8: 13781.321 | M8: 0 | N8: 7346.2285 | O8: 7668.3585 | P8: 8095.6753 | Q8: 1701.1098 | R8: 1640.8034 | S8: 22783.28 | T8: 19153.553 | U8: 13142.982 | V8: 5485.4464 | W8: 9120.3749 | X8: 14356.079 | Y8: 10557.714 | Z8: 49212.122 | AA8: 3390.9372 | AB8: 19703.749 | AC8: 6476.1876 | AD8: 7014.6983 | AE8: 1187.1748 | AF8: =IFERROR(_xlfn.XLOOKUP(AF$7,'Product Tgt'!$B:$B,'Product Tgt'!$G:$G)*G8/G$60,0) -> 15645.195 | AG8: =IFERROR(_xlfn.XLOOKUP(AG$7,'Product Tgt'!$B:$B,'Product Tgt'!$G:$G)*H8/H$60,0) -> 20334.306 | AH8: =IFERROR(_xlfn.XLOOKUP(AH$7,'Product Tgt'!$B:$B,'Product Tgt'!$G:$G)*I8/I$60,0) -> 88284.225 | AI8: =IFERROR(_xlfn.XLOOKUP(AI$7,'Product Tgt'!$B:$B,'Product Tgt'!$G:$G)*J8/J$60,0) -> 93632.138 | AJ8: =IFERROR(_xlfn.XLOOKUP(AJ$7,'Product Tgt'!$B:$B,'Product Tgt'!$G:$G)*K8/K$60,0) -> 26511.165 | AK8: =IFERROR(_xlfn.XLOOKUP(AK$7,'Product Tgt'!$B:$B,'Product Tgt'!$G:$G)*L8/L$60,0) -> 14183.409 | AL8: =IFERROR(_xlfn.XLOOKUP(AL$7,'Product Tgt'!$B:$B,'Product Tgt'!$G:$G)*M8/M$60,0) -> 0 | AM8: =IFERROR(_xlfn.XLOOKUP(AM$7,'Product Tgt'!$B:$B,'Product Tgt'!$G:$G)*N8/N$60,0) -> 7297.2103 | ... BD8: =IFERROR(_xlfn.XLOOKUP(BD$7,'Product Tgt'!$B:$B,'Product Tgt'!$G:$G)*AE8/AE$60,0) -> 1189.372 | BE8: =ROUND(IFERROR(AF8/_xlfn.XLOOKUP(BE$7,'Product Tgt'!$B:$B,'Product Tgt'!$D:$D),0),0) -> 0 | BF8: =ROUND(IFERROR(AG8/_xlfn.XLOOKUP(BF$7,'Product Tgt'!$B:$B,'Product Tgt'!$D:$D),0),0) -> 0 | BG8: =ROUND(IFERROR(AH8/_xlfn.XLOOKUP(BG$7,'Product Tgt'!$B:$B,'Product Tgt'!$D:$D),0),0) -> 0 | BH8: =ROUND(IFERROR(AI8/_xlfn.XLOOKUP(BH$7,'Product Tgt'!$B:$B,'Product Tgt'!$D:$D),0),0) -> 0 | BI8: =ROUND(IFERROR(AM8/_xlfn.XLOOKUP(BI$7,'Product Tgt'!$B:$B,'Product Tgt'!$D:$D),0),0) -> 0 | BJ8: =ROUND(IFERROR(#REF!/_xlfn.XLOOKUP(BJ$7,'Product Tgt'!$B:$B,'Product Tgt'!$D:$D),0),0) -> 0 | BK8: =ROUND(IFERROR(#REF!/_xlfn.XLOOKUP(BK$7,'Product Tgt'!$B:$B,'Product Tgt'!$D:$D),0),0) -> 0 | BL8: =ROUND(IFERROR(AN8/_xlfn.XLOOKUP(BL$7,'Product Tgt'!$B:$B,'Product Tgt'!$D:$D),0),0) -> 0 | BM8: =ROUND(IFERROR(AQ8/_xlfn.XLOOKUP(BM$7,'Product Tgt'!$B:$B,'Product Tgt'!$D:$D),0),0) -> 0 | BN8: =ROUND(IFERROR(AR8/_xlfn.XLOOKUP(BN$7,'Product Tgt'!$B:$B,'Product Tgt'!$D:$D),0),0) -> 0 | BO8: =ROUND(IFERROR(AS8/_xlfn.XLOOKUP(BO$7,'Product Tgt'!$B:$B,'Product Tgt'!$D:$D),0),0) -> 0 | BP8: =ROUND(IFERROR(AT8/_xlfn.XLOOKUP(BP$7,'Product Tgt'!$B:$B,'Product Tgt'!$D:$D),0),0) -> 0 | BQ8: =ROUND(IFERROR(AU8/_xlfn.XLOOKUP(BQ$7,'Product Tgt'!$B:$B,'Product Tgt'!$D:$D),0),0) -> 0 | BR8: =ROUND(IFERROR(AV8/_xlfn.XLOOKUP(BR$7,'Product Tgt'!$B:$B,'Product Tgt'!$D:$D),0),0) -> 0 | BS8: =ROUND(IFERROR(AW8/_xlfn.XLOOKUP(BS$7,'Product Tgt'!$B:$B,'Product Tgt'!$D:$D),0),0) -> 0 | BT8: =ROUND(IFERROR(AX8/_xlfn.XLOOKUP(BT$7,'Product Tgt'!$B:$B,'Product Tgt'!$D:$D),0),0) -> 0 | ... BZ8: =ROUND(IFERROR(BD8/_xlfn.XLOOKUP(BZ$7,'Product Tgt'!$B:$B,'Product Tgt'!$D:$D),0),0) -> 0
A9: SYK-BIRA-BIR1 | B9: =_xlfn.XLOOKUP(A9,'Terr Target'!$A:$A,'Terr Target'!$E:$E) -> 190803.23 | C9: =SUM(AF9:BD9) -> 190802.9 | D9: =C9-B9 -> -0.32977019 | E9: =ABS(D9)/C9 -> 1.728329e-06 | F9: =(1-(D9/C9)) -> 1.0000017 | G9: 2004.1072 | H9: 5889.378 | I9: 15288.489 | J9: 34697.397 | K9: 3179.9585 | L9: 2631.6514 | M9: 0 | N9: 2504.2298 | O9: 10230.609 | P9: 1740.3382 | Q9: 1202.5676 | R9: 1489.9831 | S9: 5510.7401 | T9: 3483.8982 | U9: 5203.3254 | V9: 5346.1365 | W9: 13074.522 | X9: 7824.7239 | Y9: 4978.714 | Z9: 46095.752 | AA9: 3188.1142 | AB9: 15219.637 | AC9: 1669.3716 | AD9: 1808.1838 | AE9: 306.0189 | AF9: =IFERROR(_xlfn.XLOOKUP(AF$7,'Product Tgt'!$B:$B,'Product Tgt'!$G:$G)*G9/G$60,0) -> 2018.9044 | AG9: =IFERROR(_xlfn.XLOOKUP(AG$7,'Product Tgt'!$B:$B,'Product Tgt'!$G:$G)*H9/H$60,0) -> 6029.8226 | AH9: =IFERROR(_xlfn.XLOOKUP(AH$7,'Product Tgt'!$B:$B,'Product Tgt'!$G:$G)*I9/I$60,0) -> 15267.971 | AI9: =IFERROR(_xlfn.XLOOKUP(AI$7,'Product Tgt'!$B:$B,'Product Tgt'!$G:$G)*J9/J$60,0) -> 34548.041 | AJ9: =IFERROR(_xlfn.XLOOKUP(AJ$7,'Product Tgt'!$B:$B,'Product Tgt'!$G:$G)*K9/K$60,0) -> 3127.769 | AK9: =IFERROR(_xlfn.XLOOKUP(AK$7,'Product Tgt'!$B:$B,'Product Tgt'!$G:$G)*L9/L$60,0) -> 2708.4333 | AL9: =IFERROR(_xlfn.XLOOKUP(AL$7,'Product Tgt'!$B:$B,'Product Tgt'!$G:$G)*M9/M$60,0) -> 0 | AM9: =IFERROR(_xlfn.XLOOKUP(AM$7,'Product Tgt'!$B:$B,'Product Tgt'!$G:$G)*N9/N$60,0) -> 2487.5201 | ... BD9: =IFERROR(_xlfn.XLOOKUP(BD$7,'Product Tgt'!$B:$B,'Product Tgt'!$G:$G)*AE9/AE$60,0) -> 306.58529 | BE9: =ROUND(IFERROR(AF9/_xlfn.XLOOKUP(BE$7,'Product Tgt'!$B:$B,'Product Tgt'!$D:$D),0),0) -> 0 | BF9: =ROUND(IFERROR(AG9/_xlfn.XLOOKUP(BF$7,'Product Tgt'!$B:$B,'Product Tgt'!$D:$D),0),0) -> 0 | BG9: =ROUND(IFERROR(AH9/_xlfn.XLOOKUP(BG$7,'Product Tgt'!$B:$B,'Product Tgt'!$D:$D),0),0) -> 0 | BH9: =ROUND(IFERROR(AI9/_xlfn.XLOOKUP(BH$7,'Product Tgt'!$B:$B,'Product Tgt'!$D:$D),0),0) -> 0 | BI9: =ROUND(IFERROR(AM9/_xlfn.XLOOKUP(BI$7,'Product Tgt'!$B:$B,'Product Tgt'!$D:$D),0),0) -> 0 | BJ9: =ROUND(IFERROR(#REF!/_xlfn.XLOOKUP(BJ$7,'Product Tgt'!$B:$B,'Product Tgt'!$D:$D),0),0) -> 0 | BK9: =ROUND(IFERROR(#REF!/_xlfn.XLOOKUP(BK$7,'Product Tgt'!$B:$B,'Product Tgt'!$D:$D),0),0) -> 0 | BL9: =ROUND(IFERROR(AN9/_xlfn.XLOOKUP(BL$7,'Product Tgt'!$B:$B,'Product Tgt'!$D:$D),0),0) -> 0 | BM9: =ROUND(IFERROR(AQ9/_xlfn.XLOOKUP(BM$7,'Product Tgt'!$B:$B,'Product Tgt'!$D:$D),0),0) -> 0 | BN9: =ROUND(IFERROR(AR9/_xlfn.XLOOKUP(BN$7,'Product Tgt'!$B:$B,'Product Tgt'!$D:$D),0),0) -> 0 | BO9: =ROUND(IFERROR(AS9/_xlfn.XLOOKUP(BO$7,'Product Tgt'!$B:$B,'Product Tgt'!$D:$D),0),0) -> 0 | BP9: =ROUND(IFERROR(AT9/_xlfn.XLOOKUP(BP$7,'Product Tgt'!$B:$B,'Product Tgt'!$D:$D),0),0) -> 0 | BQ9: =ROUND(IFERROR(AU9/_xlfn.XLOOKUP(BQ$7,'Product Tgt'!$B:$B,'Product Tgt'!$D:$D),0),0) -> 0 | BR9: =ROUND(IFERROR(AV9/_xlfn.XLOOKUP(BR$7,'Product Tgt'!$B:$B,'Product Tgt'!$D:$D),0),0) -> 0 | BS9: =ROUND(IFERROR(AW9/_xlfn.XLOOKUP(BS$7,'Product Tgt'!$B:$B,'Product Tgt'!$D:$D),0),0) -> 0 | BT9: =ROUND(IFERROR(AX9/_xlfn.XLOOKUP(BT$7,'Product Tgt'!$B:$B,'Product Tgt'!$D:$D),0),0) -> 0 | ... BZ9: =ROUND(IFERROR(BD9/_xlfn.XLOOKUP(BZ$7,'Product Tgt'!$B:$B,'Product Tgt'!$D:$D),0),0) -> 0
A10: SYK-BMCA-BMC1 | B10: =_xlfn.XLOOKUP(A10,'Terr Target'!$A:$A,'Terr Target'!$E:$E) -> 367688.38 | C10: =SUM(AF10:BD10) -> 367687.96 | D10: =C10-B10 -> -0.41984059 | E10: =ABS(D10)/C10 -> 1.1418394e-06 | F10: =(1-(D10/C10)) -> 1.0000011 | G10: 8380.4443 | H10: 13411.906 | I10: 55180.438 | J10: 105201.5 | K10: 9853.6647 | L10: 10580.165 | M10: 0 | N10: 5706.504 | O10: 7888.7963 | P10: 2320.7097 | Q10: 0 | R10: 6717.9029 | S10: 12901.852 | T10: 4015.9807 | U10: 15297.305 | V10: 8292.0333 | W10: 11582.179 | X10: 9647.8933 | Y10: 7842.0456 | Z10: 43670.048 | AA10: 4012.7349 | AB10: 23232.479 | AC10: 3787.7992 | AD10: 4102.7638 | AE10: 694.35598 | AF10: =IFERROR(_xlfn.XLOOKUP(AF$7,'Product Tgt'!$B:$B,'Product Tgt'!$G:$G)*G10/G$60,0) -> 8442.3208 | AG10: =IFERROR(_xlfn.XLOOKUP(AG$7,'Product Tgt'!$B:$B,'Product Tgt'!$G:$G)*H10/H$60,0) -> 13731.741 | AH10: =IFERROR(_xlfn.XLOOKUP(AH$7,'Product Tgt'!$B:$B,'Product Tgt'!$G:$G)*I10/I$60,0) -> 55106.383 | AI10: =IFERROR(_xlfn.XLOOKUP(AI$7,'Product Tgt'!$B:$B,'Product Tgt'!$G:$G)*J10/J$60,0) -> 104748.66 | AJ10: =IFERROR(_xlfn.XLOOKUP(AJ$7,'Product Tgt'!$B:$B,'Product Tgt'!$G:$G)*K10/K$60,0) -> 9691.9461 | AK10: =IFERROR(_xlfn.XLOOKUP(AK$7,'Product Tgt'!$B:$B,'Product Tgt'!$G:$G)*L10/L$60,0) -> 10888.855 | AL10: =IFERROR(_xlfn.XLOOKUP(AL$7,'Product Tgt'!$B:$B,'Product Tgt'!$G:$G)*M10/M$60,0) -> 0 | AM10: =IFERROR(_xlfn.XLOOKUP(AM$7,'Product Tgt'!$B:$B,'Product Tgt'!$G:$G)*N10/N$60,0) -> 5668.4269 | ... BD10: =IFERROR(_xlfn.XLOOKUP(BD$7,'Product Tgt'!$B:$B,'Product Tgt'!$G:$G)*AE10/AE$60,0) -> 695.64112 | BE10: =ROUND(IFERROR(AF10/_xlfn.XLOOKUP(BE$7,'Product Tgt'!$B:$B,'Product Tgt'!$D:$D),0),0) -> 0 | BF10: =ROUND(IFERROR(AG10/_xlfn.XLOOKUP(BF$7,'Product Tgt'!$B:$B,'Product Tgt'!$D:$D),0),0) -> 0 | BG10: =ROUND(IFERROR(AH10/_xlfn.XLOOKUP(BG$7,'Product Tgt'!$B:$B,'Product Tgt'!$D:$D),0),0) -> 0 | BH10: =ROUND(IFERROR(AI10/_xlfn.XLOOKUP(BH$7,'Product Tgt'!$B:$B,'Product Tgt'!$D:$D),0),0) -> 0 | BI10: =ROUND(IFERROR(AM10/_xlfn.XLOOKUP(BI$7,'Product Tgt'!$B:$B,'Product Tgt'!$D:$D),0),0) -> 0 | BJ10: =ROUND(IFERROR(#REF!/_xlfn.XLOOKUP(BJ$7,'Product Tgt'!$B:$B,'Product Tgt'!$D:$D),0),0) -> 0 | BK10: =ROUND(IFERROR(#REF!/_xlfn.XLOOKUP(BK$7,'Product Tgt'!$B:$B,'Product Tgt'!$D:$D),0),0) -> 0 | BL10: =ROUND(IFERROR(AN10/_xlfn.XLOOKUP(BL$7,'Product Tgt'!$B:$B,'Product Tgt'!$D:$D),0),0) -> 0 | BM10: =ROUND(IFERROR(AQ10/_xlfn.XLOOKUP(BM$7,'Product Tgt'!$B:$B,'Product Tgt'!$D:$D),0),0) -> 0 | BN10: =ROUND(IFERROR(AR10/_xlfn.XLOOKUP(BN$7,'Product Tgt'!$B:$B,'Product Tgt'!$D:$D),0),0) -> 0 | BO10: =ROUND(IFERROR(AS10/_xlfn.XLOOKUP(BO$7,'Product Tgt'!$B:$B,'Product Tgt'!$D:$D),0),0) -> 0 | BP10: =ROUND(IFERROR(AT10/_xlfn.XLOOKUP(BP$7,'Product Tgt'!$B:$B,'Product Tgt'!$D:$D),0),0) -> 0 | BQ10: =ROUND(IFERROR(AU10/_xlfn.XLOOKUP(BQ$7,'Product Tgt'!$B:$B,'Product Tgt'!$D:$D),0),0) -> 0 | BR10: =ROUND(IFERROR(AV10/_xlfn.XLOOKUP(BR$7,'Product Tgt'!$B:$B,'Product Tgt'!$D:$D),0),0) -> 0 | BS10: =ROUND(IFERROR(AW10/_xlfn.XLOOKUP(BS$7,'Product Tgt'!$B:$B,'Product Tgt'!$D:$D),0),0) -> 0 | BT10: =ROUND(IFERROR(AX10/_xlfn.XLOOKUP(BT$7,'Product Tgt'!$B:$B,'Product Tgt'!$D:$D),0),0) -> 0 | ... BZ10: =ROUND(IFERROR(BD10/_xlfn.XLOOKUP(BZ$7,'Product Tgt'!$B:$B,'Product Tgt'!$D:$D),0),0) -> 0
A11: SYK-BOGA-BOG1 | B11: =_xlfn.XLOOKUP(A11,'Terr Target'!$A:$A,'Terr Target'!$E:$E) -> 491068.86 | C11: =SUM(AF11:BD11) -> 491068.52 | D11: =C11-B11 -> -0.33637954 | E11: =ABS(D11)/C11 -> 6.8499513e-07 | F11: =(1-(D11/C11)) -> 1.0000007 | G11: 13473.577 | H11: 18526.024 | I11: 86987.558 | J11: 124920.35 | K11: 28798.887 | L11: 7944.4205 | M11: 0 | N11: 5946.5192 | O11: 6975.4481 | P11: 2146.9716 | Q11: 3191.4551 | R11: 2589.1379 | S11: 27268.276 | T11: 12261.886 | U11: 18779.182 | V11: 4558.4322 | W11: 14679.813 | X11: 14740.44 | Y11: 9666.9324 | Z11: 41928.63 | AA11: 9260.0292 | AB11: 30373.6 | AC11: 6855.91 | AD11: 7425.9955 | AE11: 1256.7831 | AF11: =IFERROR(_xlfn.XLOOKUP(AF$7,'Product Tgt'!$B:$B,'Product Tgt'!$G:$G)*G11/G$60,0) -> 13573.058 | AG11: =IFERROR(_xlfn.XLOOKUP(AG$7,'Product Tgt'!$B:$B,'Product Tgt'!$G:$G)*H11/H$60,0) -> 18967.816 | AH11: =IFERROR(_xlfn.XLOOKUP(AH$7,'Product Tgt'!$B:$B,'Product Tgt'!$G:$G)*I11/I$60,0) -> 86870.815 | AI11: =IFERROR(_xlfn.XLOOKUP(AI$7,'Product Tgt'!$B:$B,'Product Tgt'!$G:$G)*J11/J$60,0) -> 124382.62 | AJ11: =IFERROR(_xlfn.XLOOKUP(AJ$7,'Product Tgt'!$B:$B,'Product Tgt'!$G:$G)*K11/K$60,0) -> 28326.239 | AK11: =IFERROR(_xlfn.XLOOKUP(AK$7,'Product Tgt'!$B:$B,'Product Tgt'!$G:$G)*L11/L$60,0) -> 8176.2093 | AL11: =IFERROR(_xlfn.XLOOKUP(AL$7,'Product Tgt'!$B:$B,'Product Tgt'!$G:$G)*M11/M$60,0) -> 0 | AM11: =IFERROR(_xlfn.XLOOKUP(AM$7,'Product Tgt'!$B:$B,'Product Tgt'!$G:$G)*N11/N$60,0) -> 5906.8407 | ... BD11: =IFERROR(_xlfn.XLOOKUP(BD$7,'Product Tgt'!$B:$B,'Product Tgt'!$G:$G)*AE11/AE$60,0) -> 1259.1092 | BE11: =ROUND(IFERROR(AF11/_xlfn.XLOOKUP(BE$7,'Product Tgt'!$B:$B,'Product Tgt'!$D:$D),0),0) -> 0 | BF11: =ROUND(IFERROR(AG11/_xlfn.XLOOKUP(BF$7,'Product Tgt'!$B:$B,'Product Tgt'!$D:$D),0),0) -> 0 | BG11: =ROUND(IFERROR(AH11/_xlfn.XLOOKUP(BG$7,'Product Tgt'!$B:$B,'Product Tgt'!$D:$D),0),0) -> 0 | BH11: =ROUND(IFERROR(AI11/_xlfn.XLOOKUP(BH$7,'Product Tgt'!$B:$B,'Product Tgt'!$D:$D),0),0) -> 0 | BI11: =ROUND(IFERROR(AM11/_xlfn.XLOOKUP(BI$7,'Product Tgt'!$B:$B,'Product Tgt'!$D:$D),0),0) -> 0 | BJ11: =ROUND(IFERROR(#REF!/_xlfn.XLOOKUP(BJ$7,'Product Tgt'!$B:$B,'Product Tgt'!$D:$D),0),0) -> 0 | BK11: =ROUND(IFERROR(#REF!/_xlfn.XLOOKUP(BK$7,'Product Tgt'!$B:$B,'Product Tgt'!$D:$D),0),0) -> 0 | BL11: =ROUND(IFERROR(AN11/_xlfn.XLOOKUP(BL$7,'Product Tgt'!$B:$B,'Product Tgt'!$D:$D),0),0) -> 0 | BM11: =ROUND(IFERROR(AQ11/_xlfn.XLOOKUP(BM$7,'Product Tgt'!$B:$B,'Product Tgt'!$D:$D),0),0) -> 0 | BN11: =ROUND(IFERROR(AR11/_xlfn.XLOOKUP(BN$7,'Product Tgt'!$B:$B,'Product Tgt'!$D:$D),0),0) -> 0 | BO11: =ROUND(IFERROR(AS11/_xlfn.XLOOKUP(BO$7,'Product Tgt'!$B:$B,'Product Tgt'!$D:$D),0),0) -> 0 | BP11: =ROUND(IFERROR(AT11/_xlfn.XLOOKUP(BP$7,'Product Tgt'!$B:$B,'Product Tgt'!$D:$D),0),0) -> 0 | BQ11: =ROUND(IFERROR(AU11/_xlfn.XLOOKUP(BQ$7,'Product Tgt'!$B:$B,'Product Tgt'!$D:$D),0),0) -> 0 | BR11: =ROUND(IFERROR(AV11/_xlfn.XLOOKUP(BR$7,'Product Tgt'!$B:$B,'Product Tgt'!$D:$D),0),0) -> 0 | BS11: =ROUND(IFERROR(AW11/_xlfn.XLOOKUP(BS$7,'Product Tgt'!$B:$B,'Product Tgt'!$D:$D),0),0) -> 0 | BT11: =ROUND(IFERROR(AX11/_xlfn.XLOOKUP(BT$7,'Product Tgt'!$B:$B,'Product Tgt'!$D:$D),0),0) -> 0 | ... BZ11: =ROUND(IFERROR(BD11/_xlfn.XLOOKUP(BZ$7,'Product Tgt'!$B:$B,'Product Tgt'!$D:$D),0),0) -> 0
A12: SYK-BSLA-BSL1 | B12: =_xlfn.XLOOKUP(A12,'Terr Target'!$A:$A,'Terr Target'!$E:$E) -> 368041.71 | C12: =SUM(AF12:BD12) -> 368042.76 | D12: =C12-B12 -> 1.0558007 | E12: =ABS(D12)/C12 -> 2.8686904e-06 | F12: =(1-(D12/C12)) -> 0.99999713 | G12: 18427.861 | H12: 20767.934 | I12: 81112.888 | J12: 108255.48 | K12: 7069.0501 | L12: 2644.0142 | M12: 0 | N12: 1867.0098 | O12: 8940.1202 | P12: 895.64307 | Q12: 1193.8746 | R12: 1081.9736 | S12: 25102.743 | T12: 6964.756 | U12: 24219.726 | V12: 5384.9922 | W12: 9603.2971 | X12: 7897.4656 | Y12: 4325.5529 | Z12: 14623.512 | AA12: 2380.5177 | AB12: 5811.3266 | AC12: 6618.1528 | AD12: 7168.4682 | AE12: 1213.199 | AF12: =IFERROR(_xlfn.XLOOKUP(AF$7,'Product Tgt'!$B:$B,'Product Tgt'!$G:$G)*G12/G$60,0) -> 18563.922 | AG12: =IFERROR(_xlfn.XLOOKUP(AG$7,'Product Tgt'!$B:$B,'Product Tgt'!$G:$G)*H12/H$60,0) -> 21263.189 | AH12: =IFERROR(_xlfn.XLOOKUP(AH$7,'Product Tgt'!$B:$B,'Product Tgt'!$G:$G)*I12/I$60,0) -> 81004.03 | AI12: =IFERROR(_xlfn.XLOOKUP(AI$7,'Product Tgt'!$B:$B,'Product Tgt'!$G:$G)*J12/J$60,0) -> 107789.49 | AJ12: =IFERROR(_xlfn.XLOOKUP(AJ$7,'Product Tgt'!$B:$B,'Product Tgt'!$G:$G)*K12/K$60,0) -> 6953.0326 | AK12: =IFERROR(_xlfn.XLOOKUP(AK$7,'Product Tgt'!$B:$B,'Product Tgt'!$G:$G)*L12/L$60,0) -> 2721.1568 | AL12: =IFERROR(_xlfn.XLOOKUP(AL$7,'Product Tgt'!$B:$B,'Product Tgt'!$G:$G)*M12/M$60,0) -> 0 | AM12: =IFERROR(_xlfn.XLOOKUP(AM$7,'Product Tgt'!$B:$B,'Product Tgt'!$G:$G)*N12/N$60,0) -> 1854.552 | ... BD12: =IFERROR(_xlfn.XLOOKUP(BD$7,'Product Tgt'!$B:$B,'Product Tgt'!$G:$G)*AE12/AE$60,0) -> 1215.4444 | BE12: =ROUND(IFERROR(AF12/_xlfn.XLOOKUP(BE$7,'Product Tgt'!$B:$B,'Product Tgt'!$D:$D),0),0) -> 0 | BF12: =ROUND(IFERROR(AG12/_xlfn.XLOOKUP(BF$7,'Product Tgt'!$B:$B,'Product Tgt'!$D:$D),0),0) -> 0 | BG12: =ROUND(IFERROR(AH12/_xlfn.XLOOKUP(BG$7,'Product Tgt'!$B:$B,'Product Tgt'!$D:$D),0),0) -> 0 | BH12: =ROUND(IFERROR(AI12/_xlfn.XLOOKUP(BH$7,'Product Tgt'!$B:$B,'Product Tgt'!$D:$D),0),0) -> 0 | BI12: =ROUND(IFERROR(AM12/_xlfn.XLOOKUP(BI$7,'Product Tgt'!$B:$B,'Product Tgt'!$D:$D),0),0) -> 0 | BJ12: =ROUND(IFERROR(#REF!/_xlfn.XLOOKUP(BJ$7,'Product Tgt'!$B:$B,'Product Tgt'!$D:$D),0),0) -> 0 | BK12: =ROUND(IFERROR(#REF!/_xlfn.XLOOKUP(BK$7,'Product Tgt'!$B:$B,'Product Tgt'!$D:$D),0),0) -> 0 | BL12: =ROUND(IFERROR(AN12/_xlfn.XLOOKUP(BL$7,'Product Tgt'!$B:$B,'Product Tgt'!$D:$D),0),0) -> 0 | BM12: =ROUND(IFERROR(AQ12/_xlfn.XLOOKUP(BM$7,'Product Tgt'!$B:$B,'Product Tgt'!$D:$D),0),0) -> 0 | BN12: =ROUND(IFERROR(AR12/_xlfn.XLOOKUP(BN$7,'Product Tgt'!$B:$B,'Product Tgt'!$D:$D),0),0) -> 0 | BO12: =ROUND(IFERROR(AS12/_xlfn.XLOOKUP(BO$7,'Product Tgt'!$B:$B,'Product Tgt'!$D:$D),0),0) -> 0 | BP12: =ROUND(IFERROR(AT12/_xlfn.XLOOKUP(BP$7,'Product Tgt'!$B:$B,'Product Tgt'!$D:$D),0),0) -> 0 | BQ12: =ROUND(IFERROR(AU12/_xlfn.XLOOKUP(BQ$7,'Product Tgt'!$B:$B,'Product Tgt'!$D:$D),0),0) -> 0 | BR12: =ROUND(IFERROR(AV12/_xlfn.XLOOKUP(BR$7,'Product Tgt'!$B:$B,'Product Tgt'!$D:$D),0),0) -> 0 | BS12: =ROUND(IFERROR(AW12/_xlfn.XLOOKUP(BS$7,'Product Tgt'!$B:$B,'Product Tgt'!$D:$D),0),0) -> 0 | BT12: =ROUND(IFERROR(AX12/_xlfn.XLOOKUP(BT$7,'Product Tgt'!$B:$B,'Product Tgt'!$D:$D),0),0) -> 0 | ... BZ12: =ROUND(IFERROR(BD12/_xlfn.XLOOKUP(BZ$7,'Product Tgt'!$B:$B,'Product Tgt'!$D:$D),0),0) -> 0
A13: SYK-BSLB-BSL2 | B13: =_xlfn.XLOOKUP(A13,'Terr Target'!$A:$A,'Terr Target'!$E:$E) -> 349147.34 | C13: =SUM(AF13:BD13) -> 349148.36 | D13: =C13-B13 -> 1.0222675 | E13: =ABS(D13)/C13 -> 2.9278885e-06 | F13: =(1-(D13/C13)) -> 0.99999707 | G13: 21242.737 | H13: 13242.706 | I13: 76622.929 | J13: 100633.34 | K13: 8209.7185 | L13: 3032.7108 | M13: 0 | N13: 1250.4908 | O13: 8158.6918 | P13: 0 | Q13: 1114.1105 | R13: 1057.3561 | S13: 27897.234 | T13: 4291.6501 | U13: 23251.729 | V13: 6051.9944 | W13: 9536.3945 | X13: 7695.0443 | Y13: 3486.0366 | Z13: 16862.471 | AA13: 2089.1199 | AB13: 3902.0289 | AC13: 6518.6097 | AD13: 7060.6478 | AE13: 1194.9513 | AF13: =IFERROR(_xlfn.XLOOKUP(AF$7,'Product Tgt'!$B:$B,'Product Tgt'!$G:$G)*G13/G$60,0) -> 21399.582 | AG13: =IFERROR(_xlfn.XLOOKUP(AG$7,'Product Tgt'!$B:$B,'Product Tgt'!$G:$G)*H13/H$60,0) -> 13558.506 | AH13: =IFERROR(_xlfn.XLOOKUP(AH$7,'Product Tgt'!$B:$B,'Product Tgt'!$G:$G)*I13/I$60,0) -> 76520.097 | AI13: =IFERROR(_xlfn.XLOOKUP(AI$7,'Product Tgt'!$B:$B,'Product Tgt'!$G:$G)*J13/J$60,0) -> 100200.16 | AJ13: =IFERROR(_xlfn.XLOOKUP(AJ$7,'Product Tgt'!$B:$B,'Product Tgt'!$G:$G)*K13/K$60,0) -> 8074.9804 | AK13: =IFERROR(_xlfn.XLOOKUP(AK$7,'Product Tgt'!$B:$B,'Product Tgt'!$G:$G)*L13/L$60,0) -> 3121.1941 | AL13: =IFERROR(_xlfn.XLOOKUP(AL$7,'Product Tgt'!$B:$B,'Product Tgt'!$G:$G)*M13/M$60,0) -> 0 | AM13: =IFERROR(_xlfn.XLOOKUP(AM$7,'Product Tgt'!$B:$B,'Product Tgt'!$G:$G)*N13/N$60,0) -> 1242.1468 | ... BD13: =IFERROR(_xlfn.XLOOKUP(BD$7,'Product Tgt'!$B:$B,'Product Tgt'!$G:$G)*AE13/AE$60,0) -> 1197.163 | BE13: =ROUND(IFERROR(AF13/_xlfn.XLOOKUP(BE$7,'Product Tgt'!$B:$B,'Product Tgt'!$D:$D),0),0) -> 0 | BF13: =ROUND(IFERROR(AG13/_xlfn.XLOOKUP(BF$7,'Product Tgt'!$B:$B,'Product Tgt'!$D:$D),0),0) -> 0 | BG13: =ROUND(IFERROR(AH13/_xlfn.XLOOKUP(BG$7,'Product Tgt'!$B:$B,'Product Tgt'!$D:$D),0),0) -> 0 | BH13: =ROUND(IFERROR(AI13/_xlfn.XLOOKUP(BH$7,'Product Tgt'!$B:$B,'Product Tgt'!$D:$D),0),0) -> 0 | BI13: =ROUND(IFERROR(AM13/_xlfn.XLOOKUP(BI$7,'Product Tgt'!$B:$B,'Product Tgt'!$D:$D),0),0) -> 0 | BJ13: =ROUND(IFERROR(#REF!/_xlfn.XLOOKUP(BJ$7,'Product Tgt'!$B:$B,'Product Tgt'!$D:$D),0),0) -> 0 | BK13: =ROUND(IFERROR(#REF!/_xlfn.XLOOKUP(BK$7,'Product Tgt'!$B:$B,'Product Tgt'!$D:$D),0),0) -> 0 | BL13: =ROUND(IFERROR(AN13/_xlfn.XLOOKUP(BL$7,'Product Tgt'!$B:$B,'Product Tgt'!$D:$D),0),0) -> 0 | BM13: =ROUND(IFERROR(AQ13/_xlfn.XLOOKUP(BM$7,'Product Tgt'!$B:$B,'Product Tgt'!$D:$D),0),0) -> 0 | BN13: =ROUND(IFERROR(AR13/_xlfn.XLOOKUP(BN$7,'Product Tgt'!$B:$B,'Product Tgt'!$D:$D),0),0) -> 0 | BO13: =ROUND(IFERROR(AS13/_xlfn.XLOOKUP(BO$7,'Product Tgt'!$B:$B,'Product Tgt'!$D:$D),0),0) -> 0 | BP13: =ROUND(IFERROR(AT13/_xlfn.XLOOKUP(BP$7,'Product Tgt'!$B:$B,'Product Tgt'!$D:$D),0),0) -> 0 | BQ13: =ROUND(IFERROR(AU13/_xlfn.XLOOKUP(BQ$7,'Product Tgt'!$B:$B,'Product Tgt'!$D:$D),0),0) -> 0 | BR13: =ROUND(IFERROR(AV13/_xlfn.XLOOKUP(BR$7,'Product Tgt'!$B:$B,'Product Tgt'!$D:$D),0),0) -> 0 | BS13: =ROUND(IFERROR(AW13/_xlfn.XLOOKUP(BS$7,'Product Tgt'!$B:$B,'Product Tgt'!$D:$D),0),0) -> 0 | BT13: =ROUND(IFERROR(AX13/_xlfn.XLOOKUP(BT$7,'Product Tgt'!$B:$B,'Product Tgt'!$D:$D),0),0) -> 0 | ... BZ13: =ROUND(IFERROR(BD13/_xlfn.XLOOKUP(BZ$7,'Product Tgt'!$B:$B,'Product Tgt'!$D:$D),0),0) -> 0
A14: SYK-BSMA-BSM1 | B14: =_xlfn.XLOOKUP(A14,'Terr Target'!$A:$A,'Terr Target'!$E:$E) -> 407086.47 | C14: =SUM(AF14:BD14) -> 407086.2 | D14: =C14-B14 -> -0.27558492 | E14: =ABS(D14)/C14 -> 6.7696946e-07 | F14: =(1-(D14/C14)) -> 1.0000007 | G14: 9052.8447 | H14: 15821.049 | I14: 69324.587 | J14: 107818.23 | K14: 13874.482 | L14: 7845.3138 | M14: 0 | N14: 4861.5042 | O14: 16628.087 | P14: 2901.1902 | Q14: 2126.625 | R14: 4647.8718 | S14: 17367.515 | T14: 7510.0867 | U14: 14412.33 | V14: 8066.7312 | W14: 14215.691 | X14: 14494.759 | Y14: 9664.5054 | Z14: 39146.424 | AA14: 4725.3614 | AB14: 18099.487 | AC14: 4619.641 | AD14: 5003.7753 | AE14: 846.84409 | AF14: =IFERROR(_xlfn.XLOOKUP(AF$7,'Product Tgt'!$B:$B,'Product Tgt'!$G:$G)*G14/G$60,0) -> 9119.6858 | AG14: =IFERROR(_xlfn.XLOOKUP(AG$7,'Product Tgt'!$B:$B,'Product Tgt'!$G:$G)*H14/H$60,0) -> 16198.336 | AH14: =IFERROR(_xlfn.XLOOKUP(AH$7,'Product Tgt'!$B:$B,'Product Tgt'!$G:$G)*I14/I$60,0) -> 69231.55 | AI14: =IFERROR(_xlfn.XLOOKUP(AI$7,'Product Tgt'!$B:$B,'Product Tgt'!$G:$G)*J14/J$60,0) -> 107354.12 | AJ14: =IFERROR(_xlfn.XLOOKUP(AJ$7,'Product Tgt'!$B:$B,'Product Tgt'!$G:$G)*K14/K$60,0) -> 13646.773 | AK14: =IFERROR(_xlfn.XLOOKUP(AK$7,'Product Tgt'!$B:$B,'Product Tgt'!$G:$G)*L14/L$60,0) -> 8074.2111 | AL14: =IFERROR(_xlfn.XLOOKUP(AL$7,'Product Tgt'!$B:$B,'Product Tgt'!$G:$G)*M14/M$60,0) -> 0 | AM14: =IFERROR(_xlfn.XLOOKUP(AM$7,'Product Tgt'!$B:$B,'Product Tgt'!$G:$G)*N14/N$60,0) -> 4829.0654 | ... BD14: =IFERROR(_xlfn.XLOOKUP(BD$7,'Product Tgt'!$B:$B,'Product Tgt'!$G:$G)*AE14/AE$60,0) -> 848.41146 | BE14: =ROUND(IFERROR(AF14/_xlfn.XLOOKUP(BE$7,'Product Tgt'!$B:$B,'Product Tgt'!$D:$D),0),0) -> 0 | BF14: =ROUND(IFERROR(AG14/_xlfn.XLOOKUP(BF$7,'Product Tgt'!$B:$B,'Product Tgt'!$D:$D),0),0) -> 0 | BG14: =ROUND(IFERROR(AH14/_xlfn.XLOOKUP(BG$7,'Product Tgt'!$B:$B,'Product Tgt'!$D:$D),0),0) -> 0 | BH14: =ROUND(IFERROR(AI14/_xlfn.XLOOKUP(BH$7,'Product Tgt'!$B:$B,'Product Tgt'!$D:$D),0),0) -> 0 | BI14: =ROUND(IFERROR(AM14/_xlfn.XLOOKUP(BI$7,'Product Tgt'!$B:$B,'Product Tgt'!$D:$D),0),0) -> 0 | BJ14: =ROUND(IFERROR(#REF!/_xlfn.XLOOKUP(BJ$7,'Product Tgt'!$B:$B,'Product Tgt'!$D:$D),0),0) -> 0 | BK14: =ROUND(IFERROR(#REF!/_xlfn.XLOOKUP(BK$7,'Product Tgt'!$B:$B,'Product Tgt'!$D:$D),0),0) -> 0 | BL14: =ROUND(IFERROR(AN14/_xlfn.XLOOKUP(BL$7,'Product Tgt'!$B:$B,'Product Tgt'!$D:$D),0),0) -> 0 | BM14: =ROUND(IFERROR(AQ14/_xlfn.XLOOKUP(BM$7,'Product Tgt'!$B:$B,'Product Tgt'!$D:$D),0),0) -> 0 | BN14: =ROUND(IFERROR(AR14/_xlfn.XLOOKUP(BN$7,'Product Tgt'!$B:$B,'Product Tgt'!$D:$D),0),0) -> 0 | BO14: =ROUND(IFERROR(AS14/_xlfn.XLOOKUP(BO$7,'Product Tgt'!$B:$B,'Product Tgt'!$D:$D),0),0) -> 0 | BP14: =ROUND(IFERROR(AT14/_xlfn.XLOOKUP(BP$7,'Product Tgt'!$B:$B,'Product Tgt'!$D:$D),0),0) -> 0 | BQ14: =ROUND(IFERROR(AU14/_xlfn.XLOOKUP(BQ$7,'Product Tgt'!$B:$B,'Product Tgt'!$D:$D),0),0) -> 0 | BR14: =ROUND(IFERROR(AV14/_xlfn.XLOOKUP(BR$7,'Product Tgt'!$B:$B,'Product Tgt'!$D:$D),0),0) -> 0 | BS14: =ROUND(IFERROR(AW14/_xlfn.XLOOKUP(BS$7,'Product Tgt'!$B:$B,'Product Tgt'!$D:$D),0),0) -> 0 | BT14: =ROUND(IFERROR(AX14/_xlfn.XLOOKUP(BT$7,'Product Tgt'!$B:$B,'Product Tgt'!$D:$D),0),0) -> 0 | ... BZ14: =ROUND(IFERROR(BD14/_xlfn.XLOOKUP(BZ$7,'Product Tgt'!$B:$B,'Product Tgt'!$D:$D),0),0) -> 0
A15: SYK-CHDA-CHD1 | B15: =_xlfn.XLOOKUP(A15,'Terr Target'!$A:$A,'Terr Target'!$E:$E) -> 384584.07 | C15: =SUM(AF15:BD15) -> 384583.52 | D15: =C15-B15 -> -0.54634511 | E15: =ABS(D15)/C15 -> 1.420615e-06 | F15: =(1-(D15/C15)) -> 1.0000014 | G15: 13024.741 | H15: 18029.995 | I15: 88464.756 | J15: 108413.17 | K15: 13995.915 | L15: 14028.72 | M15: 0 | N15: 3367.2042 | O15: 6623.1939 | P15: 1374.3799 | Q15: 1172.862 | R15: 1350.43 | S15: 16168.574 | T15: 3062.5754 | U15: 14817.081 | V15: 2963.5064 | W15: 12325.331 | X15: 10614.82 | Y15: 2477.0772 | Z15: 27453.88 | AA15: 7272.6889 | AB15: 13246.709 | AC15: 4003.3309 | AD15: 4336.2176 | AE15: 733.86594 | AF15: =IFERROR(_xlfn.XLOOKUP(AF$7,'Product Tgt'!$B:$B,'Product Tgt'!$G:$G)*G15/G$60,0) -> 13120.909 | AG15: =IFERROR(_xlfn.XLOOKUP(AG$7,'Product Tgt'!$B:$B,'Product Tgt'!$G:$G)*H15/H$60,0) -> 18459.958 | AH15: =IFERROR(_xlfn.XLOOKUP(AH$7,'Product Tgt'!$B:$B,'Product Tgt'!$G:$G)*I15/I$60,0) -> 88346.032 | AI15: =IFERROR(_xlfn.XLOOKUP(AI$7,'Product Tgt'!$B:$B,'Product Tgt'!$G:$G)*J15/J$60,0) -> 107946.5 | AJ15: =IFERROR(_xlfn.XLOOKUP(AJ$7,'Product Tgt'!$B:$B,'Product Tgt'!$G:$G)*K15/K$60,0) -> 13766.213 | AK15: =IFERROR(_xlfn.XLOOKUP(AK$7,'Product Tgt'!$B:$B,'Product Tgt'!$G:$G)*L15/L$60,0) -> 14438.027 | AL15: =IFERROR(_xlfn.XLOOKUP(AL$7,'Product Tgt'!$B:$B,'Product Tgt'!$G:$G)*M15/M$60,0) -> 0 | AM15: =IFERROR(_xlfn.XLOOKUP(AM$7,'Product Tgt'!$B:$B,'Product Tgt'!$G:$G)*N15/N$60,0) -> 3344.7363 | ... BD15: =IFERROR(_xlfn.XLOOKUP(BD$7,'Product Tgt'!$B:$B,'Product Tgt'!$G:$G)*AE15/AE$60,0) -> 735.2242 | BE15: =ROUND(IFERROR(AF15/_xlfn.XLOOKUP(BE$7,'Product Tgt'!$B:$B,'Product Tgt'!$D:$D),0),0) -> 0 | BF15: =ROUND(IFERROR(AG15/_xlfn.XLOOKUP(BF$7,'Product Tgt'!$B:$B,'Product Tgt'!$D:$D),0),0) -> 0 | BG15: =ROUND(IFERROR(AH15/_xlfn.XLOOKUP(BG$7,'Product Tgt'!$B:$B,'Product Tgt'!$D:$D),0),0) -> 0 | BH15: =ROUND(IFERROR(AI15/_xlfn.XLOOKUP(BH$7,'Product Tgt'!$B:$B,'Product Tgt'!$D:$D),0),0) -> 0 | BI15: =ROUND(IFERROR(AM15/_xlfn.XLOOKUP(BI$7,'Product Tgt'!$B:$B,'Product Tgt'!$D:$D),0),0) -> 0 | BJ15: =ROUND(IFERROR(#REF!/_xlfn.XLOOKUP(BJ$7,'Product Tgt'!$B:$B,'Product Tgt'!$D:$D),0),0) -> 0 | BK15: =ROUND(IFERROR(#REF!/_xlfn.XLOOKUP(BK$7,'Product Tgt'!$B:$B,'Product Tgt'!$D:$D),0),0) -> 0 | BL15: =ROUND(IFERROR(AN15/_xlfn.XLOOKUP(BL$7,'Product Tgt'!$B:$B,'Product Tgt'!$D:$D),0),0) -> 0 | BM15: =ROUND(IFERROR(AQ15/_xlfn.XLOOKUP(BM$7,'Product Tgt'!$B:$B,'Product Tgt'!$D:$D),0),0) -> 0 | BN15: =ROUND(IFERROR(AR15/_xlfn.XLOOKUP(BN$7,'Product Tgt'!$B:$B,'Product Tgt'!$D:$D),0),0) -> 0 | BO15: =ROUND(IFERROR(AS15/_xlfn.XLOOKUP(BO$7,'Product Tgt'!$B:$B,'Product Tgt'!$D:$D),0),0) -> 0 | BP15: =ROUND(IFERROR(AT15/_xlfn.XLOOKUP(BP$7,'Product Tgt'!$B:$B,'Product Tgt'!$D:$D),0),0) -> 0 | BQ15: =ROUND(IFERROR(AU15/_xlfn.XLOOKUP(BQ$7,'Product Tgt'!$B:$B,'Product Tgt'!$D:$D),0),0) -> 0 | BR15: =ROUND(IFERROR(AV15/_xlfn.XLOOKUP(BR$7,'Product Tgt'!$B:$B,'Product Tgt'!$D:$D),0),0) -> 0 | BS15: =ROUND(IFERROR(AW15/_xlfn.XLOOKUP(BS$7,'Product Tgt'!$B:$B,'Product Tgt'!$D:$D),0),0) -> 0 | BT15: =ROUND(IFERROR(AX15/_xlfn.XLOOKUP(BT$7,'Product Tgt'!$B:$B,'Product Tgt'!$D:$D),0),0) -> 0 | ... BZ15: =ROUND(IFERROR(BD15/_xlfn.XLOOKUP(BZ$7,'Product Tgt'!$B:$B,'Product Tgt'!$D:$D),0),0) -> 0
A16: SYK-CHWA-CHW1 | B16: =_xlfn.XLOOKUP(A16,'Terr Target'!$A:$A,'Terr Target'!$E:$E) -> 391562.72 | C16: =SUM(AF16:BD16) -> 391563.17 | D16: =C16-B16 -> 0.45244065 | E16: =ABS(D16)/C16 -> 1.1554729e-06 | F16: =(1-(D16/C16)) -> 0.99999884 | G16: 15500.958 | H16: 34578.725 | I16: 102016.91 | J16: 88571.859 | K16: 5524.3084 | L16: 4314.2976 | M16: 0 | N16: 1609.6673 | O16: 9630.7621 | P16: 937.55478 | Q16: 1369.3734 | R16: 0 | S16: 22915.892 | T16: 1506.1967 | U16: 24537.999 | V16: 3853.035 | W16: 11859.348 | X16: 14734.65 | Y16: 2829.5986 | Z16: 25316.181 | AA16: 3319.452 | AB16: 8413.3605 | AC16: 5756.6409 | AD16: 6235.3195 | AE16: 1055.2719 | AF16: =IFERROR(_xlfn.XLOOKUP(AF$7,'Product Tgt'!$B:$B,'Product Tgt'!$G:$G)*G16/G$60,0) -> 15615.408 | AG16: =IFERROR(_xlfn.XLOOKUP(AG$7,'Product Tgt'!$B:$B,'Product Tgt'!$G:$G)*H16/H$60,0) -> 35403.328 | AH16: =IFERROR(_xlfn.XLOOKUP(AH$7,'Product Tgt'!$B:$B,'Product Tgt'!$G:$G)*I16/I$60,0) -> 101879.99 | AI16: =IFERROR(_xlfn.XLOOKUP(AI$7,'Product Tgt'!$B:$B,'Product Tgt'!$G:$G)*J16/J$60,0) -> 88190.598 | AJ16: =IFERROR(_xlfn.XLOOKUP(AJ$7,'Product Tgt'!$B:$B,'Product Tgt'!$G:$G)*K16/K$60,0) -> 5433.6433 | AK16: =IFERROR(_xlfn.XLOOKUP(AK$7,'Product Tgt'!$B:$B,'Product Tgt'!$G:$G)*L16/L$60,0) -> 4440.1729 | AL16: =IFERROR(_xlfn.XLOOKUP(AL$7,'Product Tgt'!$B:$B,'Product Tgt'!$G:$G)*M16/M$60,0) -> 0 | AM16: =IFERROR(_xlfn.XLOOKUP(AM$7,'Product Tgt'!$B:$B,'Product Tgt'!$G:$G)*N16/N$60,0) -> 1598.9267 | ... BD16: =IFERROR(_xlfn.XLOOKUP(BD$7,'Product Tgt'!$B:$B,'Product Tgt'!$G:$G)*AE16/AE$60,0) -> 1057.225 | BE16: =ROUND(IFERROR(AF16/_xlfn.XLOOKUP(BE$7,'Product Tgt'!$B:$B,'Product Tgt'!$D:$D),0),0) -> 0 | BF16: =ROUND(IFERROR(AG16/_xlfn.XLOOKUP(BF$7,'Product Tgt'!$B:$B,'Product Tgt'!$D:$D),0),0) -> 0 | BG16: =ROUND(IFERROR(AH16/_xlfn.XLOOKUP(BG$7,'Product Tgt'!$B:$B,'Product Tgt'!$D:$D),0),0) -> 0 | BH16: =ROUND(IFERROR(AI16/_xlfn.XLOOKUP(BH$7,'Product Tgt'!$B:$B,'Product Tgt'!$D:$D),0),0) -> 0 | BI16: =ROUND(IFERROR(AM16/_xlfn.XLOOKUP(BI$7,'Product Tgt'!$B:$B,'Product Tgt'!$D:$D),0),0) -> 0 | BJ16: =ROUND(IFERROR(#REF!/_xlfn.XLOOKUP(BJ$7,'Product Tgt'!$B:$B,'Product Tgt'!$D:$D),0),0) -> 0 | BK16: =ROUND(IFERROR(#REF!/_xlfn.XLOOKUP(BK$7,'Product Tgt'!$B:$B,'Product Tgt'!$D:$D),0),0) -> 0 | BL16: =ROUND(IFERROR(AN16/_xlfn.XLOOKUP(BL$7,'Product Tgt'!$B:$B,'Product Tgt'!$D:$D),0),0) -> 0 | BM16: =ROUND(IFERROR(AQ16/_xlfn.XLOOKUP(BM$7,'Product Tgt'!$B:$B,'Product Tgt'!$D:$D),0),0) -> 0 | BN16: =ROUND(IFERROR(AR16/_xlfn.XLOOKUP(BN$7,'Product Tgt'!$B:$B,'Product Tgt'!$D:$D),0),0) -> 0 | BO16: =ROUND(IFERROR(AS16/_xlfn.XLOOKUP(BO$7,'Product Tgt'!$B:$B,'Product Tgt'!$D:$D),0),0) -> 0 | BP16: =ROUND(IFERROR(AT16/_xlfn.XLOOKUP(BP$7,'Product Tgt'!$B:$B,'Product Tgt'!$D:$D),0),0) -> 0 | BQ16: =ROUND(IFERROR(AU16/_xlfn.XLOOKUP(BQ$7,'Product Tgt'!$B:$B,'Product Tgt'!$D:$D),0),0) -> 0 | BR16: =ROUND(IFERROR(AV16/_xlfn.XLOOKUP(BR$7,'Product Tgt'!$B:$B,'Product Tgt'!$D:$D),0),0) -> 0 | BS16: =ROUND(IFERROR(AW16/_xlfn.XLOOKUP(BS$7,'Product Tgt'!$B:$B,'Product Tgt'!$D:$D),0),0) -> 0 | BT16: =ROUND(IFERROR(AX16/_xlfn.XLOOKUP(BT$7,'Product Tgt'!$B:$B,'Product Tgt'!$D:$D),0),0) -> 0 | ... BZ16: =ROUND(IFERROR(BD16/_xlfn.XLOOKUP(BZ$7,'Product Tgt'!$B:$B,'Product Tgt'!$D:$D),0),0) -> 0
A17: SYK-COXA-COX1 | B17: =_xlfn.XLOOKUP(A17,'Terr Target'!$A:$A,'Terr Target'!$E:$E) -> 327757.6 | C17: =SUM(AF17:BD17) -> 327757.33 | D17: =C17-B17 -> -0.27876529 | E17: =ABS(D17)/C17 -> 8.5052343e-07 | F17: =(1-(D17/C17)) -> 1.0000009 | G17: 10231.803 | H17: 29361.653 | I17: 93558.282 | J17: 66357.984 | K17: 6637.531 | L17: 5573.1261 | M17: 0 | N17: 1520.5469 | O17: 3300.5475 | P17: 1213.9891 | Q17: 1258.5264 | R17: 1221.8197 | S17: 14478.995 | T17: 3097.0813 | U17: 8742.7586 | V17: 1668.2261 | W17: 12998.132 | X17: 19745.453 | Y17: 3411.6202 | Z17: 25413.729 | AA17: 2932.1768 | AB17: 11451.587 | AC17: 3094.5222 | AD17: 3351.8392 | AE17: 567.26873 | AF17: =IFERROR(_xlfn.XLOOKUP(AF$7,'Product Tgt'!$B:$B,'Product Tgt'!$G:$G)*G17/G$60,0) -> 10307.348 | AG17: =IFERROR(_xlfn.XLOOKUP(AG$7,'Product Tgt'!$B:$B,'Product Tgt'!$G:$G)*H17/H$60,0) -> 30061.843 | AH17: =IFERROR(_xlfn.XLOOKUP(AH$7,'Product Tgt'!$B:$B,'Product Tgt'!$G:$G)*I17/I$60,0) -> 93432.721 | AI17: =IFERROR(_xlfn.XLOOKUP(AI$7,'Product Tgt'!$B:$B,'Product Tgt'!$G:$G)*J17/J$60,0) -> 66072.344 | AJ17: =IFERROR(_xlfn.XLOOKUP(AJ$7,'Product Tgt'!$B:$B,'Product Tgt'!$G:$G)*K17/K$60,0) -> 6528.5956 | AK17: =IFERROR(_xlfn.XLOOKUP(AK$7,'Product Tgt'!$B:$B,'Product Tgt'!$G:$G)*L17/L$60,0) -> 5735.7294 | AL17: =IFERROR(_xlfn.XLOOKUP(AL$7,'Product Tgt'!$B:$B,'Product Tgt'!$G:$G)*M17/M$60,0) -> 0 | AM17: =IFERROR(_xlfn.XLOOKUP(AM$7,'Product Tgt'!$B:$B,'Product Tgt'!$G:$G)*N17/N$60,0) -> 1510.4009 | ... BD17: =IFERROR(_xlfn.XLOOKUP(BD$7,'Product Tgt'!$B:$B,'Product Tgt'!$G:$G)*AE17/AE$60,0) -> 568.31865 | BE17: =ROUND(IFERROR(AF17/_xlfn.XLOOKUP(BE$7,'Product Tgt'!$B:$B,'Product Tgt'!$D:$D),0),0) -> 0 | BF17: =ROUND(IFERROR(AG17/_xlfn.XLOOKUP(BF$7,'Product Tgt'!$B:$B,'Product Tgt'!$D:$D),0),0) -> 0 | BG17: =ROUND(IFERROR(AH17/_xlfn.XLOOKUP(BG$7,'Product Tgt'!$B:$B,'Product Tgt'!$D:$D),0),0) -> 0 | BH17: =ROUND(IFERROR(AI17/_xlfn.XLOOKUP(BH$7,'Product Tgt'!$B:$B,'Product Tgt'!$D:$D),0),0) -> 0 | BI17: =ROUND(IFERROR(AM17/_xlfn.XLOOKUP(BI$7,'Product Tgt'!$B:$B,'Product Tgt'!$D:$D),0),0) -> 0 | BJ17: =ROUND(IFERROR(#REF!/_xlfn.XLOOKUP(BJ$7,'Product Tgt'!$B:$B,'Product Tgt'!$D:$D),0),0) -> 0 | BK17: =ROUND(IFERROR(#REF!/_xlfn.XLOOKUP(BK$7,'Product Tgt'!$B:$B,'Product Tgt'!$D:$D),0),0) -> 0 | BL17: =ROUND(IFERROR(AN17/_xlfn.XLOOKUP(BL$7,'Product Tgt'!$B:$B,'Product Tgt'!$D:$D),0),0) -> 0 | BM17: =ROUND(IFERROR(AQ17/_xlfn.XLOOKUP(BM$7,'Product Tgt'!$B:$B,'Product Tgt'!$D:$D),0),0) -> 0 | BN17: =ROUND(IFERROR(AR17/_xlfn.XLOOKUP(BN$7,'Product Tgt'!$B:$B,'Product Tgt'!$D:$D),0),0) -> 0 | BO17: =ROUND(IFERROR(AS17/_xlfn.XLOOKUP(BO$7,'Product Tgt'!$B:$B,'Product Tgt'!$D:$D),0),0) -> 0 | BP17: =ROUND(IFERROR(AT17/_xlfn.XLOOKUP(BP$7,'Product Tgt'!$B:$B,'Product Tgt'!$D:$D),0),0) -> 0 | BQ17: =ROUND(IFERROR(AU17/_xlfn.XLOOKUP(BQ$7,'Product Tgt'!$B:$B,'Product Tgt'!$D:$D),0),0) -> 0 | BR17: =ROUND(IFERROR(AV17/_xlfn.XLOOKUP(BR$7,'Product Tgt'!$B:$B,'Product Tgt'!$D:$D),0),0) -> 0 | BS17: =ROUND(IFERROR(AW17/_xlfn.XLOOKUP(BS$7,'Product Tgt'!$B:$B,'Product Tgt'!$D:$D),0),0) -> 0 | BT17: =ROUND(IFERROR(AX17/_xlfn.XLOOKUP(BT$7,'Product Tgt'!$B:$B,'Product Tgt'!$D:$D),0),0) -> 0 | ... BZ17: =ROUND(IFERROR(BD17/_xlfn.XLOOKUP(BZ$7,'Product Tgt'!$B:$B,'Product Tgt'!$D:$D),0),0) -> 0
A18: SYK-CTGA-CGH1 | B18: =_xlfn.XLOOKUP(A18,'Terr Target'!$A:$A,'Terr Target'!$E:$E) -> 915961.21 | C18: =SUM(AF18:BD18) -> 915960.33 | D18: =C18-B18 -> -0.8841007 | E18: =ABS(D18)/C18 -> 9.6521725e-07 | F18: =(1-(D18/C18)) -> 1.000001 | G18: 43574.277 | H18: 66667.649 | I18: 199259.2 | J18: 218697.92 | K18: 30420.704 | L18: 8411.5923 | M18: 0 | N18: 7597.6298 | O18: 38968.621 | P18: 5119.8461 | Q18: 4732.0082 | R18: 4286.5903 | S18: 40166.55 | T18: 4317.2556 | U18: 29899.933 | V18: 7334.9138 | W18: 32149.417 | X18: 47905.675 | Y18: 11478.909 | Z18: 73768.191 | AA18: 5003.5758 | AB18: 24526.263 | AC18: 8745.9091 | AD18: 9473.1526 | AE18: 1603.2461 | AF18: =IFERROR(_xlfn.XLOOKUP(AF$7,'Product Tgt'!$B:$B,'Product Tgt'!$G:$G)*G18/G$60,0) -> 43896.004 | AG18: =IFERROR(_xlfn.XLOOKUP(AG$7,'Product Tgt'!$B:$B,'Product Tgt'!$G:$G)*H18/H$60,0) -> 68257.479 | AH18: =IFERROR(_xlfn.XLOOKUP(AH$7,'Product Tgt'!$B:$B,'Product Tgt'!$G:$G)*I18/I$60,0) -> 198991.78 | AI18: =IFERROR(_xlfn.XLOOKUP(AI$7,'Product Tgt'!$B:$B,'Product Tgt'!$G:$G)*J18/J$60,0) -> 217756.53 | AJ18: =IFERROR(_xlfn.XLOOKUP(AJ$7,'Product Tgt'!$B:$B,'Product Tgt'!$G:$G)*K18/K$60,0) -> 29921.439 | AK18: =IFERROR(_xlfn.XLOOKUP(AK$7,'Product Tgt'!$B:$B,'Product Tgt'!$G:$G)*L18/L$60,0) -> 8657.0115 | AL18: =IFERROR(_xlfn.XLOOKUP(AL$7,'Product Tgt'!$B:$B,'Product Tgt'!$G:$G)*M18/M$60,0) -> 0 | AM18: =IFERROR(_xlfn.XLOOKUP(AM$7,'Product Tgt'!$B:$B,'Product Tgt'!$G:$G)*N18/N$60,0) -> 7546.9341 | ... BD18: =IFERROR(_xlfn.XLOOKUP(BD$7,'Product Tgt'!$B:$B,'Product Tgt'!$G:$G)*AE18/AE$60,0) -> 1606.2135 | BE18: =ROUND(IFERROR(AF18/_xlfn.XLOOKUP(BE$7,'Product Tgt'!$B:$B,'Product Tgt'!$D:$D),0),0) -> 0 | BF18: =ROUND(IFERROR(AG18/_xlfn.XLOOKUP(BF$7,'Product Tgt'!$B:$B,'Product Tgt'!$D:$D),0),0) -> 0 | BG18: =ROUND(IFERROR(AH18/_xlfn.XLOOKUP(BG$7,'Product Tgt'!$B:$B,'Product Tgt'!$D:$D),0),0) -> 0 | BH18: =ROUND(IFERROR(AI18/_xlfn.XLOOKUP(BH$7,'Product Tgt'!$B:$B,'Product Tgt'!$D:$D),0),0) -> 0 | BI18: =ROUND(IFERROR(AM18/_xlfn.XLOOKUP(BI$7,'Product Tgt'!$B:$B,'Product Tgt'!$D:$D),0),0) -> 0 | BJ18: =ROUND(IFERROR(#REF!/_xlfn.XLOOKUP(BJ$7,'Product Tgt'!$B:$B,'Product Tgt'!$D:$D),0),0) -> 0 | BK18: =ROUND(IFERROR(#REF!/_xlfn.XLOOKUP(BK$7,'Product Tgt'!$B:$B,'Product Tgt'!$D:$D),0),0) -> 0 | BL18: =ROUND(IFERROR(AN18/_xlfn.XLOOKUP(BL$7,'Product Tgt'!$B:$B,'Product Tgt'!$D:$D),0),0) -> 0 | BM18: =ROUND(IFERROR(AQ18/_xlfn.XLOOKUP(BM$7,'Product Tgt'!$B:$B,'Product Tgt'!$D:$D),0),0) -> 0 | BN18: =ROUND(IFERROR(AR18/_xlfn.XLOOKUP(BN$7,'Product Tgt'!$B:$B,'Product Tgt'!$D:$D),0),0) -> 0 | BO18: =ROUND(IFERROR(AS18/_xlfn.XLOOKUP(BO$7,'Product Tgt'!$B:$B,'Product Tgt'!$D:$D),0),0) -> 0 | BP18: =ROUND(IFERROR(AT18/_xlfn.XLOOKUP(BP$7,'Product Tgt'!$B:$B,'Product Tgt'!$D:$D),0),0) -> 0 | BQ18: =ROUND(IFERROR(AU18/_xlfn.XLOOKUP(BQ$7,'Product Tgt'!$B:$B,'Product Tgt'!$D:$D),0),0) -> 0 | BR18: =ROUND(IFERROR(AV18/_xlfn.XLOOKUP(BR$7,'Product Tgt'!$B:$B,'Product Tgt'!$D:$D),0),0) -> 0 | BS18: =ROUND(IFERROR(AW18/_xlfn.XLOOKUP(BS$7,'Product Tgt'!$B:$B,'Product Tgt'!$D:$D),0),0) -> 0 | BT18: =ROUND(IFERROR(AX18/_xlfn.XLOOKUP(BT$7,'Product Tgt'!$B:$B,'Product Tgt'!$D:$D),0),0) -> 0 | ... BZ18: =ROUND(IFERROR(BD18/_xlfn.XLOOKUP(BZ$7,'Product Tgt'!$B:$B,'Product Tgt'!$D:$D),0),0) -> 0
A19: SYK-CTGB-CMC3 | B19: =_xlfn.XLOOKUP(A19,'Terr Target'!$A:$A,'Terr Target'!$E:$E) -> 552125.88 | C19: =SUM(AF19:BD19) -> 552125.35 | D19: =C19-B19 -> -0.52476792 | E19: =ABS(D19)/C19 -> 9.5045068e-07 | F19: =(1-(D19/C19)) -> 1.000001 | G19: 25282.113 | H19: 35633.114 | I19: 120415.09 | J19: 119630.98 | K19: 15187.872 | L19: 6289.0289 | M19: 0 | N19: 5267.2038 | O19: 19583.643 | P19: 3147.4396 | Q19: 3959.2962 | R19: 2798.5291 | S19: 20063.558 | T19: 3638.0918 | U19: 19670.925 | V19: 5837.6629 | W19: 23652.519 | X19: 34618.694 | Y19: 9701.1166 | Z19: 45823.347 | AA19: 4085.7148 | AB19: 22605.436 | AC19: 5099.671 | AD19: 5523.721 | AE19: 934.84024 | AF19: =IFERROR(_xlfn.XLOOKUP(AF$7,'Product Tgt'!$B:$B,'Product Tgt'!$G:$G)*G19/G$60,0) -> 25468.781 | AG19: =IFERROR(_xlfn.XLOOKUP(AG$7,'Product Tgt'!$B:$B,'Product Tgt'!$G:$G)*H19/H$60,0) -> 36482.861 | AH19: =IFERROR(_xlfn.XLOOKUP(AH$7,'Product Tgt'!$B:$B,'Product Tgt'!$G:$G)*I19/I$60,0) -> 120253.49 | AI19: =IFERROR(_xlfn.XLOOKUP(AI$7,'Product Tgt'!$B:$B,'Product Tgt'!$G:$G)*J19/J$60,0) -> 119116.03 | AJ19: =IFERROR(_xlfn.XLOOKUP(AJ$7,'Product Tgt'!$B:$B,'Product Tgt'!$G:$G)*K19/K$60,0) -> 14938.608 | AK19: =IFERROR(_xlfn.XLOOKUP(AK$7,'Product Tgt'!$B:$B,'Product Tgt'!$G:$G)*L19/L$60,0) -> 6472.5195 | AL19: =IFERROR(_xlfn.XLOOKUP(AL$7,'Product Tgt'!$B:$B,'Product Tgt'!$G:$G)*M19/M$60,0) -> 0 | AM19: =IFERROR(_xlfn.XLOOKUP(AM$7,'Product Tgt'!$B:$B,'Product Tgt'!$G:$G)*N19/N$60,0) -> 5232.058 | ... BD19: =IFERROR(_xlfn.XLOOKUP(BD$7,'Product Tgt'!$B:$B,'Product Tgt'!$G:$G)*AE19/AE$60,0) -> 936.57047 | BE19: =ROUND(IFERROR(AF19/_xlfn.XLOOKUP(BE$7,'Product Tgt'!$B:$B,'Product Tgt'!$D:$D),0),0) -> 0 | BF19: =ROUND(IFERROR(AG19/_xlfn.XLOOKUP(BF$7,'Product Tgt'!$B:$B,'Product Tgt'!$D:$D),0),0) -> 0 | BG19: =ROUND(IFERROR(AH19/_xlfn.XLOOKUP(BG$7,'Product Tgt'!$B:$B,'Product Tgt'!$D:$D),0),0) -> 0 | BH19: =ROUND(IFERROR(AI19/_xlfn.XLOOKUP(BH$7,'Product Tgt'!$B:$B,'Product Tgt'!$D:$D),0),0) -> 0 | BI19: =ROUND(IFERROR(AM19/_xlfn.XLOOKUP(BI$7,'Product Tgt'!$B:$B,'Product Tgt'!$D:$D),0),0) -> 0 | BJ19: =ROUND(IFERROR(#REF!/_xlfn.XLOOKUP(BJ$7,'Product Tgt'!$B:$B,'Product Tgt'!$D:$D),0),0) -> 0 | BK19: =ROUND(IFERROR(#REF!/_xlfn.XLOOKUP(BK$7,'Product Tgt'!$B:$B,'Product Tgt'!$D:$D),0),0) -> 0 | BL19: =ROUND(IFERROR(AN19/_xlfn.XLOOKUP(BL$7,'Product Tgt'!$B:$B,'Product Tgt'!$D:$D),0),0) -> 0 | BM19: =ROUND(IFERROR(AQ19/_xlfn.XLOOKUP(BM$7,'Product Tgt'!$B:$B,'Product Tgt'!$D:$D),0),0) -> 0 | BN19: =ROUND(IFERROR(AR19/_xlfn.XLOOKUP(BN$7,'Product Tgt'!$B:$B,'Product Tgt'!$D:$D),0),0) -> 0 | BO19: =ROUND(IFERROR(AS19/_xlfn.XLOOKUP(BO$7,'Product Tgt'!$B:$B,'Product Tgt'!$D:$D),0),0) -> 0 | BP19: =ROUND(IFERROR(AT19/_xlfn.XLOOKUP(BP$7,'Product Tgt'!$B:$B,'Product Tgt'!$D:$D),0),0) -> 0 | BQ19: =ROUND(IFERROR(AU19/_xlfn.XLOOKUP(BQ$7,'Product Tgt'!$B:$B,'Product Tgt'!$D:$D),0),0) -> 0 | BR19: =ROUND(IFERROR(AV19/_xlfn.XLOOKUP(BR$7,'Product Tgt'!$B:$B,'Product Tgt'!$D:$D),0),0) -> 0 | BS19: =ROUND(IFERROR(AW19/_xlfn.XLOOKUP(BS$7,'Product Tgt'!$B:$B,'Product Tgt'!$D:$D),0),0) -> 0 | BT19: =ROUND(IFERROR(AX19/_xlfn.XLOOKUP(BT$7,'Product Tgt'!$B:$B,'Product Tgt'!$D:$D),0),0) -> 0 | ... BZ19: =ROUND(IFERROR(BD19/_xlfn.XLOOKUP(BZ$7,'Product Tgt'!$B:$B,'Product Tgt'!$D:$D),0),0) -> 0
... A56: SYK-SYLA-SYL1 | B56: =_xlfn.XLOOKUP(A56,'Terr Target'!$A:$A,'Terr Target'!$E:$E) -> 612139.72 | C56: =SUM(AF56:BD56) -> 612140.43 | D56: =C56-B56 -> 0.70853622 | E56: =ABS(D56)/C56 -> 1.1574733e-06 | F56: =(1-(D56/C56)) -> 0.99999884 | G56: 22593.81 | H56: 25422.551 | I56: 125096.39 | J56: 201896.2 | K56: 11712.646 | L56: 3778.1716 | M56: 0 | N56: 4069.9558 | O56: 7105.8664 | P56: 1281.1986 | Q56: 2269.9718 | R56: 2377.0422 | S56: 20528.403 | T56: 6541.4483 | U56: 29326.562 | V56: 5846.5927 | W56: 25840.886 | X56: 46756.766 | Y56: 6785.7671 | Z56: 35501.808 | AA56: 5596.3145 | AB56: 14688.491 | AC56: 6630.9911 | AD56: 7182.374 | AE56: 1215.5524 | AF56: =IFERROR(_xlfn.XLOOKUP(AF$7,'Product Tgt'!$B:$B,'Product Tgt'!$G:$G)*G56/G$60,0) -> 22760.63 | AG56: =IFERROR(_xlfn.XLOOKUP(AG$7,'Product Tgt'!$B:$B,'Product Tgt'!$G:$G)*H56/H$60,0) -> 26028.805 | AH56: =IFERROR(_xlfn.XLOOKUP(AH$7,'Product Tgt'!$B:$B,'Product Tgt'!$G:$G)*I56/I$60,0) -> 124928.5 | AI56: =IFERROR(_xlfn.XLOOKUP(AI$7,'Product Tgt'!$B:$B,'Product Tgt'!$G:$G)*J56/J$60,0) -> 201027.14 | AJ56: =IFERROR(_xlfn.XLOOKUP(AJ$7,'Product Tgt'!$B:$B,'Product Tgt'!$G:$G)*K56/K$60,0) -> 11520.418 | AK56: =IFERROR(_xlfn.XLOOKUP(AK$7,'Product Tgt'!$B:$B,'Product Tgt'!$G:$G)*L56/L$60,0) -> 3888.4047 | AL56: =IFERROR(_xlfn.XLOOKUP(AL$7,'Product Tgt'!$B:$B,'Product Tgt'!$G:$G)*M56/M$60,0) -> 0 | AM56: =IFERROR(_xlfn.XLOOKUP(AM$7,'Product Tgt'!$B:$B,'Product Tgt'!$G:$G)*N56/N$60,0) -> 4042.7988 | ... BD56: =IFERROR(_xlfn.XLOOKUP(BD$7,'Product Tgt'!$B:$B,'Product Tgt'!$G:$G)*AE56/AE$60,0) -> 1217.8022 | BE56: =ROUND(IFERROR(AF56/_xlfn.XLOOKUP(BE$7,'Product Tgt'!$B:$B,'Product Tgt'!$D:$D),0),0) -> 0 | BF56: =ROUND(IFERROR(AG56/_xlfn.XLOOKUP(BF$7,'Product Tgt'!$B:$B,'Product Tgt'!$D:$D),0),0) -> 0 | BG56: =ROUND(IFERROR(AH56/_xlfn.XLOOKUP(BG$7,'Product Tgt'!$B:$B,'Product Tgt'!$D:$D),0),0) -> 0 | BH56: =ROUND(IFERROR(AI56/_xlfn.XLOOKUP(BH$7,'Product Tgt'!$B:$B,'Product Tgt'!$D:$D),0),0) -> 0 | BI56: =ROUND(IFERROR(AM56/_xlfn.XLOOKUP(BI$7,'Product Tgt'!$B:$B,'Product Tgt'!$D:$D),0),0) -> 0 | BJ56: =ROUND(IFERROR(#REF!/_xlfn.XLOOKUP(BJ$7,'Product Tgt'!$B:$B,'Product Tgt'!$D:$D),0),0) -> 0 | BK56: =ROUND(IFERROR(#REF!/_xlfn.XLOOKUP(BK$7,'Product Tgt'!$B:$B,'Product Tgt'!$D:$D),0),0) -> 0 | BL56: =ROUND(IFERROR(AN56/_xlfn.XLOOKUP(BL$7,'Product Tgt'!$B:$B,'Product Tgt'!$D:$D),0),0) -> 0 | BM56: =ROUND(IFERROR(AQ56/_xlfn.XLOOKUP(BM$7,'Product Tgt'!$B:$B,'Product Tgt'!$D:$D),0),0) -> 0 | BN56: =ROUND(IFERROR(AR56/_xlfn.XLOOKUP(BN$7,'Product Tgt'!$B:$B,'Product Tgt'!$D:$D),0),0) -> 0 | BO56: =ROUND(IFERROR(AS56/_xlfn.XLOOKUP(BO$7,'Product Tgt'!$B:$B,'Product Tgt'!$D:$D),0),0) -> 0 | BP56: =ROUND(IFERROR(AT56/_xlfn.XLOOKUP(BP$7,'Product Tgt'!$B:$B,'Product Tgt'!$D:$D),0),0) -> 0 | BQ56: =ROUND(IFERROR(AU56/_xlfn.XLOOKUP(BQ$7,'Product Tgt'!$B:$B,'Product Tgt'!$D:$D),0),0) -> 0 | BR56: =ROUND(IFERROR(AV56/_xlfn.XLOOKUP(BR$7,'Product Tgt'!$B:$B,'Product Tgt'!$D:$D),0),0) -> 0 | BS56: =ROUND(IFERROR(AW56/_xlfn.XLOOKUP(BS$7,'Product Tgt'!$B:$B,'Product Tgt'!$D:$D),0),0) -> 0 | BT56: =ROUND(IFERROR(AX56/_xlfn.XLOOKUP(BT$7,'Product Tgt'!$B:$B,'Product Tgt'!$D:$D),0),0) -> 0 | ... BZ56: =ROUND(IFERROR(BD56/_xlfn.XLOOKUP(BZ$7,'Product Tgt'!$B:$B,'Product Tgt'!$D:$D),0),0) -> 0
A57: SYK-SYLB-SYL2 | B57: =_xlfn.XLOOKUP(A57,'Terr Target'!$A:$A,'Terr Target'!$E:$E) -> 603155.37 | C57: =SUM(AF57:BD57) -> 603156.19 | D57: =C57-B57 -> 0.8220882 | E57: =ABS(D57)/C57 -> 1.3629773e-06 | F57: =(1-(D57/C57)) -> 0.99999864 | G57: 20533.649 | H57: 27840.846 | I57: 124946.83 | J57: 207119.35 | K57: 11732.555 | L57: 3731.2107 | M57: 0 | N57: 2927.8411 | O57: 6792.195 | P57: 1241.9502 | Q57: 2143.7121 | R57: 2305.526 | S57: 22555.898 | T57: 6544.959 | U57: 33270.888 | V57: 5092.7937 | W57: 19900.584 | X57: 33576.166 | Y57: 6282.1426 | Z57: 36466.916 | AA57: 5739.1795 | AB57: 14540.963 | AC57: 7333.56 | AD57: 7943.3633 | AE57: 1344.343 | AF57: =IFERROR(_xlfn.XLOOKUP(AF$7,'Product Tgt'!$B:$B,'Product Tgt'!$G:$G)*G57/G$60,0) -> 20685.258 | AG57: =IFERROR(_xlfn.XLOOKUP(AG$7,'Product Tgt'!$B:$B,'Product Tgt'!$G:$G)*H57/H$60,0) -> 28504.77 | AH57: =IFERROR(_xlfn.XLOOKUP(AH$7,'Product Tgt'!$B:$B,'Product Tgt'!$G:$G)*I57/I$60,0) -> 124779.14 | AI57: =IFERROR(_xlfn.XLOOKUP(AI$7,'Product Tgt'!$B:$B,'Product Tgt'!$G:$G)*J57/J$60,0) -> 206227.8 | AJ57: =IFERROR(_xlfn.XLOOKUP(AJ$7,'Product Tgt'!$B:$B,'Product Tgt'!$G:$G)*K57/K$60,0) -> 11540 | AK57: =IFERROR(_xlfn.XLOOKUP(AK$7,'Product Tgt'!$B:$B,'Product Tgt'!$G:$G)*L57/L$60,0) -> 3840.0736 | AL57: =IFERROR(_xlfn.XLOOKUP(AL$7,'Product Tgt'!$B:$B,'Product Tgt'!$G:$G)*M57/M$60,0) -> 0 | AM57: =IFERROR(_xlfn.XLOOKUP(AM$7,'Product Tgt'!$B:$B,'Product Tgt'!$G:$G)*N57/N$60,0) -> 2908.3049 | ... BD57: =IFERROR(_xlfn.XLOOKUP(BD$7,'Product Tgt'!$B:$B,'Product Tgt'!$G:$G)*AE57/AE$60,0) -> 1346.8312
A58: SYK-TANA-TAN1 | B58: =_xlfn.XLOOKUP(A58,'Terr Target'!$A:$A,'Terr Target'!$E:$E) -> 363051.34 | C58: =SUM(AF58:BD58) -> 363051.27 | D58: =C58-B58 -> -0.076930205 | E58: =ABS(D58)/C58 -> 2.1189901e-07 | F58: =(1-(D58/C58)) -> 1.0000002 | G58: 17794.529 | H58: 15606.926 | I58: 73991.626 | J58: 84877.396 | K58: 9371.4608 | L58: 7204.2437 | M58: 0 | N58: 2655.0139 | O58: 8749.7782 | P58: 2333.6235 | Q58: 1360.5092 | R58: 1203.6381 | S58: 12896.587 | T58: 2960.7061 | U58: 17829.468 | V58: 7395.2712 | W58: 25527.682 | X58: 17982.254 | Y58: 5616.6334 | Z58: 31565.274 | AA58: 2170.2985 | AB58: 9991.8386 | AC58: 3960.8302 | AD58: 4290.1827 | AE58: 726.07496 | AF58: =IFERROR(_xlfn.XLOOKUP(AF$7,'Product Tgt'!$B:$B,'Product Tgt'!$G:$G)*G58/G$60,0) -> 17925.914 | AG58: =IFERROR(_xlfn.XLOOKUP(AG$7,'Product Tgt'!$B:$B,'Product Tgt'!$G:$G)*H58/H$60,0) -> 15979.106 | AH58: =IFERROR(_xlfn.XLOOKUP(AH$7,'Product Tgt'!$B:$B,'Product Tgt'!$G:$G)*I58/I$60,0) -> 73892.326 | AI58: =IFERROR(_xlfn.XLOOKUP(AI$7,'Product Tgt'!$B:$B,'Product Tgt'!$G:$G)*J58/J$60,0) -> 84512.039 | AJ58: =IFERROR(_xlfn.XLOOKUP(AJ$7,'Product Tgt'!$B:$B,'Product Tgt'!$G:$G)*K58/K$60,0) -> 9217.6561 | AK58: =IFERROR(_xlfn.XLOOKUP(AK$7,'Product Tgt'!$B:$B,'Product Tgt'!$G:$G)*L58/L$60,0) -> 7414.4369 | AL58: =IFERROR(_xlfn.XLOOKUP(AL$7,'Product Tgt'!$B:$B,'Product Tgt'!$G:$G)*M58/M$60,0) -> 0 | AM58: =IFERROR(_xlfn.XLOOKUP(AM$7,'Product Tgt'!$B:$B,'Product Tgt'!$G:$G)*N58/N$60,0) -> 2637.2981 | ... BD58: =IFERROR(_xlfn.XLOOKUP(BD$7,'Product Tgt'!$B:$B,'Product Tgt'!$G:$G)*AE58/AE$60,0) -> 727.4188
A59: SYK-UTTA-UTT1 | B59: =_xlfn.XLOOKUP(A59,'Terr Target'!$A:$A,'Terr Target'!$E:$E) -> 505843.8 | C59: =SUM(AF59:BD59) -> 505843.5 | D59: =C59-B59 -> -0.29218343 | E59: =ABS(D59)/C59 -> 5.7761625e-07 | F59: =(1-(D59/C59)) -> 1.0000006 | G59: 12538.229 | H59: 21150.575 | I59: 95488.834 | J59: 133499.89 | K59: 10296.9 | L59: 7607.9324 | M59: 0 | N59: 7535.3433 | O59: 28550.707 | P59: 4398.2241 | Q59: 4697.7645 | R59: 4567.8328 | S59: 17569.198 | T59: 7741.0157 | U59: 18034.825 | V59: 8203.2693 | W59: 17990.992 | X59: 15904.226 | Y59: 9648.1956 | Z59: 43200.222 | AA59: 5317.02 | AB59: 27277.296 | AC59: 5096.4333 | AD59: 5520.2141 | AE59: 934.24673 | AF59: =IFERROR(_xlfn.XLOOKUP(AF$7,'Product Tgt'!$B:$B,'Product Tgt'!$G:$G)*G59/G$60,0) -> 12630.804 | AG59: =IFERROR(_xlfn.XLOOKUP(AG$7,'Product Tgt'!$B:$B,'Product Tgt'!$G:$G)*H59/H$60,0) -> 21654.955 | AH59: =IFERROR(_xlfn.XLOOKUP(AH$7,'Product Tgt'!$B:$B,'Product Tgt'!$G:$G)*I59/I$60,0) -> 95360.683 | AI59: =IFERROR(_xlfn.XLOOKUP(AI$7,'Product Tgt'!$B:$B,'Product Tgt'!$G:$G)*J59/J$60,0) -> 132925.24 | AJ59: =IFERROR(_xlfn.XLOOKUP(AJ$7,'Product Tgt'!$B:$B,'Product Tgt'!$G:$G)*K59/K$60,0) -> 10127.907 | AK59: =IFERROR(_xlfn.XLOOKUP(AK$7,'Product Tgt'!$B:$B,'Product Tgt'!$G:$G)*L59/L$60,0) -> 7829.9038 | AL59: =IFERROR(_xlfn.XLOOKUP(AL$7,'Product Tgt'!$B:$B,'Product Tgt'!$G:$G)*M59/M$60,0) -> 0 | AM59: =IFERROR(_xlfn.XLOOKUP(AM$7,'Product Tgt'!$B:$B,'Product Tgt'!$G:$G)*N59/N$60,0) -> 7485.0632 | ... BD59: =IFERROR(_xlfn.XLOOKUP(BD$7,'Product Tgt'!$B:$B,'Product Tgt'!$G:$G)*AE59/AE$60,0) -> 935.97587
B60: =SUM(B8:B59) -> 22152846 | C60: =SUM(C8:C59) -> 22152846 | D60: =SUM(D8:D59) -> -1.891749e-09 | G60: =SUM(G8:G59) -> 788177.54 | H60: =SUM(H8:H59) -> 1142711.2 | I60: =SUM(I8:I59) -> 4747179.2 | J60: =SUM(J8:J59) -> 5768343.4 | K60: =SUM(K8:K59) -> 739133.52 | L60: =SUM(L8:L59) -> 361743.95 | M60: =SUM(M8:M59) -> 39883.784 | N60: =SUM(N8:N59) -> 218721.23 | ... AE60: =SUM(AE8:AE59) -> 49378.608

Sheet Product Tgt
A1: Family | B1: Product Id | C1: Product Name | D1: TP | E1: Group | F1: Sales Line | G1: Nov'25 TGT | H1: Qty
A2: Epilim | B2: 542 | C2: Epilim 100ml Syp | D2: 60.38 | E2: CNS | F2: SYNKEI | G2: 793997 | H2: =G2/D2 -> 13150 | I2: =_xlfn.XLOOKUP($B2,SYK_SORT!$B$2:$Z$2,SYK_SORT!$B$2:$Z$2) -> 542
A3: Epilim | B3: 543 | C3: EPILIM 200mg Tab | D3: 225.6 | E3: CNS | F3: SYNKEI | G3: 1169961.6 | H3: =G3/D3 -> 5186 | I3: =_xlfn.XLOOKUP($B3,SYK_SORT!$B$2:$Z$2,SYK_SORT!$B$2:$Z$2) -> 543
A4: Epilim | B4: 545 | C4: EPILIM 300mg Tab | D4: 360.6 | E4: CNS | F4: SYNKEI | G4: 4740808.2 | H4: =G4/D4 -> 13147 | I4: =_xlfn.XLOOKUP($B4,SYK_SORT!$B$2:$Z$2,SYK_SORT!$B$2:$Z$2) -> 545
A5: Epilim | B5: 547 | C5: EPILIM 500mg Tab | D5: 433.44 | E5: CNS | F5: SYNKEI | G5: 5743513.4 | H5: =G5/D5 -> 13251 | I5: =_xlfn.XLOOKUP($B5,SYK_SORT!$B$2:$Z$2,SYK_SORT!$B$2:$Z$2) -> 547
A6: EXPRES | B6: 552 | C6: EXPRES 5mg Tab | D6: 157.42 | E6: CNS | F6: SYNKEI | G6: 372298.3 | H6: =G6/D6 -> 2365 | I6: =_xlfn.XLOOKUP($B6,SYK_SORT!$B$2:$Z$2,SYK_SORT!$B$2:$Z$2) -> 552
A7: EXPRES | B7: 551 | C7: EXPRES 10mg Tab | D7: 269.86 | E7: CNS | F7: SYNKEI | G7: 727002.84 | H7: =G7/D7 -> 2694 | I7: =_xlfn.XLOOKUP($B7,SYK_SORT!$B$2:$Z$2,SYK_SORT!$B$2:$Z$2) -> 551
A8: Imovane | B8: 578 | C8: Imovane 7.5mg Tab 3x10's | D8: 225.56 | E8: CNS | F8: SYNKEI | G8: 39924.12 | H8: =G8/D8 -> 177 | I8: =_xlfn.XLOOKUP($B8,SYK_SORT!$B$2:$Z$2,SYK_SORT!$B$2:$Z$2) -> 578
A9: Leveron | B9: 596 | C9: Leveron 250mg Tab 5x6's | D9: 360.9 | E9: CNS | F9: SYNKEI | G9: 217261.8 | H9: =G9/D9 -> 602 | I9: =_xlfn.XLOOKUP($B9,SYK_SORT!$B$2:$Z$2,SYK_SORT!$B$2:$Z$2) -> 596
A10: Leveron | B10: 598 | C10: Leveron 500mg Tab 5x4's | D10: 451.13 | E10: CNS | F10: SYNKEI | G10: 683461.95 | H10: =G10/D10 -> 1515 | I10: =_xlfn.XLOOKUP($B10,SYK_SORT!$B$2:$Z$2,SYK_SORT!$B$2:$Z$2) -> 598
A11: Leveron | B11: 597 | C11: LEVERON 100ml Syp | D11: 299.85 | E11: CNS | F11: SYNKEI | G11: 113943 | H11: =G11/D11 -> 380 | I11: =_xlfn.XLOOKUP($B11,SYK_SORT!$B$2:$Z$2,SYK_SORT!$B$2:$Z$2) -> 597
A12: Qpine | B12: 636 | C12: Qpine 25mg Tab 10x10's | D12: 226.32 | E12: CNS | F12: SYNKEI | G12: 817954.96 | H12: =G12/D12 -> 3614.1523 | I12: =_xlfn.XLOOKUP($B12,SYK_SORT!$B$2:$Z$2,SYK_SORT!$B$2:$Z$2) -> 636
A13: Qpine | B13: 634 | C13: Qpine 100mg Tab 3x10's | D13: 226.47 | E13: CNS | F13: SYNKEI | G13: 979524.15 | H13: =G13/D13 -> 4325.1828 | I13: =_xlfn.XLOOKUP($B13,SYK_SORT!$B$2:$Z$2,SYK_SORT!$B$2:$Z$2) -> 634
... A26: Qpine XR | B26: 815 | C26: Qpine XR 300 mg Tab 2x10's | D26: 329.8 | E26: CNS | F26: SYNKEI | G26: 49470 | H26: =G26/D26 -> 150 | I26: =_xlfn.XLOOKUP($B26,SYK_SORT!$B$2:$Z$2,SYK_SORT!$B$2:$Z$2) -> 815
G27: =SUM(G2:G26) -> 22152846
G28: 22152846
G29: =G27-G28 -> 0

Sheet Terr Target
A1: Territory | B1: Team | C1: Region | D1: Sales line | E1: Current Month
A2: SYK-BBRB-BBR1 | B2: SYGK-BBRB | C2: B. Baria | D2: Synkei | E2: 458787.33
A3: SYK-HABA-HAB1 | B3: SYGK-HABA | C3: B. Baria | D3: Synkei | E3: 349169.74
A4: SYK-NARA-NAR1 | B4: SYGK-NARA | C4: B. Baria | D4: Synkei | E4: 324797.38
A5: SYK-BSLA-BSL1 | B5: SYGK-BSLA | C5: Barishal | D5: Synkei | E5: 368041.71
A6: SYK-BSLB-BSL2 | B6: SYGK-BSLB | C6: Barishal | D6: Synkei | E6: 349147.34
A7: SYK-BOGA-BOG1 | B7: SYGK-BOGA | C7: Bogura | D7: Synkei | E7: 491068.86
A8: SYK-NAOA-NAO1 | B8: SYGK-NAOA | C8: Bogura | D8: Synkei | E8: 246203.88
A9: SYK-CTGA-CGH1 | B9: SYGK-CTGA | C9: Chattogram-1 | D9: Synkei | E9: 915961.21
A10: SYK-CTGD-MOS1 | B10: SYGK-CTGD | C10: Chattogram-1 | D10: Synkei | E10: 811435.87
A11: SYK-COXA-COX1 | B11: SYGK-COXA | C11: Chattogram-2 | D11: Synkei | E11: 327757.6
A12: SYK-CTGB-CMC3 | B12: SYGK-CTGB | C12: Chattogram-2 | D12: Synkei | E12: 552125.88
A13: SYK-CTGC-CMC4 | B13: SYGK-CTGC | C13: Chattogram-2 | D13: Synkei | E13: 402649.42
... A53: SYK-SYLB-SYL2 | B53: SYGK-SYLB | C53: Sylhet | D53: Synkei | E53: 603155.37
E54: =SUM(E2:E53) -> 22152846

Sheet SYK_SORT
B1: EPILIM 100ml Syrup 1 Bottle | C1: EPILIM 200mg Tab 6x10's | D1: EPILIM 300mg Tab 6x10's | E1: EPILIM 500mg Tab 8x6's | F1: EXPRES 10mg tab 3x10's | G1: EXPRES 5mg Tab 3x10's | H1: IMOVANE 7.5mg Tablet 3x10's | I1: LEVERON 250mg Tab 3X10's | J1: LEVERON 500mg Tab 2X10's | K1: Leveron Syrup 100 ml 1X 100 ml Bottle | L1: Leveron XR 500 mg Tab 2x10's | M1: Leveron XR 750 mg Tab 2x6's | N1: QPINE 100mg Tablet 3x10's | O1: QPINE 200mg Tablet 3x10's | P1: QPINE 25mg Tablet 10x10's | Q1: SPERDAL 1mg tablet 5X10's | R1: SPERDAL 2mg tablet 5X10's | S1: SPERDAL 4mg tablet 3x10's | T1: Sperdal Oral Solution 100 ml | U1: Vortiox 10 mg Tablet 3x10's | V1: Vortiox 20 mg Tablet 2x10's | W1: Vortiox 5 mg Tablet 3x10's | X1: Qpine XR 50 mg Tab 5 x 10's | Y1: Qpine XR 200 mg Tab 3 x 10's | Z1: Qpine XR 300 mg Tab 2 x 10's | AA1: Qpine TOT | AB1: Ratio
A2: Row Labels | B2: 542 | C2: 543 | D2: 545 | E2: 547 | F2: 551 | G2: 552 | H2: 578 | I2: 596 | J2: 598 | K2: 597 | L2: 788 | M2: 789 | N2: 634 | O2: 635 | P2: 636 | Q2: 666 | R2: 667 | S2: 668 | T2: 665 | U2: 770 | V2: 771 | W2: 769 | X2: 813 | Y2: 814 | Z2: 815
B3: =_xlfn.XLOOKUP(B$2,'Product Tgt'!$I:$I,'Product Tgt'!$I:$I) -> 542 | C3: =_xlfn.XLOOKUP(C$2,'Product Tgt'!$I:$I,'Product Tgt'!$I:$I) -> 543 | D3: =_xlfn.XLOOKUP(D$2,'Product Tgt'!$I:$I,'Product Tgt'!$I:$I) -> 545 | E3: =_xlfn.XLOOKUP(E$2,'Product Tgt'!$I:$I,'Product Tgt'!$I:$I) -> 547 | F3: =_xlfn.XLOOKUP(F$2,'Product Tgt'!$I:$I,'Product Tgt'!$I:$I) -> 551 | G3: =_xlfn.XLOOKUP(G$2,'Product Tgt'!$I:$I,'Product Tgt'!$I:$I) -> 552 | H3: =_xlfn.XLOOKUP(H$2,'Product Tgt'!$I:$I,'Product Tgt'!$I:$I) -> 578 | I3: =_xlfn.XLOOKUP(I$2,'Product Tgt'!$I:$I,'Product Tgt'!$I:$I) -> 596 | ... W3: =_xlfn.XLOOKUP(W$2,'Product Tgt'!$I:$I,'Product Tgt'!$I:$I) -> 769 | X3: 269865.07 | Y3: 292305 | Z3: 49470
A4: SYK-BBRB-BBR1 | B4: 15554.63 | C4: 19891.51 | D4: 88540.07 | E4: 94182.87 | F4: 26995.36 | G4: 13802.71 | H4: 0 | I4: 7357.63 | J4: 7680.26 | K4: 8108.24 | L4: 1703.75 | M4: 1643.35 | N4: 22818.64 | O4: 19183.28 | P4: 13163.38 | Q4: 5493.96 | R4: 9134.53 | S4: 14378.36 | T4: 10574.1 | U4: 49288.5 | V4: 3396.2 | W4: 19734.33 | X4: =X$3*$AB4 -> 6486.2389 | Y4: =Y$3*$AB4 -> 7025.5853 | Z4: =Z$3*$AB4 -> 1189.0173 | AA4: =N4+O4+P4 -> 55165.3 | AB4: =$AA4/SUM($AA$4:$AA$55) -> 0.024035118
