Workbook

Sheet Ter. Ratio Dev
B1: Betanol | C1: Amaryl | E1: ve | F1: -ve | AM1: =AM3-AM2 -> -0.77307813 | AN1: =AN3-AN2 -> -3.3625234 | AO1: =AO3-AO2 -> 0.15813784 | AP1: =AP3-AP2 -> -1.5265519 | AQ1: =AQ3-AQ2 -> 1.870978 | AR1: =AR3-AR2 -> -1.2512102 | AS1: =AS3-AS2 -> 2.1459793 | AT1: =AT3-AT2 -> 3.0126798 | ... BQ1: =BQ3-BQ2 -> 6.2502669
C2: =171*AP5 -> 81000.99 | E2: 1 | F2: -1 | AM2: =IFERROR(_xlfn.XLOOKUP(AM$7,'Product Tgt'!$B:$B,'Product Tgt'!$G:$G),0) -> 4840263.8 | AN2: =IFERROR(_xlfn.XLOOKUP(AN$7,'Product Tgt'!$B:$B,'Product Tgt'!$G:$G),0) -> 9670920.4 | AO2: =IFERROR(_xlfn.XLOOKUP(AO$7,'Product Tgt'!$B:$B,'Product Tgt'!$G:$G),0) -> 4688699.8 | AP2: =IFERROR(_xlfn.XLOOKUP(AP$7,'Product Tgt'!$B:$B,'Product Tgt'!$G:$G),0) -> 5233797.5 | AQ2: =IFERROR(_xlfn.XLOOKUP(AQ$7,'Product Tgt'!$B:$B,'Product Tgt'!$G:$G),0) -> 4620335.1 | AR2: =IFERROR(_xlfn.XLOOKUP(AR$7,'Product Tgt'!$B:$B,'Product Tgt'!$G:$G),0) -> 3450135.3 | AS2: =IFERROR(_xlfn.XLOOKUP(AS$7,'Product Tgt'!$B:$B,'Product Tgt'!$G:$G),0) -> 60975.854 | AT2: =IFERROR(_xlfn.XLOOKUP(AT$7,'Product Tgt'!$B:$B,'Product Tgt'!$G:$G),0) -> 452098.99 | ... BQ2: =IFERROR(_xlfn.XLOOKUP(BQ$7,'Product Tgt'!$B:$B,'Product Tgt'!$G:$G),0) -> 234173.75
B3: =171*AX5*2 -> 169207.92 | C3: =171*#REF! -> #REF! | E3: 2 | F3: -2 | AM3: =SUM(AM8:AM247) -> 4840263 | AN3: =SUM(AN8:AN247) -> 9670917 | AO3: =SUM(AO8:AO247) -> 4688700 | AP3: =SUM(AP8:AP247) -> 5233796 | AQ3: =SUM(AQ8:AQ247) -> 4620337 | AR3: =SUM(AR8:AR247) -> 3450134 | AS3: =SUM(AS8:AS247) -> 60978 | AT3: =SUM(AT8:AT247) -> 452102 | ... BQ3: =SUM(BQ8:BQ247) -> 234180
E4: Max | F4: =MAX(E8:E120) -> 8.0141641 | BR4: TGT QTY | DA4: TGT Value
C5: Territory Target | E5: Min | F5: =MIN(E8:E120) -> -11.768713 | G5: Price | H5: =_xlfn.XLOOKUP(H$7,'Product Tgt'!$B:$B,'Product Tgt'!$D:$D,0) -> 311.24 | I5: =_xlfn.XLOOKUP(I$7,'Product Tgt'!$B:$B,'Product Tgt'!$D:$D,0) -> 436.51 | J5: =_xlfn.XLOOKUP(J$7,'Product Tgt'!$B:$B,'Product Tgt'!$D:$D,0) -> 372.18 | K5: =_xlfn.XLOOKUP(K$7,'Product Tgt'!$B:$B,'Product Tgt'!$D:$D,0) -> 473.69 | L5: =_xlfn.XLOOKUP(L$7,'Product Tgt'!$B:$B,'Product Tgt'!$D:$D,0) -> 404.7 | M5: =_xlfn.XLOOKUP(M$7,'Product Tgt'!$B:$B,'Product Tgt'!$D:$D,0) -> 270 | N5: =_xlfn.XLOOKUP(N$7,'Product Tgt'!$B:$B,'Product Tgt'!$D:$D,0) -> 68 | O5: =_xlfn.XLOOKUP(O$7,'Product Tgt'!$B:$B,'Product Tgt'!$D:$D,0) -> 116 | ... EI5: =_xlfn.XLOOKUP(EI$7,'Product Tgt'!$B:$B,'Product Tgt'!$D:$D,0) -> 0
B6: Month | C6: Current Month | G6: Brand | H6: =_xlfn.XLOOKUP(H$7,'Product Tgt'!$B:$B,'Product Tgt'!$C:$C,0) -> Amaryl 1mg Tab 4x15s | I6: =_xlfn.XLOOKUP(I$7,'Product Tgt'!$B:$B,'Product Tgt'!$C:$C,0) -> Amaryl 2mg Tab 3x15s | J6: =_xlfn.XLOOKUP(J$7,'Product Tgt'!$B:$B,'Product Tgt'!$C:$C,0) -> Amaryl 3mg Tab 2x15's | K6: =_xlfn.XLOOKUP(K$7,'Product Tgt'!$B:$B,'Product Tgt'!$C:$C,0) -> Amaryl 4mg Tab 2x15's | L6: =_xlfn.XLOOKUP(L$7,'Product Tgt'!$B:$B,'Product Tgt'!$C:$C,0) -> AMARYL M 2mg Tab 3x10's | M6: =_xlfn.XLOOKUP(M$7,'Product Tgt'!$B:$B,'Product Tgt'!$C:$C,0) -> AMARYL M1 1mg Tab 3x10's | N6: =_xlfn.XLOOKUP(N$7,'Product Tgt'!$B:$B,'Product Tgt'!$C:$C,0) -> Betanol 25mg Tab 20x10's | O6: =_xlfn.XLOOKUP(O$7,'Product Tgt'!$B:$B,'Product Tgt'!$C:$C,0) -> BETANOL 50mg Tab. 5x4x10?s | ... BQ6: =_xlfn.XLOOKUP(BQ$7,'Product Tgt'!$B:$B,'Product Tgt'!$C:$C,0) -> Tritace 5mg Tab 2x14's | BR6: Amaryl 1mg Tab 4x15s | BS6: Amaryl 2mg Tab 3x15s | BT6: Amaryl 3mg Tab 2x15's | BU6: Amaryl 4mg Tab 2x15's | BV6: AMARYL M 2mg Tab 3x10's | BW6: AMARYL M1 1mg Tab 3x10's | BX6: Betanol 100mg Tab 10x10's | BY6: Betanol 25mg Tab 20x10's | BZ6: BETANOL 50mg Tab. 5x4x10?s | CA6: Copixa 2.5mg Tab 3x10's | CB6: Copixa 5mg Tab 3x10's | CC6: ERTU 15mg Tablet 2 x10s | CD6: ERTU 5mg Tablet 3 x 10s | CE6: Incrit 50mg Tab 2x10's | CF6: Incrit-M 1000mg Tab | CG6: Incrit-M 500mg Tab | CH6: Lasix 2ml Inj 5x5's Amp | CI6: Lasix 40mg Tab 10x10's | CJ6: Metsa 500mg Tab 10x10's | CK6: Metsa 850mg Tab 5x10's | CL6: METSA XR 500mg Tab | CM6: METSA XR 750mg Tab | CN6: Orva 10mg Tab 2X15's | CO6: Orva 20mg Tab 3x10's | CP6: Ovenox 20mg Inj 1 PFS | CQ6: Ovenox 40mg Inj 1 PFS | CR6: Ovenox 60mg Inj 1 PFS | CS6: Ovenox 80mg Inj 1 PFS | CT6: Rozenon 10mg Tab 3 x 10s | CU6: Rozenon 20mg Tablet 2x10?s | CV6: Rozenon 5mg Tab 3 x 10s | CW6: Sacutril 100 mg Tablet | CX6: Sacutril 50 mg Tablet | CY6: Tritace 2.5mg Tab 2x14's | CZ6: Tritace 5mg Tab 2x14's | DA6: Amaryl 1mg Tab 4x15s | DB6: Amaryl 2mg Tab 3x15s | DC6: Amaryl 3mg Tab 2x15's | DD6: Amaryl 4mg Tab 2x15's | DE6: AMARYL M 2mg Tab 3x10's | DF6: AMARYL M1 1mg Tab 3x10's | DG6: Betanol 100mg Tab 10x10's | DH6: Betanol 25mg Tab 20x10's | DI6: BETANOL 50mg Tab. 5x4x10?s | DJ6: Copixa 2.5mg Tab 3x10's | DK6: Copixa 5mg Tab 3x10's | DL6: ERTU 15mg Tablet 2 x10s | DM6: ERTU 5mg Tablet 3 x 10s | DN6: Incrit 50mg Tab 2x10's | DO6: Incrit-M 1000mg Tab | DP6: Incrit-M 500mg Tab | DQ6: Lasix 2ml Inj 5x5's Amp | DR6: Lasix 40mg Tab 10x10's | DS6: Metsa 500mg Tab 10x10's | DT6: Metsa 850mg Tab 5x10's | DU6: METSA XR 500mg Tab | DV6: METSA XR 750mg Tab | DW6: Orva 10mg Tab 2X15's | DX6: Orva 20mg Tab 3x10's | DY6: Ovenox 20mg Inj 1 PFS | DZ6: Ovenox 40mg Inj 1 PFS | EA6: Ovenox 60mg Inj 1 PFS | EB6: Ovenox 80mg Inj 1 PFS | EC6: Rozenon 10mg Tab 3 x 10s | ED6: Rozenon 20mg Tablet 2x10?s | EE6: Rozenon 5mg Tab 3 x 10s | EF6: Sacutril 100 mg Tablet | EG6: Sacutril 50 mg Tablet | EH6: Tritace 2.5mg Tab 2x14's | EI6: Tritace 5mg Tab 2x14's
A7: Region | B7: Territory | C7: Total | D7: New Terr | E7: Diff | F7: Diff% | G7: Multiplier | H7: 502 | I7: 504 | J7: 505 | K7: 506 | L7: 508 | M7: 507 | N7: 520 | O7: 521 | P7: 784 | Q7: 785 | R7: 758 | S7: 757 | T7: 580 | U7: 582 | V7: 594 | W7: 595 | X7: 603 | Y7: 606 | Z7: 772 | AA7: 615 | AB7: 617 | AC7: 751 | AD7: 752 | AE7: 753 | AF7: 754 | AG7: 614 | AH7: 797 | AI7: 613 | AJ7: 767 | AK7: 807 | AL7: 808 | AM7: 502 | AN7: 504 | AO7: 505 | AP7: 506 | AQ7: 508 | AR7: 507 | AS7: 520 | AT7: 521 | AU7: 784 | AV7: 785 | AW7: 758 | AX7: 757 | AY7: 580 | AZ7: 582 | BA7: 594 | BB7: 595 | BC7: 603 | BD7: 606 | BE7: 772 | BF7: 615 | BG7: 617 | BH7: 751 | BI7: 752 | BJ7: 753 | BK7: 754 | BL7: 614 | BM7: 797 | BN7: 613 | BO7: 767 | BP7: 807 | BQ7: 808 | BR7: 344733 | BS7: 344734 | BT7: 373068 | BU7: 373346 | BV7: 318675 | BW7: 318674 | BX7: 373380 | BY7: 320750 | BZ7: 337348 | CA7: 4011000147 | CB7: 4011000148 | CC7: 352748 | CD7: 352734 | CE7: 334747 | CF7: 337303 | CG7: 336152 | CH7: 372906 | CI7: 372970 | CJ7: 321864 | CK7: 321865 | CL7: 4011000061 | CM7: 4011000137 | CN7: 339102 | CO7: 320752 | CP7: 352336 | CQ7: 352337 | CR7: 352338 | CS7: 352339 | CT7: 348292 | CU7: 4011000159 | CV7: 348290 | CW7: 4011000131 | CX7: 4011000130 | CY7: 4011000173 | CZ7: 4011000174 | DA7: 344733 | DB7: 344734 | DC7: 373068 | DD7: 373346 | DE7: 318675 | DF7: 318674 | DG7: 373380 | DH7: 320750 | DI7: 337348 | DJ7: 4011000147 | DK7: 4011000148 | DL7: 352748 | DM7: 352734 | DN7: 334747 | DO7: 337303 | DP7: 336152 | DQ7: 372906 | DR7: 372970 | DS7: 321864 | DT7: 321865 | DU7: 4011000061 | DV7: 4011000137 | DW7: 339102 | DX7: 320752 | DY7: 352336 | DZ7: 352337 | EA7: 352338 | EB7: 352339 | EC7: 348292 | ED7: 4011000159 | EE7: 348290 | EF7: 4011000131 | EG7: 4011000130 | EH7: 373085 | EI7: 373211
B8: SYT-BBRA-BBR1 | C8: =_xlfn.XLOOKUP($B8,'Terr Target'!$A:$A,'Terr Target'!$E:$E) -> 684081.29 | D8: =SUM(AM8:BQ8) -> 684085 | E8: =D8-C8 -> 3.709616 | F8: =ABS(E8)/D8 -> 5.4227413e-06 | G8: =1-E8/D8 -> 0.99999458 | H8: 46306.769 | I8: 95978.107 | J8: 87390.402 | K8: 131836.64 | L8: 58537.745 | M8: 45716.339 | N8: 1144.9574 | O8: 8638.8152 | P8: 1931.5186 | Q8: 1279.2953 | R8: 20152.655 | S8: 35402.575 | T8: 0 | U8: 2482.794 | V8: 24178.826 | W8: 42781.117 | X8: 3136.0774 | Y8: 4025.5654 | Z8: 518.00642 | AA8: 9415.2998 | AB8: 3356.2382 | AC8: 0 | AD8: 7645.2796 | AE8: 10449.172 | AF8: 0 | AG8: 33266.959 | AH8: 2816.978 | AI8: 17513.007 | AJ8: 15307.784 | AK8: 1218.8054 | AL8: 1696.0712 | AM8: =IFERROR(ROUND(_xlfn.XLOOKUP(AM$7,'Product Tgt'!$B:$B,'Product Tgt'!$G:$G)*H8/H$121,0),0) -> 45018 | AN8: =IFERROR(ROUND(_xlfn.XLOOKUP(AN$7,'Product Tgt'!$B:$B,'Product Tgt'!$G:$G)*I8/I$121,0),0) -> 94481 | AO8: =IFERROR(ROUND(_xlfn.XLOOKUP(AO$7,'Product Tgt'!$B:$B,'Product Tgt'!$G:$G)*J8/J$121,0),0) -> 84672 | AP8: =IFERROR(ROUND(_xlfn.XLOOKUP(AP$7,'Product Tgt'!$B:$B,'Product Tgt'!$G:$G)*K8/K$121,0),0) -> 128610 | AQ8: =IFERROR(ROUND(_xlfn.XLOOKUP(AQ$7,'Product Tgt'!$B:$B,'Product Tgt'!$G:$G)*L8/L$121,0),0) -> 56602 | AR8: =IFERROR(ROUND(_xlfn.XLOOKUP(AR$7,'Product Tgt'!$B:$B,'Product Tgt'!$G:$G)*M8/M$121,0),0) -> 44290 | AS8: =IFERROR(ROUND(_xlfn.XLOOKUP(AS$7,'Product Tgt'!$B:$B,'Product Tgt'!$G:$G)*N8/N$121,0),0) -> 1058 | AT8: =IFERROR(ROUND(_xlfn.XLOOKUP(AT$7,'Product Tgt'!$B:$B,'Product Tgt'!$G:$G)*O8/O$121,0),0) -> 7776 | ... BQ8: =IFERROR(ROUND(_xlfn.XLOOKUP(BQ$7,'Product Tgt'!$B:$B,'Product Tgt'!$G:$G)*AL8/AL$121,0),0) -> 1326 | BR8: =ROUND(IFERROR(AM8/_xlfn.XLOOKUP(BR$7,'Product Tgt'!$B:$B,'Product Tgt'!$D:$D),0),0) -> 0 | BS8: =ROUND(IFERROR(AN8/_xlfn.XLOOKUP(BS$7,'Product Tgt'!$B:$B,'Product Tgt'!$D:$D),0),0) -> 0 | BT8: =ROUND(IFERROR(AO8/_xlfn.XLOOKUP(BT$7,'Product Tgt'!$B:$B,'Product Tgt'!$D:$D),0),0) -> 0 | BU8: =ROUND(IFERROR(AP8/_xlfn.XLOOKUP(BU$7,'Product Tgt'!$B:$B,'Product Tgt'!$D:$D),0),0) -> 0 | BV8: =ROUND(IFERROR(AQ8/_xlfn.XLOOKUP(BV$7,'Product Tgt'!$B:$B,'Product Tgt'!$D:$D),0),0) -> 0 | BW8: =ROUND(IFERROR(AU8/_xlfn.XLOOKUP(BW$7,'Product Tgt'!$B:$B,'Product Tgt'!$D:$D),0),0) -> 0 | BX8: =ROUND(IFERROR(#REF!/_xlfn.XLOOKUP(BX$7,'Product Tgt'!$B:$B,'Product Tgt'!$D:$D),0),0) -> 0 | BY8: =ROUND(IFERROR(#REF!/_xlfn.XLOOKUP(BY$7,'Product Tgt'!$B:$B,'Product Tgt'!$D:$D),0),0) -> 0 | BZ8: =ROUND(IFERROR(#REF!/_xlfn.XLOOKUP(BZ$7,'Product Tgt'!$B:$B,'Product Tgt'!$D:$D),0),0) -> 0 | CA8: =ROUND(IFERROR(#REF!/_xlfn.XLOOKUP(CA$7,'Product Tgt'!$B:$B,'Product Tgt'!$D:$D),0),0) -> 0 | CB8: =ROUND(IFERROR(AV8/_xlfn.XLOOKUP(CB$7,'Product Tgt'!$B:$B,'Product Tgt'!$D:$D),0),0) -> 0 | CC8: =ROUND(IFERROR(AW8/_xlfn.XLOOKUP(CC$7,'Product Tgt'!$B:$B,'Product Tgt'!$D:$D),0),0) -> 0 | CD8: =ROUND(IFERROR(AX8/_xlfn.XLOOKUP(CD$7,'Product Tgt'!$B:$B,'Product Tgt'!$D:$D),0),0) -> 0 | CE8: =ROUND(IFERROR(AY8/_xlfn.XLOOKUP(CE$7,'Product Tgt'!$B:$B,'Product Tgt'!$D:$D),0),0) -> 0 | CF8: =ROUND(IFERROR(AZ8/_xlfn.XLOOKUP(CF$7,'Product Tgt'!$B:$B,'Product Tgt'!$D:$D),0),0) -> 0 | CG8: =ROUND(IFERROR(BA8/_xlfn.XLOOKUP(CG$7,'Product Tgt'!$B:$B,'Product Tgt'!$D:$D),0),0) -> 0 | CH8: =ROUND(IFERROR(BB8/_xlfn.XLOOKUP(CH$7,'Product Tgt'!$B:$B,'Product Tgt'!$D:$D),0),0) -> 0 | CI8: =ROUND(IFERROR(BC8/_xlfn.XLOOKUP(CI$7,'Product Tgt'!$B:$B,'Product Tgt'!$D:$D),0),0) -> 0 | ... CW8: =ROUND(IFERROR(BQ8/_xlfn.XLOOKUP(CW$7,'Product Tgt'!$B:$B,'Product Tgt'!$D:$D),0),0) -> 0 | CX8: =ROUND(IFERROR(#REF!/_xlfn.XLOOKUP(CX$7,'Product Tgt'!$B:$B,'Product Tgt'!$D:$D),0),0) -> 0 | CY8: =ROUND(IFERROR(#REF!/_xlfn.XLOOKUP(CY$7,'Product Tgt'!$B:$B,'Product Tgt'!$D:$D),0),0) -> 0 | CZ8: =ROUND(IFERROR(#REF!/_xlfn.XLOOKUP(CZ$7,'Product Tgt'!$B:$B,'Product Tgt'!$D:$D),0),0) -> 0 | DA8: =IFERROR(BR8*_xlfn.XLOOKUP(DA$7,'Product Tgt'!$B:$B,'Product Tgt'!$D:$D),0) -> 0 | DB8: =IFERROR(BS8*_xlfn.XLOOKUP(DB$7,'Product Tgt'!$B:$B,'Product Tgt'!$D:$D),0) -> 0 | DC8: =IFERROR(BT8*_xlfn.XLOOKUP(DC$7,'Product Tgt'!$B:$B,'Product Tgt'!$D:$D),0) -> 0 | DD8: =IFERROR(BU8*_xlfn.XLOOKUP(DD$7,'Product Tgt'!$B:$B,'Product Tgt'!$D:$D),0) -> 0 | DE8: =IFERROR(BV8*_xlfn.XLOOKUP(DE$7,'Product Tgt'!$B:$B,'Product Tgt'!$D:$D),0) -> 0 | DF8: =IFERROR(BW8*_xlfn.XLOOKUP(DF$7,'Product Tgt'!$B:$B,'Product Tgt'!$D:$D),0) -> 0 | DG8: =IFERROR(BX8*_xlfn.XLOOKUP(DG$7,'Product Tgt'!$B:$B,'Product Tgt'!$D:$D),0) -> 0 | DH8: =IFERROR(BY8*_xlfn.XLOOKUP(DH$7,'Product Tgt'!$B:$B,'Product Tgt'!$D:$D),0) -> 0 | ... EI8: =IFERROR(CZ8*_xlfn.XLOOKUP(EI$7,'Product Tgt'!$B:$B,'Product Tgt'!$D:$D),0) -> 0
B9: SYT-BBRA-BBR2 | C9: =_xlfn.XLOOKUP($B9,'Terr Target'!$A:$A,'Terr Target'!$E:$E) -> 535351 | D9: =SUM(AM9:BQ9) -> 535348 | E9: =D9-C9 -> -3 | F9: =ABS(E9)/D9 -> 5.6038315e-06 | G9: =1-E9/D9 -> 1.0000056 | H9: 35058.568 | I9: 70661.747 | J9: 64035.527 | K9: 82867.724 | L9: 51451.474 | M9: 37910.926 | N9: 908.44869 | O9: 6875.7637 | P9: 2926.5056 | Q9: 2187.5221 | R9: 15206.466 | S9: 25626.392 | T9: 0 | U9: 2385.5072 | V9: 21021.373 | W9: 37674.887 | X9: 3719.6298 | Y9: 3992.1501 | Z9: 542.06004 | AA9: 6135.7595 | AB9: 2062.9802 | AC9: 0 | AD9: 13565.771 | AE9: 15106.085 | AF9: 0 | AG9: 26770.247 | AH9: 2699.8885 | AI9: 13628.129 | AJ9: 12411.352 | AK9: 1656.8435 | AL9: 2362.8056 | AM9: =IFERROR(ROUND(_xlfn.XLOOKUP(AM$7,'Product Tgt'!$B:$B,'Product Tgt'!$G:$G)*H9/H$121,0),0) -> 34083 | AN9: =IFERROR(ROUND(_xlfn.XLOOKUP(AN$7,'Product Tgt'!$B:$B,'Product Tgt'!$G:$G)*I9/I$121,0),0) -> 69559 | AO9: =IFERROR(ROUND(_xlfn.XLOOKUP(AO$7,'Product Tgt'!$B:$B,'Product Tgt'!$G:$G)*J9/J$121,0),0) -> 62044 | AP9: =IFERROR(ROUND(_xlfn.XLOOKUP(AP$7,'Product Tgt'!$B:$B,'Product Tgt'!$G:$G)*K9/K$121,0),0) -> 80839 | AQ9: =IFERROR(ROUND(_xlfn.XLOOKUP(AQ$7,'Product Tgt'!$B:$B,'Product Tgt'!$G:$G)*L9/L$121,0),0) -> 49750 | AR9: =IFERROR(ROUND(_xlfn.XLOOKUP(AR$7,'Product Tgt'!$B:$B,'Product Tgt'!$G:$G)*M9/M$121,0),0) -> 36728 | AS9: =IFERROR(ROUND(_xlfn.XLOOKUP(AS$7,'Product Tgt'!$B:$B,'Product Tgt'!$G:$G)*N9/N$121,0),0) -> 839 | AT9: =IFERROR(ROUND(_xlfn.XLOOKUP(AT$7,'Product Tgt'!$B:$B,'Product Tgt'!$G:$G)*O9/O$121,0),0) -> 6189 | ... BQ9: =IFERROR(ROUND(_xlfn.XLOOKUP(BQ$7,'Product Tgt'!$B:$B,'Product Tgt'!$G:$G)*AL9/AL$121,0),0) -> 1847 | BR9: =ROUND(IFERROR(AM9/_xlfn.XLOOKUP(BR$7,'Product Tgt'!$B:$B,'Product Tgt'!$D:$D),0),0) -> 0 | BS9: =ROUND(IFERROR(AN9/_xlfn.XLOOKUP(BS$7,'Product Tgt'!$B:$B,'Product Tgt'!$D:$D),0),0) -> 0 | BT9: =ROUND(IFERROR(AO9/_xlfn.XLOOKUP(BT$7,'Product Tgt'!$B:$B,'Product Tgt'!$D:$D),0),0) -> 0 | BU9: =ROUND(IFERROR(AP9/_xlfn.XLOOKUP(BU$7,'Product Tgt'!$B:$B,'Product Tgt'!$D:$D),0),0) -> 0 | BV9: =ROUND(IFERROR(AQ9/_xlfn.XLOOKUP(BV$7,'Product Tgt'!$B:$B,'Product Tgt'!$D:$D),0),0) -> 0 | BW9: =ROUND(IFERROR(AU9/_xlfn.XLOOKUP(BW$7,'Product Tgt'!$B:$B,'Product Tgt'!$D:$D),0),0) -> 0 | BX9: =ROUND(IFERROR(#REF!/_xlfn.XLOOKUP(BX$7,'Product Tgt'!$B:$B,'Product Tgt'!$D:$D),0),0) -> 0 | BY9: =ROUND(IFERROR(#REF!/_xlfn.XLOOKUP(BY$7,'Product Tgt'!$B:$B,'Product Tgt'!$D:$D),0),0) -> 0 | BZ9: =ROUND(IFERROR(#REF!/_xlfn.XLOOKUP(BZ$7,'Product Tgt'!$B:$B,'Product Tgt'!$D:$D),0),0) -> 0 | CA9: =ROUND(IFERROR(#REF!/_xlfn.XLOOKUP(CA$7,'Product Tgt'!$B:$B,'Product Tgt'!$D:$D),0),0) -> 0 | CB9: =ROUND(IFERROR(AV9/_xlfn.XLOOKUP(CB$7,'Product Tgt'!$B:$B,'Product Tgt'!$D:$D),0),0) -> 0 | CC9: =ROUND(IFERROR(AW9/_xlfn.XLOOKUP(CC$7,'Product Tgt'!$B:$B,'Product Tgt'!$D:$D),0),0) -> 0 | CD9: =ROUND(IFERROR(AX9/_xlfn.XLOOKUP(CD$7,'Product Tgt'!$B:$B,'Product Tgt'!$D:$D),0),0) -> 0 | CE9: =ROUND(IFERROR(AY9/_xlfn.XLOOKUP(CE$7,'Product Tgt'!$B:$B,'Product Tgt'!$D:$D),0),0) -> 0 | CF9: =ROUND(IFERROR(AZ9/_xlfn.XLOOKUP(CF$7,'Product Tgt'!$B:$B,'Product Tgt'!$D:$D),0),0) -> 0 | CG9: =ROUND(IFERROR(BA9/_xlfn.XLOOKUP(CG$7,'Product Tgt'!$B:$B,'Product Tgt'!$D:$D),0),0) -> 0 | CH9: =ROUND(IFERROR(BB9/_xlfn.XLOOKUP(CH$7,'Product Tgt'!$B:$B,'Product Tgt'!$D:$D),0),0) -> 0 | CI9: =ROUND(IFERROR(BC9/_xlfn.XLOOKUP(CI$7,'Product Tgt'!$B:$B,'Product Tgt'!$D:$D),0),0) -> 0 | ... CW9: =ROUND(IFERROR(BQ9/_xlfn.XLOOKUP(CW$7,'Product Tgt'!$B:$B,'Product Tgt'!$D:$D),0),0) -> 0 | CX9: =ROUND(IFERROR(#REF!/_xlfn.XLOOKUP(CX$7,'Product Tgt'!$B:$B,'Product Tgt'!$D:$D),0),0) -> 0 | CY9: =ROUND(IFERROR(#REF!/_xlfn.XLOOKUP(CY$7,'Product Tgt'!$B:$B,'Product Tgt'!$D:$D),0),0) -> 0 | CZ9: =ROUND(IFERROR(#REF!/_xlfn.XLOOKUP(CZ$7,'Product Tgt'!$B:$B,'Product Tgt'!$D:$D),0),0) -> 0 | DA9: =IFERROR(BR9*_xlfn.XLOOKUP(DA$7,'Product Tgt'!$B:$B,'Product Tgt'!$D:$D),0) -> 0 | DB9: =IFERROR(BS9*_xlfn.XLOOKUP(DB$7,'Product Tgt'!$B:$B,'Product Tgt'!$D:$D),0) -> 0 | DC9: =IFERROR(BT9*_xlfn.XLOOKUP(DC$7,'Product Tgt'!$B:$B,'Product Tgt'!$D:$D),0) -> 0 | DD9: =IFERROR(BU9*_xlfn.XLOOKUP(DD$7,'Product Tgt'!$B:$B,'Product Tgt'!$D:$D),0) -> 0 | DE9: =IFERROR(BV9*_xlfn.XLOOKUP(DE$7,'Product Tgt'!$B:$B,'Product Tgt'!$D:$D),0) -> 0 | DF9: =IFERROR(BW9*_xlfn.XLOOKUP(DF$7,'Product Tgt'!$B:$B,'Product Tgt'!$D:$D),0) -> 0 | DG9: =IFERROR(BX9*_xlfn.XLOOKUP(DG$7,'Product Tgt'!$B:$B,'Product Tgt'!$D:$D),0) -> 0 | DH9: =IFERROR(BY9*_xlfn.XLOOKUP(DH$7,'Product Tgt'!$B:$B,'Product Tgt'!$D:$D),0) -> 0 | ... EI9: =IFERROR(CZ9*_xlfn.XLOOKUP(EI$7,'Product Tgt'!$B:$B,'Product Tgt'!$D:$D),0) -> 0
B10: SYT-BBRA-HAB1 | C10: =_xlfn.XLOOKUP($B10,'Terr Target'!$A:$A,'Terr Target'!$E:$E) -> 365084.91 | D10: =SUM(AM10:BQ10) -> 365088 | E10: =D10-C10 -> 3.091024 | F10: =ABS(E10)/D10 -> 8.4665176e-06 | G10: =1-E10/D10 -> 0.99999153 | H10: 26359.506 | I10: 52210.659 | J10: 43604.141 | K10: 44134.914 | L10: 34744.827 | M10: 25328.101 | N10: 773.97901 | O10: 6727.8945 | P10: 1697.9759 | Q10: 1000.9858 | R10: 8477.7797 | S10: 20065.255 | T10: 0 | U10: 1966.9721 | V10: 11644.835 | W10: 30137.532 | X10: 4100.9418 | Y10: 5543.9013 | Z10: 903.05718 | AA10: 6197.942 | AB10: 2090.9903 | AC10: 0 | AD10: 3848.9554 | AE10: 8009.8563 | AF10: 0 | AG10: 19018.73 | AH10: 1872.9834 | AI10: 10725.908 | AJ10: 9166.8499 | AK10: 892.08734 | AL10: 1491.8188 | AM10: =IFERROR(ROUND(_xlfn.XLOOKUP(AM$7,'Product Tgt'!$B:$B,'Product Tgt'!$G:$G)*H10/H$121,0),0) -> 25626 | AN10: =IFERROR(ROUND(_xlfn.XLOOKUP(AN$7,'Product Tgt'!$B:$B,'Product Tgt'!$G:$G)*I10/I$121,0),0) -> 51396 | AO10: =IFERROR(ROUND(_xlfn.XLOOKUP(AO$7,'Product Tgt'!$B:$B,'Product Tgt'!$G:$G)*J10/J$121,0),0) -> 42248 | AP10: =IFERROR(ROUND(_xlfn.XLOOKUP(AP$7,'Product Tgt'!$B:$B,'Product Tgt'!$G:$G)*K10/K$121,0),0) -> 43055 | AQ10: =IFERROR(ROUND(_xlfn.XLOOKUP(AQ$7,'Product Tgt'!$B:$B,'Product Tgt'!$G:$G)*L10/L$121,0),0) -> 33596 | AR10: =IFERROR(ROUND(_xlfn.XLOOKUP(AR$7,'Product Tgt'!$B:$B,'Product Tgt'!$G:$G)*M10/M$121,0),0) -> 24538 | AS10: =IFERROR(ROUND(_xlfn.XLOOKUP(AS$7,'Product Tgt'!$B:$B,'Product Tgt'!$G:$G)*N10/N$121,0),0) -> 715 | AT10: =IFERROR(ROUND(_xlfn.XLOOKUP(AT$7,'Product Tgt'!$B:$B,'Product Tgt'!$G:$G)*O10/O$121,0),0) -> 6056 | ... BQ10: =IFERROR(ROUND(_xlfn.XLOOKUP(BQ$7,'Product Tgt'!$B:$B,'Product Tgt'!$G:$G)*AL10/AL$121,0),0) -> 1166 | BR10: =ROUND(IFERROR(AM10/_xlfn.XLOOKUP(BR$7,'Product Tgt'!$B:$B,'Product Tgt'!$D:$D),0),0) -> 0 | BS10: =ROUND(IFERROR(AN10/_xlfn.XLOOKUP(BS$7,'Product Tgt'!$B:$B,'Product Tgt'!$D:$D),0),0) -> 0 | BT10: =ROUND(IFERROR(AO10/_xlfn.XLOOKUP(BT$7,'Product Tgt'!$B:$B,'Product Tgt'!$D:$D),0),0) -> 0 | BU10: =ROUND(IFERROR(AP10/_xlfn.XLOOKUP(BU$7,'Product Tgt'!$B:$B,'Product Tgt'!$D:$D),0),0) -> 0 | BV10: =ROUND(IFERROR(AQ10/_xlfn.XLOOKUP(BV$7,'Product Tgt'!$B:$B,'Product Tgt'!$D:$D),0),0) -> 0 | BW10: =ROUND(IFERROR(AU10/_xlfn.XLOOKUP(BW$7,'Product Tgt'!$B:$B,'Product Tgt'!$D:$D),0),0) -> 0 | BX10: =ROUND(IFERROR(#REF!/_xlfn.XLOOKUP(BX$7,'Product Tgt'!$B:$B,'Product Tgt'!$D:$D),0),0) -> 0 | BY10: =ROUND(IFERROR(#REF!/_xlfn.XLOOKUP(BY$7,'Product Tgt'!$B:$B,'Product Tgt'!$D:$D),0),0) -> 0 | BZ10: =ROUND(IFERROR(#REF!/_xlfn.XLOOKUP(BZ$7,'Product Tgt'!$B:$B,'Product Tgt'!$D:$D),0),0) -> 0 | CA10: =ROUND(IFERROR(#REF!/_xlfn.XLOOKUP(CA$7,'Product Tgt'!$B:$B,'Product Tgt'!$D:$D),0),0) -> 0 | CB10: =ROUND(IFERROR(AV10/_xlfn.XLOOKUP(CB$7,'Product Tgt'!$B:$B,'Product Tgt'!$D:$D),0),0) -> 0 | CC10: =ROUND(IFERROR(AW10/_xlfn.XLOOKUP(CC$7,'Product Tgt'!$B:$B,'Product Tgt'!$D:$D),0),0) -> 0 | CD10: =ROUND(IFERROR(AX10/_xlfn.XLOOKUP(CD$7,'Product Tgt'!$B:$B,'Product Tgt'!$D:$D),0),0) -> 0 | CE10: =ROUND(IFERROR(AY10/_xlfn.XLOOKUP(CE$7,'Product Tgt'!$B:$B,'Product Tgt'!$D:$D),0),0) -> 0 | CF10: =ROUND(IFERROR(AZ10/_xlfn.XLOOKUP(CF$7,'Product Tgt'!$B:$B,'Product Tgt'!$D:$D),0),0) -> 0 | CG10: =ROUND(IFERROR(BA10/_xlfn.XLOOKUP(CG$7,'Product Tgt'!$B:$B,'Product Tgt'!$D:$D),0),0) -> 0 | CH10: =ROUND(IFERROR(BB10/_xlfn.XLOOKUP(CH$7,'Product Tgt'!$B:$B,'Product Tgt'!$D:$D),0),0) -> 0 | CI10: =ROUND(IFERROR(BC10/_xlfn.XLOOKUP(CI$7,'Product Tgt'!$B:$B,'Product Tgt'!$D:$D),0),0) -> 0 | ... CW10: =ROUND(IFERROR(BQ10/_xlfn.XLOOKUP(CW$7,'Product Tgt'!$B:$B,'Product Tgt'!$D:$D),0),0) -> 0 | CX10: =ROUND(IFERROR(#REF!/_xlfn.XLOOKUP(CX$7,'Product Tgt'!$B:$B,'Product Tgt'!$D:$D),0),0) -> 0 | CY10: =ROUND(IFERROR(#REF!/_xlfn.XLOOKUP(CY$7,'Product Tgt'!$B:$B,'Product Tgt'!$D:$D),0),0) -> 0 | CZ10: =ROUND(IFERROR(#REF!/_xlfn.XLOOKUP(CZ$7,'Product Tgt'!$B:$B,'Product Tgt'!$D:$D),0),0) -> 0 | DA10: =IFERROR(BR10*_xlfn.XLOOKUP(DA$7,'Product Tgt'!$B:$B,'Product Tgt'!$D:$D),0) -> 0 | DB10: =IFERROR(BS10*_xlfn.XLOOKUP(DB$7,'Product Tgt'!$B:$B,'Product Tgt'!$D:$D),0) -> 0 | DC10: =IFERROR(BT10*_xlfn.XLOOKUP(DC$7,'Product Tgt'!$B:$B,'Product Tgt'!$D:$D),0) -> 0 | DD10: =IFERROR(BU10*_xlfn.XLOOKUP(DD$7,'Product Tgt'!$B:$B,'Product Tgt'!$D:$D),0) -> 0 | DE10: =IFERROR(BV10*_xlfn.XLOOKUP(DE$7,'Product Tgt'!$B:$B,'Product Tgt'!$D:$D),0) -> 0 | DF10: =IFERROR(BW10*_xlfn.XLOOKUP(DF$7,'Product Tgt'!$B:$B,'Product Tgt'!$D:$D),0) -> 0 | DG10: =IFERROR(BX10*_xlfn.XLOOKUP(DG$7,'Product Tgt'!$B:$B,'Product Tgt'!$D:$D),0) -> 0 | DH10: =IFERROR(BY10*_xlfn.XLOOKUP(DH$7,'Product Tgt'!$B:$B,'Product Tgt'!$D:$D),0) -> 0 | ... EI10: =IFERROR(CZ10*_xlfn.XLOOKUP(EI$7,'Product Tgt'!$B:$B,'Product Tgt'!$D:$D),0) -> 0
B11: SYT-BBRA-MOU1 | C11: =_xlfn.XLOOKUP($B11,'Terr Target'!$A:$A,'Terr Target'!$E:$E) -> 340830.85 | D11: =SUM(AM11:BQ11) -> 340835 | E11: =D11-C11 -> 4.148398 | F11: =ABS(E11)/D11 -> 1.2171279e-05 | G11: =1-E11/D11 -> 0.99998783 | H11: 25139.509 | I11: 53072.295 | J11: 44497.649 | K11: 47586.795 | L11: 32596.885 | M11: 33937.945 | N11: 1131.9657 | O11: 7539.5819 | P11: 1234.5513 | Q11: 826.36943 | R11: 4936.214 | S11: 12152.886 | T11: 0 | U11: 2650.2601 | V11: 9085.7528 | W11: 23871.237 | X11: 3051.4828 | Y11: 2912.0803 | Z11: 342.50281 | AA11: 6204.5457 | AB11: 2657.2691 | AC11: 0 | AD11: 3690.6515 | AE11: 5726.6228 | AF11: 0 | AG11: 13817.821 | AH11: 1229.5734 | AI11: 6941.2822 | AJ11: 6699.3041 | AK11: 1396.9519 | AL11: 1859.5826 | AM11: =IFERROR(ROUND(_xlfn.XLOOKUP(AM$7,'Product Tgt'!$B:$B,'Product Tgt'!$G:$G)*H11/H$121,0),0) -> 24440 | AN11: =IFERROR(ROUND(_xlfn.XLOOKUP(AN$7,'Product Tgt'!$B:$B,'Product Tgt'!$G:$G)*I11/I$121,0),0) -> 52244 | AO11: =IFERROR(ROUND(_xlfn.XLOOKUP(AO$7,'Product Tgt'!$B:$B,'Product Tgt'!$G:$G)*J11/J$121,0),0) -> 43114 | AP11: =IFERROR(ROUND(_xlfn.XLOOKUP(AP$7,'Product Tgt'!$B:$B,'Product Tgt'!$G:$G)*K11/K$121,0),0) -> 46422 | AQ11: =IFERROR(ROUND(_xlfn.XLOOKUP(AQ$7,'Product Tgt'!$B:$B,'Product Tgt'!$G:$G)*L11/L$121,0),0) -> 31519 | AR11: =IFERROR(ROUND(_xlfn.XLOOKUP(AR$7,'Product Tgt'!$B:$B,'Product Tgt'!$G:$G)*M11/M$121,0),0) -> 32879 | AS11: =IFERROR(ROUND(_xlfn.XLOOKUP(AS$7,'Product Tgt'!$B:$B,'Product Tgt'!$G:$G)*N11/N$121,0),0) -> 1046 | AT11: =IFERROR(ROUND(_xlfn.XLOOKUP(AT$7,'Product Tgt'!$B:$B,'Product Tgt'!$G:$G)*O11/O$121,0),0) -> 6786 | ... BQ11: =IFERROR(ROUND(_xlfn.XLOOKUP(BQ$7,'Product Tgt'!$B:$B,'Product Tgt'!$G:$G)*AL11/AL$121,0),0) -> 1454 | BR11: =ROUND(IFERROR(AM11/_xlfn.XLOOKUP(BR$7,'Product Tgt'!$B:$B,'Product Tgt'!$D:$D),0),0) -> 0 | BS11: =ROUND(IFERROR(AN11/_xlfn.XLOOKUP(BS$7,'Product Tgt'!$B:$B,'Product Tgt'!$D:$D),0),0) -> 0 | BT11: =ROUND(IFERROR(AO11/_xlfn.XLOOKUP(BT$7,'Product Tgt'!$B:$B,'Product Tgt'!$D:$D),0),0) -> 0 | BU11: =ROUND(IFERROR(AP11/_xlfn.XLOOKUP(BU$7,'Product Tgt'!$B:$B,'Product Tgt'!$D:$D),0),0) -> 0 | BV11: =ROUND(IFERROR(AQ11/_xlfn.XLOOKUP(BV$7,'Product Tgt'!$B:$B,'Product Tgt'!$D:$D),0),0) -> 0 | BW11: =ROUND(IFERROR(AU11/_xlfn.XLOOKUP(BW$7,'Product Tgt'!$B:$B,'Product Tgt'!$D:$D),0),0) -> 0 | BX11: =ROUND(IFERROR(#REF!/_xlfn.XLOOKUP(BX$7,'Product Tgt'!$B:$B,'Product Tgt'!$D:$D),0),0) -> 0 | BY11: =ROUND(IFERROR(#REF!/_xlfn.XLOOKUP(BY$7,'Product Tgt'!$B:$B,'Product Tgt'!$D:$D),0),0) -> 0 | BZ11: =ROUND(IFERROR(#REF!/_xlfn.XLOOKUP(BZ$7,'Product Tgt'!$B:$B,'Product Tgt'!$D:$D),0),0) -> 0 | CA11: =ROUND(IFERROR(#REF!/_xlfn.XLOOKUP(CA$7,'Product Tgt'!$B:$B,'Product Tgt'!$D:$D),0),0) -> 0 | CB11: =ROUND(IFERROR(AV11/_xlfn.XLOOKUP(CB$7,'Product Tgt'!$B:$B,'Product Tgt'!$D:$D),0),0) -> 0 | CC11: =ROUND(IFERROR(AW11/_xlfn.XLOOKUP(CC$7,'Product Tgt'!$B:$B,'Product Tgt'!$D:$D),0),0) -> 0 | CD11: =ROUND(IFERROR(AX11/_xlfn.XLOOKUP(CD$7,'Product Tgt'!$B:$B,'Product Tgt'!$D:$D),0),0) -> 0 | CE11: =ROUND(IFERROR(AY11/_xlfn.XLOOKUP(CE$7,'Product Tgt'!$B:$B,'Product Tgt'!$D:$D),0),0) -> 0 | CF11: =ROUND(IFERROR(AZ11/_xlfn.XLOOKUP(CF$7,'Product Tgt'!$B:$B,'Product Tgt'!$D:$D),0),0) -> 0 | CG11: =ROUND(IFERROR(BA11/_xlfn.XLOOKUP(CG$7,'Product Tgt'!$B:$B,'Product Tgt'!$D:$D),0),0) -> 0 | CH11: =ROUND(IFERROR(BB11/_xlfn.XLOOKUP(CH$7,'Product Tgt'!$B:$B,'Product Tgt'!$D:$D),0),0) -> 0 | CI11: =ROUND(IFERROR(BC11/_xlfn.XLOOKUP(CI$7,'Product Tgt'!$B:$B,'Product Tgt'!$D:$D),0),0) -> 0 | ... CW11: =ROUND(IFERROR(BQ11/_xlfn.XLOOKUP(CW$7,'Product Tgt'!$B:$B,'Product Tgt'!$D:$D),0),0) -> 0 | CX11: =ROUND(IFERROR(#REF!/_xlfn.XLOOKUP(CX$7,'Product Tgt'!$B:$B,'Product Tgt'!$D:$D),0),0) -> 0 | CY11: =ROUND(IFERROR(#REF!/_xlfn.XLOOKUP(CY$7,'Product Tgt'!$B:$B,'Product Tgt'!$D:$D),0),0) -> 0 | CZ11: =ROUND(IFERROR(#REF!/_xlfn.XLOOKUP(CZ$7,'Product Tgt'!$B:$B,'Product Tgt'!$D:$D),0),0) -> 0 | DA11: =IFERROR(BR11*_xlfn.XLOOKUP(DA$7,'Product Tgt'!$B:$B,'Product Tgt'!$D:$D),0) -> 0 | DB11: =IFERROR(BS11*_xlfn.XLOOKUP(DB$7,'Product Tgt'!$B:$B,'Product Tgt'!$D:$D),0) -> 0 | DC11: =IFERROR(BT11*_xlfn.XLOOKUP(DC$7,'Product Tgt'!$B:$B,'Product Tgt'!$D:$D),0) -> 0 | DD11: =IFERROR(BU11*_xlfn.XLOOKUP(DD$7,'Product Tgt'!$B:$B,'Product Tgt'!$D:$D),0) -> 0 | DE11: =IFERROR(BV11*_xlfn.XLOOKUP(DE$7,'Product Tgt'!$B:$B,'Product Tgt'!$D:$D),0) -> 0 | DF11: =IFERROR(BW11*_xlfn.XLOOKUP(DF$7,'Product Tgt'!$B:$B,'Product Tgt'!$D:$D),0) -> 0 | DG11: =IFERROR(BX11*_xlfn.XLOOKUP(DG$7,'Product Tgt'!$B:$B,'Product Tgt'!$D:$D),0) -> 0 | DH11: =IFERROR(BY11*_xlfn.XLOOKUP(DH$7,'Product Tgt'!$B:$B,'Product Tgt'!$D:$D),0) -> 0 | ... EI11: =IFERROR(CZ11*_xlfn.XLOOKUP(EI$7,'Product Tgt'!$B:$B,'Product Tgt'!$D:$D),0) -> 0
B12: SYT-BIRA-BIR1 | C12: =_xlfn.XLOOKUP($B12,'Terr Target'!$A:$A,'Terr Target'!$E:$E) -> 163481.17 | D12: =SUM(AM12:BQ12) -> 163481 | E12: =D12-C12 -> -0.17253931 | F12: =ABS(E12)/D12 -> 1.0554089e-06 | G12: =1-E12/D12 -> 1.0000011 | H12: 12567.979 | I12: 24122.736 | J12: 12933.638 | K12: 12617.714 | L12: 12672.257 | M12: 9411.4675 | N12: 176.759 | O12: 1054.4937 | P12: 1046.4234 | Q12: 883.80512 | R12: 8084.1993 | S12: 14280.774 | T12: 0 | U12: 0 | V12: 10388.389 | W12: 7246.1091 | X12: 1772.6302 | Y12: 1912.0274 | Z12: 382.8398 | AA12: 3273.5868 | AB12: 942.4083 | AC12: 1857.5149 | AD12: 6863.2693 | AE12: 9885.3836 | AF12: 0 | AG12: 5990.605 | AH12: 941.35785 | AI12: 3392.7729 | AJ12: 4668.4578 | AK12: 1699.0883 | AL12: 2043.1119 | AM12: =IFERROR(ROUND(_xlfn.XLOOKUP(AM$7,'Product Tgt'!$B:$B,'Product Tgt'!$G:$G)*H12/H$121,0),0) -> 12218 | AN12: =IFERROR(ROUND(_xlfn.XLOOKUP(AN$7,'Product Tgt'!$B:$B,'Product Tgt'!$G:$G)*I12/I$121,0),0) -> 23746 | AO12: =IFERROR(ROUND(_xlfn.XLOOKUP(AO$7,'Product Tgt'!$B:$B,'Product Tgt'!$G:$G)*J12/J$121,0),0) -> 12531 | AP12: =IFERROR(ROUND(_xlfn.XLOOKUP(AP$7,'Product Tgt'!$B:$B,'Product Tgt'!$G:$G)*K12/K$121,0),0) -> 12309 | AQ12: =IFERROR(ROUND(_xlfn.XLOOKUP(AQ$7,'Product Tgt'!$B:$B,'Product Tgt'!$G:$G)*L12/L$121,0),0) -> 12253 | AR12: =IFERROR(ROUND(_xlfn.XLOOKUP(AR$7,'Product Tgt'!$B:$B,'Product Tgt'!$G:$G)*M12/M$121,0),0) -> 9118 | AS12: =IFERROR(ROUND(_xlfn.XLOOKUP(AS$7,'Product Tgt'!$B:$B,'Product Tgt'!$G:$G)*N12/N$121,0),0) -> 163 | AT12: =IFERROR(ROUND(_xlfn.XLOOKUP(AT$7,'Product Tgt'!$B:$B,'Product Tgt'!$G:$G)*O12/O$121,0),0) -> 949 | ... BQ12: =IFERROR(ROUND(_xlfn.XLOOKUP(BQ$7,'Product Tgt'!$B:$B,'Product Tgt'!$G:$G)*AL12/AL$121,0),0) -> 1597 | BR12: =ROUND(IFERROR(AM12/_xlfn.XLOOKUP(BR$7,'Product Tgt'!$B:$B,'Product Tgt'!$D:$D),0),0) -> 0 | BS12: =ROUND(IFERROR(AN12/_xlfn.XLOOKUP(BS$7,'Product Tgt'!$B:$B,'Product Tgt'!$D:$D),0),0) -> 0 | BT12: =ROUND(IFERROR(AO12/_xlfn.XLOOKUP(BT$7,'Product Tgt'!$B:$B,'Product Tgt'!$D:$D),0),0) -> 0 | BU12: =ROUND(IFERROR(AP12/_xlfn.XLOOKUP(BU$7,'Product Tgt'!$B:$B,'Product Tgt'!$D:$D),0),0) -> 0 | BV12: =ROUND(IFERROR(AQ12/_xlfn.XLOOKUP(BV$7,'Product Tgt'!$B:$B,'Product Tgt'!$D:$D),0),0) -> 0 | BW12: =ROUND(IFERROR(AU12/_xlfn.XLOOKUP(BW$7,'Product Tgt'!$B:$B,'Product Tgt'!$D:$D),0),0) -> 0 | BX12: =ROUND(IFERROR(#REF!/_xlfn.XLOOKUP(BX$7,'Product Tgt'!$B:$B,'Product Tgt'!$D:$D),0),0) -> 0 | BY12: =ROUND(IFERROR(#REF!/_xlfn.XLOOKUP(BY$7,'Product Tgt'!$B:$B,'Product Tgt'!$D:$D),0),0) -> 0 | BZ12: =ROUND(IFERROR(#REF!/_xlfn.XLOOKUP(BZ$7,'Product Tgt'!$B:$B,'Product Tgt'!$D:$D),0),0) -> 0 | CA12: =ROUND(IFERROR(#REF!/_xlfn.XLOOKUP(CA$7,'Product Tgt'!$B:$B,'Product Tgt'!$D:$D),0),0) -> 0 | CB12: =ROUND(IFERROR(AV12/_xlfn.XLOOKUP(CB$7,'Product Tgt'!$B:$B,'Product Tgt'!$D:$D),0),0) -> 0 | CC12: =ROUND(IFERROR(AW12/_xlfn.XLOOKUP(CC$7,'Product Tgt'!$B:$B,'Product Tgt'!$D:$D),0),0) -> 0 | CD12: =ROUND(IFERROR(AX12/_xlfn.XLOOKUP(CD$7,'Product Tgt'!$B:$B,'Product Tgt'!$D:$D),0),0) -> 0 | CE12: =ROUND(IFERROR(AY12/_xlfn.XLOOKUP(CE$7,'Product Tgt'!$B:$B,'Product Tgt'!$D:$D),0),0) -> 0 | CF12: =ROUND(IFERROR(AZ12/_xlfn.XLOOKUP(CF$7,'Product Tgt'!$B:$B,'Product Tgt'!$D:$D),0),0) -> 0 | CG12: =ROUND(IFERROR(BA12/_xlfn.XLOOKUP(CG$7,'Product Tgt'!$B:$B,'Product Tgt'!$D:$D),0),0) -> 0 | CH12: =ROUND(IFERROR(BB12/_xlfn.XLOOKUP(CH$7,'Product Tgt'!$B:$B,'Product Tgt'!$D:$D),0),0) -> 0 | CI12: =ROUND(IFERROR(BC12/_xlfn.XLOOKUP(CI$7,'Product Tgt'!$B:$B,'Product Tgt'!$D:$D),0),0) -> 0 | ... CW12: =ROUND(IFERROR(BQ12/_xlfn.XLOOKUP(CW$7,'Product Tgt'!$B:$B,'Product Tgt'!$D:$D),0),0) -> 0 | CX12: =ROUND(IFERROR(#REF!/_xlfn.XLOOKUP(CX$7,'Product Tgt'!$B:$B,'Product Tgt'!$D:$D),0),0) -> 0 | CY12: =ROUND(IFERROR(#REF!/_xlfn.XLOOKUP(CY$7,'Product Tgt'!$B:$B,'Product Tgt'!$D:$D),0),0) -> 0 | CZ12: =ROUND(IFERROR(#REF!/_xlfn.XLOOKUP(CZ$7,'Product Tgt'!$B:$B,'Product Tgt'!$D:$D),0),0) -> 0 | DA12: =IFERROR(BR12*_xlfn.XLOOKUP(DA$7,'Product Tgt'!$B:$B,'Product Tgt'!$D:$D),0) -> 0 | DB12: =IFERROR(BS12*_xlfn.XLOOKUP(DB$7,'Product Tgt'!$B:$B,'Product Tgt'!$D:$D),0) -> 0 | DC12: =IFERROR(BT12*_xlfn.XLOOKUP(DC$7,'Product Tgt'!$B:$B,'Product Tgt'!$D:$D),0) -> 0 | DD12: =IFERROR(BU12*_xlfn.XLOOKUP(DD$7,'Product Tgt'!$B:$B,'Product Tgt'!$D:$D),0) -> 0 | DE12: =IFERROR(BV12*_xlfn.XLOOKUP(DE$7,'Product Tgt'!$B:$B,'Product Tgt'!$D:$D),0) -> 0 | DF12: =IFERROR(BW12*_xlfn.XLOOKUP(DF$7,'Product Tgt'!$B:$B,'Product Tgt'!$D:$D),0) -> 0 | DG12: =IFERROR(BX12*_xlfn.XLOOKUP(DG$7,'Product Tgt'!$B:$B,'Product Tgt'!$D:$D),0) -> 0 | DH12: =IFERROR(BY12*_xlfn.XLOOKUP(DH$7,'Product Tgt'!$B:$B,'Product Tgt'!$D:$D),0) -> 0 | ... EI12: =IFERROR(CZ12*_xlfn.XLOOKUP(EI$7,'Product Tgt'!$B:$B,'Product Tgt'!$D:$D),0) -> 0
B13: SYT-BIRA-BIR2 | C13: =_xlfn.XLOOKUP($B13,'Terr Target'!$A:$A,'Terr Target'!$E:$E) -> 134305.45 | D13: =SUM(AM13:BQ13) -> 134303 | E13: =D13-C13 -> -2.4516152 | F13: =ABS(E13)/D13 -> 1.8254359e-05 | G13: =1-E13/D13 -> 1.0000183 | H13: 10287.436 | I13: 19004.848 | J13: 10204.882 | K13: 12019.699 | L13: 11808.188 | M13: 6918.9492 | N13: 255.76805 | O13: 953.62945 | P13: 338.34209 | Q13: 0 | R13: 7033.415 | S13: 7636.9204 | T13: 0 | U13: 0 | V13: 8863.6383 | W13: 6587.7971 | X13: 2332.2131 | Y13: 2555.7773 | Z13: 0 | AA13: 2654.4734 | AB13: 889.2217 | AC13: 1011.0385 | AD13: 4727.8471 | AE13: 8868.6834 | AF13: 0 | AG13: 5363.2845 | AH13: 680.73232 | AI13: 2789.3913 | AJ13: 4599.9983 | AK13: 1459.2947 | AL13: 1942.2924 | AM13: =IFERROR(ROUND(_xlfn.XLOOKUP(AM$7,'Product Tgt'!$B:$B,'Product Tgt'!$G:$G)*H13/H$121,0),0) -> 10001 | AN13: =IFERROR(ROUND(_xlfn.XLOOKUP(AN$7,'Product Tgt'!$B:$B,'Product Tgt'!$G:$G)*I13/I$121,0),0) -> 18708 | AO13: =IFERROR(ROUND(_xlfn.XLOOKUP(AO$7,'Product Tgt'!$B:$B,'Product Tgt'!$G:$G)*J13/J$121,0),0) -> 9887 | AP13: =IFERROR(ROUND(_xlfn.XLOOKUP(AP$7,'Product Tgt'!$B:$B,'Product Tgt'!$G:$G)*K13/K$121,0),0) -> 11725 | AQ13: =IFERROR(ROUND(_xlfn.XLOOKUP(AQ$7,'Product Tgt'!$B:$B,'Product Tgt'!$G:$G)*L13/L$121,0),0) -> 11418 | AR13: =IFERROR(ROUND(_xlfn.XLOOKUP(AR$7,'Product Tgt'!$B:$B,'Product Tgt'!$G:$G)*M13/M$121,0),0) -> 6703 | AS13: =IFERROR(ROUND(_xlfn.XLOOKUP(AS$7,'Product Tgt'!$B:$B,'Product Tgt'!$G:$G)*N13/N$121,0),0) -> 236 | AT13: =IFERROR(ROUND(_xlfn.XLOOKUP(AT$7,'Product Tgt'!$B:$B,'Product Tgt'!$G:$G)*O13/O$121,0),0) -> 858 | ... BQ13: =IFERROR(ROUND(_xlfn.XLOOKUP(BQ$7,'Product Tgt'!$B:$B,'Product Tgt'!$G:$G)*AL13/AL$121,0),0) -> 1518 | BR13: =ROUND(IFERROR(AM13/_xlfn.XLOOKUP(BR$7,'Product Tgt'!$B:$B,'Product Tgt'!$D:$D),0),0) -> 0 | BS13: =ROUND(IFERROR(AN13/_xlfn.XLOOKUP(BS$7,'Product Tgt'!$B:$B,'Product Tgt'!$D:$D),0),0) -> 0 | BT13: =ROUND(IFERROR(AO13/_xlfn.XLOOKUP(BT$7,'Product Tgt'!$B:$B,'Product Tgt'!$D:$D),0),0) -> 0 | BU13: =ROUND(IFERROR(AP13/_xlfn.XLOOKUP(BU$7,'Product Tgt'!$B:$B,'Product Tgt'!$D:$D),0),0) -> 0 | BV13: =ROUND(IFERROR(AQ13/_xlfn.XLOOKUP(BV$7,'Product Tgt'!$B:$B,'Product Tgt'!$D:$D),0),0) -> 0 | BW13: =ROUND(IFERROR(AU13/_xlfn.XLOOKUP(BW$7,'Product Tgt'!$B:$B,'Product Tgt'!$D:$D),0),0) -> 0 | BX13: =ROUND(IFERROR(#REF!/_xlfn.XLOOKUP(BX$7,'Product Tgt'!$B:$B,'Product Tgt'!$D:$D),0),0) -> 0 | BY13: =ROUND(IFERROR(#REF!/_xlfn.XLOOKUP(BY$7,'Product Tgt'!$B:$B,'Product Tgt'!$D:$D),0),0) -> 0 | BZ13: =ROUND(IFERROR(#REF!/_xlfn.XLOOKUP(BZ$7,'Product Tgt'!$B:$B,'Product Tgt'!$D:$D),0),0) -> 0 | CA13: =ROUND(IFERROR(#REF!/_xlfn.XLOOKUP(CA$7,'Product Tgt'!$B:$B,'Product Tgt'!$D:$D),0),0) -> 0 | CB13: =ROUND(IFERROR(AV13/_xlfn.XLOOKUP(CB$7,'Product Tgt'!$B:$B,'Product Tgt'!$D:$D),0),0) -> 0 | CC13: =ROUND(IFERROR(AW13/_xlfn.XLOOKUP(CC$7,'Product Tgt'!$B:$B,'Product Tgt'!$D:$D),0),0) -> 0 | CD13: =ROUND(IFERROR(AX13/_xlfn.XLOOKUP(CD$7,'Product Tgt'!$B:$B,'Product Tgt'!$D:$D),0),0) -> 0 | CE13: =ROUND(IFERROR(AY13/_xlfn.XLOOKUP(CE$7,'Product Tgt'!$B:$B,'Product Tgt'!$D:$D),0),0) -> 0 | CF13: =ROUND(IFERROR(AZ13/_xlfn.XLOOKUP(CF$7,'Product Tgt'!$B:$B,'Product Tgt'!$D:$D),0),0) -> 0 | CG13: =ROUND(IFERROR(BA13/_xlfn.XLOOKUP(CG$7,'Product Tgt'!$B:$B,'Product Tgt'!$D:$D),0),0) -> 0 | CH13: =ROUND(IFERROR(BB13/_xlfn.XLOOKUP(CH$7,'Product Tgt'!$B:$B,'Product Tgt'!$D:$D),0),0) -> 0 | CI13: =ROUND(IFERROR(BC13/_xlfn.XLOOKUP(CI$7,'Product Tgt'!$B:$B,'Product Tgt'!$D:$D),0),0) -> 0 | ... CW13: =ROUND(IFERROR(BQ13/_xlfn.XLOOKUP(CW$7,'Product Tgt'!$B:$B,'Product Tgt'!$D:$D),0),0) -> 0 | CX13: =ROUND(IFERROR(#REF!/_xlfn.XLOOKUP(CX$7,'Product Tgt'!$B:$B,'Product Tgt'!$D:$D),0),0) -> 0 | CY13: =ROUND(IFERROR(#REF!/_xlfn.XLOOKUP(CY$7,'Product Tgt'!$B:$B,'Product Tgt'!$D:$D),0),0) -> 0 | CZ13: =ROUND(IFERROR(#REF!/_xlfn.XLOOKUP(CZ$7,'Product Tgt'!$B:$B,'Product Tgt'!$D:$D),0),0) -> 0 | DA13: =IFERROR(BR13*_xlfn.XLOOKUP(DA$7,'Product Tgt'!$B:$B,'Product Tgt'!$D:$D),0) -> 0 | DB13: =IFERROR(BS13*_xlfn.XLOOKUP(DB$7,'Product Tgt'!$B:$B,'Product Tgt'!$D:$D),0) -> 0 | DC13: =IFERROR(BT13*_xlfn.XLOOKUP(DC$7,'Product Tgt'!$B:$B,'Product Tgt'!$D:$D),0) -> 0 | DD13: =IFERROR(BU13*_xlfn.XLOOKUP(DD$7,'Product Tgt'!$B:$B,'Product Tgt'!$D:$D),0) -> 0 | DE13: =IFERROR(BV13*_xlfn.XLOOKUP(DE$7,'Product Tgt'!$B:$B,'Product Tgt'!$D:$D),0) -> 0 | DF13: =IFERROR(BW13*_xlfn.XLOOKUP(DF$7,'Product Tgt'!$B:$B,'Product Tgt'!$D:$D),0) -> 0 | DG13: =IFERROR(BX13*_xlfn.XLOOKUP(DG$7,'Product Tgt'!$B:$B,'Product Tgt'!$D:$D),0) -> 0 | DH13: =IFERROR(BY13*_xlfn.XLOOKUP(DH$7,'Product Tgt'!$B:$B,'Product Tgt'!$D:$D),0) -> 0 | ... EI13: =IFERROR(CZ13*_xlfn.XLOOKUP(EI$7,'Product Tgt'!$B:$B,'Product Tgt'!$D:$D),0) -> 0
B14: SYT-BIRA-BIR3 | C14: =_xlfn.XLOOKUP($B14,'Terr Target'!$A:$A,'Terr Target'!$E:$E) -> 127483.42 | D14: =SUM(AM14:BQ14) -> 127484 | E14: =D14-C14 -> 0.58 | F14: =ABS(E14)/D14 -> 4.5495905e-06 | G14: =1-E14/D14 -> 0.99999545 | H14: 9850.1174 | I14: 17880.151 | J14: 10012.323 | K14: 10389.816 | L14: 9190.9937 | M14: 6461.3605 | N14: 253.32974 | O14: 1126.7344 | P14: 262.87995 | Q14: 0 | R14: 3911.072 | S14: 6392.4739 | T14: 0 | U14: 1734.0792 | V14: 8136.2516 | W14: 5500.1172 | X14: 1189.2718 | Y14: 1159.593 | Z14: 217.3018 | AA14: 2271.488 | AB14: 697.44115 | AC14: 2298.0081 | AD14: 10552.89 | AE14: 11306.562 | AF14: 431.38133 | AG14: 4031.0167 | AH14: 480.14995 | AI14: 2139.0146 | AJ14: 4854.614 | AK14: 1028.2538 | AL14: 1368.2668 | AM14: =IFERROR(ROUND(_xlfn.XLOOKUP(AM$7,'Product Tgt'!$B:$B,'Product Tgt'!$G:$G)*H14/H$121,0),0) -> 9576 | AN14: =IFERROR(ROUND(_xlfn.XLOOKUP(AN$7,'Product Tgt'!$B:$B,'Product Tgt'!$G:$G)*I14/I$121,0),0) -> 17601 | AO14: =IFERROR(ROUND(_xlfn.XLOOKUP(AO$7,'Product Tgt'!$B:$B,'Product Tgt'!$G:$G)*J14/J$121,0),0) -> 9701 | AP14: =IFERROR(ROUND(_xlfn.XLOOKUP(AP$7,'Product Tgt'!$B:$B,'Product Tgt'!$G:$G)*K14/K$121,0),0) -> 10136 | AQ14: =IFERROR(ROUND(_xlfn.XLOOKUP(AQ$7,'Product Tgt'!$B:$B,'Product Tgt'!$G:$G)*L14/L$121,0),0) -> 8887 | AR14: =IFERROR(ROUND(_xlfn.XLOOKUP(AR$7,'Product Tgt'!$B:$B,'Product Tgt'!$G:$G)*M14/M$121,0),0) -> 6260 | AS14: =IFERROR(ROUND(_xlfn.XLOOKUP(AS$7,'Product Tgt'!$B:$B,'Product Tgt'!$G:$G)*N14/N$121,0),0) -> 234 | AT14: =IFERROR(ROUND(_xlfn.XLOOKUP(AT$7,'Product Tgt'!$B:$B,'Product Tgt'!$G:$G)*O14/O$121,0),0) -> 1014 | ... BQ14: =IFERROR(ROUND(_xlfn.XLOOKUP(BQ$7,'Product Tgt'!$B:$B,'Product Tgt'!$G:$G)*AL14/AL$121,0),0) -> 1070 | BR14: =ROUND(IFERROR(AM14/_xlfn.XLOOKUP(BR$7,'Product Tgt'!$B:$B,'Product Tgt'!$D:$D),0),0) -> 0 | BS14: =ROUND(IFERROR(AN14/_xlfn.XLOOKUP(BS$7,'Product Tgt'!$B:$B,'Product Tgt'!$D:$D),0),0) -> 0 | BT14: =ROUND(IFERROR(AO14/_xlfn.XLOOKUP(BT$7,'Product Tgt'!$B:$B,'Product Tgt'!$D:$D),0),0) -> 0 | BU14: =ROUND(IFERROR(AP14/_xlfn.XLOOKUP(BU$7,'Product Tgt'!$B:$B,'Product Tgt'!$D:$D),0),0) -> 0 | BV14: =ROUND(IFERROR(AQ14/_xlfn.XLOOKUP(BV$7,'Product Tgt'!$B:$B,'Product Tgt'!$D:$D),0),0) -> 0 | BW14: =ROUND(IFERROR(AU14/_xlfn.XLOOKUP(BW$7,'Product Tgt'!$B:$B,'Product Tgt'!$D:$D),0),0) -> 0 | BX14: =ROUND(IFERROR(#REF!/_xlfn.XLOOKUP(BX$7,'Product Tgt'!$B:$B,'Product Tgt'!$D:$D),0),0) -> 0 | BY14: =ROUND(IFERROR(#REF!/_xlfn.XLOOKUP(BY$7,'Product Tgt'!$B:$B,'Product Tgt'!$D:$D),0),0) -> 0 | BZ14: =ROUND(IFERROR(#REF!/_xlfn.XLOOKUP(BZ$7,'Product Tgt'!$B:$B,'Product Tgt'!$D:$D),0),0) -> 0 | CA14: =ROUND(IFERROR(#REF!/_xlfn.XLOOKUP(CA$7,'Product Tgt'!$B:$B,'Product Tgt'!$D:$D),0),0) -> 0 | CB14: =ROUND(IFERROR(AV14/_xlfn.XLOOKUP(CB$7,'Product Tgt'!$B:$B,'Product Tgt'!$D:$D),0),0) -> 0 | CC14: =ROUND(IFERROR(AW14/_xlfn.XLOOKUP(CC$7,'Product Tgt'!$B:$B,'Product Tgt'!$D:$D),0),0) -> 0 | CD14: =ROUND(IFERROR(AX14/_xlfn.XLOOKUP(CD$7,'Product Tgt'!$B:$B,'Product Tgt'!$D:$D),0),0) -> 0 | CE14: =ROUND(IFERROR(AY14/_xlfn.XLOOKUP(CE$7,'Product Tgt'!$B:$B,'Product Tgt'!$D:$D),0),0) -> 0 | CF14: =ROUND(IFERROR(AZ14/_xlfn.XLOOKUP(CF$7,'Product Tgt'!$B:$B,'Product Tgt'!$D:$D),0),0) -> 0 | CG14: =ROUND(IFERROR(BA14/_xlfn.XLOOKUP(CG$7,'Product Tgt'!$B:$B,'Product Tgt'!$D:$D),0),0) -> 0 | CH14: =ROUND(IFERROR(BB14/_xlfn.XLOOKUP(CH$7,'Product Tgt'!$B:$B,'Product Tgt'!$D:$D),0),0) -> 0 | CI14: =ROUND(IFERROR(BC14/_xlfn.XLOOKUP(CI$7,'Product Tgt'!$B:$B,'Product Tgt'!$D:$D),0),0) -> 0 | ... CW14: =ROUND(IFERROR(BQ14/_xlfn.XLOOKUP(CW$7,'Product Tgt'!$B:$B,'Product Tgt'!$D:$D),0),0) -> 0 | CX14: =ROUND(IFERROR(#REF!/_xlfn.XLOOKUP(CX$7,'Product Tgt'!$B:$B,'Product Tgt'!$D:$D),0),0) -> 0 | CY14: =ROUND(IFERROR(#REF!/_xlfn.XLOOKUP(CY$7,'Product Tgt'!$B:$B,'Product Tgt'!$D:$D),0),0) -> 0 | CZ14: =ROUND(IFERROR(#REF!/_xlfn.XLOOKUP(CZ$7,'Product Tgt'!$B:$B,'Product Tgt'!$D:$D),0),0) -> 0 | DA14: =IFERROR(BR14*_xlfn.XLOOKUP(DA$7,'Product Tgt'!$B:$B,'Product Tgt'!$D:$D),0) -> 0 | DB14: =IFERROR(BS14*_xlfn.XLOOKUP(DB$7,'Product Tgt'!$B:$B,'Product Tgt'!$D:$D),0) -> 0 | DC14: =IFERROR(BT14*_xlfn.XLOOKUP(DC$7,'Product Tgt'!$B:$B,'Product Tgt'!$D:$D),0) -> 0 | DD14: =IFERROR(BU14*_xlfn.XLOOKUP(DD$7,'Product Tgt'!$B:$B,'Product Tgt'!$D:$D),0) -> 0 | DE14: =IFERROR(BV14*_xlfn.XLOOKUP(DE$7,'Product Tgt'!$B:$B,'Product Tgt'!$D:$D),0) -> 0 | DF14: =IFERROR(BW14*_xlfn.XLOOKUP(DF$7,'Product Tgt'!$B:$B,'Product Tgt'!$D:$D),0) -> 0 | DG14: =IFERROR(BX14*_xlfn.XLOOKUP(DG$7,'Product Tgt'!$B:$B,'Product Tgt'!$D:$D),0) -> 0 | DH14: =IFERROR(BY14*_xlfn.XLOOKUP(DH$7,'Product Tgt'!$B:$B,'Product Tgt'!$D:$D),0) -> 0 | ... EI14: =IFERROR(CZ14*_xlfn.XLOOKUP(EI$7,'Product Tgt'!$B:$B,'Product Tgt'!$D:$D),0) -> 0
B15: SYT-BIRA-ICH1 | C15: =_xlfn.XLOOKUP($B15,'Terr Target'!$A:$A,'Terr Target'!$E:$E) -> 200671.52 | D15: =SUM(AM15:BQ15) -> 200663 | E15: =D15-C15 -> -8.5196618 | F15: =ABS(E15)/D15 -> 4.2457562e-05 | G15: =1-E15/D15 -> 1.0000425 | H15: 15820.847 | I15: 27715.627 | J15: 14916.237 | K15: 16489.316 | L15: 11570.668 | M15: 9040.3456 | N15: 212.26689 | O15: 1171.5111 | P15: 2283.3852 | Q15: 1719.4123 | R15: 5553.5487 | S15: 8018.4625 | T15: 0 | U15: 1235.2012 | V15: 13842.854 | W15: 9042.5592 | X15: 2930.3039 | Y15: 2871.6576 | Z15: 0 | AA15: 3074.8476 | AB15: 1182.6298 | AC15: 2954.5933 | AD15: 12011.223 | AE15: 18365.129 | AF15: 6235.3802 | AG15: 7133.1377 | AH15: 544.81834 | AI15: 3942.1195 | AJ15: 10204.933 | AK15: 1182.741 | AL15: 1383.6263 | AM15: =IFERROR(ROUND(_xlfn.XLOOKUP(AM$7,'Product Tgt'!$B:$B,'Product Tgt'!$G:$G)*H15/H$121,0),0) -> 15380 | AN15: =IFERROR(ROUND(_xlfn.XLOOKUP(AN$7,'Product Tgt'!$B:$B,'Product Tgt'!$G:$G)*I15/I$121,0),0) -> 27283 | AO15: =IFERROR(ROUND(_xlfn.XLOOKUP(AO$7,'Product Tgt'!$B:$B,'Product Tgt'!$G:$G)*J15/J$121,0),0) -> 14452 | AP15: =IFERROR(ROUND(_xlfn.XLOOKUP(AP$7,'Product Tgt'!$B:$B,'Product Tgt'!$G:$G)*K15/K$121,0),0) -> 16086 | AQ15: =IFERROR(ROUND(_xlfn.XLOOKUP(AQ$7,'Product Tgt'!$B:$B,'Product Tgt'!$G:$G)*L15/L$121,0),0) -> 11188 | AR15: =IFERROR(ROUND(_xlfn.XLOOKUP(AR$7,'Product Tgt'!$B:$B,'Product Tgt'!$G:$G)*M15/M$121,0),0) -> 8758 | AS15: =IFERROR(ROUND(_xlfn.XLOOKUP(AS$7,'Product Tgt'!$B:$B,'Product Tgt'!$G:$G)*N15/N$121,0),0) -> 196 | AT15: =IFERROR(ROUND(_xlfn.XLOOKUP(AT$7,'Product Tgt'!$B:$B,'Product Tgt'!$G:$G)*O15/O$121,0),0) -> 1054 | ... BQ15: =IFERROR(ROUND(_xlfn.XLOOKUP(BQ$7,'Product Tgt'!$B:$B,'Product Tgt'!$G:$G)*AL15/AL$121,0),0) -> 1082 | BR15: =ROUND(IFERROR(AM15/_xlfn.XLOOKUP(BR$7,'Product Tgt'!$B:$B,'Product Tgt'!$D:$D),0),0) -> 0 | BS15: =ROUND(IFERROR(AN15/_xlfn.XLOOKUP(BS$7,'Product Tgt'!$B:$B,'Product Tgt'!$D:$D),0),0) -> 0 | BT15: =ROUND(IFERROR(AO15/_xlfn.XLOOKUP(BT$7,'Product Tgt'!$B:$B,'Product Tgt'!$D:$D),0),0) -> 0 | BU15: =ROUND(IFERROR(AP15/_xlfn.XLOOKUP(BU$7,'Product Tgt'!$B:$B,'Product Tgt'!$D:$D),0),0) -> 0 | BV15: =ROUND(IFERROR(AQ15/_xlfn.XLOOKUP(BV$7,'Product Tgt'!$B:$B,'Product Tgt'!$D:$D),0),0) -> 0 | BW15: =ROUND(IFERROR(AU15/_xlfn.XLOOKUP(BW$7,'Product Tgt'!$B:$B,'Product Tgt'!$D:$D),0),0) -> 0 | BX15: =ROUND(IFERROR(#REF!/_xlfn.XLOOKUP(BX$7,'Product Tgt'!$B:$B,'Product Tgt'!$D:$D),0),0) -> 0 | BY15: =ROUND(IFERROR(#REF!/_xlfn.XLOOKUP(BY$7,'Product Tgt'!$B:$B,'Product Tgt'!$D:$D),0),0) -> 0 | BZ15: =ROUND(IFERROR(#REF!/_xlfn.XLOOKUP(BZ$7,'Product Tgt'!$B:$B,'Product Tgt'!$D:$D),0),0) -> 0 | CA15: =ROUND(IFERROR(#REF!/_xlfn.XLOOKUP(CA$7,'Product Tgt'!$B:$B,'Product Tgt'!$D:$D),0),0) -> 0 | CB15: =ROUND(IFERROR(AV15/_xlfn.XLOOKUP(CB$7,'Product Tgt'!$B:$B,'Product Tgt'!$D:$D),0),0) -> 0 | CC15: =ROUND(IFERROR(AW15/_xlfn.XLOOKUP(CC$7,'Product Tgt'!$B:$B,'Product Tgt'!$D:$D),0),0) -> 0 | CD15: =ROUND(IFERROR(AX15/_xlfn.XLOOKUP(CD$7,'Product Tgt'!$B:$B,'Product Tgt'!$D:$D),0),0) -> 0 | CE15: =ROUND(IFERROR(AY15/_xlfn.XLOOKUP(CE$7,'Product Tgt'!$B:$B,'Product Tgt'!$D:$D),0),0) -> 0 | CF15: =ROUND(IFERROR(AZ15/_xlfn.XLOOKUP(CF$7,'Product Tgt'!$B:$B,'Product Tgt'!$D:$D),0),0) -> 0 | CG15: =ROUND(IFERROR(BA15/_xlfn.XLOOKUP(CG$7,'Product Tgt'!$B:$B,'Product Tgt'!$D:$D),0),0) -> 0 | CH15: =ROUND(IFERROR(BB15/_xlfn.XLOOKUP(CH$7,'Product Tgt'!$B:$B,'Product Tgt'!$D:$D),0),0) -> 0 | CI15: =ROUND(IFERROR(BC15/_xlfn.XLOOKUP(CI$7,'Product Tgt'!$B:$B,'Product Tgt'!$D:$D),0),0) -> 0 | ... CW15: =ROUND(IFERROR(BQ15/_xlfn.XLOOKUP(CW$7,'Product Tgt'!$B:$B,'Product Tgt'!$D:$D),0),0) -> 0 | CX15: =ROUND(IFERROR(#REF!/_xlfn.XLOOKUP(CX$7,'Product Tgt'!$B:$B,'Product Tgt'!$D:$D),0),0) -> 0 | CY15: =ROUND(IFERROR(#REF!/_xlfn.XLOOKUP(CY$7,'Product Tgt'!$B:$B,'Product Tgt'!$D:$D),0),0) -> 0 | CZ15: =ROUND(IFERROR(#REF!/_xlfn.XLOOKUP(CZ$7,'Product Tgt'!$B:$B,'Product Tgt'!$D:$D),0),0) -> 0 | DA15: =IFERROR(BR15*_xlfn.XLOOKUP(DA$7,'Product Tgt'!$B:$B,'Product Tgt'!$D:$D),0) -> 0 | DB15: =IFERROR(BS15*_xlfn.XLOOKUP(DB$7,'Product Tgt'!$B:$B,'Product Tgt'!$D:$D),0) -> 0 | DC15: =IFERROR(BT15*_xlfn.XLOOKUP(DC$7,'Product Tgt'!$B:$B,'Product Tgt'!$D:$D),0) -> 0 | DD15: =IFERROR(BU15*_xlfn.XLOOKUP(DD$7,'Product Tgt'!$B:$B,'Product Tgt'!$D:$D),0) -> 0 | DE15: =IFERROR(BV15*_xlfn.XLOOKUP(DE$7,'Product Tgt'!$B:$B,'Product Tgt'!$D:$D),0) -> 0 | DF15: =IFERROR(BW15*_xlfn.XLOOKUP(DF$7,'Product Tgt'!$B:$B,'Product Tgt'!$D:$D),0) -> 0 | DG15: =IFERROR(BX15*_xlfn.XLOOKUP(DG$7,'Product Tgt'!$B:$B,'Product Tgt'!$D:$D),0) -> 0 | DH15: =IFERROR(BY15*_xlfn.XLOOKUP(DH$7,'Product Tgt'!$B:$B,'Product Tgt'!$D:$D),0) -> 0 | ... EI15: =IFERROR(CZ15*_xlfn.XLOOKUP(EI$7,'Product Tgt'!$B:$B,'Product Tgt'!$D:$D),0) -> 0
B16: SYT-BOGA-BOG1 | C16: =_xlfn.XLOOKUP($B16,'Terr Target'!$A:$A,'Terr Target'!$E:$E) -> 319622.16 | D16: =SUM(AM16:BQ16) -> 319621 | E16: =D16-C16 -> -1.1550293 | F16: =ABS(E16)/D16 -> 3.6137465e-06 | G16: =1-E16/D16 -> 1.0000036 | H16: 35360.079 | I16: 66712.788 | J16: 25727.298 | K16: 23685.834 | L16: 31275.753 | M16: 22712.063 | N16: 293.41275 | O16: 2568.8486 | P16: 1307.4033 | Q16: 1111.8347 | R16: 4890.2724 | S16: 12692.307 | T16: 0 | U16: 1480.0378 | V16: 18838.336 | W16: 19826.349 | X16: 3366.2826 | Y16: 8793.3905 | Z16: 335.34882 | AA16: 6023.9434 | AB16: 1676.6742 | AC16: 396.21699 | AD16: 3335.3046 | AE16: 7335.3287 | AF16: 911.14639 | AG16: 13024.951 | AH16: 1416.1457 | AI16: 8105.7967 | AJ16: 8684.6381 | AK16: 884.3101 | AL16: 1641.5246 | AM16: =IFERROR(ROUND(_xlfn.XLOOKUP(AM$7,'Product Tgt'!$B:$B,'Product Tgt'!$G:$G)*H16/H$121,0),0) -> 34376 | AN16: =IFERROR(ROUND(_xlfn.XLOOKUP(AN$7,'Product Tgt'!$B:$B,'Product Tgt'!$G:$G)*I16/I$121,0),0) -> 65672 | AO16: =IFERROR(ROUND(_xlfn.XLOOKUP(AO$7,'Product Tgt'!$B:$B,'Product Tgt'!$G:$G)*J16/J$121,0),0) -> 24927 | AP16: =IFERROR(ROUND(_xlfn.XLOOKUP(AP$7,'Product Tgt'!$B:$B,'Product Tgt'!$G:$G)*K16/K$121,0),0) -> 23106 | AQ16: =IFERROR(ROUND(_xlfn.XLOOKUP(AQ$7,'Product Tgt'!$B:$B,'Product Tgt'!$G:$G)*L16/L$121,0),0) -> 30242 | AR16: =IFERROR(ROUND(_xlfn.XLOOKUP(AR$7,'Product Tgt'!$B:$B,'Product Tgt'!$G:$G)*M16/M$121,0),0) -> 22003 | AS16: =IFERROR(ROUND(_xlfn.XLOOKUP(AS$7,'Product Tgt'!$B:$B,'Product Tgt'!$G:$G)*N16/N$121,0),0) -> 271 | AT16: =IFERROR(ROUND(_xlfn.XLOOKUP(AT$7,'Product Tgt'!$B:$B,'Product Tgt'!$G:$G)*O16/O$121,0),0) -> 2312 | ... BQ16: =IFERROR(ROUND(_xlfn.XLOOKUP(BQ$7,'Product Tgt'!$B:$B,'Product Tgt'!$G:$G)*AL16/AL$121,0),0) -> 1283 | BR16: =ROUND(IFERROR(AM16/_xlfn.XLOOKUP(BR$7,'Product Tgt'!$B:$B,'Product Tgt'!$D:$D),0),0) -> 0 | BS16: =ROUND(IFERROR(AN16/_xlfn.XLOOKUP(BS$7,'Product Tgt'!$B:$B,'Product Tgt'!$D:$D),0),0) -> 0 | BT16: =ROUND(IFERROR(AO16/_xlfn.XLOOKUP(BT$7,'Product Tgt'!$B:$B,'Product Tgt'!$D:$D),0),0) -> 0 | BU16: =ROUND(IFERROR(AP16/_xlfn.XLOOKUP(BU$7,'Product Tgt'!$B:$B,'Product Tgt'!$D:$D),0),0) -> 0 | BV16: =ROUND(IFERROR(AQ16/_xlfn.XLOOKUP(BV$7,'Product Tgt'!$B:$B,'Product Tgt'!$D:$D),0),0) -> 0 | BW16: =ROUND(IFERROR(AU16/_xlfn.XLOOKUP(BW$7,'Product Tgt'!$B:$B,'Product Tgt'!$D:$D),0),0) -> 0 | BX16: =ROUND(IFERROR(#REF!/_xlfn.XLOOKUP(BX$7,'Product Tgt'!$B:$B,'Product Tgt'!$D:$D),0),0) -> 0 | BY16: =ROUND(IFERROR(#REF!/_xlfn.XLOOKUP(BY$7,'Product Tgt'!$B:$B,'Product Tgt'!$D:$D),0),0) -> 0 | BZ16: =ROUND(IFERROR(#REF!/_xlfn.XLOOKUP(BZ$7,'Product Tgt'!$B:$B,'Product Tgt'!$D:$D),0),0) -> 0 | CA16: =ROUND(IFERROR(#REF!/_xlfn.XLOOKUP(CA$7,'Product Tgt'!$B:$B,'Product Tgt'!$D:$D),0),0) -> 0 | CB16: =ROUND(IFERROR(AV16/_xlfn.XLOOKUP(CB$7,'Product Tgt'!$B:$B,'Product Tgt'!$D:$D),0),0) -> 0 | CC16: =ROUND(IFERROR(AW16/_xlfn.XLOOKUP(CC$7,'Product Tgt'!$B:$B,'Product Tgt'!$D:$D),0),0) -> 0 | CD16: =ROUND(IFERROR(AX16/_xlfn.XLOOKUP(CD$7,'Product Tgt'!$B:$B,'Product Tgt'!$D:$D),0),0) -> 0 | CE16: =ROUND(IFERROR(AY16/_xlfn.XLOOKUP(CE$7,'Product Tgt'!$B:$B,'Product Tgt'!$D:$D),0),0) -> 0 | CF16: =ROUND(IFERROR(AZ16/_xlfn.XLOOKUP(CF$7,'Product Tgt'!$B:$B,'Product Tgt'!$D:$D),0),0) -> 0 | CG16: =ROUND(IFERROR(BA16/_xlfn.XLOOKUP(CG$7,'Product Tgt'!$B:$B,'Product Tgt'!$D:$D),0),0) -> 0 | CH16: =ROUND(IFERROR(BB16/_xlfn.XLOOKUP(CH$7,'Product Tgt'!$B:$B,'Product Tgt'!$D:$D),0),0) -> 0 | CI16: =ROUND(IFERROR(BC16/_xlfn.XLOOKUP(CI$7,'Product Tgt'!$B:$B,'Product Tgt'!$D:$D),0),0) -> 0 | ... CW16: =ROUND(IFERROR(BQ16/_xlfn.XLOOKUP(CW$7,'Product Tgt'!$B:$B,'Product Tgt'!$D:$D),0),0) -> 0 | CX16: =ROUND(IFERROR(#REF!/_xlfn.XLOOKUP(CX$7,'Product Tgt'!$B:$B,'Product Tgt'!$D:$D),0),0) -> 0 | CY16: =ROUND(IFERROR(#REF!/_xlfn.XLOOKUP(CY$7,'Product Tgt'!$B:$B,'Product Tgt'!$D:$D),0),0) -> 0 | CZ16: =ROUND(IFERROR(#REF!/_xlfn.XLOOKUP(CZ$7,'Product Tgt'!$B:$B,'Product Tgt'!$D:$D),0),0) -> 0 | DA16: =IFERROR(BR16*_xlfn.XLOOKUP(DA$7,'Product Tgt'!$B:$B,'Product Tgt'!$D:$D),0) -> 0 | DB16: =IFERROR(BS16*_xlfn.XLOOKUP(DB$7,'Product Tgt'!$B:$B,'Product Tgt'!$D:$D),0) -> 0 | DC16: =IFERROR(BT16*_xlfn.XLOOKUP(DC$7,'Product Tgt'!$B:$B,'Product Tgt'!$D:$D),0) -> 0 | DD16: =IFERROR(BU16*_xlfn.XLOOKUP(DD$7,'Product Tgt'!$B:$B,'Product Tgt'!$D:$D),0) -> 0 | DE16: =IFERROR(BV16*_xlfn.XLOOKUP(DE$7,'Product Tgt'!$B:$B,'Product Tgt'!$D:$D),0) -> 0 | DF16: =IFERROR(BW16*_xlfn.XLOOKUP(DF$7,'Product Tgt'!$B:$B,'Product Tgt'!$D:$D),0) -> 0 | DG16: =IFERROR(BX16*_xlfn.XLOOKUP(DG$7,'Product Tgt'!$B:$B,'Product Tgt'!$D:$D),0) -> 0 | DH16: =IFERROR(BY16*_xlfn.XLOOKUP(DH$7,'Product Tgt'!$B:$B,'Product Tgt'!$D:$D),0) -> 0 | ... EI16: =IFERROR(CZ16*_xlfn.XLOOKUP(EI$7,'Product Tgt'!$B:$B,'Product Tgt'!$D:$D),0) -> 0
B17: SYT-BOGA-BOG2 | C17: =_xlfn.XLOOKUP($B17,'Terr Target'!$A:$A,'Terr Target'!$E:$E) -> 355435.28 | D17: =SUM(AM17:BQ17) -> 355437 | E17: =D17-C17 -> 1.7185006 | F17: =ABS(E17)/D17 -> 4.8348949e-06 | G17: =1-E17/D17 -> 0.99999517 | H17: 40073.952 | I17: 75709.976 | J17: 29875.894 | K17: 26512.613 | L17: 34210.467 | M17: 24488.446 | N17: 274.83547 | O17: 2548.4762 | P17: 1183.4775 | Q17: 727.10025 | R17: 5208.8597 | S17: 13540.931 | T17: 0 | U17: 1483.9618 | V17: 19597.146 | W17: 23750.608 | X17: 3993.4878 | Y17: 9909.8086 | Z17: 260.49836 | AA17: 6762.4456 | AB17: 1471.6655 | AC17: 428.67728 | AD17: 3481.721 | AE17: 6893.705 | AF17: 969.10806 | AG17: 14408.889 | AH17: 1274.7303 | AI17: 10002.159 | AJ17: 9855.4753 | AK17: 937.44953 | AL17: 1558.6521 | AM17: =IFERROR(ROUND(_xlfn.XLOOKUP(AM$7,'Product Tgt'!$B:$B,'Product Tgt'!$G:$G)*H17/H$121,0),0) -> 38958 | AN17: =IFERROR(ROUND(_xlfn.XLOOKUP(AN$7,'Product Tgt'!$B:$B,'Product Tgt'!$G:$G)*I17/I$121,0),0) -> 74529 | AO17: =IFERROR(ROUND(_xlfn.XLOOKUP(AO$7,'Product Tgt'!$B:$B,'Product Tgt'!$G:$G)*J17/J$121,0),0) -> 28947 | AP17: =IFERROR(ROUND(_xlfn.XLOOKUP(AP$7,'Product Tgt'!$B:$B,'Product Tgt'!$G:$G)*K17/K$121,0),0) -> 25864 | AQ17: =IFERROR(ROUND(_xlfn.XLOOKUP(AQ$7,'Product Tgt'!$B:$B,'Product Tgt'!$G:$G)*L17/L$121,0),0) -> 33079 | AR17: =IFERROR(ROUND(_xlfn.XLOOKUP(AR$7,'Product Tgt'!$B:$B,'Product Tgt'!$G:$G)*M17/M$121,0),0) -> 23724 | AS17: =IFERROR(ROUND(_xlfn.XLOOKUP(AS$7,'Product Tgt'!$B:$B,'Product Tgt'!$G:$G)*N17/N$121,0),0) -> 254 | AT17: =IFERROR(ROUND(_xlfn.XLOOKUP(AT$7,'Product Tgt'!$B:$B,'Product Tgt'!$G:$G)*O17/O$121,0),0) -> 2294 | ... BQ17: =IFERROR(ROUND(_xlfn.XLOOKUP(BQ$7,'Product Tgt'!$B:$B,'Product Tgt'!$G:$G)*AL17/AL$121,0),0) -> 1218 | BR17: =ROUND(IFERROR(AM17/_xlfn.XLOOKUP(BR$7,'Product Tgt'!$B:$B,'Product Tgt'!$D:$D),0),0) -> 0 | BS17: =ROUND(IFERROR(AN17/_xlfn.XLOOKUP(BS$7,'Product Tgt'!$B:$B,'Product Tgt'!$D:$D),0),0) -> 0 | BT17: =ROUND(IFERROR(AO17/_xlfn.XLOOKUP(BT$7,'Product Tgt'!$B:$B,'Product Tgt'!$D:$D),0),0) -> 0 | BU17: =ROUND(IFERROR(AP17/_xlfn.XLOOKUP(BU$7,'Product Tgt'!$B:$B,'Product Tgt'!$D:$D),0),0) -> 0 | BV17: =ROUND(IFERROR(AQ17/_xlfn.XLOOKUP(BV$7,'Product Tgt'!$B:$B,'Product Tgt'!$D:$D),0),0) -> 0 | BW17: =ROUND(IFERROR(AU17/_xlfn.XLOOKUP(BW$7,'Product Tgt'!$B:$B,'Product Tgt'!$D:$D),0),0) -> 0 | BX17: =ROUND(IFERROR(#REF!/_xlfn.XLOOKUP(BX$7,'Product Tgt'!$B:$B,'Product Tgt'!$D:$D),0),0) -> 0 | BY17: =ROUND(IFERROR(#REF!/_xlfn.XLOOKUP(BY$7,'Product Tgt'!$B:$B,'Product Tgt'!$D:$D),0),0) -> 0 | BZ17: =ROUND(IFERROR(#REF!/_xlfn.XLOOKUP(BZ$7,'Product Tgt'!$B:$B,'Product Tgt'!$D:$D),0),0) -> 0 | CA17: =ROUND(IFERROR(#REF!/_xlfn.XLOOKUP(CA$7,'Product Tgt'!$B:$B,'Product Tgt'!$D:$D),0),0) -> 0 | CB17: =ROUND(IFERROR(AV17/_xlfn.XLOOKUP(CB$7,'Product Tgt'!$B:$B,'Product Tgt'!$D:$D),0),0) -> 0 | CC17: =ROUND(IFERROR(AW17/_xlfn.XLOOKUP(CC$7,'Product Tgt'!$B:$B,'Product Tgt'!$D:$D),0),0) -> 0 | CD17: =ROUND(IFERROR(AX17/_xlfn.XLOOKUP(CD$7,'Product Tgt'!$B:$B,'Product Tgt'!$D:$D),0),0) -> 0 | CE17: =ROUND(IFERROR(AY17/_xlfn.XLOOKUP(CE$7,'Product Tgt'!$B:$B,'Product Tgt'!$D:$D),0),0) -> 0 | CF17: =ROUND(IFERROR(AZ17/_xlfn.XLOOKUP(CF$7,'Product Tgt'!$B:$B,'Product Tgt'!$D:$D),0),0) -> 0 | CG17: =ROUND(IFERROR(BA17/_xlfn.XLOOKUP(CG$7,'Product Tgt'!$B:$B,'Product Tgt'!$D:$D),0),0) -> 0 | CH17: =ROUND(IFERROR(BB17/_xlfn.XLOOKUP(CH$7,'Product Tgt'!$B:$B,'Product Tgt'!$D:$D),0),0) -> 0 | CI17: =ROUND(IFERROR(BC17/_xlfn.XLOOKUP(CI$7,'Product Tgt'!$B:$B,'Product Tgt'!$D:$D),0),0) -> 0 | ... CW17: =ROUND(IFERROR(BQ17/_xlfn.XLOOKUP(CW$7,'Product Tgt'!$B:$B,'Product Tgt'!$D:$D),0),0) -> 0 | CX17: =ROUND(IFERROR(#REF!/_xlfn.XLOOKUP(CX$7,'Product Tgt'!$B:$B,'Product Tgt'!$D:$D),0),0) -> 0 | CY17: =ROUND(IFERROR(#REF!/_xlfn.XLOOKUP(CY$7,'Product Tgt'!$B:$B,'Product Tgt'!$D:$D),0),0) -> 0 | CZ17: =ROUND(IFERROR(#REF!/_xlfn.XLOOKUP(CZ$7,'Product Tgt'!$B:$B,'Product Tgt'!$D:$D),0),0) -> 0 | DA17: =IFERROR(BR17*_xlfn.XLOOKUP(DA$7,'Product Tgt'!$B:$B,'Product Tgt'!$D:$D),0) -> 0 | DB17: =IFERROR(BS17*_xlfn.XLOOKUP(DB$7,'Product Tgt'!$B:$B,'Product Tgt'!$D:$D),0) -> 0 | DC17: =IFERROR(BT17*_xlfn.XLOOKUP(DC$7,'Product Tgt'!$B:$B,'Product Tgt'!$D:$D),0) -> 0 | DD17: =IFERROR(BU17*_xlfn.XLOOKUP(DD$7,'Product Tgt'!$B:$B,'Product Tgt'!$D:$D),0) -> 0 | DE17: =IFERROR(BV17*_xlfn.XLOOKUP(DE$7,'Product Tgt'!$B:$B,'Product Tgt'!$D:$D),0) -> 0 | DF17: =IFERROR(BW17*_xlfn.XLOOKUP(DF$7,'Product Tgt'!$B:$B,'Product Tgt'!$D:$D),0) -> 0 | DG17: =IFERROR(BX17*_xlfn.XLOOKUP(DG$7,'Product Tgt'!$B:$B,'Product Tgt'!$D:$D),0) -> 0 | DH17: =IFERROR(BY17*_xlfn.XLOOKUP(DH$7,'Product Tgt'!$B:$B,'Product Tgt'!$D:$D),0) -> 0 | ... EI17: =IFERROR(CZ17*_xlfn.XLOOKUP(EI$7,'Product Tgt'!$B:$B,'Product Tgt'!$D:$D),0) -> 0
B18: SYT-BOGA-BOG3 | C18: =_xlfn.XLOOKUP($B18,'Terr Target'!$A:$A,'Terr Target'!$E:$E) -> 472811.12 | D18: =SUM(AM18:BQ18) -> 472815 | E18: =D18-C18 -> 3.8774987 | F18: =ABS(E18)/D18 -> 8.2008791e-06 | G18: =1-E18/D18 -> 0.9999918 | H18: 57458.74 | I18: 96301.436 | J18: 37966.63 | K18: 32925.024 | L18: 47735.431 | M18: 38058.99 | N18: 474.16486 | O18: 3734.4912 | P18: 2382.8933 | Q18: 959.35054 | R18: 8716.7511 | S18: 17483.136 | T18: 0 | U18: 2266.0566 | V18: 21775.157 | W18: 32322.802 | X18: 5568.34 | Y18: 12162.824 | Z18: 347.42541 | AA18: 9876.8423 | AB18: 2168.2468 | AC18: 521.09319 | AD18: 4460.1984 | AE18: 10071.464 | AF18: 1119.0227 | AG18: 18410.931 | AH18: 2012.4978 | AI18: 12299.636 | AJ18: 10391.926 | AK18: 1597.3802 | AL18: 3251.9909 | AM18: =IFERROR(ROUND(_xlfn.XLOOKUP(AM$7,'Product Tgt'!$B:$B,'Product Tgt'!$G:$G)*H18/H$121,0),0) -> 55859 | AN18: =IFERROR(ROUND(_xlfn.XLOOKUP(AN$7,'Product Tgt'!$B:$B,'Product Tgt'!$G:$G)*I18/I$121,0),0) -> 94799 | AO18: =IFERROR(ROUND(_xlfn.XLOOKUP(AO$7,'Product Tgt'!$B:$B,'Product Tgt'!$G:$G)*J18/J$121,0),0) -> 36786 | AP18: =IFERROR(ROUND(_xlfn.XLOOKUP(AP$7,'Product Tgt'!$B:$B,'Product Tgt'!$G:$G)*K18/K$121,0),0) -> 32119 | AQ18: =IFERROR(ROUND(_xlfn.XLOOKUP(AQ$7,'Product Tgt'!$B:$B,'Product Tgt'!$G:$G)*L18/L$121,0),0) -> 46157 | AR18: =IFERROR(ROUND(_xlfn.XLOOKUP(AR$7,'Product Tgt'!$B:$B,'Product Tgt'!$G:$G)*M18/M$121,0),0) -> 36871 | AS18: =IFERROR(ROUND(_xlfn.XLOOKUP(AS$7,'Product Tgt'!$B:$B,'Product Tgt'!$G:$G)*N18/N$121,0),0) -> 438 | AT18: =IFERROR(ROUND(_xlfn.XLOOKUP(AT$7,'Product Tgt'!$B:$B,'Product Tgt'!$G:$G)*O18/O$121,0),0) -> 3361 | ... BQ18: =IFERROR(ROUND(_xlfn.XLOOKUP(BQ$7,'Product Tgt'!$B:$B,'Product Tgt'!$G:$G)*AL18/AL$121,0),0) -> 2542 | BR18: =ROUND(IFERROR(AM18/_xlfn.XLOOKUP(BR$7,'Product Tgt'!$B:$B,'Product Tgt'!$D:$D),0),0) -> 0 | BS18: =ROUND(IFERROR(AN18/_xlfn.XLOOKUP(BS$7,'Product Tgt'!$B:$B,'Product Tgt'!$D:$D),0),0) -> 0 | BT18: =ROUND(IFERROR(AO18/_xlfn.XLOOKUP(BT$7,'Product Tgt'!$B:$B,'Product Tgt'!$D:$D),0),0) -> 0 | BU18: =ROUND(IFERROR(AP18/_xlfn.XLOOKUP(BU$7,'Product Tgt'!$B:$B,'Product Tgt'!$D:$D),0),0) -> 0 | BV18: =ROUND(IFERROR(AQ18/_xlfn.XLOOKUP(BV$7,'Product Tgt'!$B:$B,'Product Tgt'!$D:$D),0),0) -> 0 | BW18: =ROUND(IFERROR(AU18/_xlfn.XLOOKUP(BW$7,'Product Tgt'!$B:$B,'Product Tgt'!$D:$D),0),0) -> 0 | BX18: =ROUND(IFERROR(#REF!/_xlfn.XLOOKUP(BX$7,'Product Tgt'!$B:$B,'Product Tgt'!$D:$D),0),0) -> 0 | BY18: =ROUND(IFERROR(#REF!/_xlfn.XLOOKUP(BY$7,'Product Tgt'!$B:$B,'Product Tgt'!$D:$D),0),0) -> 0 | BZ18: =ROUND(IFERROR(#REF!/_xlfn.XLOOKUP(BZ$7,'Product Tgt'!$B:$B,'Product Tgt'!$D:$D),0),0) -> 0 | CA18: =ROUND(IFERROR(#REF!/_xlfn.XLOOKUP(CA$7,'Product Tgt'!$B:$B,'Product Tgt'!$D:$D),0),0) -> 0 | CB18: =ROUND(IFERROR(AV18/_xlfn.XLOOKUP(CB$7,'Product Tgt'!$B:$B,'Product Tgt'!$D:$D),0),0) -> 0 | CC18: =ROUND(IFERROR(AW18/_xlfn.XLOOKUP(CC$7,'Product Tgt'!$B:$B,'Product Tgt'!$D:$D),0),0) -> 0 | CD18: =ROUND(IFERROR(AX18/_xlfn.XLOOKUP(CD$7,'Product Tgt'!$B:$B,'Product Tgt'!$D:$D),0),0) -> 0 | CE18: =ROUND(IFERROR(AY18/_xlfn.XLOOKUP(CE$7,'Product Tgt'!$B:$B,'Product Tgt'!$D:$D),0),0) -> 0 | CF18: =ROUND(IFERROR(AZ18/_xlfn.XLOOKUP(CF$7,'Product Tgt'!$B:$B,'Product Tgt'!$D:$D),0),0) -> 0 | CG18: =ROUND(IFERROR(BA18/_xlfn.XLOOKUP(CG$7,'Product Tgt'!$B:$B,'Product Tgt'!$D:$D),0),0) -> 0 | CH18: =ROUND(IFERROR(BB18/_xlfn.XLOOKUP(CH$7,'Product Tgt'!$B:$B,'Product Tgt'!$D:$D),0),0) -> 0 | CI18: =ROUND(IFERROR(BC18/_xlfn.XLOOKUP(CI$7,'Product Tgt'!$B:$B,'Product Tgt'!$D:$D),0),0) -> 0 | ... CW18: =ROUND(IFERROR(BQ18/_xlfn.XLOOKUP(CW$7,'Product Tgt'!$B:$B,'Product Tgt'!$D:$D),0),0) -> 0 | CX18: =ROUND(IFERROR(#REF!/_xlfn.XLOOKUP(CX$7,'Product Tgt'!$B:$B,'Product Tgt'!$D:$D),0),0) -> 0 | CY18: =ROUND(IFERROR(#REF!/_xlfn.XLOOKUP(CY$7,'Product Tgt'!$B:$B,'Product Tgt'!$D:$D),0),0) -> 0 | CZ18: =ROUND(IFERROR(#REF!/_xlfn.XLOOKUP(CZ$7,'Product Tgt'!$B:$B,'Product Tgt'!$D:$D),0),0) -> 0 | DA18: =IFERROR(BR18*_xlfn.XLOOKUP(DA$7,'Product Tgt'!$B:$B,'Product Tgt'!$D:$D),0) -> 0 | DB18: =IFERROR(BS18*_xlfn.XLOOKUP(DB$7,'Product Tgt'!$B:$B,'Product Tgt'!$D:$D),0) -> 0 | DC18: =IFERROR(BT18*_xlfn.XLOOKUP(DC$7,'Product Tgt'!$B:$B,'Product Tgt'!$D:$D),0) -> 0 | DD18: =IFERROR(BU18*_xlfn.XLOOKUP(DD$7,'Product Tgt'!$B:$B,'Product Tgt'!$D:$D),0) -> 0 | DE18: =IFERROR(BV18*_xlfn.XLOOKUP(DE$7,'Product Tgt'!$B:$B,'Product Tgt'!$D:$D),0) -> 0 | DF18: =IFERROR(BW18*_xlfn.XLOOKUP(DF$7,'Product Tgt'!$B:$B,'Product Tgt'!$D:$D),0) -> 0 | DG18: =IFERROR(BX18*_xlfn.XLOOKUP(DG$7,'Product Tgt'!$B:$B,'Product Tgt'!$D:$D),0) -> 0 | DH18: =IFERROR(BY18*_xlfn.XLOOKUP(DH$7,'Product Tgt'!$B:$B,'Product Tgt'!$D:$D),0) -> 0 | ... EI18: =IFERROR(CZ18*_xlfn.XLOOKUP(EI$7,'Product Tgt'!$B:$B,'Product Tgt'!$D:$D),0) -> 0
