Workbook

Sheet 3_Years_CountRx_with_RxShare_wi
B1: Column Labels | P1: Rx Share 23-24 | Q1: Rx Share 24-25 | R1: Rx Yield 23-24 | S1: Rx Yield 24-25 | T1: Rx Penetration 23-24 | U1: Rx Penetration 24-25 | V1: Rx Share Growth | W1: Rx Yield Growth | X1: Rx Penetration Growth | Y1: Broader market
B2: FY 23-24 | F2: FY 23-24 Sum of Count Rx | G2: FY 23-24 Sum of Count of Dr. Code | H2: FY 24-25 | L2: FY 24-25 Sum of Count Rx | M2: FY 24-25 Sum of Count of Dr. Code | N2: Total Sum of Count Rx | O2: Total Sum of Count of Dr. Code | Z2: FY 22-23 | AB2: FY 23-24 | AD2: FY 25-26
B3: Competitors | D3: Synovia | H3: Competitors | J3: Synovia
A4: Row Labels | B4: Sum of Count Rx | C4: Sum of Count of Dr. Code | D4: Sum of Count Rx | E4: Sum of Count of Dr. Code | H4: Sum of Count Rx | I4: Sum of Count of Dr. Code | J4: Sum of Count Rx | K4: Sum of Count of Dr. Code | Z4: Sum of Count Rx | AA4: Count of Dr. Code | AB4: Sum of Count Rx | AC4: Sum of Count of Dr Code | AD4: Sum of Count Rx | AE4: Sum of Count of Dr. Code | AF4: Total Sum of Count Rx | AG4: Total Sum of Dr. Code | AJ4: Rx Share | AK4: Rx Yield | AL4: Rx Penetration | AM4: Market Rx Share Growth | AN4: Gap From Market Rx Share Growth
A5: AMARYL | B5: 79753 | C5: 11368 | D5: 2076 | E5: 903 | F5: 81829 | G5: 12271 | H5: 61039 | I5: 11174 | J5: 1642 | K5: 862 | L5: 62681 | M5: 12036 | AJ5: =D5/(D5+B5) -> 0.025369979 | AK5: =D5/E5 -> 2.2990033 | AL5: =K5/(K5+I5) -> 0.071618478 | AM5: =F5/L5 -> 1.3054833 | AN5: =AM5-AJ5 -> 1.2801133
A6: APIDRA | B6: 3974 | C6: 1228 | D6: 166 | E6: 108 | F6: 4140 | G6: 1336 | H6: 3125 | I6: 1206 | J6: 83 | K6: 64 | L6: 3208 | M6: 1270 | N6: 7348 | O6: 2606 | P6: 0.040096618 | Q6: 0.025872818 | R6: =D6/C6 -> 0.13517915 | S6: =J6/K6 -> 1.296875 | T6: 0.080838323 | U6: 0.050393701 | V6: =(Q6/P6-1)*100 -> -35.473815 | W6: =S6/R6-1 -> 8.59375 | X6: =(U6/T6-1)*100 -> -37.661125 | Y6: Avil | Z6: 271107 | AA6: 33192 | AB6: 268305 | AC6: 32837 | AD6: 62916 | AE6: 20427 | AF6: 860015 | AG6: 119543 | AJ6: =D6/(D6+B6) -> 0.040096618 | AK6: =D6/E6 -> 1.537037 | AL6: =K6/(K6+I6) -> 0.050393701 | AM6: =F6/L6 -> 1.2905237 | AN6: =AM6-AJ6 -> 1.2504271
A7: AVAXIM | B7: 8 | C7: 5 | F7: 8 | G7: 5 | H7: 15 | I7: 11 | L7: 15 | M7: 11 | N7: 23 | O7: 16 | P7: 0 | Q7: 0 | R7: =D7/C7 -> 0 | S7: 0 | T7: 0 | U7: 0 | V7: 0 | W7: 0 | X7: 0 | Y7: Betanol | Z7: 62295 | AA7: 15527 | AB7: 54607 | AC7: 14124 | AD7: 14891 | AE7: 7361 | AF7: 182472 | AG7: 50952 | AJ7: =D7/(D7+B7) -> 0 | AK7: 0 | AL7: =K7/(K7+I7) -> 0 | AM7: =F7/L7 -> 0.53333333 | AN7: =AM7-AJ7 -> 0.53333333
A8: AVIL | B8: 225 | C8: 96 | D8: 841 | E8: 563 | F8: 1066 | G8: 659 | H8: 215 | I8: 83 | J8: 1024 | K8: 579 | L8: 1239 | M8: 662 | N8: 2305 | O8: 1321 | P8: 0.78893058 | Q8: 0.82647296 | R8: =D8/C8 -> 8.7604167 | S8: =J8/K8 -> 1.7685665 | T8: 0.85432473 | U8: 0.87462236 | V8: =(Q8/P8-1)*100 -> 4.7586417 | W8: =S8/R8-1 -> -0.79811845 | X8: =(U8/T8-1)*100 -> 2.3758673 | Y8: Brodactam | Z8: 50884 | AA8: 13613 | AB8: 46915 | AC8: 12906 | AD8: 10299 | AE8: 5996 | AF8: 146104 | AG8: 44482 | AJ8: =D8/(D8+B8) -> 0.78893058 | AK8: =D8/E8 -> 1.4937833 | AL8: =K8/(K8+I8) -> 0.87462236 | AM8: =F8/L8 -> 0.86037127 | AN8: =AM8-AJ8 -> 0.071440686
A9: BETANOL | B9: 1062 | C9: 703 | D9: 83 | E9: 74 | F9: 1145 | G9: 777 | H9: 807 | I9: 579 | J9: 65 | K9: 54 | L9: 872 | M9: 633 | N9: 2017 | O9: 1410 | P9: 0.072489083 | Q9: 0.074541284 | R9: =D9/C9 -> 0.11806543 | S9: =J9/K9 -> 1.2037037 | T9: 0.095238095 | U9: 0.085308057 | V9: =(Q9/P9-1)*100 -> 2.8310484 | W9: =S9/R9-1 -> 9.1952253 | X9: =(U9/T9-1)*100 -> -10.42654 | Y9: Butapan | Z9: 107427 | AA9: 22987 | AB9: 89932 | AC9: 21266 | AD9: 21203 | AE9: 10483 | AF9: 298396 | AG9: 75850 | AJ9: =D9/(D9+B9) -> 0.072489083 | AK9: =D9/E9 -> 1.1216216 | AL9: =K9/(K9+I9) -> 0.085308057 | AM9: =F9/L9 -> 1.3130734 | AN9: =AM9-AJ9 -> 1.2405843
A10: BETANOL A | B10: 6455 | C10: 3531 | F10: 6455 | G10: 3531 | H10: 4999 | I10: 3067 | L10: 4999 | M10: 3067 | N10: 11454 | O10: 6598 | P10: 0 | Q10: 0 | R10: =D10/C10 -> 0 | S10: 0 | T10: 0 | U10: 0 | V10: 0 | W10: 0 | X10: 0 | Y10: Carbanem | Z10: 23193 | AA10: 4837 | AB10: 35579 | AC10: 5949 | AD10: 10913 | AE10: 3920 | AF10: 128374 | AG10: 22654 | AJ10: =D10/(D10+B10) -> 0 | AK10: 0 | AL10: =K10/(K10+I10) -> 0 | AM10: =F10/L10 -> 1.2912583 | AN10: =AM10-AJ10 -> 1.2912583
A11: BRODACTAM | B11: 35 | C11: 32 | D11: 20 | E11: 15 | F11: 55 | G11: 47 | H11: 58 | I11: 45 | J11: 25 | K11: 16 | L11: 83 | M11: 61 | N11: 138 | O11: 108 | P11: 0.36363636 | Q11: 0.30120482 | R11: =D11/C11 -> 0.625 | S11: =J11/K11 -> 1.5625 | T11: 0.31914894 | U11: 0.26229508 | V11: =(Q11/P11-1)*100 -> -17.168675 | W11: =S11/R11-1 -> 1.5 | X11: =(U11/T11-1)*100 -> -17.814208 | Y11: CopiXa | Z11: 1051 | AA11: 665 | AB11: 974 | AC11: 601 | AD11: 307 | AE11: 251 | AF11: 3487 | AG11: 2170 | AJ11: =D11/(D11+B11) -> 0.36363636 | AK11: =D11/E11 -> 1.3333333 | AL11: =K11/(K11+I11) -> 0.26229508 | AM11: =F11/L11 -> 0.6626506 | AN11: =AM11-AJ11 -> 0.29901424
A12: BUTAPAN | B12: 1042 | C12: 414 | D12: 168 | E12: 76 | F12: 1210 | G12: 490 | H12: 864 | I12: 347 | J12: 361 | K12: 191 | L12: 1225 | M12: 538 | N12: 2435 | O12: 1028 | P12: 0.13884298 | Q12: 0.29469388 | R12: =D12/C12 -> 0.4057971 | S12: =J12/K12 -> 1.8900524 | T12: 0.15510204 | U12: 0.35501859 | V12: =(Q12/P12-1)*100 -> 112.24976 | W12: =S12/R12-1 -> 3.657629 | X12: =(U12/T12-1)*100 -> 128.89356 | Y12: Curazith | Z12: 97219 | AA12: 19745 | AB12: 86206 | AC12: 18515 | AD12: 16697 | AE12: 8284 | AF12: 266865 | AG12: 63391 | AJ12: =D12/(D12+B12) -> 0.13884298 | AK12: =D12/E12 -> 2.2105263 | AL12: =K12/(K12+I12) -> 0.35501859 | AM12: =F12/L12 -> 0.9877551 | AN12: =AM12-AJ12 -> 0.84891213
A13: CARBANEM | B13: 2298 | C13: 1171 | D13: 15 | E13: 9 | F13: 2313 | G13: 1180 | H13: 2105 | I13: 1185 | J13: 21 | K13: 11 | L13: 2126 | M13: 1196 | N13: 4439 | O13: 2376 | P13: 0.006485084 | Q13: 0.009877705 | R13: =D13/C13 -> 0.012809564 | S13: =J13/K13 -> 1.9090909 | T13: 0.007627119 | U13: 0.009197324 | V13: =(Q13/P13-1)*100 -> 52.314218 | W13: =S13/R13-1 -> 148.03636 | X13: =(U13/T13-1)*100 -> 20.587131 | Y13: Enterogermina | Z13: 21970 | AA13: 6030 | AB13: 18805 | AC13: 5381 | AD13: 3337 | AE13: 2018 | AF13: 60521 | AG13: 18589 | AJ13: =D13/(D13+B13) -> 0.0064850843 | AK13: =D13/E13 -> 1.6666667 | AL13: =K13/(K13+I13) -> 0.0091973244 | AM13: =F13/L13 -> 1.0879586 | AN13: =AM13-AJ13 -> 1.0814735
A14: CDENS | B14: 3432 | C14: 1454 | F14: 3432 | G14: 1454 | H14: 2026 | I14: 803 | L14: 2026 | M14: 803 | N14: 5458 | O14: 2257 | P14: 0 | Q14: 0 | R14: =D14/C14 -> 0 | S14: 0 | T14: 0 | U14: 0 | V14: 0 | W14: 0 | X14: 0 | Y14: Epilim | Z14: 130823 | AA14: 24215 | AB14: 108780 | AC14: 21473 | AD14: 25881 | AE14: 10821 | AF14: 359722 | AG14: 77385 | AJ14: =D14/(D14+B14) -> 0 | AK14: 0 | AL14: =K14/(K14+I14) -> 0 | AM14: =F14/L14 -> 1.6939783 | AN14: =AM14-AJ14 -> 1.6939783
A15: COPIXA | B15: 106 | C15: 78 | F15: 106 | G15: 78 | H15: 135 | I15: 81 | J15: 4 | K15: 4 | L15: 139 | M15: 85 | N15: 245 | O15: 163 | P15: 0 | Q15: 0.028776978 | R15: =D15/C15 -> 0 | S15: =J15/K15 -> 1 | T15: 0 | U15: 0.047058824 | V15: 0 | W15: 0 | X15: 0 | Y15: ERTU | Z15: 30843 | AA15: 5586 | AB15: 29891 | AC15: 5813 | AD15: 8209 | AE15: 4024 | AF15: 96181 | AG15: 21884 | AJ15: =D15/(D15+B15) -> 0 | AK15: 0 | AL15: =K15/(K15+I15) -> 0.047058824 | AM15: =F15/L15 -> 0.76258993 | AN15: =AM15-AJ15 -> 0.76258993
A16: CURAZITH | B16: 67027 | C16: 14869 | D16: 24 | E16: 18 | F16: 67051 | G16: 14887 | H16: 50152 | I16: 13163 | J16: 17 | K16: 15 | L16: 50169 | M16: 13178 | N16: 117220 | O16: 28065 | P16: 0.000357936 | Q16: 0.000338855 | R16: =D16/C16 -> 0.0016140964 | S16: =J16/K16 -> 1.1333333 | T16: 0.001209109 | U16: 0.001138261 | V16: =(Q16/P16-1)*100 -> -5.3308413 | W16: =S16/R16-1 -> 701.14722 | X16: =(U16/T16-1)*100 -> -5.8595214 | Y16: EXPRES | Z16: 33144 | AA16: 7766 | AB16: 30427 | AC16: 7229 | AD16: 8421 | AE16: 4124 | AF16: 100092 | AG16: 26413 | AJ16: =D16/(D16+B16) -> 0.0003579365 | AK16: =D16/E16 -> 1.3333333 | AL16: =K16/(K16+I16) -> 0.0011382607 | AM16: =F16/L16 -> 1.3365026 | AN16: =AM16-AJ16 -> 1.3361447
A17: DOXOVIA | B17: 61674 | C17: 13519 | F17: 61674 | G17: 13519 | H17: 49155 | I17: 12771 | L17: 49155 | M17: 12771 | N17: 110829 | O17: 26290 | P17: 0 | Q17: 0 | R17: =D17/C17 -> 0 | S17: 0 | T17: 0 | U17: 0 | V17: 0 | W17: 0 | X17: 0 | Y17: Farpem | Z17: 2292 | AA17: 1137 | AB17: 2709 | AC17: 1395 | AD17: 1434 | AE17: 1022 | AF17: 10415 | AG17: 5754 | AJ17: =D17/(D17+B17) -> 0 | AK17: 0 | AL17: =K17/(K17+I17) -> 0 | AM17: =F17/L17 -> 1.2546842 | AN17: =AM17-AJ17 -> 1.2546842
A18: ELOXATIN | B18: 13 | C18: 9 | F18: 13 | G18: 9 | N18: 13 | O18: 9 | P18: 0 | Q18: 0 | R18: =D18/C18 -> 0 | S18: 0 | T18: 0 | U18: #DIV/0! | V18: 0 | W18: 0 | X18: 0 | Y18: Fimoxyclav | Z18: 50884 | AA18: 13613 | AB18: 46915 | AC18: 12906 | AD18: 10299 | AE18: 5996 | AF18: 146104 | AG18: 44482 | AJ18: =D18/(D18+B18) -> 0 | AK18: 0 | AL18: 0 | AM18: 0 | AN18: =AM18-AJ18 -> 0
A19: ENDOXAN | B19: 68 | C19: 50 | D19: 55 | E19: 38 | F19: 123 | G19: 88 | N19: 123 | O19: 88 | P19: 0.44715447 | Q19: 0 | R19: =D19/C19 -> 1.1 | S19: 0 | T19: 0.43181818 | U19: #DIV/0! | V19: =(Q19/P19-1)*100 -> -100 | W19: =S19/R19-1 -> -1 | X19: 0 | Y19: Fimoxyl | Z19: 50884 | AA19: 13613 | AB19: 46915 | AC19: 12906 | AD19: 10299 | AE19: 5996 | AF19: 146104 | AG19: 44482 | AJ19: =D19/(D19+B19) -> 0.44715447 | AK19: =D19/E19 -> 1.4473684 | AL19: 0 | AM19: 0 | AN19: =AM19-AJ19 -> -0.44715447
A20: ENTEROGERMINA | B20: 14503 | C20: 4493 | D20: 3168 | E20: 1303 | F20: 17671 | G20: 5796 | H20: 12924 | I20: 4352 | J20: 2762 | K20: 1197 | L20: 15686 | M20: 5549 | N20: 33357 | O20: 11345 | P20: 0.17927678 | Q20: 0.17608058 | R20: =D20/C20 -> 0.70509682 | S20: =J20/K20 -> 2.3074353 | T20: 0.22481021 | U20: 0.21571454 | V20: =(Q20/P20-1)*100 -> -1.7828299 | W20: =S20/R20-1 -> 2.2725084 | X20: =(U20/T20-1)*100 -> -4.0459332 | Y20: Flagyl | Z20: 54676 | AA20: 15532 | AB20: 45283 | AC20: 13934 | AD20: 8856 | AE20: 5342 | AF20: 148138 | AG20: 47782 | AJ20: =D20/(D20+B20) -> 0.17927678 | AK20: =D20/E20 -> 2.4313124 | AL20: =K20/(K20+I20) -> 0.21571454 | AM20: =F20/L20 -> 1.126546 | AN20: =AM20-AJ20 -> 0.94726918
A21: EPILIM | B21: 8121 | C21: 2239 | D21: 681 | E21: 333 | F21: 8802 | G21: 2572 | H21: 7888 | I21: 2306 | J21: 858 | K21: 395 | L21: 8746 | M21: 2701 | N21: 17548 | O21: 5273 | P21: 0.07736878 | Q21: 0.098101989 | R21: =D21/C21 -> 0.30415364 | S21: =J21/K21 -> 2.1721519 | T21: 0.12947123 | U21: 0.14624213 | V21: =(Q21/P21-1)*100 -> 26.797901 | W21: =S21/R21-1 -> 6.1416272 | X21: =(U21/T21-1)*100 -> 12.953383 | Y21: Frisium | Z21: 45463 | AA21: 13363 | AB21: 43658 | AC21: 12646 | AD21: 11858 | AE21: 6243 | AF21: 144891 | AG21: 44964 | AJ21: =D21/(D21+B21) -> 0.07736878 | AK21: =D21/E21 -> 2.045045 | AL21: =K21/(K21+I21) -> 0.14624213 | AM21: =F21/L21 -> 1.0064029 | AN21: =AM21-AJ21 -> 0.92903415
A22: ERTU | B22: 29487 | C22: 5790 | D22: 404 | E22: 168 | F22: 29891 | G22: 5958 | H22: 26992 | I22: 6435 | J22: 246 | K22: 133 | L22: 27238 | M22: 6568 | N22: 57129 | O22: 12526 | P22: 0.013515774 | Q22: 0.0090315 | R22: =D22/C22 -> 0.069775475 | S22: =J22/K22 -> 1.8496241 | T22: 0.028197382 | U22: 0.020249695 | V22: =(Q22/P22-1)*100 -> -33.178078 | W22: =S22/R22-1 -> 25.508226 | X22: =(U22/T22-1)*100 -> -28.185904 | Y22: Gavisyn | Z22: 96866 | AA22: 20124 | AB22: 81321 | AC22: 18362 | AD22: 19793 | AE22: 9474 | AF22: 268705 | AG22: 66013 | AJ22: =D22/(D22+B22) -> 0.013515774 | AK22: =D22/E22 -> 2.4047619 | AL22: =K22/(K22+I22) -> 0.020249695 | AM22: =F22/L22 -> 1.0974007 | AN22: =AM22-AJ22 -> 1.0838849
A23: ESCAP | B23: 394898 | C23: 46060 | D23: 4 | E23: 3 | F23: 394902 | G23: 46063 | H23: 364241 | I23: 47938 | J23: 9 | K23: 9 | L23: 364250 | M23: 47947 | N23: 759152 | O23: 94010 | P23: 1.01e-05 | Q23: 2.47e-05 | R23: =D23/C23 -> 8.6843248e-05 | S23: =J23/K23 -> 1 | T23: 6.51282e-05 | U23: 0.000187707 | V23: =(Q23/P23-1)*100 -> 144.55446 | W23: =S23/R23-1 -> 11514 | X23: =(U23/T23-1)*100 -> 188.21156 | Y23: Imovane | Z23: 2082 | AA23: 1086 | AB23: 1917 | AC23: 954 | AD23: 428 | AE23: 295 | AF23: 6043 | AG23: 3181 | AJ23: =D23/(D23+B23) -> 1.0129095e-05 | AK23: =D23/E23 -> 1.3333333 | AL23: =K23/(K23+I23) -> 0.00018770726 | AM23: =F23/L23 -> 1.084151 | AN23: =AM23-AJ23 -> 1.0841409
A24: EXPRES | B24: 20451 | C24: 5521 | D24: 218 | E24: 110 | F24: 20669 | G24: 5631 | H24: 18966 | I24: 5645 | J24: 216 | K24: 119 | L24: 19182 | M24: 5764 | N24: 39851 | O24: 11395 | P24: 0.010547196 | Q24: 0.011260557 | R24: =D24/C24 -> 0.0394856 | S24: =J24/K24 -> 1.8151261 | T24: 0.019534719 | U24: 0.020645385 | V24: =(Q24/P24-1)*100 -> 6.7635133 | W24: =S24/R24-1 -> 44.969316 | X24: =(U24/T24-1)*100 -> 5.6856001 | Y24: INCRIT | Z24: 144638 | AA24: 23320 | AB24: 128570 | AC24: 21723 | AD24: 34419 | AE24: 13713 | AF24: 423929 | AG24: 81229 | AJ24: =D24/(D24+B24) -> 0.010547196 | AK24: =D24/E24 -> 1.9818182 | AL24: =K24/(K24+I24) -> 0.020645385 | AM24: =F24/L24 -> 1.0775206 | AN24: =AM24-AJ24 -> 1.0669734
A25: FARPEM | B25: 371 | C25: 265 | F25: 371 | G25: 265 | H25: 1781 | I25: 1142 | J25: 54 | K25: 44 | L25: 1835 | M25: 1186 | N25: 2206 | O25: 1451 | P25: 0 | Q25: 0.029427793 | R25: =D25/C25 -> 0 | S25: =J25/K25 -> 1.2272727 | T25: 0 | U25: 0.037099494 | V25: 0 | W25: 0 | X25: 0 | Y25: Kuracef | Z25: 83333 | AA25: 20215 | AB25: 72292 | AC25: 18522 | AD25: 14835 | AE25: 8451 | AF25: 234176 | AG25: 65089 | AJ25: =D25/(D25+B25) -> 0 | AK25: 0 | AL25: =K25/(K25+I25) -> 0.037099494 | AM25: =F25/L25 -> 0.20217984 | AN25: =AM25-AJ25 -> 0.20217984
A26: FIMOXYCLAV | B26: 31849 | C26: 10335 | D26: 2503 | E26: 1407 | F26: 34352 | G26: 11742 | H26: 25094 | I26: 9362 | J26: 2413 | K26: 1444 | L26: 27507 | M26: 10806 | N26: 61859 | O26: 22548 | P26: 0.072863298 | Q26: 0.087723125 | R26: =D26/C26 -> 0.24218674 | S26: =J26/K26 -> 1.6710526 | T26: 0.11982627 | U26: 0.13362947 | V26: =(Q26/P26-1)*100 -> 20.394118 | W26: =S26/R26-1 -> 5.8998518 | X26: =(U26/T26-1)*100 -> 11.519344 | Y26: Lantus | Z26: 45274 | AA26: 7157 | AB26: 38234 | AC26: 6568 | AD26: 6638 | AE26: 3343 | AF26: 119414 | AG26: 23692 | AJ26: =D26/(D26+B26) -> 0.072863298 | AK26: =D26/E26 -> 1.7789623 | AL26: =K26/(K26+I26) -> 0.13362947 | AM26: =F26/L26 -> 1.2488457 | AN26: =AM26-AJ26 -> 1.1759825
A27: FIMOXYL | B27: 11749 | C27: 3152 | D27: 458 | E27: 269 | F27: 12207 | G27: 3421 | H27: 9890 | I27: 2826 | J27: 410 | K27: 261 | L27: 10300 | M27: 3087 | N27: 22507 | O27: 6508 | P27: 0.037519456 | Q27: 0.039805825 | R27: =D27/C27 -> 0.14530457 | S27: =J27/K27 -> 1.5708812 | T27: 0.078631979 | U27: 0.084548105 | V27: =(Q27/P27-1)*100 -> 6.0938224 | W27: =S27/R27-1 -> 9.8109555 | X27: =(U27/T27-1)*100 -> 7.5238167 | Y27: Lasix | Z27: 2514 | AA27: 1379 | AB27: 2604 | AC27: 1395 | AD27: 911 | AE27: 684 | AF27: 9302 | AG27: 5133 | AJ27: =D27/(D27+B27) -> 0.037519456 | AK27: =D27/E27 -> 1.7026022 | AL27: =K27/(K27+I27) -> 0.084548105 | AM27: =F27/L27 -> 1.1851456 | AN27: =AM27-AJ27 -> 1.1476262
A28: FLAGYL | B28: 32237 | C28: 10746 | D28: 430 | E28: 309 | F28: 32667 | G28: 11055 | H28: 27998 | I28: 9803 | J28: 455 | K28: 314 | L28: 28453 | M28: 10117 | N28: 61120 | O28: 21172 | P28: 0.013163131 | Q28: 0.015991284 | R28: =D28/C28 -> 0.040014889 | S28: =J28/K28 -> 1.4490446 | T28: 0.027951153 | U28: 0.031036869 | V28: =(Q28/P28-1)*100 -> 21.485413 | W28: =S28/R28-1 -> 35.212635 | X28: =(U28/T28-1)*100 -> 11.039673 | Y28: Leveron | Z28: 130823 | AA28: 24215 | AB28: 108780 | AC28: 21473 | AD28: 25881 | AE28: 10821 | AF28: 359722 | AG28: 77385 | AJ28: =D28/(D28+B28) -> 0.013163131 | AK28: =D28/E28 -> 1.3915858 | AL28: =K28/(K28+I28) -> 0.031036869 | AM28: =F28/L28 -> 1.1481039 | AN28: =AM28-AJ28 -> 1.1349408
A29: FRISIUM | B29: 1110 | C29: 564 | D29: 252 | E29: 105 | F29: 1362 | G29: 669 | H29: 1014 | I29: 567 | J29: 184 | K29: 87 | L29: 1198 | M29: 654 | N29: 2560 | O29: 1323 | P29: 0.18502203 | Q29: 0.15358932 | R29: =D29/C29 -> 0.44680851 | S29: =J29/K29 -> 2.1149425 | T29: 0.15695067 | U29: 0.13302752 | V29: =(Q29/P29-1)*100 -> -16.988631 | W29: =S29/R29-1 -> 3.7334428 | X29: =(U29/T29-1)*100 -> -15.242464 | Y29: Luzol | Z29: 71366 | AA29: 15130 | AB29: 70641 | AC29: 14533 | AD29: 19156 | AE29: 7585 | AF29: 234706 | AG29: 52231 | AJ29: =D29/(D29+B29) -> 0.18502203 | AK29: =D29/E29 -> 2.4 | AL29: =K29/(K29+I29) -> 0.13302752 | AM29: =F29/L29 -> 1.1368948 | AN29: =AM29-AJ29 -> 0.9518728
A30: GAVISYN | B30: 52742 | C30: 13678 | D30: 261 | E30: 175 | F30: 53003 | G30: 13853 | H30: 47255 | I30: 13683 | J30: 284 | K30: 175 | L30: 47539 | M30: 13858 | N30: 100542 | O30: 27711 | P30: 0.00492425 | Q30: 0.005974042 | R30: =D30/C30 -> 0.019081737 | S30: =J30/K30 -> 1.6228571 | T30: 0.012632643 | U30: 0.012628085 | V30: =(Q30/P30-1)*100 -> 21.31882 | W30: =S30/R30-1 -> 84.047663 | X30: =(U30/T30-1)*100 -> -0.036081127 | Y30: Metsa | Z30: 186282 | AA30: 18242 | AB30: 161232 | AC30: 17051 | AD30: 33928 | AE30: 10546 | AF30: 509587 | AG30: 63384 | AJ30: =D30/(D30+B30) -> 0.0049242496 | AK30: =D30/E30 -> 1.4914286 | AL30: =K30/(K30+I30) -> 0.012628085 | AM30: =F30/L30 -> 1.1149372 | AN30: =AM30-AJ30 -> 1.110013
A31: IMOVANE | B31: 16 | C31: 14 | D31: 7 | E31: 6 | F31: 23 | G31: 20 | H31: 8 | I31: 6 | J31: 11 | K31: 9 | L31: 19 | M31: 15 | N31: 42 | O31: 35 | P31: 0.30434783 | Q31: 0.57894737 | R31: =D31/C31 -> 0.5 | S31: =J31/K31 -> 1.2222222 | T31: 0.3 | U31: 0.6 | V31: =(Q31/P31-1)*100 -> 90.225564 | W31: =S31/R31-1 -> 1.4444444 | X31: =(U31/T31-1)*100 -> 100 | Y31: Monfast | Z31: 449109 | AA31: 32249 | AB31: 421224 | AC31: 31237 | AD31: 78357 | AE31: 17592 | AF31: 1275883 | AG31: 111101 | AJ31: =D31/(D31+B31) -> 0.30434783 | AK31: =D31/E31 -> 1.1666667 | AL31: =K31/(K31+I31) -> 0.6 | AM31: =F31/L31 -> 1.2105263 | AN31: =AM31-AJ31 -> 0.90617849
A32: INCRIT | B32: 1210 | C32: 550 | F32: 1210 | G32: 550 | H32: 730 | I32: 461 | L32: 730 | M32: 461 | N32: 1940 | O32: 1011 | P32: 0 | Q32: 0 | R32: =D32/C32 -> 0 | S32: 0 | T32: 0 | U32: 0 | V32: =(Q32/P32-1)*100 -> #DIV/0! | W32: 0 | X32: 0 | Y32: Oracyn-K | Z32: 47917 | AA32: 14463 | AB32: 44452 | AC32: 13851 | AD32: 9019 | AE32: 5360 | AF32: 144488 | AG32: 47365 | AJ32: =D32/(D32+B32) -> 0 | AK32: 0 | AL32: =K32/(K32+I32) -> 0 | AM32: =F32/L32 -> 1.6575342 | AN32: =AM32-AJ32 -> 1.6575342
A33: INCRIT M | B33: 7947 | C33: 2733 | D33: 17 | E33: 11 | F33: 7964 | G33: 2744 | H33: 5459 | I33: 2433 | J33: 4 | K33: 3 | L33: 5463 | M33: 2436 | N33: 13427 | O33: 5180 | P33: 0.002134606 | Q33: 0.000732198 | R33: =D33/C33 -> 0.0062202708 | S33: =J33/K33 -> 1.3333333 | T33: 0.004008746 | U33: 0.001231527 | V33: =(Q33/P33-1)*100 -> -65.698682 | W33: =S33/R33-1 -> 213.35294 | X33: =(U33/T33-1)*100 -> -69.278996 | Y33: Orva | Z33: 86393 | AA33: 14160 | AB33: 75318 | AC33: 13027 | AD33: 21471 | AE33: 8357 | AF33: 251923 | AG33: 48795 | AJ33: =D33/(D33+B33) -> 0.0021346057 | AK33: =D33/E33 -> 1.5454545 | AL33: =K33/(K33+I33) -> 0.0012315271 | AM33: =F33/L33 -> 1.4578071 | AN33: =AM33-AJ33 -> 1.4556725
A34: KURACEF | B34: 110487 | C34: 22164 | D34: 107 | E34: 47 | F34: 110594 | G34: 22211 | H34: 88177 | I34: 21092 | J34: 94 | K34: 36 | L34: 88271 | M34: 21128 | N34: 198865 | O34: 43339 | P34: 0.000967503 | Q34: 0.001064902 | R34: =D34/C34 -> 0.0048276484 | S34: =J34/K34 -> 2.6111111 | T34: 0.002116069 | U34: 0.0017039 | V34: =(Q34/P34-1)*100 -> 10.067049 | W34: =S34/R34-1 -> 539.86604 | X34: =(U34/T34-1)*100 -> -19.478051 | Y34: Ovenox | Z34: 901 | AA34: 521 | AB34: 895 | AC34: 510 | AD34: 179 | AE34: 140 | AF34: 2859 | AG34: 1707 | AJ34: =D34/(D34+B34) -> 0.00096750276 | AK34: =D34/E34 -> 2.2765957 | AL34: =K34/(K34+I34) -> 0.0017039 | AM34: =F34/L34 -> 1.2528917 | AN34: =AM34-AJ34 -> 1.2519242
A35: LANTUS+TOUJEO | B35: 3017 | C35: 1244 | D35: 731 | E35: 454 | F35: 3776 | G35: 1717 | H35: 2282 | I35: 1219 | J35: 716 | K35: 473 | L35: 3025 | M35: 1712 | N35: 6801 | O35: 3429 | P35: 0.20100636 | Q35: 0.24561984 | R35: =D35/C35 -> 0.58762058 | S35: =J35/K35 -> 1.5137421 | T35: 0.27548049 | U35: 0.28796729 | V35: =(Q35/P35-1)*100 -> 22.195059 | W35: =S35/R35-1 -> 1.5760535 | X35: =(U35/T35-1)*100 -> 4.5327352 | Y35: Pevisone | Z35: 24056 | AA35: 7583 | AB35: 21291 | AC35: 6875 | AD35: 4219 | AE35: 2687 | AF35: 68750 | AG35: 23914 | AJ35: =D35/(D35+B35) -> 0.19503735 | AK35: =D35/E35 -> 1.6101322 | AL35: =K35/(K35+I35) -> 0.27955083 | AM35: =F35/L35 -> 1.2482645 | AN35: =AM35-AJ35 -> 1.0532271
A36: TOUJEO | B36: 3017 | C36: 1244 | D36: 28 | E36: 19 | F36: 3776 | G36: 1717 | H36: 2282 | I36: 1219 | J36: 27 | K36: 20 | L36: 3025 | M36: 1712 | N36: 6801 | O36: 3429 | P36: 0.20100636 | Q36: 0.24561984 | R36: 0.61012862 | S36: 1.5070994 | T36: 0.27548049 | U36: 0.28796729 | V36: 22.195059 | W36: 1.4701339 | X36: 4.5327352 | Y36: Pevisone | Z36: 24056 | AA36: 7583 | AB36: 21291 | AC36: 6875 | AD36: 4219 | AE36: 2687 | AF36: 68750 | AG36: 23914
A37: LASILACTONE | B37: 24738 | C37: 8076 | D37: 2 | E37: 2 | F37: 24740 | G37: 8078 | H37: 23948 | I37: 7939 | L37: 23948 | M37: 7939 | N37: 48688 | O37: 16017 | P37: 8.08e-05 | Q37: 0 | R37: =D37/C37 -> 0.00024764735 | S37: 0 | T37: 0.000247586 | U37: 0 | V37: =(Q37/P37-1)*100 -> -100 | W37: =S37/R37-1 -> -1 | X37: =(U37/T37-1)*100 -> -100 | Y37: Phenergan Plus | Z37: 271107 | AA37: 33192 | AB37: 268305 | AC37: 32837 | AD37: 62916 | AE37: 20427 | AF37: 860015 | AG37: 119543 | AJ37: =D37/(D37+B37) -> 8.0840744e-05 | AK37: =D37/E37 -> 1 | AL37: =K37/(K37+I37) -> 0 | AM37: =F37/L37 -> 1.0330717 | AN37: =AM37-AJ37 -> 1.0329908
A38: LASIX | B38: 4737 | C38: 2167 | D38: 3152 | E38: 1654 | F38: 7889 | G38: 3821 | H38: 4414 | I38: 2103 | J38: 3439 | K38: 1730 | L38: 7853 | M38: 3833 | N38: 15742 | O38: 7654 | P38: 0.39954367 | Q38: 0.43792181 | R38: =D38/C38 -> 1.4545455 | S38: =J38/K38 -> 1.9878613 | T38: 0.43287098 | U38: 0.45134359 | V38: =(Q38/P38-1)*100 -> 9.6054945 | W38: =S38/R38-1 -> 0.36665462 | X38: =(U38/T38-1)*100 -> 4.2674654 | Y38: Profenid | Z38: 279456 | AA38: 37548 | AB38: 242234 | AC38: 34883 | AD38: 64342 | AE38: 21281 | AF38: 805344 | AG38: 128664 | AJ38: =D38/(D38+B38) -> 0.39954367 | AK38: =D38/E38 -> 1.9056832 | AL38: =K38/(K38+I38) -> 0.4513436 | AM38: =F38/L38 -> 1.0045842 | AN38: =AM38-AJ38 -> 0.60504057
A39: LEVERON | B39: 2263 | C39: 1137 | D39: 40 | E39: 20 | F39: 2303 | G39: 1157 | H39: 2584 | I39: 1237 | J39: 22 | K39: 19 | L39: 2606 | M39: 1256 | N39: 4909 | O39: 2413 | P39: 0.01736865 | Q39: 0.008442057 | R39: =D39/C39 -> 0.035180299 | S39: =J39/K39 -> 1.1578947 | T39: 0.017286085 | U39: 0.015127389 | V39: =(Q39/P39-1)*100 -> -51.394858 | W39: =S39/R39-1 -> 31.913158 | X39: =(U39/T39-1)*100 -> -12.488056 | Y39: Qpine | Z39: 76150 | AA39: 17223 | AB39: 73530 | AC39: 16995 | AD39: 18418 | AE39: 8214 | AF39: 234007 | AG39: 58961 | AJ39: =D39/(D39+B39) -> 0.01736865 | AK39: =D39/E39 -> 2 | AL39: =K39/(K39+I39) -> 0.015127389 | AM39: =F39/L39 -> 0.88372985 | AN39: =AM39-AJ39 -> 0.8663612
A40: LUZOL | B40: 11868 | C40: 3376 | D40: 185 | E40: 103 | F40: 12053 | G40: 3479 | H40: 15529 | I40: 4169 | J40: 227 | K40: 140 | L40: 15756 | M40: 4309 | N40: 27809 | O40: 7788 | P40: 0.015348876 | Q40: 0.01440721 | R40: =D40/C40 -> 0.054798578 | S40: =J40/K40 -> 1.6214286 | T40: 0.029606209 | U40: 0.032490137 | V40: =(Q40/P40-1)*100 -> -6.1350812 | W40: =S40/R40-1 -> 28.58888 | X40: =(U40/T40-1)*100 -> 9.7409567 | Y40: Renvela | Z40: 8864 | AA40: 3506 | AB40: 10863 | AC40: 4295 | AD40: 4344 | AE40: 2769 | AF40: 36912 | AG40: 15806 | AJ40: =D40/(D40+B40) -> 0.015348876 | AK40: =D40/E40 -> 1.7961165 | AL40: =K40/(K40+I40) -> 0.032490137 | AM40: =F40/L40 -> 0.76497842 | AN40: =AM40-AJ40 -> 0.74962955
...

Sheet Sheet1
A1: 2025
B2: IQVIA
B3: 1. IQVIA Market Share Growth%
B4: 2. IQVIA Growth%
B5: 3. IQVIA Market Position
B6: 4. Gap from Relevant Market growth
B8: Rx
B9: 1. Rx Share growth
B10: 2. Rxer penetration growth
B11: 3. Rx Yield growth
B12: 4. Gap from Relevant Market growth

Sheet BBB_Brands_Growths
A1: BBB Brands | B1: MS Growth | C1: Growth % | D1: Gap From Market Growth | E1: Position Q2 2025 | F1: Position Q2 2024 | J1: Row Labels | K1: Rx Share | L1: Rx Yield | M1: Rx Penetration | N1: Market Rx Share Growth | O1: Gap from Market Rx Share Growth
A2: Enterogermina | B2: =_xlfn.XLOOKUP(A2,'Updated_List_for_BBB_Rx&IQVIA'!D:D,'Updated_List_for_BBB_Rx&IQVIA'!P:P) -> -0.29089106 | C2: =_xlfn.XLOOKUP(A2,'Updated_List_for_BBB_Rx&IQVIA'!D:D,'Updated_List_for_BBB_Rx&IQVIA'!Q:Q) -> 0.075515888 | D2: =_xlfn.XLOOKUP(A2,'Updated_List_for_BBB_Rx&IQVIA'!D:D,'Updated_List_for_BBB_Rx&IQVIA'!R:R) -> 0.51671462 | E2: =_xlfn.XLOOKUP(A2,'Updated_List_for_BBB_Rx&IQVIA'!D:D,'Updated_List_for_BBB_Rx&IQVIA'!T:T) -> 1 | F2: =_xlfn.XLOOKUP(A2,'Updated_List_for_BBB_Rx&IQVIA'!D:D,'Updated_List_for_BBB_Rx&IQVIA'!U:U) -> 1 | Q2: AMARYL | R2: 0.037973187 | S2: 2.1356383 | T2: 0.079031723
A3: Lantus | B3: =_xlfn.XLOOKUP(A3,'Updated_List_for_BBB_Rx&IQVIA'!D:D,'Updated_List_for_BBB_Rx&IQVIA'!P:P) -> -0.23584741 | C3: =_xlfn.XLOOKUP(A3,'Updated_List_for_BBB_Rx&IQVIA'!D:D,'Updated_List_for_BBB_Rx&IQVIA'!Q:Q) -> -0.0089444441 | D3: =_xlfn.XLOOKUP(A3,'Updated_List_for_BBB_Rx&IQVIA'!D:D,'Updated_List_for_BBB_Rx&IQVIA'!R:R) -> 0.2969341 | E3: =_xlfn.XLOOKUP(A3,'Updated_List_for_BBB_Rx&IQVIA'!D:D,'Updated_List_for_BBB_Rx&IQVIA'!T:T) -> 1 | F3: =_xlfn.XLOOKUP(A3,'Updated_List_for_BBB_Rx&IQVIA'!D:D,'Updated_List_for_BBB_Rx&IQVIA'!U:U) -> 1 | J3: AMARYL | K3: 0.02423789 | L3: 2.0340092 | M3: 0.068810333 | N3: =_xlfn.XLOOKUP(BBB_Brands_Growths!J3,'3_Years_CountRx_with_RxShare_wi'!A:A,'3_Years_CountRx_with_RxShare_wi'!AM:AM) -> 1.3054833 | O3: =_xlfn.XLOOKUP(J3,'3_Years_CountRx_with_RxShare_wi'!A:A,'3_Years_CountRx_with_RxShare_wi'!AN:AN) -> 1.2801133 | Q3: AMARYL M | R3: 0.0118879 | S3: 1.87251 | T3: 0.02642228
A4: Toujeo | B4: =_xlfn.XLOOKUP(A4,'Updated_List_for_BBB_Rx&IQVIA'!D:D,'Updated_List_for_BBB_Rx&IQVIA'!P:P) -> -0.030579794 | C4: =_xlfn.XLOOKUP(A4,'Updated_List_for_BBB_Rx&IQVIA'!D:D,'Updated_List_for_BBB_Rx&IQVIA'!Q:Q) -> 0.25727412 | D4: =_xlfn.XLOOKUP(A4,'Updated_List_for_BBB_Rx&IQVIA'!D:D,'Updated_List_for_BBB_Rx&IQVIA'!R:R) -> 0.2969341 | E4: =_xlfn.XLOOKUP(A4,'Updated_List_for_BBB_Rx&IQVIA'!D:D,'Updated_List_for_BBB_Rx&IQVIA'!T:T) -> 7 | F4: =_xlfn.XLOOKUP(A4,'Updated_List_for_BBB_Rx&IQVIA'!D:D,'Updated_List_for_BBB_Rx&IQVIA'!U:U) -> 7 | J4: APIDRA | K4: =_xlfn.XLOOKUP(BBB_Brands_Growths!J4,'3_Years_CountRx_with_RxShare_wi'!A:A,'3_Years_CountRx_with_RxShare_wi'!AJ:AJ) -> 0.040096618 | L4: =_xlfn.XLOOKUP(J4,'3_Years_CountRx_with_RxShare_wi'!A:A,'3_Years_CountRx_with_RxShare_wi'!AK:AK) -> 1.537037 | M4: =_xlfn.XLOOKUP(J4,'3_Years_CountRx_with_RxShare_wi'!A:A,'3_Years_CountRx_with_RxShare_wi'!AL:AL) -> 0.050393701 | N4: =_xlfn.XLOOKUP(BBB_Brands_Growths!J4,'3_Years_CountRx_with_RxShare_wi'!A:A,'3_Years_CountRx_with_RxShare_wi'!AM:AM) -> 1.2905237 | O4: =_xlfn.XLOOKUP(J4,'3_Years_CountRx_with_RxShare_wi'!A:A,'3_Years_CountRx_with_RxShare_wi'!AN:AN) -> 1.2504271
A5: Synkolin | B5: 0 | C5: 0 | D5: =_xlfn.XLOOKUP(A5,'Updated_List_for_BBB_Rx&IQVIA'!D:D,'Updated_List_for_BBB_Rx&IQVIA'!R:R) -> 1.4764939 | E5: =_xlfn.XLOOKUP(A5,'Updated_List_for_BBB_Rx&IQVIA'!D:D,'Updated_List_for_BBB_Rx&IQVIA'!T:T) -> 16 | F5: =_xlfn.XLOOKUP(A5,'Updated_List_for_BBB_Rx&IQVIA'!D:D,'Updated_List_for_BBB_Rx&IQVIA'!U:U) -> 0 | J5: AVAXIM | K5: =_xlfn.XLOOKUP(BBB_Brands_Growths!J5,'3_Years_CountRx_with_RxShare_wi'!A:A,'3_Years_CountRx_with_RxShare_wi'!AJ:AJ) -> 0 | L5: 0 | M5: =_xlfn.XLOOKUP(J5,'3_Years_CountRx_with_RxShare_wi'!A:A,'3_Years_CountRx_with_RxShare_wi'!AL:AL) -> 0 | N5: =_xlfn.XLOOKUP(BBB_Brands_Growths!J5,'3_Years_CountRx_with_RxShare_wi'!A:A,'3_Years_CountRx_with_RxShare_wi'!AM:AM) -> 0.53333333 | O5: =_xlfn.XLOOKUP(J5,'3_Years_CountRx_with_RxShare_wi'!A:A,'3_Years_CountRx_with_RxShare_wi'!AN:AN) -> 0.53333333
A6: Amaryl | B6: =_xlfn.XLOOKUP(A6,'Updated_List_for_BBB_Rx&IQVIA'!D:D,'Updated_List_for_BBB_Rx&IQVIA'!P:P) -> -0.099367229 | C6: =_xlfn.XLOOKUP(A6,'Updated_List_for_BBB_Rx&IQVIA'!D:D,'Updated_List_for_BBB_Rx&IQVIA'!Q:Q) -> -0.0090318317 | D6: =_xlfn.XLOOKUP(A6,'Updated_List_for_BBB_Rx&IQVIA'!D:D,'Updated_List_for_BBB_Rx&IQVIA'!R:R) -> 0.10030214 | E6: =_xlfn.XLOOKUP(A6,'Updated_List_for_BBB_Rx&IQVIA'!D:D,'Updated_List_for_BBB_Rx&IQVIA'!T:T) -> 4 | F6: =_xlfn.XLOOKUP(A6,'Updated_List_for_BBB_Rx&IQVIA'!D:D,'Updated_List_for_BBB_Rx&IQVIA'!U:U) -> 4 | J6: AVIL | K6: =_xlfn.XLOOKUP(BBB_Brands_Growths!J6,'3_Years_CountRx_with_RxShare_wi'!A:A,'3_Years_CountRx_with_RxShare_wi'!AJ:AJ) -> 0.78893058 | L6: =_xlfn.XLOOKUP(J6,'3_Years_CountRx_with_RxShare_wi'!A:A,'3_Years_CountRx_with_RxShare_wi'!AK:AK) -> 1.4937833 | M6: =_xlfn.XLOOKUP(J6,'3_Years_CountRx_with_RxShare_wi'!A:A,'3_Years_CountRx_with_RxShare_wi'!AL:AL) -> 0.87462236 | N6: =_xlfn.XLOOKUP(BBB_Brands_Growths!J6,'3_Years_CountRx_with_RxShare_wi'!A:A,'3_Years_CountRx_with_RxShare_wi'!AM:AM) -> 0.86037127 | O6: =_xlfn.XLOOKUP(J6,'3_Years_CountRx_with_RxShare_wi'!A:A,'3_Years_CountRx_with_RxShare_wi'!AN:AN) -> 0.071440686
A7: Oracyn-K | B7: =_xlfn.XLOOKUP(A7,'Updated_List_for_BBB_Rx&IQVIA'!D:D,'Updated_List_for_BBB_Rx&IQVIA'!P:P) -> -0.020798881 | C7: =_xlfn.XLOOKUP(A7,'Updated_List_for_BBB_Rx&IQVIA'!D:D,'Updated_List_for_BBB_Rx&IQVIA'!Q:Q) -> 0.47706553 | D7: =_xlfn.XLOOKUP(A7,'Updated_List_for_BBB_Rx&IQVIA'!D:D,'Updated_List_for_BBB_Rx&IQVIA'!R:R) -> 0.50843938 | E7: =_xlfn.XLOOKUP(A7,'Updated_List_for_BBB_Rx&IQVIA'!D:D,'Updated_List_for_BBB_Rx&IQVIA'!T:T) -> 2 | F7: =_xlfn.XLOOKUP(A7,'Updated_List_for_BBB_Rx&IQVIA'!D:D,'Updated_List_for_BBB_Rx&IQVIA'!U:U) -> 2 | J7: BETANOL | K7: =_xlfn.XLOOKUP(BBB_Brands_Growths!J7,'3_Years_CountRx_with_RxShare_wi'!A:A,'3_Years_CountRx_with_RxShare_wi'!AJ:AJ) -> 0.072489083 | L7: =_xlfn.XLOOKUP(J7,'3_Years_CountRx_with_RxShare_wi'!A:A,'3_Years_CountRx_with_RxShare_wi'!AK:AK) -> 1.1216216 | M7: =_xlfn.XLOOKUP(J7,'3_Years_CountRx_with_RxShare_wi'!A:A,'3_Years_CountRx_with_RxShare_wi'!AL:AL) -> 0.085308057 | N7: =_xlfn.XLOOKUP(BBB_Brands_Growths!J7,'3_Years_CountRx_with_RxShare_wi'!A:A,'3_Years_CountRx_with_RxShare_wi'!AM:AM) -> 1.3130734 | O7: =_xlfn.XLOOKUP(J7,'3_Years_CountRx_with_RxShare_wi'!A:A,'3_Years_CountRx_with_RxShare_wi'!AN:AN) -> 1.2405843
A8: Luzol | B8: =_xlfn.XLOOKUP(A8,'Updated_List_for_BBB_Rx&IQVIA'!D:D,'Updated_List_for_BBB_Rx&IQVIA'!P:P) -> -0.078418486 | C8: =_xlfn.XLOOKUP(A8,'Updated_List_for_BBB_Rx&IQVIA'!D:D,'Updated_List_for_BBB_Rx&IQVIA'!Q:Q) -> 0.41464574 | D8: =_xlfn.XLOOKUP(A8,'Updated_List_for_BBB_Rx&IQVIA'!D:D,'Updated_List_for_BBB_Rx&IQVIA'!R:R) -> 0.53501966 | E8: =_xlfn.XLOOKUP(A8,'Updated_List_for_BBB_Rx&IQVIA'!D:D,'Updated_List_for_BBB_Rx&IQVIA'!T:T) -> 14 | F8: =_xlfn.XLOOKUP(A8,'Updated_List_for_BBB_Rx&IQVIA'!D:D,'Updated_List_for_BBB_Rx&IQVIA'!U:U) -> 9 | J8: BETANOL A | K8: =_xlfn.XLOOKUP(BBB_Brands_Growths!J8,'3_Years_CountRx_with_RxShare_wi'!A:A,'3_Years_CountRx_with_RxShare_wi'!AJ:AJ) -> 0 | L8: 0 | M8: =_xlfn.XLOOKUP(J8,'3_Years_CountRx_with_RxShare_wi'!A:A,'3_Years_CountRx_with_RxShare_wi'!AL:AL) -> 0 | N8: =_xlfn.XLOOKUP(BBB_Brands_Growths!J8,'3_Years_CountRx_with_RxShare_wi'!A:A,'3_Years_CountRx_with_RxShare_wi'!AM:AM) -> 1.2912583 | O8: =_xlfn.XLOOKUP(J8,'3_Years_CountRx_with_RxShare_wi'!A:A,'3_Years_CountRx_with_RxShare_wi'!AN:AN) -> 1.2912583
A9: Sperdal | B9: =_xlfn.XLOOKUP(A9,'Updated_List_for_BBB_Rx&IQVIA'!D:D,'Updated_List_for_BBB_Rx&IQVIA'!P:P) -> -0.0053494335 | C9: =_xlfn.XLOOKUP(A9,'Updated_List_for_BBB_Rx&IQVIA'!D:D,'Updated_List_for_BBB_Rx&IQVIA'!Q:Q) -> 0.041174164 | D9: =_xlfn.XLOOKUP(A9,'Updated_List_for_BBB_Rx&IQVIA'!D:D,'Updated_List_for_BBB_Rx&IQVIA'!R:R) -> 0.046773811 | E9: =_xlfn.XLOOKUP(A9,'Updated_List_for_BBB_Rx&IQVIA'!D:D,'Updated_List_for_BBB_Rx&IQVIA'!T:T) -> 8 | F9: =_xlfn.XLOOKUP(A9,'Updated_List_for_BBB_Rx&IQVIA'!D:D,'Updated_List_for_BBB_Rx&IQVIA'!U:U) -> 8 | J9: BRODACTAM | K9: =_xlfn.XLOOKUP(BBB_Brands_Growths!J9,'3_Years_CountRx_with_RxShare_wi'!A:A,'3_Years_CountRx_with_RxShare_wi'!AJ:AJ) -> 0.36363636 | L9: =_xlfn.XLOOKUP(J9,'3_Years_CountRx_with_RxShare_wi'!A:A,'3_Years_CountRx_with_RxShare_wi'!AK:AK) -> 1.3333333 | M9: =_xlfn.XLOOKUP(J9,'3_Years_CountRx_with_RxShare_wi'!A:A,'3_Years_CountRx_with_RxShare_wi'!AL:AL) -> 0.26229508 | N9: =_xlfn.XLOOKUP(BBB_Brands_Growths!J9,'3_Years_CountRx_with_RxShare_wi'!A:A,'3_Years_CountRx_with_RxShare_wi'!AM:AM) -> 0.6626506 | O9: =_xlfn.XLOOKUP(J9,'3_Years_CountRx_with_RxShare_wi'!A:A,'3_Years_CountRx_with_RxShare_wi'!AN:AN) -> 0.29901424
A10: Carbanem | B10: =_xlfn.XLOOKUP(A10,'Updated_List_for_BBB_Rx&IQVIA'!D:D,'Updated_List_for_BBB_Rx&IQVIA'!P:P) -> -0.44833139 | C10: =_xlfn.XLOOKUP(A10,'Updated_List_for_BBB_Rx&IQVIA'!D:D,'Updated_List_for_BBB_Rx&IQVIA'!Q:Q) -> -0.29464038 | D10: =_xlfn.XLOOKUP(A10,'Updated_List_for_BBB_Rx&IQVIA'!D:D,'Updated_List_for_BBB_Rx&IQVIA'!R:R) -> 0.278593 | E10: =_xlfn.XLOOKUP(A10,'Updated_List_for_BBB_Rx&IQVIA'!D:D,'Updated_List_for_BBB_Rx&IQVIA'!T:T) -> 17 | F10: =_xlfn.XLOOKUP(A10,'Updated_List_for_BBB_Rx&IQVIA'!D:D,'Updated_List_for_BBB_Rx&IQVIA'!U:U) -> 17 | J10: BUTAPAN | K10: =_xlfn.XLOOKUP(BBB_Brands_Growths!J10,'3_Years_CountRx_with_RxShare_wi'!A:A,'3_Years_CountRx_with_RxShare_wi'!AJ:AJ) -> 0.13884298 | L10: =_xlfn.XLOOKUP(J10,'3_Years_CountRx_with_RxShare_wi'!A:A,'3_Years_CountRx_with_RxShare_wi'!AK:AK) -> 2.2105263 | M10: =_xlfn.XLOOKUP(J10,'3_Years_CountRx_with_RxShare_wi'!A:A,'3_Years_CountRx_with_RxShare_wi'!AL:AL) -> 0.35501859 | N10: =_xlfn.XLOOKUP(BBB_Brands_Growths!J10,'3_Years_CountRx_with_RxShare_wi'!A:A,'3_Years_CountRx_with_RxShare_wi'!AM:AM) -> 0.9877551 | O10: =_xlfn.XLOOKUP(J10,'3_Years_CountRx_with_RxShare_wi'!A:A,'3_Years_CountRx_with_RxShare_wi'!AN:AN) -> 0.84891213
A11: Flagyl | B11: =_xlfn.XLOOKUP(A11,'Updated_List_for_BBB_Rx&IQVIA'!D:D,'Updated_List_for_BBB_Rx&IQVIA'!P:P) -> -0.043070217 | C11: =_xlfn.XLOOKUP(A11,'Updated_List_for_BBB_Rx&IQVIA'!D:D,'Updated_List_for_BBB_Rx&IQVIA'!Q:Q) -> 0.01438503 | D11: =_xlfn.XLOOKUP(A11,'Updated_List_for_BBB_Rx&IQVIA'!D:D,'Updated_List_for_BBB_Rx&IQVIA'!R:R) -> 0.060041236 | E11: =_xlfn.XLOOKUP(A11,'Updated_List_for_BBB_Rx&IQVIA'!D:D,'Updated_List_for_BBB_Rx&IQVIA'!T:T) -> 3 | F11: =_xlfn.XLOOKUP(A11,'Updated_List_for_BBB_Rx&IQVIA'!D:D,'Updated_List_for_BBB_Rx&IQVIA'!U:U) -> 3 | J11: CARBANEM | K11: =_xlfn.XLOOKUP(BBB_Brands_Growths!J11,'3_Years_CountRx_with_RxShare_wi'!A:A,'3_Years_CountRx_with_RxShare_wi'!AJ:AJ) -> 0.0064850843 | L11: =_xlfn.XLOOKUP(J11,'3_Years_CountRx_with_RxShare_wi'!A:A,'3_Years_CountRx_with_RxShare_wi'!AK:AK) -> 1.6666667 | M11: =_xlfn.XLOOKUP(J11,'3_Years_CountRx_with_RxShare_wi'!A:A,'3_Years_CountRx_with_RxShare_wi'!AL:AL) -> 0.0091973244 | N11: =_xlfn.XLOOKUP(BBB_Brands_Growths!J11,'3_Years_CountRx_with_RxShare_wi'!A:A,'3_Years_CountRx_with_RxShare_wi'!AM:AM) -> 1.0879586 | O11: =_xlfn.XLOOKUP(J11,'3_Years_CountRx_with_RxShare_wi'!A:A,'3_Years_CountRx_with_RxShare_wi'!AN:AN) -> 1.0814735
A12: Profenid | B12: =_xlfn.XLOOKUP(A12,'Updated_List_for_BBB_Rx&IQVIA'!D:D,'Updated_List_for_BBB_Rx&IQVIA'!P:P) -> -0.079841717 | C12: =_xlfn.XLOOKUP(A12,'Updated_List_for_BBB_Rx&IQVIA'!D:D,'Updated_List_for_BBB_Rx&IQVIA'!Q:Q) -> -0.012182778 | D12: =_xlfn.XLOOKUP(A12,'Updated_List_for_BBB_Rx&IQVIA'!D:D,'Updated_List_for_BBB_Rx&IQVIA'!R:R) -> 0.073529674 | E12: =_xlfn.XLOOKUP(A12,'Updated_List_for_BBB_Rx&IQVIA'!D:D,'Updated_List_for_BBB_Rx&IQVIA'!T:T) -> 9 | F12: =_xlfn.XLOOKUP(A12,'Updated_List_for_BBB_Rx&IQVIA'!D:D,'Updated_List_for_BBB_Rx&IQVIA'!U:U) -> 9 | J12: CDENS | K12: =_xlfn.XLOOKUP(BBB_Brands_Growths!J12,'3_Years_CountRx_with_RxShare_wi'!A:A,'3_Years_CountRx_with_RxShare_wi'!AJ:AJ) -> 0 | L12: 0 | M12: =_xlfn.XLOOKUP(J12,'3_Years_CountRx_with_RxShare_wi'!A:A,'3_Years_CountRx_with_RxShare_wi'!AL:AL) -> 0 | N12: =_xlfn.XLOOKUP(BBB_Brands_Growths!J12,'3_Years_CountRx_with_RxShare_wi'!A:A,'3_Years_CountRx_with_RxShare_wi'!AM:AM) -> 1.6939783 | O12: =_xlfn.XLOOKUP(J12,'3_Years_CountRx_with_RxShare_wi'!A:A,'3_Years_CountRx_with_RxShare_wi'!AN:AN) -> 1.6939783
A13: Telfast | B13: =_xlfn.XLOOKUP(A13,'Updated_List_for_BBB_Rx&IQVIA'!D:D,'Updated_List_for_BBB_Rx&IQVIA'!P:P) -> 0.058744565 | C13: =_xlfn.XLOOKUP(A13,'Updated_List_for_BBB_Rx&IQVIA'!D:D,'Updated_List_for_BBB_Rx&IQVIA'!Q:Q) -> 0.1646471 | D13: =_xlfn.XLOOKUP(A13,'Updated_List_for_BBB_Rx&IQVIA'!D:D,'Updated_List_for_BBB_Rx&IQVIA'!R:R) -> 0.10002652 | E13: =_xlfn.XLOOKUP(A13,'Updated_List_for_BBB_Rx&IQVIA'!D:D,'Updated_List_for_BBB_Rx&IQVIA'!T:T) -> 7 | F13: =_xlfn.XLOOKUP(A13,'Updated_List_for_BBB_Rx&IQVIA'!D:D,'Updated_List_for_BBB_Rx&IQVIA'!U:U) -> 7 | J13: COPIXA | K13: =_xlfn.XLOOKUP(BBB_Brands_Growths!J13,'3_Years_CountRx_with_RxShare_wi'!A:A,'3_Years_CountRx_with_RxShare_wi'!AJ:AJ) -> 0 | L13: 0 | M13: =_xlfn.XLOOKUP(J13,'3_Years_CountRx_with_RxShare_wi'!A:A,'3_Years_CountRx_with_RxShare_wi'!AL:AL) -> 0.047058824 | N13: =_xlfn.XLOOKUP(BBB_Brands_Growths!J13,'3_Years_CountRx_with_RxShare_wi'!A:A,'3_Years_CountRx_with_RxShare_wi'!AM:AM) -> 0.76258993 | O13: =_xlfn.XLOOKUP(J13,'3_Years_CountRx_with_RxShare_wi'!A:A,'3_Years_CountRx_with_RxShare_wi'!AN:AN) -> 0.76258993
A14: Apidra | B14: =_xlfn.XLOOKUP(A14,'Updated_List_for_BBB_Rx&IQVIA'!D:D,'Updated_List_for_BBB_Rx&IQVIA'!P:P) -> 0.027903298 | C14: =_xlfn.XLOOKUP(A14,'Updated_List_for_BBB_Rx&IQVIA'!D:D,'Updated_List_for_BBB_Rx&IQVIA'!Q:Q) -> -0.075574262 | D14: =_xlfn.XLOOKUP(A14,'Updated_List_for_BBB_Rx&IQVIA'!D:D,'Updated_List_for_BBB_Rx&IQVIA'!R:R) -> -0.10066857 | E14: =_xlfn.XLOOKUP(A14,'Updated_List_for_BBB_Rx&IQVIA'!D:D,'Updated_List_for_BBB_Rx&IQVIA'!T:T) -> 13 | F14: =_xlfn.XLOOKUP(A14,'Updated_List_for_BBB_Rx&IQVIA'!D:D,'Updated_List_for_BBB_Rx&IQVIA'!U:U) -> 13 | J14: CURAZITH | K14: =_xlfn.XLOOKUP(BBB_Brands_Growths!J14,'3_Years_CountRx_with_RxShare_wi'!A:A,'3_Years_CountRx_with_RxShare_wi'!AJ:AJ) -> 0.0003579365 | L14: =_xlfn.XLOOKUP(J14,'3_Years_CountRx_with_RxShare_wi'!A:A,'3_Years_CountRx_with_RxShare_wi'!AK:AK) -> 1.3333333 | M14: =_xlfn.XLOOKUP(J14,'3_Years_CountRx_with_RxShare_wi'!A:A,'3_Years_CountRx_with_RxShare_wi'!AL:AL) -> 0.0011382607 | N14: =_xlfn.XLOOKUP(BBB_Brands_Growths!J14,'3_Years_CountRx_with_RxShare_wi'!A:A,'3_Years_CountRx_with_RxShare_wi'!AM:AM) -> 1.3365026 | O14: =_xlfn.XLOOKUP(J14,'3_Years_CountRx_with_RxShare_wi'!A:A,'3_Years_CountRx_with_RxShare_wi'!AN:AN) -> 1.3361447
A15: Copixa | B15: 0 | C15: 0 | D15: =_xlfn.XLOOKUP(A15,'Updated_List_for_BBB_Rx&IQVIA'!D:D,'Updated_List_for_BBB_Rx&IQVIA'!R:R) -> 0.46011244 | E15: =_xlfn.XLOOKUP(A15,'Updated_List_for_BBB_Rx&IQVIA'!D:D,'Updated_List_for_BBB_Rx&IQVIA'!T:T) -> 3 | F15: =_xlfn.XLOOKUP(A15,'Updated_List_for_BBB_Rx&IQVIA'!D:D,'Updated_List_for_BBB_Rx&IQVIA'!U:U) -> 0 | J15: DOXOVIA | K15: =_xlfn.XLOOKUP(BBB_Brands_Growths!J15,'3_Years_CountRx_with_RxShare_wi'!A:A,'3_Years_CountRx_with_RxShare_wi'!AJ:AJ) -> 0 | L15: 0 | M15: =_xlfn.XLOOKUP(J15,'3_Years_CountRx_with_RxShare_wi'!A:A,'3_Years_CountRx_with_RxShare_wi'!AL:AL) -> 0 | N15: =_xlfn.XLOOKUP(BBB_Brands_Growths!J15,'3_Years_CountRx_with_RxShare_wi'!A:A,'3_Years_CountRx_with_RxShare_wi'!AM:AM) -> 1.2546842 | O15: =_xlfn.XLOOKUP(J15,'3_Years_CountRx_with_RxShare_wi'!A:A,'3_Years_CountRx_with_RxShare_wi'!AN:AN) -> 1.2546842
A16: Ovenox | B16: =_xlfn.XLOOKUP(A16,'Updated_List_for_BBB_Rx&IQVIA'!D:D,'Updated_List_for_BBB_Rx&IQVIA'!P:P) -> -0.65591121 | C16: =_xlfn.XLOOKUP(A16,'Updated_List_for_BBB_Rx&IQVIA'!D:D,'Updated_List_for_BBB_Rx&IQVIA'!Q:Q) -> -0.62293489 | D16: =_xlfn.XLOOKUP(A16,'Updated_List_for_BBB_Rx&IQVIA'!D:D,'Updated_List_for_BBB_Rx&IQVIA'!R:R) -> 0.095836654 | E16: =_xlfn.XLOOKUP(A16,'Updated_List_for_BBB_Rx&IQVIA'!D:D,'Updated_List_for_BBB_Rx&IQVIA'!T:T) -> 12 | F16: =_xlfn.XLOOKUP(A16,'Updated_List_for_BBB_Rx&IQVIA'!D:D,'Updated_List_for_BBB_Rx&IQVIA'!U:U) -> 8 | J16: ELOXATIN | K16: =_xlfn.XLOOKUP(BBB_Brands_Growths!J16,'3_Years_CountRx_with_RxShare_wi'!A:A,'3_Years_CountRx_with_RxShare_wi'!AJ:AJ) -> 0 | L16: 0 | M16: 0 | N16: =_xlfn.XLOOKUP(BBB_Brands_Growths!J16,'3_Years_CountRx_with_RxShare_wi'!A:A,'3_Years_CountRx_with_RxShare_wi'!AM:AM) -> 0 | O16: =_xlfn.XLOOKUP(J16,'3_Years_CountRx_with_RxShare_wi'!A:A,'3_Years_CountRx_with_RxShare_wi'!AN:AN) -> 0
A17: Fimoxyclav | B17: =_xlfn.XLOOKUP(A17,'Updated_List_for_BBB_Rx&IQVIA'!D:D,'Updated_List_for_BBB_Rx&IQVIA'!P:P) -> -0.19575148 | C17: =_xlfn.XLOOKUP(A17,'Updated_List_for_BBB_Rx&IQVIA'!D:D,'Updated_List_for_BBB_Rx&IQVIA'!Q:Q) -> -0.14511044 | D17: =_xlfn.XLOOKUP(A17,'Updated_List_for_BBB_Rx&IQVIA'!D:D,'Updated_List_for_BBB_Rx&IQVIA'!R:R) -> 0.062966904 | E17: =_xlfn.XLOOKUP(A17,'Updated_List_for_BBB_Rx&IQVIA'!D:D,'Updated_List_for_BBB_Rx&IQVIA'!T:T) -> 4 | F17: =_xlfn.XLOOKUP(A17,'Updated_List_for_BBB_Rx&IQVIA'!D:D,'Updated_List_for_BBB_Rx&IQVIA'!U:U) -> 3 | J17: ENDOXAN | K17: =_xlfn.XLOOKUP(BBB_Brands_Growths!J17,'3_Years_CountRx_with_RxShare_wi'!A:A,'3_Years_CountRx_with_RxShare_wi'!AJ:AJ) -> 0.44715447 | L17: =_xlfn.XLOOKUP(J17,'3_Years_CountRx_with_RxShare_wi'!A:A,'3_Years_CountRx_with_RxShare_wi'!AK:AK) -> 1.4473684 | M17: 0 | N17: =_xlfn.XLOOKUP(BBB_Brands_Growths!J17,'3_Years_CountRx_with_RxShare_wi'!A:A,'3_Years_CountRx_with_RxShare_wi'!AM:AM) -> 0 | O17: =_xlfn.XLOOKUP(J17,'3_Years_CountRx_with_RxShare_wi'!A:A,'3_Years_CountRx_with_RxShare_wi'!AN:AN) -> -0.44715447
A18: Epilim | B18: =_xlfn.XLOOKUP(A18,'Updated_List_for_BBB_Rx&IQVIA'!D:D,'Updated_List_for_BBB_Rx&IQVIA'!P:P) -> 0.10703058 | C18: =_xlfn.XLOOKUP(A18,'Updated_List_for_BBB_Rx&IQVIA'!D:D,'Updated_List_for_BBB_Rx&IQVIA'!Q:Q) -> 0.17993334 | D18: =_xlfn.XLOOKUP(A18,'Updated_List_for_BBB_Rx&IQVIA'!D:D,'Updated_List_for_BBB_Rx&IQVIA'!R:R) -> 0.065854332 | E18: =_xlfn.XLOOKUP(A18,'Updated_List_for_BBB_Rx&IQVIA'!D:D,'Updated_List_for_BBB_Rx&IQVIA'!T:T) -> 2 | F18: =_xlfn.XLOOKUP(A18,'Updated_List_for_BBB_Rx&IQVIA'!D:D,'Updated_List_for_BBB_Rx&IQVIA'!U:U) -> 2 | J18: ENTEROGERMINA | K18: =_xlfn.XLOOKUP(BBB_Brands_Growths!J18,'3_Years_CountRx_with_RxShare_wi'!A:A,'3_Years_CountRx_with_RxShare_wi'!AJ:AJ) -> 0.17927678 | L18: =_xlfn.XLOOKUP(J18,'3_Years_CountRx_with_RxShare_wi'!A:A,'3_Years_CountRx_with_RxShare_wi'!AK:AK) -> 2.4313124 | M18: =_xlfn.XLOOKUP(J18,'3_Years_CountRx_with_RxShare_wi'!A:A,'3_Years_CountRx_with_RxShare_wi'!AL:AL) -> 0.21571454 | N18: =_xlfn.XLOOKUP(BBB_Brands_Growths!J18,'3_Years_CountRx_with_RxShare_wi'!A:A,'3_Years_CountRx_with_RxShare_wi'!AM:AM) -> 1.126546 | O18: =_xlfn.XLOOKUP(J18,'3_Years_CountRx_with_RxShare_wi'!A:A,'3_Years_CountRx_with_RxShare_wi'!AN:AN) -> 0.94726918
A19: Vaxigrip | B19: =_xlfn.XLOOKUP(A19,'Updated_List_for_BBB_Rx&IQVIA'!D:D,'Updated_List_for_BBB_Rx&IQVIA'!P:P) -> -0.50976657 | C19: =_xlfn.XLOOKUP(A19,'Updated_List_for_BBB_Rx&IQVIA'!D:D,'Updated_List_for_BBB_Rx&IQVIA'!Q:Q) -> -0.39017094 | D19: =_xlfn.XLOOKUP(A19,'Updated_List_for_BBB_Rx&IQVIA'!D:D,'Updated_List_for_BBB_Rx&IQVIA'!R:R) -> 0.24395649 | E19: =_xlfn.XLOOKUP(A19,'Updated_List_for_BBB_Rx&IQVIA'!D:D,'Updated_List_for_BBB_Rx&IQVIA'!T:T) -> 0 | F19: =_xlfn.XLOOKUP(A19,'Updated_List_for_BBB_Rx&IQVIA'!D:D,'Updated_List_for_BBB_Rx&IQVIA'!U:U) -> 0 | J19: EPILIM | K19: =_xlfn.XLOOKUP(BBB_Brands_Growths!J19,'3_Years_CountRx_with_RxShare_wi'!A:A,'3_Years_CountRx_with_RxShare_wi'!AJ:AJ) -> 0.07736878 | L19: =_xlfn.XLOOKUP(J19,'3_Years_CountRx_with_RxShare_wi'!A:A,'3_Years_CountRx_with_RxShare_wi'!AK:AK) -> 2.045045 | M19: =_xlfn.XLOOKUP(J19,'3_Years_CountRx_with_RxShare_wi'!A:A,'3_Years_CountRx_with_RxShare_wi'!AL:AL) -> 0.14624213 | N19: =_xlfn.XLOOKUP(BBB_Brands_Growths!J19,'3_Years_CountRx_with_RxShare_wi'!A:A,'3_Years_CountRx_with_RxShare_wi'!AM:AM) -> 1.0064029 | O19: =_xlfn.XLOOKUP(J19,'3_Years_CountRx_with_RxShare_wi'!A:A,'3_Years_CountRx_with_RxShare_wi'!AN:AN) -> 0.92903415
A20: Phenergan Plus | B20: =_xlfn.XLOOKUP(A20,'Updated_List_for_BBB_Rx&IQVIA'!D:D,'Updated_List_for_BBB_Rx&IQVIA'!P:P) -> -0.27620562 | C20: =_xlfn.XLOOKUP(A20,'Updated_List_for_BBB_Rx&IQVIA'!D:D,'Updated_List_for_BBB_Rx&IQVIA'!Q:Q) -> -0.3713094 | D20: =_xlfn.XLOOKUP(A20,'Updated_List_for_BBB_Rx&IQVIA'!D:D,'Updated_List_for_BBB_Rx&IQVIA'!R:R) -> -0.13139613 | E20: =_xlfn.XLOOKUP(A20,'Updated_List_for_BBB_Rx&IQVIA'!D:D,'Updated_List_for_BBB_Rx&IQVIA'!T:T) -> 1 | F20: =_xlfn.XLOOKUP(A20,'Updated_List_for_BBB_Rx&IQVIA'!D:D,'Updated_List_for_BBB_Rx&IQVIA'!U:U) -> 1 | J20: ERTU | K20: =_xlfn.XLOOKUP(BBB_Brands_Growths!J20,'3_Years_CountRx_with_RxShare_wi'!A:A,'3_Years_CountRx_with_RxShare_wi'!AJ:AJ) -> 0.013515774 | L20: =_xlfn.XLOOKUP(J20,'3_Years_CountRx_with_RxShare_wi'!A:A,'3_Years_CountRx_with_RxShare_wi'!AK:AK) -> 2.4047619 | M20: =_xlfn.XLOOKUP(J20,'3_Years_CountRx_with_RxShare_wi'!A:A,'3_Years_CountRx_with_RxShare_wi'!AL:AL) -> 0.020249695 | N20: =_xlfn.XLOOKUP(BBB_Brands_Growths!J20,'3_Years_CountRx_with_RxShare_wi'!A:A,'3_Years_CountRx_with_RxShare_wi'!AM:AM) -> 1.0974007 | O20: =_xlfn.XLOOKUP(J20,'3_Years_CountRx_with_RxShare_wi'!A:A,'3_Years_CountRx_with_RxShare_wi'!AN:AN) -> 1.0838849
J21: ESCAP | K21: =_xlfn.XLOOKUP(BBB_Brands_Growths!J21,'3_Years_CountRx_with_RxShare_wi'!A:A,'3_Years_CountRx_with_RxShare_wi'!AJ:AJ) -> 1.0129095e-05 | L21: =_xlfn.XLOOKUP(J21,'3_Years_CountRx_with_RxShare_wi'!A:A,'3_Years_CountRx_with_RxShare_wi'!AK:AK) -> 1.3333333 | M21: =_xlfn.XLOOKUP(J21,'3_Years_CountRx_with_RxShare_wi'!A:A,'3_Years_CountRx_with_RxShare_wi'!AL:AL) -> 0.00018770726 | N21: =_xlfn.XLOOKUP(BBB_Brands_Growths!J21,'3_Years_CountRx_with_RxShare_wi'!A:A,'3_Years_CountRx_with_RxShare_wi'!AM:AM) -> 1.084151 | O21: =_xlfn.XLOOKUP(J21,'3_Years_CountRx_with_RxShare_wi'!A:A,'3_Years_CountRx_with_RxShare_wi'!AN:AN) -> 1.0841409
J22: EXPRES | K22: =_xlfn.XLOOKUP(BBB_Brands_Growths!J22,'3_Years_CountRx_with_RxShare_wi'!A:A,'3_Years_CountRx_with_RxShare_wi'!AJ:AJ) -> 0.010547196 | L22: =_xlfn.XLOOKUP(J22,'3_Years_CountRx_with_RxShare_wi'!A:A,'3_Years_CountRx_with_RxShare_wi'!AK:AK) -> 1.9818182 | M22: =_xlfn.XLOOKUP(J22,'3_Years_CountRx_with_RxShare_wi'!A:A,'3_Years_CountRx_with_RxShare_wi'!AL:AL) -> 0.020645385 | N22: =_xlfn.XLOOKUP(BBB_Brands_Growths!J22,'3_Years_CountRx_with_RxShare_wi'!A:A,'3_Years_CountRx_with_RxShare_wi'!AM:AM) -> 1.0775206 | O22: =_xlfn.XLOOKUP(J22,'3_Years_CountRx_with_RxShare_wi'!A:A,'3_Years_CountRx_with_RxShare_wi'!AN:AN) -> 1.0669734
J23: FARPEM | K23: =_xlfn.XLOOKUP(BBB_Brands_Growths!J23,'3_Years_CountRx_with_RxShare_wi'!A:A,'3_Years_CountRx_with_RxShare_wi'!AJ:AJ) -> 0 | L23: 0 | M23: =_xlfn.XLOOKUP(J23,'3_Years_CountRx_with_RxShare_wi'!A:A,'3_Years_CountRx_with_RxShare_wi'!AL:AL) -> 0.037099494 | N23: =_xlfn.XLOOKUP(BBB_Brands_Growths!J23,'3_Years_CountRx_with_RxShare_wi'!A:A,'3_Years_CountRx_with_RxShare_wi'!AM:AM) -> 0.20217984 | O23: =_xlfn.XLOOKUP(J23,'3_Years_CountRx_with_RxShare_wi'!A:A,'3_Years_CountRx_with_RxShare_wi'!AN:AN) -> 0.20217984
J24: FIMOXYCLAV | K24: =_xlfn.XLOOKUP(BBB_Brands_Growths!J24,'3_Years_CountRx_with_RxShare_wi'!A:A,'3_Years_CountRx_with_RxShare_wi'!AJ:AJ) -> 0.072863298 | L24: =_xlfn.XLOOKUP(J24,'3_Years_CountRx_with_RxShare_wi'!A:A,'3_Years_CountRx_with_RxShare_wi'!AK:AK) -> 1.7789623 | M24: =_xlfn.XLOOKUP(J24,'3_Years_CountRx_with_RxShare_wi'!A:A,'3_Years_CountRx_with_RxShare_wi'!AL:AL) -> 0.13362947 | N24: =_xlfn.XLOOKUP(BBB_Brands_Growths!J24,'3_Years_CountRx_with_RxShare_wi'!A:A,'3_Years_CountRx_with_RxShare_wi'!AM:AM) -> 1.2488457 | O24: =_xlfn.XLOOKUP(J24,'3_Years_CountRx_with_RxShare_wi'!A:A,'3_Years_CountRx_with_RxShare_wi'!AN:AN) -> 1.1759825
J25: FIMOXYL | K25: =_xlfn.XLOOKUP(BBB_Brands_Growths!J25,'3_Years_CountRx_with_RxShare_wi'!A:A,'3_Years_CountRx_with_RxShare_wi'!AJ:AJ) -> 0.037519456 | L25: =_xlfn.XLOOKUP(J25,'3_Years_CountRx_with_RxShare_wi'!A:A,'3_Years_CountRx_with_RxShare_wi'!AK:AK) -> 1.7026022 | M25: =_xlfn.XLOOKUP(J25,'3_Years_CountRx_with_RxShare_wi'!A:A,'3_Years_CountRx_with_RxShare_wi'!AL:AL) -> 0.084548105 | N25: =_xlfn.XLOOKUP(BBB_Brands_Growths!J25,'3_Years_CountRx_with_RxShare_wi'!A:A,'3_Years_CountRx_with_RxShare_wi'!AM:AM) -> 1.1851456 | O25: =_xlfn.XLOOKUP(J25,'3_Years_CountRx_with_RxShare_wi'!A:A,'3_Years_CountRx_with_RxShare_wi'!AN:AN) -> 1.1476262
J26: FLAGYL | K26: =_xlfn.XLOOKUP(BBB_Brands_Growths!J26,'3_Years_CountRx_with_RxShare_wi'!A:A,'3_Years_CountRx_with_RxShare_wi'!AJ:AJ) -> 0.013163131 | L26: =_xlfn.XLOOKUP(J26,'3_Years_CountRx_with_RxShare_wi'!A:A,'3_Years_CountRx_with_RxShare_wi'!AK:AK) -> 1.3915858 | M26: =_xlfn.XLOOKUP(J26,'3_Years_CountRx_with_RxShare_wi'!A:A,'3_Years_CountRx_with_RxShare_wi'!AL:AL) -> 0.031036869 | N26: =_xlfn.XLOOKUP(BBB_Brands_Growths!J26,'3_Years_CountRx_with_RxShare_wi'!A:A,'3_Years_CountRx_with_RxShare_wi'!AM:AM) -> 1.1481039 | O26: =_xlfn.XLOOKUP(J26,'3_Years_CountRx_with_RxShare_wi'!A:A,'3_Years_CountRx_with_RxShare_wi'!AN:AN) -> 1.1349408
J27: FRISIUM | K27: =_xlfn.XLOOKUP(BBB_Brands_Growths!J27,'3_Years_CountRx_with_RxShare_wi'!A:A,'3_Years_CountRx_with_RxShare_wi'!AJ:AJ) -> 0.18502203 | L27: =_xlfn.XLOOKUP(J27,'3_Years_CountRx_with_RxShare_wi'!A:A,'3_Years_CountRx_with_RxShare_wi'!AK:AK) -> 2.4 | M27: =_xlfn.XLOOKUP(J27,'3_Years_CountRx_with_RxShare_wi'!A:A,'3_Years_CountRx_with_RxShare_wi'!AL:AL) -> 0.13302752 | N27: =_xlfn.XLOOKUP(BBB_Brands_Growths!J27,'3_Years_CountRx_with_RxShare_wi'!A:A,'3_Years_CountRx_with_RxShare_wi'!AM:AM) -> 1.1368948 | O27: =_xlfn.XLOOKUP(J27,'3_Years_CountRx_with_RxShare_wi'!A:A,'3_Years_CountRx_with_RxShare_wi'!AN:AN) -> 0.9518728
J28: GAVISYN | K28: =_xlfn.XLOOKUP(BBB_Brands_Growths!J28,'3_Years_CountRx_with_RxShare_wi'!A:A,'3_Years_CountRx_with_RxShare_wi'!AJ:AJ) -> 0.0049242496 | L28: =_xlfn.XLOOKUP(J28,'3_Years_CountRx_with_RxShare_wi'!A:A,'3_Years_CountRx_with_RxShare_wi'!AK:AK) -> 1.4914286 | M28: =_xlfn.XLOOKUP(J28,'3_Years_CountRx_with_RxShare_wi'!A:A,'3_Years_CountRx_with_RxShare_wi'!AL:AL) -> 0.012628085 | N28: =_xlfn.XLOOKUP(BBB_Brands_Growths!J28,'3_Years_CountRx_with_RxShare_wi'!A:A,'3_Years_CountRx_with_RxShare_wi'!AM:AM) -> 1.1149372 | O28: =_xlfn.XLOOKUP(J28,'3_Years_CountRx_with_RxShare_wi'!A:A,'3_Years_CountRx_with_RxShare_wi'!AN:AN) -> 1.110013
J29: IMOVANE | K29: =_xlfn.XLOOKUP(BBB_Brands_Growths!J29,'3_Years_CountRx_with_RxShare_wi'!A:A,'3_Years_CountRx_with_RxShare_wi'!AJ:AJ) -> 0.30434783 | L29: =_xlfn.XLOOKUP(J29,'3_Years_CountRx_with_RxShare_wi'!A:A,'3_Years_CountRx_with_RxShare_wi'!AK:AK) -> 1.1666667 | M29: =_xlfn.XLOOKUP(J29,'3_Years_CountRx_with_RxShare_wi'!A:A,'3_Years_CountRx_with_RxShare_wi'!AL:AL) -> 0.6 | N29: =_xlfn.XLOOKUP(BBB_Brands_Growths!J29,'3_Years_CountRx_with_RxShare_wi'!A:A,'3_Years_CountRx_with_RxShare_wi'!AM:AM) -> 1.2105263 | O29: =_xlfn.XLOOKUP(J29,'3_Years_CountRx_with_RxShare_wi'!A:A,'3_Years_CountRx_with_RxShare_wi'!AN:AN) -> 0.90617849
J30: INCRIT | K30: =_xlfn.XLOOKUP(BBB_Brands_Growths!J30,'3_Years_CountRx_with_RxShare_wi'!A:A,'3_Years_CountRx_with_RxShare_wi'!AJ:AJ) -> 0 | L30: =_xlfn.XLOOKUP(J30,'3_Years_CountRx_with_RxShare_wi'!A:A,'3_Years_CountRx_with_RxShare_wi'!AK:AK) -> 0 | M30: =_xlfn.XLOOKUP(J30,'3_Years_CountRx_with_RxShare_wi'!A:A,'3_Years_CountRx_with_RxShare_wi'!AL:AL) -> 0 | N30: =_xlfn.XLOOKUP(BBB_Brands_Growths!J30,'3_Years_CountRx_with_RxShare_wi'!A:A,'3_Years_CountRx_with_RxShare_wi'!AM:AM) -> 1.6575342 | O30: =_xlfn.XLOOKUP(J30,'3_Years_CountRx_with_RxShare_wi'!A:A,'3_Years_CountRx_with_RxShare_wi'!AN:AN) -> 1.6575342
J31: INCRIT M | K31: =_xlfn.XLOOKUP(BBB_Brands_Growths!J31,'3_Years_CountRx_with_RxShare_wi'!A:A,'3_Years_CountRx_with_RxShare_wi'!AJ:AJ) -> 0.0021346057 | L31: =_xlfn.XLOOKUP(J31,'3_Years_CountRx_with_RxShare_wi'!A:A,'3_Years_CountRx_with_RxShare_wi'!AK:AK) -> 1.5454545 | M31: =_xlfn.XLOOKUP(J31,'3_Years_CountRx_with_RxShare_wi'!A:A,'3_Years_CountRx_with_RxShare_wi'!AL:AL) -> 0.0012315271 | N31: =_xlfn.XLOOKUP(BBB_Brands_Growths!J31,'3_Years_CountRx_with_RxShare_wi'!A:A,'3_Years_CountRx_with_RxShare_wi'!AM:AM) -> 1.4578071 | O31: =_xlfn.XLOOKUP(J31,'3_Years_CountRx_with_RxShare_wi'!A:A,'3_Years_CountRx_with_RxShare_wi'!AN:AN) -> 1.4556725
J32: KURACEF | K32: =_xlfn.XLOOKUP(BBB_Brands_Growths!J32,'3_Years_CountRx_with_RxShare_wi'!A:A,'3_Years_CountRx_with_RxShare_wi'!AJ:AJ) -> 0.00096750276 | L32: =_xlfn.XLOOKUP(J32,'3_Years_CountRx_with_RxShare_wi'!A:A,'3_Years_CountRx_with_RxShare_wi'!AK:AK) -> 2.2765957 | M32: =_xlfn.XLOOKUP(J32,'3_Years_CountRx_with_RxShare_wi'!A:A,'3_Years_CountRx_with_RxShare_wi'!AL:AL) -> 0.0017039 | N32: =_xlfn.XLOOKUP(BBB_Brands_Growths!J32,'3_Years_CountRx_with_RxShare_wi'!A:A,'3_Years_CountRx_with_RxShare_wi'!AM:AM) -> 1.2528917 | O32: =_xlfn.XLOOKUP(J32,'3_Years_CountRx_with_RxShare_wi'!A:A,'3_Years_CountRx_with_RxShare_wi'!AN:AN) -> 1.2519242
J33: LANTUS+TOUJEO | K33: =_xlfn.XLOOKUP(BBB_Brands_Growths!J33,'3_Years_CountRx_with_RxShare_wi'!A:A,'3_Years_CountRx_with_RxShare_wi'!AJ:AJ) -> 0.19503735 | L33: =_xlfn.XLOOKUP(J33,'3_Years_CountRx_with_RxShare_wi'!A:A,'3_Years_CountRx_with_RxShare_wi'!AK:AK) -> 1.6101322 | M33: =_xlfn.XLOOKUP(J33,'3_Years_CountRx_with_RxShare_wi'!A:A,'3_Years_CountRx_with_RxShare_wi'!AL:AL) -> 0.27955083 | N33: =_xlfn.XLOOKUP(BBB_Brands_Growths!J33,'3_Years_CountRx_with_RxShare_wi'!A:A,'3_Years_CountRx_with_RxShare_wi'!AM:AM) -> 1.2482645 | O33: =_xlfn.XLOOKUP(J33,'3_Years_CountRx_with_RxShare_wi'!A:A,'3_Years_CountRx_with_RxShare_wi'!AN:AN) -> 1.0532271
J34: LASILACTONE | K34: =_xlfn.XLOOKUP(BBB_Brands_Growths!J34,'3_Years_CountRx_with_RxShare_wi'!A:A,'3_Years_CountRx_with_RxShare_wi'!AJ:AJ) -> 8.0840744e-05 | L34: =_xlfn.XLOOKUP(J34,'3_Years_CountRx_with_RxShare_wi'!A:A,'3_Years_CountRx_with_RxShare_wi'!AK:AK) -> 1 | M34: =_xlfn.XLOOKUP(J34,'3_Years_CountRx_with_RxShare_wi'!A:A,'3_Years_CountRx_with_RxShare_wi'!AL:AL) -> 0 | N34: =_xlfn.XLOOKUP(BBB_Brands_Growths!J34,'3_Years_CountRx_with_RxShare_wi'!A:A,'3_Years_CountRx_with_RxShare_wi'!AM:AM) -> 1.0330717 | O34: =_xlfn.XLOOKUP(J34,'3_Years_CountRx_with_RxShare_wi'!A:A,'3_Years_CountRx_with_RxShare_wi'!AN:AN) -> 1.0329908
J35: LASIX | K35: =_xlfn.XLOOKUP(BBB_Brands_Growths!J35,'3_Years_CountRx_with_RxShare_wi'!A:A,'3_Years_CountRx_with_RxShare_wi'!AJ:AJ) -> 0.39954367 | L35: =_xlfn.XLOOKUP(J35,'3_Years_CountRx_with_RxShare_wi'!A:A,'3_Years_CountRx_with_RxShare_wi'!AK:AK) -> 1.9056832 | M35: =_xlfn.XLOOKUP(J35,'3_Years_CountRx_with_RxShare_wi'!A:A,'3_Years_CountRx_with_RxShare_wi'!AL:AL) -> 0.4513436 | N35: =_xlfn.XLOOKUP(BBB_Brands_Growths!J35,'3_Years_CountRx_with_RxShare_wi'!A:A,'3_Years_CountRx_with_RxShare_wi'!AM:AM) -> 1.0045842 | O35: =_xlfn.XLOOKUP(J35,'3_Years_CountRx_with_RxShare_wi'!A:A,'3_Years_CountRx_with_RxShare_wi'!AN:AN) -> 0.60504057
... J70: XEROSEC | K70: =_xlfn.XLOOKUP(BBB_Brands_Growths!J70,'3_Years_CountRx_with_RxShare_wi'!A:A,'3_Years_CountRx_with_RxShare_wi'!AJ:AJ) -> 0 | L70: =_xlfn.XLOOKUP(J70,'3_Years_CountRx_with_RxShare_wi'!A:A,'3_Years_CountRx_with_RxShare_wi'!AK:AK) -> 0 | M70: =_xlfn.XLOOKUP(J70,'3_Years_CountRx_with_RxShare_wi'!A:A,'3_Years_CountRx_with_RxShare_wi'!AL:AL) -> 0 | N70: =_xlfn.XLOOKUP(BBB_Brands_Growths!J70,'3_Years_CountRx_with_RxShare_wi'!A:A,'3_Years_CountRx_with_RxShare_wi'!AM:AM) -> 0 | O70: =_xlfn.XLOOKUP(J70,'3_Years_CountRx_with_RxShare_wi'!A:A,'3_Years_CountRx_with_RxShare_wi'!AN:AN) -> 0

Sheet Updated_List_for_BBB_Rx&IQVIA
H2: LC TK | I2: LC TK | J2: Selected Market | L2: Brand to Molecule | N2: Molecule to TC III MS
A3: TCI/ II/III | B3: TC IV | C3: Molecule | D3: BBB Brands | E3: Revised Brand | F3: BRAND | G3: Selected Market | H3: MAT Q2'25 | I3: MAT Q2'24 | J3: MAT Q2'25 | K3: MAT Q2'24 | L3: MAT Q2'25 | M3: MAT Q2'24 | N3: MAT Q2'25 | O3: MAT Q2'24 | P3: MS Growth | Q3: Growth% | R3: Mkt Growth | S3: Gap from Mkt Growth | T3: Position Q2 2025 | U3: Position Q2 2024 | V3: IQVIA Market position change
A4: CEPHALOSPORINS & COMBS | B4: CEPHALOSPORINS ORAL | C4: CEFUROXIME AXETIL | E4: Sefurox | F4: SEFUROX S.Y | G4: CEFUROXIME AXETIL | H4: 33 | I4: 177 | J4: 2365456 | K4: 2149742 | L4: =IFERROR(H4/J4,0) -> 1.3950798e-05 | M4: =IFERROR(I4/K4,0) -> 8.2335462e-05 | N4: 0.098694134 | O4: 0.092886543 | P4: =L4/M4-1 -> -0.83056148 | Q4: =H4/I4-1 -> -0.81355932 | R4: =J4/K4-1 -> 0.10034413 | S4: =Q4-R4 -> -0.91390346
A5: INTESTINAL DISORDER PROD | B5: ANTIDIARR MICRO-ORGANISMS | C5: BACILLUS CLAUSII | D5: Enterogermina | E5: Enterogermina | F5: ENTEROGERMINA S.Y | G5: ANTIDIARR MICRO-ORGANISMS | H5: 196543 | I5: 182743 | J5: 706924 | K5: 466089 | L5: =IFERROR(H5/J5,0) -> 0.27802564 | M5: =IFERROR(I5/K5,0) -> 0.39207748 | N5: 0.49285664 | O5: 0.40592414 | P5: =L5/M5-1 -> -0.29089106 | Q5: =H5/I5-1 -> 0.075515888 | R5: =J5/K5-1 -> 0.51671462 | S5: =Q5-R5 -> -0.44119873 | T5: 1 | U5: 1 | X5: Raised to top
A6: ANTIULCERANTS | B6: PROTON PUMP INHIBITORS | C6: OMEPRAZOLE | E6: Xerosec | F6: XEROSEC S.Y | G6: OMEPRAZOLE | H6: 779 | I6: 3165 | J6: 4496179 | K6: 4594748 | L6: =IFERROR(H6/J6,0) -> 0.00017325823 | M6: =IFERROR(I6/K6,0) -> 0.00068882994 | N6: 0.097337718 | O6: 0.11201131 | P6: =L6/M6-1 -> -0.7484746 | Q6: =H6/I6-1 -> -0.75387046 | R6: =J6/K6-1 -> -0.021452537 | S6: =Q6-R6 -> -0.73241792
A7: ANTIULCERANTS | B7: PROTON PUMP INHIBITORS | C7: RABEPRAZOLE | E7: Respite | F7: RESPITE S.Y | G7: RABEPRAZOLE | H7: 553 | I7: 807 | J7: 3188959 | K7: 3261185 | L7: =IFERROR(H7/J7,0) -> 0.00017341082 | M7: =IFERROR(I7/K7,0) -> 0.00024745606 | N7: 0.06903773 | O7: 0.079501556 | P7: =L7/M7-1 -> -0.29922581 | Q7: =H7/I7-1 -> -0.31474597 | R7: =J7/K7-1 -> -0.022147164 | S7: =Q7-R7 -> -0.29259881
A8: CEPHALOSPORINS & COMBS | B8: CEPHALOSPORINS ORAL | C8: CEFIXIME | E8: Kuracef | F8: KURACEF S.Y | G8: CEFUROXIME AXETIL+CLAVULANIC ACID | H8: 12903 | I8: 16141 | J8: 9224240 | K8: 8269465 | L8: =IFERROR(H8/J8,0) -> 0.0013988144 | M8: =IFERROR(I8/K8,0) -> 0.0019518796 | N8: 0.3848638 | O8: 0.35730893 | P8: =L8/M8-1 -> -0.28335004 | Q8: =H8/I8-1 -> -0.20060715 | R8: =J8/K8-1 -> 0.11545789 | S8: =Q8-R8 -> -0.31606504
A9: CEPHALOSPORINS & COMBS | B9: CEPHALOSPORINS ORAL | C9: CEFRADINE | E9: Sefrad | F9: SEFRAD S.Y | G9: CEFRADINE | H9: 21471 | I9: 29021 | J9: 665079 | K9: 645258 | L9: =IFERROR(H9/J9,0) -> 0.032283383 | M9: =IFERROR(I9/K9,0) -> 0.044975808 | N9: 0.027749151 | O9: 0.027880455 | P9: =L9/M9-1 -> -0.28220561 | Q9: =H9/I9-1 -> -0.26015644 | R9: =J9/K9-1 -> 0.030717945 | S9: =Q9-R9 -> -0.29087438
A10: LIPID-REGULATING PRODS | B10: STATINS (HMG-COA RED) | C10: ATORVASTATIN | E10: Orva | F10: ORVA S.Y | G10: ATORVASTATIN | H10: 14677 | I10: 18935 | J10: 4091860 | K10: 3756605 | L10: =IFERROR(H10/J10,0) -> 0.0035868774 | M10: =IFERROR(I10/K10,0) -> 0.0050404554 | N10: 0.38513353 | O10: 0.41812479 | P10: =L10/M10-1 -> -0.28838229 | Q10: =H10/I10-1 -> -0.22487457 | R10: =J10/K10-1 -> 0.089244145 | S10: =Q10-R10 -> -0.31411872
A11: DPP-IV INH & BIGUAN COMB | B11: DPP-IV INH A-DIAB PLAIN | C11: SITAGLIPTIN, METFORMIN+SITAGLIPTIN | E11: INCRIT | F11: INCRIT+M S.Y | G11: SITAGLIPTIN | H11: 5628 | I11: 5511 | J11: 2177698 | K11: 1822766 | L11: =IFERROR(H11/J11,0) -> 0.0025843804 | M11: =IFERROR(I11/K11,0) -> 0.003023427 | N11: 0.045727383 | O11: 0.048331584 | P11: =L11/M11-1 -> -0.1452149 | Q11: =H11/I11-1 -> 0.021230267 | R11: =J11/K11-1 -> 0.19472165 | S11: =Q11-R11 -> -0.17349138
A12: HUMAN INSULIN+ANALOGUES | B12: H INSUL+ANA LONG ACT | C12: INSULIN GLARGINE | D12: Lantus | E12: Lantus | F12: LANTUS S.Y | G12: INSULIN GLARGINE | H12: 302155 | I12: 304882 | J12: 1031108 | K12: 795035 | L12: =IFERROR(H12/J12,0) -> 0.29303914 | M12: =IFERROR(I12/K12,0) -> 0.38348249 | N12: 0.10617519 | O12: 0.077184807 | P12: =L12/M12-1 -> -0.23584741 | Q12: =H12/I12-1 -> -0.0089444441 | R12: =J12/K12-1 -> 0.2969341 | S12: =Q12-R12 -> -0.30587854 | T12: 1 | U12: 1 | X12: Maintained Top
A13: HUMAN INSULIN+ANALOGUES | B13: H INSUL+ANA LONG ACT | C13: INSULIN GLARGINE | D13: Toujeo | E13: Toujeo | F13: TOUJEO S.Y | G13: INSULIN GLARGINE | H13: 5747 | I13: 4571 | J13: 1031108 | K13: 795035 | L13: =IFERROR(H13/J13,0) -> 0.005573616 | M13: =IFERROR(I13/K13,0) -> 0.0057494324 | N13: 0.10617519 | O13: 0.077184807 | P13: =L13/M13-1 -> -0.030579794 | Q13: =H13/I13-1 -> 0.25727412 | R13: =J13/K13-1 -> 0.2969341 | S13: =Q13-R13 -> -0.039659978 | T13: 7 | U13: 7 | X13: Stayed Same
