Workbook

Sheet Q3_Feb Mar-26 TGT
K1: =5.5/6 -> 0.91666667 | Z1: 1.01
A2: Q3'25-26 National SKU Target Proposal | Z2: Landing Ach. | AF2: BO&S proposal | AK2: Review by Marketing
A3: Feb-Mar'26 | J3: Q1'25-26 target | N3: Sales Trend | Y3: =Y4/L4 -> 0.87864702 | Z3: =Z4/AO4 -> 0.81727057 | AB3: Q2'25-26 Budget | AK3: Q3'25-26 target Qty | AO3: Q3'25-26 target
J4: =SUBTOTAL(9,J6:J156) -> 4.2476172e+08 | K4: =SUBTOTAL(9,K6:K156) -> 4.3765924e+08 | L4: =SUBTOTAL(9,L6:L156) -> 4.3086719e+08 | N4: =SUBTOTAL(9,N6:N156) -> 3.4643831e+08 | O4: =SUBTOTAL(9,O6:O156) -> 3.0649769e+08 | P4: =SUBTOTAL(9,P6:P156) -> 3.5624875e+08 | Q4: =SUBTOTAL(9,Q6:Q156) -> 3.3397016e+08 | R4: =SUBTOTAL(9,R6:R156) -> 3.1209075e+08 | S4: =SUBTOTAL(9,S6:S156) -> 3.3058125e+08 | T4: =SUBTOTAL(9,T6:T156) -> 3.7907077e+08 | U4: =SUBTOTAL(9,U6:U156) -> 401684901 | ... Z4: =SUBTOTAL(9,Z6:Z156) -> 3.5150147e+08 | AB4: =SUBTOTAL(9,AB6:AB156) -> 4.0073121e+08 | AC4: =SUBTOTAL(9,AC6:AC156) -> 3.84224e+08 | AD4: =SUBTOTAL(9,AD6:AD156) -> 3.8999798e+08 | AF4: =SUBTOTAL(9,AF6:AF156) -> 4.1326145e+08 | AG4: =SUBTOTAL(9,AG6:AG156) -> 4.3126865e+08 | AH4: =SUBTOTAL(9,AH6:AH156) -> 3.9088161e+08 | AI4: =SUBTOTAL(9,AI6:AI156) -> 4.1763411e+08 | AK4: =SUBTOTAL(9,AK6:AK156) -> 2100333.9 | AL4: =SUBTOTAL(9,AL6:AL156) -> 1915582 | AM4: =SUBTOTAL(9,AM6:AM156) -> 2110843 | AO4: =SUBTOTAL(9,AO6:AO156) -> 4.3009192e+08 | AP4: =SUBTOTAL(9,AP6:AP156) -> 3.9640319e+08 | AQ4: =SUBTOTAL(9,AQ6:AQ156) -> 4.2196778e+08
A5: Family | B5: Product Id | C5: P Code | D5: Product Name | E5: TP | F5: Group | G5: Sales Line | H5: Product Type | J5: Oct'25 | K5: Nov'25 | L5: Dec'25 | N5: 2025, Jan_S | O5: 2025, Feb_S | P5: 2025, Mar_S | Q5: 2025, Apr_S | R5: 2025, May_S | S5: 2025, Jun_S | T5: 2025, Jul_S | U5: 2025, Aug_S | V5: 2025, Sep_S | W5: 2025, Oct_S | X5: 2025, Nov_S | Y5: 2025, Dec_S | Z5: 2026, Jan Landing | AB5: Jan'26 | AC5: Feb'26 | AD5: Mar'26 | AF5: Q3 Review | AG5: Jan'26 | AH5: Feb'26 | AI5: Mar'26 | AK5: Jan'26 | AL5: Feb'26 | AM5: Mar'26 | AO5: Jan'26 | AP5: Feb'26 | AQ5: Mar'26
A6: Avil | B6: 327131 | C6: 513 | D6: Avil 22.7mg Tab 20x15's | E6: 340.59 | F6: ACC | G6: SYNGENA | H6: Regular Brands | J6: 6055545.1 | K6: 6214064.6 | L6: 6142540.6 | N6: 4128628.1 | O6: 3596289.7 | P6: 4593192.6 | Q6: 4513497.9 | R6: 4357163.6 | S6: 5530500.4 | T6: 5746775.1 | U6: 5672179 | V6: 5373489 | W6: 5369060.8 | X6: 4566971.3 | Y6: 3799962.6 | Z6: 3686916.2 | AB6: 6011952.7 | AC6: 5677955.3 | AD6: 5343957.9 | AF6: =IFERROR(SUM(AG6:AI6)/3,0) -> 5615977.7 | AG6: 5884712.9 | AH6: 5296241.6 | AI6: 5666978.5 | AK6: 16500 | AL6: 14829 | AM6: 16034 | AO6: 5619735 | AP6: =AL6*$E6 -> 5050609.1 | AQ6: =AM6*$E6 -> 5461020.1
A7: Avil | B7: 334946 | C7: 515 | D7: Avil 75ml Syp 1 Bot | E7: 18.8 | F7: ACC | G7: SYNGENA | H7: Regular Brands | J7: 562363.81 | K7: 515383.19 | L7: 508596.4 | N7: 413276.21 | O7: 393333.57 | P7: 468759.16 | Q7: 448831.16 | R7: 420217.59 | S7: 462724.4 | T7: 454114 | U7: 470442 | V7: 418375 | W7: 484833.17 | X7: 455636.83 | Y7: 386828.86 | Z7: 329611.3 | AB7: 442466.35 | AC7: 405594.15 | AD7: 368721.96 | AF7: =IFERROR(SUM(AG7:AI7)/3,0) -> 468857.43 | AG7: 491293.16 | AH7: 442163.84 | AI7: 473115.31 | AK7: 26133 | AL7: 23251 | AM7: 23049 | AO7: 491300.4 | AP7: =AL7*$E7 -> 437118.8 | AQ7: =AM7*$E7 -> 433321.2
A8: Avil | B8: 373259 | C8: 514 | D8: Avil 2ml Inj 5x5's Amp | E8: 141.54 | F8: ACC | G8: SYNGENA | H8: Regular Brands | J8: 993786.74 | K8: 1291835.7 | L8: 1148738.6 | N8: 1077542.2 | O8: 939252.35 | P8: 965018.25 | Q8: 1048811.3 | R8: 868914.02 | S8: 1021777.3 | T8: 1163600.3 | U8: 1180305 | V8: 1312501 | W8: 1208468.6 | X8: 1026589.7 | Y8: 956385.83 | Z8: 863619.72 | AB8: 832801.69 | AC8: 763401.55 | AD8: 694001.41 | AF8: =IFERROR(SUM(AG8:AI8)/3,0) -> 1095504.9 | AG8: 1147926.9 | AH8: 1033134.2 | AI8: 1105453.6 | AK8: 8000 | AL8: 6920 | AM8: 6013 | AO8: 1132320 | AP8: =AL8*$E8 -> 979456.8 | AQ8: =AM8*$E8 -> 851080.02
A9: Monfast | B9: 4011000142 | C9: 778 | D9: Monfast 4 mg ODT 3 x 10's | E9: 157.42 | F9: ACC | G9: SYNGENA | H9: New Product | J9: 459509.04 | K9: 396383.5 | L9: 358602.76 | N9: 312950.96 | O9: 333100.72 | P9: 344907.22 | Q9: 248566.18 | R9: 198506.62 | S9: 191422.72 | T9: 224008.66 | U9: 255001 | V9: 199136 | W9: 246204.85 | X9: 341601.46 | Y9: 401263.61 | Z9: 362877.87 | AB9: 448047.17 | AC9: 371239.08 | AD9: 371239.08 | AF9: =IFERROR(SUM(AG9:AI9)/3,0) -> 434306.15 | AG9: 434306.15 | AH9: 421276.97 | AI9: 447335.34 | AK9: 2945.0915 | AL9: 2175 | AM9: 2228 | AO9: 463616.3 | AP9: =AL9*$E9 -> 342388.5 | AQ9: =AM9*$E9 -> 350731.76
A10: Monfast | B10: 4011000143 | C10: 779 | D10: Monfast 5 mg ODT 3 x 10's | E10: 202.4 | F10: ACC | G10: SYNGENA | H10: New Product | J10: 492236.79 | K10: 169813.61 | L10: 153621.6 | N10: 154633.6 | O10: 224461.6 | P10: 178112 | Q10: 149978.4 | R10: 121035.2 | S10: 106057.6 | T10: 156657.6 | U10: 193472 | V10: 137632 | W10: 153824.01 | X10: 201185.62 | Y10: 200983.17 | Z10: 194710.4 | AB10: 362100.37 | AC10: 263345.72 | AD10: 263345.72 | AF10: =IFERROR(SUM(AG10:AI10)/3,0) -> 225186.14 | AG10: 225186.14 | AH10: 218430.55 | AI10: 231941.72 | AK10: 736.27287 | AL10: 643 | AM10: 658 | AO10: 149021.63 | AP10: =AL10*$E10 -> 130143.2 | AQ10: =AM10*$E10 -> 133179.2
A11: Monfast | B11: 4011000144 | C11: 780 | D11: Monfast 10 mg Tab. 3 x 10's | E11: 393.55 | F11: ACC | G11: SYNGENA | H11: New Product | J11: 2680469.2 | K11: 3633647.1 | L11: 3287716.7 | N11: 1150740.2 | O11: 1180256.5 | P11: 1199146.9 | Q11: 1048810.8 | R11: 928384.45 | S11: 997649.25 | T11: 1110204.5 | U11: 1432152 | V11: 1195999 | W11: 1262508.5 | X11: 1331773.3 | Y11: 1528941.8 | Z11: 1517668 | AB11: 1536161.7 | AC11: 1280134.8 | AD11: 1280134.8 | AF11: =IFERROR(SUM(AG11:AI11)/3,0) -> 3254447 | AG11: 3254447 | AH11: 3156813.6 | AI11: 3352080.4 | AK11: 8099.0016 | AL11: 6525 | AM11: 6683 | AO11: 3187362.1 | AP11: =AL11*$E11 -> 2567913.8 | AQ11: =AM11*$E11 -> 2630094.6
A12: Phenergan Plus | B12: 352704 | C12: 759 | D12: Phenergan plus 100ml Syp 1 Bot | E12: 69.72 | F12: ACC | G12: SYNGENA | H12: New Product | J12: 3834597.2 | K12: 4509629.1 | L12: 4200002.5 | N12: 3150690.2 | O12: 2813019 | P12: 3130326.6 | Q12: 2299226 | R12: 1819620.1 | S12: 1735749.1 | T12: 2321536.6 | U12: 3007308 | V12: 2365669 | W12: 2570437 | X12: 3263802.4 | Y12: 3975155.6 | Z12: 3198762.3 | AB12: 4179401.6 | AC12: 3582344.3 | AD12: 2985286.9 | AF12: =IFERROR(SUM(AG12:AI12)/3,0) -> 4506002.6 | AG12: 4506002.6 | AH12: 4370822.5 | AI12: 4641182.7 | AK12: 76500 | AL12: 64259 | AM12: 65821 | AO12: 5333580 | AP12: =AL12*$E12 -> 4480137.5 | AQ12: =AM12*$E12 -> 4589040.1
A13: Telfast | B13: 330987 | C13: 674 | D13: Telfast 50ml Susp | E13: 52.47 | F13: ACC | G13: SYNGENA | H13: Regular Brands | J13: 1357025.8 | K13: 1573050.6 | L13: 1482015.1 | N13: 1029459.8 | O13: 1034445.7 | P13: 1197468.8 | Q13: 988482 | R13: 879869.25 | S13: 850276.35 | T13: 1117820.9 | U13: 1268941 | V13: 982659 | W13: 1118922.9 | X13: 1340451.2 | Y13: 1399322.5 | Z13: 1259818.2 | AB13: 1130706.1 | AC13: 1002216.7 | AD13: 1002216.7 | AF13: =IFERROR(SUM(AG13:AI13)/3,0) -> 1483398.3 | AG13: 1554381.7 | AH13: 1398943.6 | AI13: 1496869.6 | AK13: 29217.391 | AL13: 25209 | AM13: 26329 | AO13: 1533036.5 | AP13: =AL13*$E13 -> 1322716.2 | AQ13: =AM13*$E13 -> 1381482.6
A14: Telfast | B14: 346157 | C14: 671 | D14: TELFAST 120mg Tab 5 X 10s | E14: 375 | F14: ACC | G14: SYNGENA | H14: Regular Brands | J14: 5414058.2 | K14: 6423750.7 | L14: 6619875 | N14: 4221741.6 | O14: 3640124.5 | P14: 4386733.8 | Q14: 3681748.5 | R14: 3566994.9 | S14: 3771000 | T14: 4510875 | U14: 5229764 | V14: 4596751 | W14: 4807125 | X14: 5080500 | Y14: 5182875 | Z14: 4473836.5 | AB14: 4995582.7 | AC14: 4775189.3 | AD14: 4775189.3 | AF14: =IFERROR(SUM(AG14:AI14)/3,0) -> 6499606.5 | AG14: 6810625 | AH14: 6129562.5 | AI14: 6558631.9 | AK14: 19826.087 | AL14: 15817 | AM14: 16708 | AO14: 7434782.6 | AP14: =AL14*$E14 -> 5931375 | AQ14: =AM14*$E14 -> 6265500
A15: Telfast | B15: 346158 | C15: 673 | D15: TELFAST 180mg Tab 3 X 10s | E15: 292.5 | F15: ACC | G15: SYNGENA | H15: Regular Brands | J15: 2590683.3 | K15: 3006314.9 | L15: 3098160 | N15: 1957116.2 | O15: 1659059.2 | P15: 2024680.4 | Q15: 1717558.5 | R15: 1683335.6 | S15: 1729260 | T15: 2168595 | U15: 2444802 | V15: 2314262 | W15: 2380950.1 | X15: 2495610.1 | Y15: 2433015 | Z15: 2216047.1 | AB15: 2206137.5 | AC15: 2091532.9 | AD15: 2091532.9 | AF15: =IFERROR(SUM(AG15:AI15)/3,0) -> 3071529.2 | AG15: 3218507.8 | AH15: 2896657 | AI15: 3099423 | AK15: 10434.783 | AL15: 8403 | AM15: 9114 | AO15: 3052173.9 | AP15: =AL15*$E15 -> 2457877.5 | AQ15: =AM15*$E15 -> 2665845
A16: Doxovia | B16: 4011000160 | C16: 798 | D16: Doxovia 200 mg Tab 6x10's | E16: 292.2 | F16: ACC | G16: SYNGENA | H16: New Product | J16: 1314899.6 | K16: 1461000.3 | L16: 1391456.4 | N16: 0 | O16: 0 | P16: 0 | Q16: 0 | R16: 0 | S16: 0 | T16: 775206.6 | U16: 709460 | V16: 598134 | W16: 586445.44 | X16: 757382.4 | Y16: 866665.2 | Z16: 748461.86 | AB16: 800000 | AC16: 800000 | AD16: 800000 | AF16: =IFERROR(SUM(AG16:AI16)/3,0) -> 1592120 | AG16: 1592120 | AH16: 1544356.4 | AI16: 1639883.6 | AK16: 6451.3275 | AL16: 5932 | AM16: 6013 | AO16: 1885077.9 | AP16: =AL16*$E16 -> 1733330.4 | AQ16: =AM16*$E16 -> 1756998.6
A17: Doxovia | B17: 4011000161 | C17: 799 | D17: Doxovia 400 mg Tab 3x10's | E17: 225 | F17: ACC | G17: SYNGENA | H17: New Product | J17: 450000.26 | K17: 270000.18 | L17: 257175 | N17: 0 | O17: 0 | P17: 0 | Q17: 0 | R17: 0 | S17: 0 | T17: 126900 | U17: 55352 | V17: 36900 | W17: 31274.99 | X17: 40500 | Y17: 42975 | Z17: 44938.089 | AB17: 266666.67 | AC17: 266666.67 | AD17: 266666.67 | AF17: =IFERROR(SUM(AG17:AI17)/3,0) -> 246990.11 | AG17: 246990.11 | AH17: 239580.41 | AI17: 254399.82 | AK17: 368.64729 | AL17: 395 | AM17: 401 | AO17: 82945.639 | AP17: =AL17*$E17 -> 88875 | AQ17: =AM17*$E17 -> 90225
A18: Doxovia | B18: 4011000164 | C18: 800 | D18: Doxovia 100 ml Syrup | E18: 82.46 | F18: ACC | G18: SYNGENA | H18: New Product | J18: 247379.98 | K18: 371070.04 | L18: 353423.56 | N18: 0 | O18: 0 | P18: 0 | Q18: 0 | R18: 0 | S18: 0 | T18: 142325.96 | U18: 231773 | V18: 180010 | W18: 295784.03 | X18: 430523.7 | Y18: 312935.72 | Z18: 219728.08 | AB18: 266666.67 | AC18: 266666.67 | AD18: 266666.67 | AF18: =IFERROR(SUM(AG18:AI18)/3,0) -> 461006.51 | AG18: 461006.51 | AH18: 447176.31 | AI18: 474836.71 | AK18: 6451.3275 | AL18: 5932 | AM18: 6013 | AO18: 531976.47 | AP18: =AL18*$E18 -> 489152.72 | AQ18: =AM18*$E18 -> 495831.98
A19: Brodactam | B19: 325054 | C19: 523 | D19: Brodactam 4.5g Inj 1 Com | E19: 751.88 | F19: ABT | G19: SYNGENA | H19: Regular Brands | J19: 8387540.8 | K19: 8387972.9 | L19: 8387221.4 | N19: 5832333.1 | O19: 9031582.5 | P19: 9501507.5 | Q19: 6863912.6 | R19: 6148874.6 | S19: 5873686.5 | T19: 7060905 | U19: 8609780 | V19: 8341356 | W19: 7845867.8 | X19: 9341357.2 | Y19: 14745119 | Z19: 7657373.3 | AB19: 7798644.5 | AC19: 7430783.9 | AD19: 7467569.9 | AF19: 8235732.9 | AG19: 8629828.4 | AH19: 7766845.6 | AI19: 8310524.8 | AK19: 10449.291 | AL19: 10330 | AM19: 11024 | AO19: 7856612.9 | AP19: =AL19*$E19 -> 7766920.4 | AQ19: =AM19*$E19 -> 8288725.1
A20: Brodactam | B20: 4011000127 | C20: 761 | D20: BRODACTAM 2.25 gm Inj 1 Com | E20: 451.27 | F20: ABT | G20: SYNGENA | H20: Regular Brands | J20: 2155265.6 | K20: 2155265.4 | L20: 2155265.5 | N20: 2257252.5 | O20: 1909323.4 | P20: 2109687.2 | Q20: 1315000.8 | R20: 1475652.9 | S20: 1643976.6 | T20: 2274852.1 | U20: 2480182 | V20: 2531624 | W20: 2431442.8 | X20: 2430991.6 | Y20: 2592546.2 | Z20: 1832640 | AB20: 1814859.5 | AC20: 1722129.4 | AD20: 1744208 | AF20: 2203641.1 | AG20: 2309089.6 | AH20: 2078180.6 | AI20: 2223653.3 | AK20: 4749.6777 | AL20: 4605 | AM20: 5011 | AO20: 2143387.1 | AP20: =AL20*$E20 -> 2078098.3 | AQ20: =AM20*$E20 -> 2261314
A21: Carbanem | B21: 314547 | C21: 528 | D21: Carbanem 500mg Inj 1 Com | E21: 526.32 | F21: ABT | G21: SYNGENA | H21: Regular Brands | J21: 2600020.8 | K21: 2412650.7 | L21: 2412650.9 | N21: 2501599 | O21: 2488967.3 | P21: 1822119.8 | Q21: 2488441 | R21: 1590012.7 | S21: 1266325.9 | T21: 2242649.5 | U21: 2238965 | V21: 2742127 | W21: 2409493 | X21: 1970542.1 | Y21: 2076332.4 | Z21: 2331017.8 | AB21: 2465780.1 | AC21: 2260298.4 | AD21: 2301394.7 | AF21: 2280352.4 | AG21: 2389471.6 | AH21: 2150524.5 | AI21: 2301061.2 | AK21: 4297.0737 | AL21: 4297 | AM21: 4306 | AO21: 2261635.8 | AP21: =AL21*$E21 -> 2261597 | AQ21: =AM21*$E21 -> 2266333.9
A22: Carbanem | B22: 314548 | C22: 527 | D22: Carbanem 1gm Inj 1 Com | E22: 977.44 | F22: ABT | G22: SYNGENA | H22: Regular Brands | J22: 8201700 | K22: 8680644.7 | L22: 8680644.6 | N22: 8486964.9 | O22: 7294634.7 | P22: 8795005.1 | Q22: 5956519.4 | R22: 8347337.6 | S22: 5070958.7 | T22: 7135312 | U22: 9194778 | V22: 8653277 | W22: 11659882 | X22: 6549825.4 | Y22: 7525310.5 | Z22: 5150529.3 | AB22: 7785722.4 | AC22: 7126461.4 | AD22: 7269563.1 | AF22: 8306349.3 | AG22: 8703823.9 | AH22: 7833441.5 | AI22: 8381782.4 | AK22: 8428.5114 | AL22: 8429 | AM22: 8447 | AO22: 8238364.2 | AP22: =AL22*$E22 -> 8238841.8 | AQ22: =AM22*$E22 -> 8256435.7
A23: Curazith | B23: 321870 | C23: 538 | D23: Curazith 250mg Tab 1x6's | E23: 90.23 | F23: ABT | G23: SYNGENA | H23: Regular Brands | J23: 1874600.5 | K23: 1718791.3 | L23: 1714370 | N23: 724998.05 | O23: 833454.51 | P23: 1175516.4 | Q23: 1007147.3 | R23: 1044412.3 | S23: 1514059.4 | T23: 2774753 | U23: 2148015 | V23: 1272062 | W23: 1075902.5 | X23: 1273776.9 | Y23: 1048833.5 | Z23: 843991.6 | AB23: 1205344.8 | AC23: 1205344.8 | AD23: 1068373.8 | AF23: 1581283.8 | AG23: 1656951.2 | AH23: 1491256.1 | AI23: 1595644 | AK23: 18364 | AL23: 11550 | AM23: 12101 | AO23: 1656983.7 | AP23: =AL23*$E23 -> 1042156.5 | AQ23: =AM23*$E23 -> 1091873.2
A24: Curazith | B24: 321871 | C24: 540 | D24: Curazith 500mg Tab 2x6's | E24: 315.79 | F24: ABT | G24: SYNGENA | H24: Regular Brands | J24: 3643194.3 | K24: 3288637.1 | L24: 3284216 | N24: 2419583 | O24: 2483356.8 | P24: 3231794.9 | Q24: 2716425.6 | R24: 2765373 | S24: 4281480.8 | T24: 7113169.7 | U24: 6473398 | V24: 3597795 | W24: 3164847.4 | X24: 3823585.4 | Y24: 3621479.8 | Z24: 2743067.7 | AB24: 3131921.4 | AC24: 3131921.4 | AD24: 2780379.2 | AF24: 3384560.5 | AG24: 3546518.2 | AH24: 3191866.4 | AI24: 3415297 | AK24: 11231 | AL24: 11550 | AM24: 12101 | AO24: 3546637.5 | AP24: =AL24*$E24 -> 3647374.5 | AQ24: =AM24*$E24 -> 3821374.8
A25: Fimoxyclav | B25: 341324 | C25: 559 | D25: FIMOXYCLAV 100ml Sus | E25: 184.21 | F25: ABT | G25: SYNGENA | H25: Regular Brands | J25: 2749724.4 | K25: 2816570.8 | L25: 2883991.8 | N25: 1494125.3 | O25: 1832705 | P25: 2279782.6 | Q25: 1772284.1 | R25: 1605942.5 | S25: 1423206.5 | T25: 2009731.1 | U25: 2224525 | V25: 1751652 | W25: 2267809.4 | X25: 2971491.6 | Y25: 2691492.4 | Z25: 2213610.9 | AB25: 2195708.7 | AC25: 2066549.4 | AD25: 2110188.6 | AF25: 2683532.3 | AG25: 2811944.4 | AH25: 2530750 | AI25: 2707902.5 | AK25: 14700 | AL25: 14175 | AM25: 15784 | AO25: 2707887 | AP25: =AL25*$E25 -> 2611176.8 | AQ25: =AM25*$E25 -> 2907570.6
A26: Fimoxyclav | B26: 341325 | C26: 563 | D26: Fimoxyclav 375mg Tab 5x6's | E26: 563.91 | F26: ABT | G26: SYNGENA | H26: Regular Brands | J26: 2061801.2 | K26: 2172180.9 | L26: 2287219 | N26: 1596417.6 | O26: 1708647.1 | P26: 1800564.5 | Q26: 1525376.4 | R26: 1530451.2 | S26: 1555263.8 | T26: 2327820.5 | U26: 2533094 | V26: 2020490 | W26: 2100000.9 | X26: 2242106.3 | Y26: 2125940.7 | Z26: 1729760.5 | AB26: 1967730 | AC26: 1858411.6 | AD26: 1886229.3 | AF26: 2282439.5 | AG26: 2391658.6 | AH26: 2152492.7 | AI26: 2303167.2 | AK26: 4084 | AL26: 3990 | AM26: 4419 | AO26: 2303008.4 | AP26: =AL26*$E26 -> 2250000.9 | AQ26: =AM26*$E26 -> 2491918.3
A27: Fimoxyclav | B27: 341326 | C27: 565 | D27: FIMOXYCLAV 625mg Tab 5x6's | E27: 721.8 | F27: ABT | G27: SYNGENA | H27: Regular Brands | J27: 15766016 | K27: 16093254 | L27: 16421672 | N27: 13414615 | O27: 13248529 | P27: 13422548 | Q27: 13456515 | R27: 11347416 | S27: 11114998 | T27: 16063659 | U27: 18563972 | V27: 14849594 | W27: 15525196 | X27: 16818662 | Y27: 16919714 | Z27: 14377696 | AB27: 15486891 | AC27: 14578774 | AD27: 14867706 | AF27: 16454006 | AG27: 17241361 | AH27: 15517225 | AI27: 16603431 | AK27: 23400 | AL27: 24150 | AM27: 25780 | AO27: 16890120 | AP27: =AL27*$E27 -> 17431470 | AQ27: =AM27*$E27 -> 18608004
A28: Fimoxyclav | B28: 341327 | C28: 561 | D28: FIMOXYCLAV 1g Tab 4x6's | E28: 812.03 | F28: ABT | G28: SYNGENA | H28: Regular Brands | J28: 2766597.3 | K28: 2786887 | L28: 2805563.6 | N28: 2138869.6 | O28: 2103968.8 | P28: 3517696.2 | Q28: 2443397.5 | R28: 2162434.8 | S28: 2033323.1 | T28: 2814496 | U28: 3176623 | V28: 2559518 | W28: 2698375.8 | X28: 2675639 | Y28: 2648029.9 | Z28: 2363810.9 | AB28: 2649923.6 | AC28: 2491719.2 | AD28: 2323961.1 | AF28: 2815593.8 | AG28: 2950325.3 | AH28: 2655292.8 | AI28: 2841163.3 | AK28: 3499 | AL28: 3360 | AM28: 3472 | AO28: 2841293 | AP28: =AL28*$E28 -> 2728420.8 | AQ28: =AM28*$E28 -> 2819368.2
A29: Fimoxyclav | B29: 341328 | C29: 567 | D29: FIMOXYCLAV-BID 50ml Sus | E29: 184.21 | F29: ABT | G29: SYNGENA | H29: Regular Brands | J29: 521498.6 | K29: 513761.68 | L29: 506209.08 | N29: 252367.59 | O29: 335630.51 | P29: 435656.56 | Q29: 342998.91 | R29: 278709.58 | S29: 305972.81 | T29: 443209.26 | U29: 491827 | V29: 405630 | W29: 509709.11 | X29: 642892.99 | Y29: 580261.54 | Z29: 429231.94 | AB29: 407852.22 | AC29: 390119.52 | AD29: 390316.37 | AF29: 503525.62 | AG29: 527620.28 | AH29: 474858.25 | AI29: 508098.33 | AK29: 2758 | AL29: 3255 | AM29: 3472 | AO29: 508051.18 | AP29: =AL29*$E29 -> 599603.55 | AQ29: =AM29*$E29 -> 639577.12
A30: Fimoxyclav | B30: 372932 | C30: 556 | D30: Fimoxyclav 0.6gm Inj 1 Com | E30: 112.78 | F30: ABT | G30: SYNGENA | H30: Regular Brands | J30: 831075.77 | K30: 932126.72 | L30: 1045470.6 | N30: 436120.26 | O30: 590064.96 | P30: 557133.2 | Q30: 626154.56 | R30: 511682.86 | S30: 267739.72 | T30: 549013.04 | U30: 653222 | V30: 512247 | W30: 830286.4 | X30: 585328.16 | Y30: 548223.62 | Z30: 505310.16 | AB30: 655618.49 | AC30: 622837.56 | AD30: 636956.43 | AF30: 906169.33 | AG30: 949531.26 | AH30: 854578.13 | AI30: 914398.6 | AK30: 8108 | AL30: 5040 | AM30: 5366 | AO30: 914420.24 | AP30: =AL30*$E30 -> 568411.2 | AQ30: =AM30*$E30 -> 605177.48
... A52: Sefurox | B52: 315048 | C52: 662 | D52: Sefurox 500mg Tab 3x4's | E52: 407.55 | F52: ABT | G52: SYNGENA | H52: Regular Brands | J52: 0 | K52: 0 | L52: 0 | N52: 9373.65 | O52: 17524.65 | P52: 0 | Q52: 0 | R52: 0 | S52: 0 | T52: 0 | U52: 0 | V52: 0 | W52: 0 | X52: 0 | Y52: 0 | Z52: 1356.631 | AB52: 0 | AC52: 0 | AD52: 0 | AF52: 0 | AG52: 0 | AH52: 0 | AI52: 0 | AK52: 0 | AL52: 0 | AM52: 0 | AO52: 0 | AP52: =AL52*$E52 -> 0 | AQ52: =AM52*$E52 -> 0
A53: Sefurox | B53: 320277 | D53: Sefurox 250mg Tab 5x4's | E53: 0 | F53: ABT | G53: SYNGENA | H53: Regular Brands | J53: 0 | K53: 0 | L53: 0 | N53: 0 | O53: 0 | P53: 0 | Q53: 0 | R53: 754.58 | S53: 0 | T53: 0 | U53: 0 | V53: 0 | W53: 0 | X53: 0 | Y53: 0 | Z53: 0 | AB53: 0 | AC53: 0 | AD53: 0 | AF53: 0 | AG53: 0 | AH53: 0 | AI53: 0 | AK53: 0 | AL53: 0 | AM53: 0 | AO53: 0 | AP53: =AL53*$E53 -> 0 | AQ53: =AM53*$E53 -> 0
A54: Targocid | B54: 348132 | C54: 729 | D54: TARGOCID 400mg Inj 1 Vial | E54: 1404.59 | F54: ABT | G54: SYNGENA | H54: Regular Brands | J54: 1320314.6 | K54: 1453750.7 | L54: 1410208.4 | N54: 1014114 | O54: 1147549.9 | P54: 1139122.5 | Q54: 1348406.5 | R54: 1094175.6 | S54: 859609.1 | T54: 1411612.9 | U54: 1540839 | V54: 1384925 | W54: 1585782.1 | X54: 1832990 | Y54: 1179855.6 | Z54: 56106.32 | AB54: 1250085.1 | AC54: 1165809.7 | AD54: 1221993.3 | AF54: 1350079.1 | AG54: 1414683 | AH54: 1273214.7 | AI54: 1362339.7 | AK54: 600 | AL54: 630 | AM54: 631 | AO54: 842754 | AP54: =AL54*$E54 -> 884891.7 | AQ54: =AM54*$E54 -> 886296.29
A55: Targocid | B55: 348296 | C55: 726 | D55: TARGOCID 200mg Inj 1 Vial | E55: 962.9 | F55: ABT | G55: SYNGENA | H55: Regular Brands | J55: 694250.64 | K55: 645143.42 | L55: 625885 | N55: 364939.1 | O55: 363976.1 | P55: 341829.5 | Q55: 414047 | R55: 451600.1 | S55: 232058.9 | T55: 469895.2 | U55: 563302 | V55: 502634 | W55: 1040895 | X55: 884905.12 | Y55: 490116.1 | Z55: 631434.4 | AB55: 500708 | AC55: 462192 | AD55: 491079 | AF55: 593032.62 | AG55: 621410.36 | AH55: 559269.33 | AI55: 598418.18 | AK55: 600 | AL55: 525 | AM55: 526 | AO55: 577740 | AP55: =AL55*$E55 -> 505522.5 | AQ55: =AM55*$E55 -> 506485.4
A56: Farpem | B56: 4011000149 | C56: 786 | D56: Farpem 150 mg Tab 3 x 4's | E56: 674.64 | F56: ABT | G56: SYNGENA | H56: New Product | J56: 1304753.8 | K56: 1551671.8 | L56: 1436308.6 | N56: 404109.36 | O56: 412879.68 | P56: 393989.76 | Q56: 330573.6 | R56: 363630.96 | S56: 362281.68 | T56: 487090.08 | U56: 714467 | V56: 626066 | W56: 557927.27 | X56: 563324.4 | Y56: 741429.44 | Z56: 503038.16 | AB56: 1008704.1 | AC56: 904355.38 | AD56: 1008704.1 | AF56: 1334236.3 | AG56: 1334236.3 | AH56: 1294209.2 | AI56: 1374263.4 | AK56: 1900 | AL56: 1000 | AM56: 1102 | AO56: 1281816 | AP56: =AL56*$E56 -> 674640 | AQ56: =AM56*$E56 -> 743453.28
A57: Farpem | B57: 4011000150 | C57: 787 | D57: Farpem 200 mg Tab 3 x 4's | E57: 854.52 | F57: ABT | G57: SYNGENA | H57: New Product | J57: 2203806.4 | K57: 2649012.3 | L57: 2414019 | N57: 747705 | O57: 888700.8 | P57: 857938.08 | Q57: 852810.96 | R57: 1045077.8 | S57: 1120275.7 | T57: 1593679.8 | U57: 1891098 | V57: 2001287 | W57: 1972232.1 | X57: 1916688.3 | Y57: 3118143.5 | Z57: 1922869.2 | AB57: 1938512.5 | AC57: 1894455.4 | AD57: 2088306.6 | AF57: 2671601.1 | AG57: 2671601.1 | AH57: 2591453.1 | AI57: 2751749.2 | AK57: 3000 | AL57: 2750 | AM57: 2806 | AO57: 2563560 | AP57: =AL57*$E57 -> 2349930 | AQ57: =AM57*$E57 -> 2397783.1
A58: Enterogermina | B58: 4021000009 | C58: 755 | D58: ENTEROGERMINA 5ml Sus 1X10 Bot | E58: 541.06 | F58: GST | G58: SYNGENA | H58: Regular Brands | J58: 39497161 | K58: 40112024 | L58: 48013123 | N58: 49777514 | O58: 38334066 | P58: 44151033 | Q58: 43840465 | R58: 40166128 | S58: 39868547 | T58: 38422294 | U58: 32850452 | V58: 28927232 | W58: 32339156 | X58: 35144011 | Y58: 49736940 | Z58: 55831713 | AB58: 50000000 | AC58: 44622596 | AD58: 44500000 | AF58: 48017320 | AG58: 51013608 | AH58: 45912247 | AI58: 47126104 | AK58: 94285 | AL58: 91673 | AM58: 98200 | AO58: 52013842 | AP58: =AL58*$E58 -> 49600593 | AQ58: =AM58*$E58 -> 53132092
A59: Gavisyn | B59: 4011000129 | C59: 765 | D59: Gavisyn Suspension 200 ml | E59: 224.89 | F59: GST | G59: SYNGENA | H59: New Product | J59: 3000707.6 | K59: 3215927 | L59: 2541481.9 | N59: 1453907.1 | O59: 1510136.3 | P59: 1750089.5 | Q59: 1476402.9 | R59: 1491468.2 | S59: 1451440.1 | T59: 1795072 | U59: 1949798 | V59: 1815987 | W59: 1780904 | X59: 1435472.9 | Y59: 1309534.5 | Z59: 1321656.8 | AB59: 2127109.9 | AC59: 2127109.9 | AD59: 2127109.9 | AF59: 2617726.3 | AG59: 2617726.3 | AH59: 2539194.6 | AI59: 2696258.1 | AK59: 11640 | AL59: 8400 | AM59: 10522 | AO59: 2617719.6 | AP59: =AL59*$E59 -> 1889076 | AQ59: =AM59*$E59 -> 2366292.6
A60: Respite | B60: 321874 | C60: 638 | D60: Respite 20mg Tab | E60: 225.56 | F60: GST | G60: SYNGENA | H60: Regular Brands | J60: 320523.72 | K60: 320746.22 | L60: 320520.76 | N60: 297062.52 | O60: 238868.04 | P60: 311498.36 | Q60: 239770.28 | R60: 256461.72 | S60: 275859.88 | T60: 297739.2 | U60: 213630 | V60: 71729 | W60: 12631.36 | X60: 92254.05 | Y60: 198041.67 | Z60: 195591.79 | AB60: 189470.4 | AC60: 219921 | AD60: 225560 | AF60: 255433.74 | AG60: 267656.73 | AH60: 240891.06 | AI60: 257753.44 | AK60: 1187 | AL60: 945 | AM60: 947 | AO60: 267739.72 | AP60: =AL60*$E60 -> 213154.2 | AQ60: =AM60*$E60 -> 213605.32
A61: Sandom | B61: 337862 | C61: 645 | D61: Sandom 10mg Tab 10x10s | E61: 151.13 | F61: GST | G61: SYNGENA | H61: Regular Brands | J61: 2534258.1 | K61: 2537926.1 | L61: 2534299 | N61: 1554219.4 | O61: 1598198 | P61: 1869326.9 | Q61: 1846355 | R61: 1754921.4 | S61: 1942927.3 | T61: 2210880.8 | U61: 2172646 | V61: 1951694 | W61: 2020759.2 | X61: 1823081.2 | Y61: 1653966.8 | Z61: 1583675.6 | AB61: 2300198.6 | AC61: 2399944.4 | AD61: 2399944.4 | AF61: 2255422.1 | AG61: 2363348.3 | AH61: 2127013.5 | AI61: 2275904.4 | AK61: 15638 | AL61: 14280 | AM61: 16310 | AO61: 2363370.9 | AP61: =AL61*$E61 -> 2158136.4 | AQ61: =AM61*$E61 -> 2464930.3
...

Sheet Adjustment Summary
C1: Previously Set target | E1: Adjusted Target
B2: Sales Line | C2: Feb'26 | D2: Mar'26 | E2: Feb'26 | F2: Mar'26
B3: INSYN | C3: 56090487 | D3: 59987398 | E3: =SUMIFS('Q3_Feb Mar-26 TGT'!AP:AP,'Q3_Feb Mar-26 TGT'!$G:$G,'Adjustment Summary'!$B3) -> 56090487 | F3: =SUMIFS('Q3_Feb Mar-26 TGT'!AQ:AQ,'Q3_Feb Mar-26 TGT'!$G:$G,'Adjustment Summary'!$B3) -> 58170620
B4: SYNGENA | C4: 2.7041873e+08 | D4: 2.8696003e+08 | E4: =SUMIFS('Q3_Feb Mar-26 TGT'!AP:AP,'Q3_Feb Mar-26 TGT'!$G:$G,'Adjustment Summary'!$B4) -> 2.6155699e+08 | F4: =SUMIFS('Q3_Feb Mar-26 TGT'!AQ:AQ,'Q3_Feb Mar-26 TGT'!$G:$G,'Adjustment Summary'!$B4) -> 2.8166775e+08
B5: SYNKEI | C5: 28471421 | D5: 29680283 | E5: =SUMIFS('Q3_Feb Mar-26 TGT'!AP:AP,'Q3_Feb Mar-26 TGT'!$G:$G,'Adjustment Summary'!$B5) -> 27606119 | F5: =SUMIFS('Q3_Feb Mar-26 TGT'!AQ:AQ,'Q3_Feb Mar-26 TGT'!$G:$G,'Adjustment Summary'!$B5) -> 28562219
B6: SYNTARA | C6: 51479057 | D6: 53396234 | E6: =SUMIFS('Q3_Feb Mar-26 TGT'!AP:AP,'Q3_Feb Mar-26 TGT'!$G:$G,'Adjustment Summary'!$B6) -> 51149585 | F6: =SUMIFS('Q3_Feb Mar-26 TGT'!AQ:AQ,'Q3_Feb Mar-26 TGT'!$G:$G,'Adjustment Summary'!$B6) -> 53567195
B7: Foundation | C7: =SUM(C3:C6) -> 4.064597e+08 | D7: =SUM(D3:D6) -> 4.3002394e+08 | E7: =SUM(E3:E6) -> 3.9640319e+08 | F7: =SUM(F3:F6) -> 4.2196778e+08
D9: Adjustment | E9: =E7-C7 -> -10056513 | F9: =F7-D7 -> -8056159
